Workbook
Name Actual_month: General!$B$3

Sheet Distribution Dashboard
A1: NAIVAWASS DISTRIBUTION DASHBOARD - NON-REVENUE WATER & ZONAL PERFORMANCE
B2: =INDEX('KPI 100'!E$18:P$18,Actual_month) -> 46054
D3: Monthly | J3: Cumulative | R3: 0.9
C4: Unit | G4: Target | H4: Actual | I4: % real. | M4: Target | N4: Actual | O4: % real.
A5: GLOBAL PERFORMNCE
B6: REGIONAL NRW | Q6: month | R6: cum
A7: 100 | B7: WATER AVAILABLE FOR SALES- REGIONS | C7: m3 | D7: l | E7: l | F7: l | G7: =IFERROR(INDEX('KPI 100'!E$19:P$19,Actual_month),0) -> 230597.54 | H7: =IFERROR(INDEX('KPI 100'!E$20:P$20,Actual_month),0) -> 222543 | I7: =IFERROR(H7/G7,"") -> 0.96507099 | J7: l | K7: l | L7: l | M7: =IFERROR(INDEX('KPI 100'!E$26:P$26,Actual_month),0) -> 1776711.4 | N7: =IFERROR(INDEX('KPI 100'!E$27:P$27,Actual_month),0) -> 1717654 | O7: =IFERROR(N7/M7,"") -> 0.96676025 | P7: details | Q7: =G7*$R$3 -> 207537.79 | R7: =M7*$R$3 -> 1599040.3 | S7: H | U7: V
A8: 128a | B8: VOLUME WATER BILLED(CUSTOMERS-M3) | C8: m3 | D8: l | E8: l | F8: l | G8: =IFERROR(INDEX('KPI 128a'!E$19:P$19,Actual_month),0) -> 183888.91 | H8: =IFERROR(INDEX('KPI 128a'!E$20:P$20,Actual_month),0) -> 172266 | I8: =IFERROR(H8/G8,"") -> 0.93679384 | J8: l | K8: l | L8: l | M8: =IFERROR(INDEX('KPI 128a'!E$26:P$26,Actual_month),0) -> 1382493.7 | N8: =IFERROR(INDEX('KPI 128a'!E$27:P$27,Actual_month),0) -> 1275843 | O8: =IFERROR(N8/M8,"") -> 0.92285629 | P8: details | Q8: =G8*$R$3 -> 165500.02 | R8: =M8*$R$3 -> 1244244.3 | S8: H | U8: V
A9: 128 | B9: GLOBAL NRW | C9: % | D9: l | E9: l | F9: l | G9: =IFERROR(INDEX('KPI 128'!E$19:P$19,Actual_month),0) -> 0.20255476 | H9: =IFERROR(INDEX('KPI 128'!E$20:P$20,Actual_month),0) -> 0.22592038 | I9: =IFERROR(G9/H9,"") -> 0.89657587 | J9: l | K9: l | L9: l | M9: =IFERROR(INDEX('KPI 128'!E$26:P$26,Actual_month),0) -> 0.22188057 | N9: =IFERROR(INDEX('KPI 128'!E$27:P$27,Actual_month),0) -> 0.25721769 | O9: =IFERROR(M9/N9,"") -> 0.86261784 | P9: details | Q9: =G9/$R$3 -> 0.22506085 | R9: =M9/$R$3 -> 0.24653397 | S9: L | U9: V
B10: Number of Active water Connections | C10: NO. | D10: l | E10: l | F10: l | G10: =IFERROR(INDEX(#REF!,Actual_month),0) -> 0 | H10: =IFERROR(INDEX(#REF!,Actual_month),0) -> 0 | I10: =IFERROR(H10/G10,"") | J10: l | K10: l | L10: l | M10: =IFERROR(INDEX(#REF!,Actual_month),0) -> 0 | N10: =IFERROR(INDEX(#REF!,Actual_month),0) -> 0 | O10: =IFERROR(N10/M10,"") | P10: details | Q10: =G10*$R$3 -> 0 | R10: =M10*$R$3 -> 0 | S10: H | U10: V
B11: Number of Active sewer Connections | C11: NO. | D11: l | E11: l | F11: l | G11: =IFERROR(INDEX(#REF!,Actual_month),0) -> 0 | H11: =IFERROR(INDEX(#REF!,Actual_month),0) -> 0 | I11: =IFERROR(H11/G11,"") | J11: l | K11: l | L11: l | M11: =IFERROR(INDEX(#REF!,Actual_month),0) -> 0 | N11: =IFERROR(INDEX(#REF!,Actual_month),0) -> 0 | O11: =IFERROR(N11/M11,"") | P11: details | Q11: =G11*$R$3 -> 0 | R11: =M11*$R$3 -> 0 | S11: H | U11: V
B12: Number of In-active Sewer Connections | C12: NO. | D12: l | E12: l | F12: l | G12: =IFERROR(INDEX(#REF!,Actual_month),0) -> 0 | H12: =IFERROR(INDEX(#REF!,Actual_month),0) -> 0 | I12: =IFERROR(H12/G12,"") | J12: l | K12: l | L12: l | M12: =IFERROR(INDEX(#REF!,Actual_month),0) -> 0 | N12: =IFERROR(INDEX(#REF!,Actual_month),0) -> 0 | O12: =IFERROR(N12/M12,"") | P12: details | Q12: =G12/$R$3 -> 0 | R12: =M12/$R$3 -> 0 | S12: L | U12: V
B13: Number of In-active Water Connections | C13: NO. | D13: l | E13: l | F13: l | G13: =IFERROR(INDEX(#REF!,Actual_month),0) -> 0 | H13: =IFERROR(INDEX(#REF!,Actual_month),0) -> 0 | I13: =IFERROR(H13/G13,"") | J13: l | K13: l | L13: l | M13: =IFERROR(INDEX(#REF!,Actual_month),0) -> 0 | N13: =IFERROR(INDEX(#REF!,Actual_month),0) -> 0 | O13: =IFERROR(N13/M13,"") | P13: details | Q13: =G13/$R$3 -> 0 | R13: =M13/$R$3 -> 0 | S13: L | U13: V
B14: Number of Connections | C14: NO. | D14: l | E14: l | F14: l | G14: =IFERROR(INDEX(#REF!,Actual_month),0) -> 0 | H14: =IFERROR(INDEX(#REF!,Actual_month),0) -> 0 | I14: =IFERROR(H14/G14,"") | J14: l | K14: l | L14: l | M14: =IFERROR(INDEX(#REF!,Actual_month),0) -> 0 | N14: =IFERROR(INDEX(#REF!,Actual_month),0) -> 0 | O14: =IFERROR(N14/M14,"") | P14: details | Q14: =G14*$R$3 -> 0 | R14: =M14*$R$3 -> 0 | S14: H | U14: V
B15: Maintenance, repair and operational cost | C15: KES | D15: l | E15: l | F15: l | G15: =IFERROR(INDEX(#REF!,Actual_month),0) -> 0 | H15: =IFERROR(INDEX(#REF!,Actual_month),0) -> 0 | I15: =IFERROR(G15/H15,"") | J15: l | K15: l | L15: l | M15: =IFERROR(INDEX(#REF!,Actual_month),0) -> 0 | N15: =IFERROR(INDEX(#REF!,Actual_month),0) -> 0 | O15: =IFERROR(M15/N15,"") | P15: details | Q15: =G15/$R$3 -> 0 | R15: =M15/$R$3 -> 0 | S15: L | U15: V
B16: CENTRAL REGION: CBD,CCCR,KABATI,SITE,KIHOTO,LAKEVIEW | Q16: month | R16: cum
A17: RA | B17: Volume Water Supplied | C17: m3 | D17: l | E17: l | F17: l | G17: =IFERROR(INDEX('KPI RA'!E$19:P$19,Actual_month),0) -> 103813.31 | H17: =IFERROR(INDEX('KPI RA'!E$20:P$20,Actual_month),0) -> 101836 | I17: =IFERROR(H17/G17,"") -> 0.98095318 | J17: l | K17: l | L17: l | M17: =IFERROR(INDEX('KPI RA'!E$26:P$26,Actual_month),0) -> 836353.87 | N17: =IFERROR(INDEX('KPI RA'!E$27:P$27,Actual_month),0) -> 820288 | O17: =IFERROR(N17/M17,"") -> 0.98079058 | P17: details | Q17: =G17*$R$3 -> 93431.982 | R17: =M17*$R$3 -> 752718.48 | S17: H | U17: V
A18: RA2 | B18: Volume Water Sold | C18: m3 | D18: l | E18: l | F18: l | G18: =IFERROR(INDEX('KPI RA2'!E$19:P$19,Actual_month),0) -> 87853.153 | H18: =IFERROR(INDEX('KPI RA2'!E$20:P$20,Actual_month),0) -> 83599 | I18: =IFERROR(H18/G18,"") -> 0.95157655 | J18: l | K18: l | L18: l | M18: =IFERROR(INDEX('KPI RA2'!E$26:P$26,Actual_month),0) -> 689333.08 | N18: =IFERROR(INDEX('KPI RA2'!E$27:P$27,Actual_month),0) -> 647518 | O18: =IFERROR(N18/M18,"") -> 0.9393398 | P18: details | Q18: =G18*$R$3 -> 79067.838 | R18: =M18*$R$3 -> 620399.77 | S18: H | U18: V
A19: RA3 | B19: NRW | C19: m3 | D19: l | E19: l | F19: l | G19: =IFERROR(INDEX('KPI RA3'!E$19:P$19,Actual_month),0) -> 15960.161 | H19: =IFERROR(INDEX('KPI RA3'!E$20:P$20,Actual_month),0) -> 18237 | I19: =IFERROR(G19/H19,"") -> 0.87515274 | J19: l | K19: l | L19: l | M19: =IFERROR(INDEX('KPI RA3'!E$26:P$26,Actual_month),0) -> 147020.79 | N19: =IFERROR(INDEX('KPI RA3'!E$27:P$27,Actual_month),0) -> 172770 | O19: =IFERROR(M19/N19,"") -> 0.8509625 | P19: details | Q19: =G19/$R$3 -> 17733.512 | R19: =M19/$R$3 -> 163356.43 | S19: L | U19: V
A20: RA4 | B20: NRW | C20: % | D20: l | E20: l | F20: l | G20: =IFERROR(INDEX('KPI RA4'!E$19:P$19,Actual_month),0) -> 0.15373905 | H20: =IFERROR(INDEX('KPI RA4'!E$20:P$20,Actual_month),0) -> 0.17908205 | I20: =IFERROR(G20/H20,"") -> 0.85848386 | J20: l | K20: l | L20: l | M20: =IFERROR(INDEX('KPI RA4'!E$26:P$26,Actual_month),0) -> 0.17578778 | N20: =IFERROR(INDEX('KPI RA4'!E$27:P$27,Actual_month),0) -> 0.21062115 | O20: =IFERROR(M20/N20,"") -> 0.834616 | P20: details | Q20: =G20/$R$3 -> 0.17082117 | R20: =M20/$R$3 -> 0.19531976 | S20: L | U20: V
B21: Amount Billed Water | C21: KES | D21: l | E21: l | F21: l | G21: =IFERROR(INDEX(#REF!,Actual_month),0) -> 0 | H21: =IFERROR(INDEX(#REF!,Actual_month),0) -> 0 | I21: =IFERROR(H21/G21,"") | J21: l | K21: l | L21: l | M21: =IFERROR(INDEX(#REF!,Actual_month),0) -> 0 | N21: =IFERROR(INDEX(#REF!,Actual_month),0) -> 0 | O21: =IFERROR(N21/M21,"") | P21: details | Q21: =G21*$R$3 -> 0 | R21: =M21*$R$3 -> 0 | S21: H | U21: V
B22: Amount Billed Sewer | C22: KES | D22: l | E22: l | F22: l | G22: =IFERROR(INDEX(#REF!,Actual_month),0) -> 0 | H22: =IFERROR(INDEX(#REF!,Actual_month),0) -> 0 | I22: =IFERROR(H22/G22,"") | J22: l | K22: l | L22: l | M22: =IFERROR(INDEX(#REF!,Actual_month),0) -> 0 | N22: =IFERROR(INDEX(#REF!,Actual_month),0) -> 0 | O22: =IFERROR(N22/M22,"") | P22: details | Q22: =G22*$R$3 -> 0 | R22: =M22*$R$3 -> 0 | S22: H | U22: V
B23: Number of Active water Connections | C23: KES | D23: l | E23: l | F23: l | G23: =IFERROR(INDEX(#REF!,Actual_month),0) -> 0 | H23: =IFERROR(INDEX(#REF!,Actual_month),0) -> 0 | I23: =IFERROR(H23/G23,"") | J23: l | K23: l | L23: l | M23: =IFERROR(INDEX(#REF!,Actual_month),0) -> 0 | N23: =IFERROR(INDEX(#REF!,Actual_month),0) -> 0 | O23: =IFERROR(N23/M23,"") | P23: details | Q23: =G23*$R$3 -> 0 | R23: =M23*$R$3 -> 0 | S23: H | U23: V
B24: Number of Active sewer Connections | C24: KES | D24: l | E24: l | F24: l | G24: =IFERROR(INDEX(#REF!,Actual_month),0) -> 0 | H24: =IFERROR(INDEX(#REF!,Actual_month),0) -> 0 | I24: =IFERROR(H24/G24,"") | J24: l | K24: l | L24: l | M24: =IFERROR(INDEX(#REF!,Actual_month),0) -> 0 | N24: =IFERROR(INDEX(#REF!,Actual_month),0) -> 0 | O24: =IFERROR(N24/M24,"") | P24: details | Q24: =G24*$R$3 -> 0 | R24: =M24*$R$3 -> 0 | S24: H | U24: V
B25: SOUTHERN REGION: MAI MAHIU,KAMERE,HELLSGATE | Q25: month | R25: cum
A26: RA6 (B) | B26: Volume Water Supplied | C26: m3 | D26: l | E26: l | F26: l | G26: =IFERROR(INDEX('KPI RA6 (B)'!E$19:P$19,Actual_month),0) -> 89353.394 | H26: =IFERROR(INDEX('KPI RA6 (B)'!E$20:P$20,Actual_month),0) -> 77635 | I26: =IFERROR(H26/G26,"") -> 0.86885339 | J26: l | K26: l | L26: l | M26: =IFERROR(INDEX('KPI RA6 (B)'!E$26:P$26,Actual_month),0) -> 649012.41 | N26: =IFERROR(INDEX('KPI RA6 (B)'!E$27:P$27,Actual_month),0) -> 576686 | O26: =IFERROR(N26/M26,"") -> 0.88855928 | P26: details | Q26: =G26*$R$3 -> 80418.055 | R26: =M26*$R$3 -> 584111.17 | S26: H | U26: V
A27: RB2 | B27: Volume Water Sold | C27: m3 | D27: l | E27: l | F27: l | G27: =IFERROR(INDEX('KPI RB2'!E$19:P$19,Actual_month),0) -> 64564.498 | H27: =IFERROR(INDEX('KPI RB2'!E$20:P$20,Actual_month),0) -> 55022 | I27: =IFERROR(H27/G27,"") -> 0.85220208 | J27: l | K27: l | L27: l | M27: =IFERROR(INDEX('KPI RB2'!E$26:P$26,Actual_month),0) -> 452009.1 | N27: =IFERROR(INDEX('KPI RB2'!E$27:P$27,Actual_month),0) -> 395248 | O27: =IFERROR(N27/M27,"") -> 0.87442488 | P27: details | Q27: =G27*$R$3 -> 58108.049 | R27: =M27*$R$3 -> 406808.19 | S27: H | U27: V
A28: RB3 (2) | B28: NRW | C28: m3 | D28: l | E28: l | F28: l | G28: =IFERROR(INDEX('KPI RB3 (2)'!E$19:P$19,Actual_month),0) -> 24788.896 | H28: =IFERROR(INDEX('KPI RB3 (2)'!E$20:P$20,Actual_month),0) -> 22613 | I28: =IFERROR(G28/H28,"") -> 1.0962232 | J28: l | K28: l | L28: l | M28: =IFERROR(INDEX('KPI RB3 (2)'!E$26:P$26,Actual_month),0) -> 197003.31 | N28: =IFERROR(INDEX('KPI RB3 (2)'!E$27:P$27,Actual_month),0) -> 181438 | O28: =IFERROR(M28/N28,"") -> 1.0857886 | P28: details | Q28: =G28/$R$3 -> 27543.218 | R28: =M28/$R$3 -> 218892.57 | S28: L | U28: V
A29: RB4 | B29: NRW | C29: % | D29: l | E29: l | F29: l | G29: =IFERROR(INDEX('KPI RB4'!E$19:P$19,Actual_month),0) -> 0.27742534 | H29: =IFERROR(INDEX('KPI RB4'!E$20:P$20,Actual_month),0) -> 0.29127327 | I29: =IFERROR(G29/H29,"") -> 0.95245728 | J29: l | K29: l | L29: l | M29: =IFERROR(INDEX('KPI RB4'!E$26:P$26,Actual_month),0) -> 0.3046841 | N29: =IFERROR(INDEX('KPI RB4'!E$27:P$27,Actual_month),0) -> 0.31392199 | O29: =IFERROR(M29/N29,"") -> 0.97057265 | P29: details | Q29: =G29/$R$3 -> 0.30825038 | R29: =M29/$R$3 -> 0.33853789 | S29: L | U29: V
B30: EASTERN REGION: KAYOLE,GONDI, KINUNGI,NJONJORO | Q30: month | R30: cum
A31: RA6 (B) (2) | B31: Volume Water Supplied | C31: m3 | D31: l | E31: l | F31: l | G31: =IFERROR(INDEX('KPI RA6 (B) (2)'!E$19:P$19,Actual_month),0) -> 37430.836 | H31: =IFERROR(INDEX('KPI RA6 (B) (2)'!E$20:P$20,Actual_month),0) -> 43072 | I31: =IFERROR(H31/G31,"") -> 1.150709 | J31: l | K31: l | L31: l | M31: =IFERROR(INDEX('KPI RA6 (B) (2)'!E$26:P$26,Actual_month),0) -> 291345.17 | N31: =IFERROR(INDEX('KPI RA6 (B) (2)'!E$27:P$27,Actual_month),0) -> 320680 | O31: =IFERROR(N31/M31,"") -> 1.1006876 | P31: details | Q31: =G31*$R$3 -> 33687.752 | R31: =M31*$R$3 -> 262210.65 | S31: H | U31: V
A32: RB2 (3) | B32: Volume Water Sold | C32: m3 | D32: l | E32: l | F32: l | G32: =IFERROR(INDEX('KPI RB2 (3)'!E$19:P$19,Actual_month),0) -> 31471.261 | H32: =IFERROR(INDEX('KPI RB2 (3)'!E$20:P$20,Actual_month),0) -> 33645 | I32: =IFERROR(H32/G32,"") -> 1.0690706 | J32: l | K32: l | L32: l | M32: =IFERROR(INDEX('KPI RB2 (3)'!E$26:P$26,Actual_month),0) -> 241151.52 | N32: =IFERROR(INDEX('KPI RB2 (3)'!E$27:P$27,Actual_month),0) -> 233077 | O32: =IFERROR(N32/M32,"") -> 0.96651682 | P32: details | Q32: =G32*$R$3 -> 28324.135 | R32: =M32*$R$3 -> 217036.37 | S32: H | U32: V
A33: RB3 (3) | B33: NRW | C33: m3 | D33: l | E33: l | F33: l | G33: =IFERROR(INDEX('KPI RB3 (3)'!E$19:P$19,Actual_month),0) -> 5959.5747 | H33: =IFERROR(INDEX('KPI RB3 (3)'!E$20:P$20,Actual_month),0) -> 9427 | I33: =IFERROR(G33/H33,"") -> 0.63218147 | J33: l | K33: l | L33: l | M33: =IFERROR(INDEX('KPI RB3 (3)'!E$26:P$26,Actual_month),0) -> 50193.646 | N33: =IFERROR(INDEX('KPI RB3 (3)'!E$27:P$27,Actual_month),0) -> 87603 | O33: =IFERROR(M33/N33,"") -> 0.5729672 | P33: details | Q33: =G33/$R$3 -> 6621.7497 | R33: =M33/$R$3 -> 55770.718 | S33: L | U33: V
A34: RB4 (2) | B34: NRW | C34: % | D34: l | E34: l | F34: l | G34: =IFERROR(INDEX('KPI RB4 (2)'!E$19:P$19,Actual_month),0) -> 0.15921565 | H34: =IFERROR(INDEX('KPI RB4 (2)'!E$20:P$20,Actual_month),0) -> 0.21886608 | I34: =IFERROR(G34/H34,"") -> 0.72745691 | J34: l | K34: l | L34: l | M34: =IFERROR(INDEX('KPI RB4 (2)'!E$26:P$26,Actual_month),0) -> 0.172438 | N34: =IFERROR(INDEX('KPI RB4 (2)'!E$27:P$27,Actual_month),0) -> 0.26963776 | O34: =IFERROR(M34/N34,"") -> 0.63951727 | P34: details | Q34: =G34/$R$3 -> 0.17690627 | R34: =M34/$R$3 -> 0.19159778 | S34: L | U34: V
B35: ZONE - CBD | Q35: month | R35: cum
A36: 101 | B36: Volume Water Supplied | C36: m3 | D36: l | E36: l | F36: l | G36: =IFERROR(INDEX('KPI 101'!E$19:P$19,Actual_month),0) -> 20399.04 | H36: =IFERROR(INDEX('KPI 101'!E$20:P$20,Actual_month),0) -> 19812 | I36: =IFERROR(H36/G36,"") -> 0.97122218 | J36: l | K36: l | L36: l | M36: =IFERROR(INDEX('KPI 101'!E$26:P$26,Actual_month),0) -> 165895.34 | N36: =IFERROR(INDEX('KPI 101'!E$27:P$27,Actual_month),0) -> 167638 | O36: =IFERROR(N36/M36,"") -> 1.0105046 | P36: details | Q36: =G36*$R$3 -> 18359.136 | R36: =M36*$R$3 -> 149305.81 | S36: H | U36: V
A37: 108 | B37: Volume Water Sold | C37: m3 | D37: l | E37: l | F37: l | G37: =IFERROR(INDEX('KPI 108'!E$19:P$19,Actual_month),0) -> 16218.625 | H37: =IFERROR(INDEX('KPI 108'!E$20:P$20,Actual_month),0) -> 15811 | I37: =IFERROR(H37/G37,"") -> 0.97486686 | J37: l | K37: l | L37: l | M37: =IFERROR(INDEX('KPI 108'!E$26:P$26,Actual_month),0) -> 129411.98 | N37: =IFERROR(INDEX('KPI 108'!E$27:P$27,Actual_month),0) -> 125957 | O37: =IFERROR(N37/M37,"") -> 0.97330248 | P37: details | Q37: =G37*$R$3 -> 14596.762 | R37: =M37*$R$3 -> 116470.78 | S37: H | U37: V
A38: 122 | B38: NRW | C38: % | D38: l | E38: l | F38: l | G38: =IFERROR(INDEX('KPI 122'!E$19:P$19,Actual_month),0) -> 0.20493195 | H38: =IFERROR(INDEX('KPI 122'!E$20:P$20,Actual_month),0) -> 0.20194831 | I38: =IFERROR(G38/H38,"") -> 1.0147742 | J38: l | K38: l | L38: l | M38: =IFERROR(INDEX('KPI 122'!E$26:P$26,Actual_month),0) -> 0.21991795 | N38: =IFERROR(INDEX('KPI 122'!E$27:P$27,Actual_month),0) -> 0.24863694 | O38: =IFERROR(M38/N38,"") -> 0.88449426 | P38: details | Q38: =G38/$R$3 -> 0.22770217 | R38: =M38/$R$3 -> 0.24435328 | S38: L | U38: V
B39: Amount Billed Water | C39: KES | D39: l | E39: l | F39: l | G39: =IFERROR(INDEX(#REF!,Actual_month),0) -> 0 | H39: =IFERROR(INDEX(#REF!,Actual_month),0) -> 0 | I39: =IFERROR(H39/G39,"") | J39: l | K39: l | L39: l | M39: =IFERROR(INDEX(#REF!,Actual_month),0) -> 0 | N39: =IFERROR(INDEX(#REF!,Actual_month),0) -> 0 | O39: =IFERROR(N39/M39,"") | P39: details | Q39: =G39*$R$3 -> 0 | R39: =M39*$R$3 -> 0 | S39: H | U39: V
B40: Amount Billed Sewer | C40: KES | D40: l | E40: l | F40: l | G40: =IFERROR(INDEX(#REF!,Actual_month),0) -> 0 | H40: =IFERROR(INDEX(#REF!,Actual_month),0) -> 0 | I40: =IFERROR(H40/G40,"") | J40: l | K40: l | L40: l | M40: =IFERROR(INDEX(#REF!,Actual_month),0) -> 0 | N40: =IFERROR(SUM(#REF!:INDEX(#REF!,Actual_month)),0) -> 0 | O40: =IFERROR(N40/M40,"") | P40: details | Q40: =G40*$R$3 -> 0 | R40: =M40*$R$3 -> 0 | S40: H | U40: V
...

Sheet Budget2526
A1: ='Distribution Dashboard'!A1 -> NAIVAWASS DISTRIBUTION DASHBOARD - NON-REVENUE WATER & ZONAL PERFORMANCE | B1: ='Distribution Dashboard'!B1 -> 0 | C1: ='Distribution Dashboard'!D1 -> 0
A2: ='Distribution Dashboard'!A2 -> 0 | B2: ='Distribution Dashboard'!B2 -> 46054 | C2: ='Distribution Dashboard'!D2 -> 0
A3: ='Distribution Dashboard'!A3 -> 0 | B3: ='Distribution Dashboard'!B3 -> 0 | C3: ='Distribution Dashboard'!D3 -> Monthly
A4: ='Distribution Dashboard'!A4 -> 0 | B4: ='Distribution Dashboard'!B4 -> 0 | C4: ='Distribution Dashboard'!C4 -> Unit | D4: 45839 | E4: 45870 | F4: 45901 | G4: 45931 | H4: 45962 | I4: 45992 | J4: 46023 | K4: 46054 | L4: 46082 | M4: 46113 | N4: 46143 | O4: 46174
A5: ='Distribution Dashboard'!#REF! -> #REF! | B5: ='Distribution Dashboard'!#REF! -> #REF! | C5: ='Distribution Dashboard'!#REF! -> #REF!
A6: ='Distribution Dashboard'!#REF! -> #REF! | B6: ='Distribution Dashboard'!#REF! -> #REF! | C6: ='Distribution Dashboard'!#REF! -> #REF! | D6: =D11 -> 214810.57 | E6: =E11 -> 215882.84 | F6: =F11 -> 217038.9 | G6: =G11 -> 220378.23 | H6: =H11 -> 223369.43 | I6: =I11 -> 226152.02 | J6: =J11 -> 228481.92 | K6: =K11 -> 230597.54 | ... O6: =O11 -> 235619.07
A7: ='Distribution Dashboard'!#REF! -> #REF! | B7: ='Distribution Dashboard'!#REF! -> #REF! | C7: ='Distribution Dashboard'!#REF! -> #REF! | D7: =D16 -> 162967.74 | E7: =E16 -> 164996.23 | F7: =F16 -> 167133.61 | G7: =G16 -> 170794.25 | H7: =H16 -> 174251.4 | I7: =I16 -> 177638.11 | J7: =J16 -> 180823.44 | K7: =K16 -> 183888.91 | ... O7: =O16 -> 194059.96
A8: ='Distribution Dashboard'!#REF! -> #REF! | B8: ='Distribution Dashboard'!#REF! -> #REF! | C8: ='Distribution Dashboard'!#REF! -> #REF! | D8: =(D6-D7)/D6 -> 0.24134206 | E8: =(E6-E7)/E6 -> 0.23571401 | F8: =(F6-F7)/F6 -> 0.22993705 | G8: =(G6-G7)/G6 -> 0.22499491 | H8: =(H6-H7)/H6 -> 0.21989592 | I8: =(I6-I7)/I6 -> 0.21451902 | J8: =(J6-J7)/J6 -> 0.20858755 | K8: =(K6-K7)/K6 -> 0.20255476 | ... O8: =(O6-O7)/O6 -> 0.17638265
A9: ='Distribution Dashboard'!#REF! -> #REF!
A10: ='Distribution Dashboard'!#REF! -> #REF! | B10: ='Distribution Dashboard'!#REF! -> #REF! | C10: ='Distribution Dashboard'!#REF! -> #REF! | D10: =D6 -> 214810.57 | E10: =E6 -> 215882.84 | F10: =F6 -> 217038.9 | G10: =G6 -> 220378.23 | H10: =H6 -> 223369.43 | I10: =I6 -> 226152.02 | J10: =J6 -> 228481.92 | K10: =K6 -> 230597.54 | ... O10: =O6 -> 235619.07
A11: ='Distribution Dashboard'!#REF! -> #REF! | B11: ='Distribution Dashboard'!#REF! -> #REF! | C11: ='Distribution Dashboard'!#REF! -> #REF! | D11: =D15 -> 214810.57 | E11: =E15 -> 215882.84 | F11: =F15 -> 217038.9 | G11: =G15 -> 220378.23 | H11: =H15 -> 223369.43 | I11: =I15 -> 226152.02 | J11: =J15 -> 228481.92 | K11: =K15 -> 230597.54 | ... O11: =O15 -> 235619.07
A12: ='Distribution Dashboard'!#REF! -> #REF! | B12: ='Distribution Dashboard'!#REF! -> #REF! | C12: ='Distribution Dashboard'!#REF! -> #REF! | D12: =(D10-D11)/D10 -> 0 | E12: =(E10-E11)/E10 -> 0 | F12: =(F10-F11)/F10 -> 0 | G12: =(G10-G11)/G10 -> 0 | H12: =(H10-H11)/H10 -> 0 | I12: =(I10-I11)/I10 -> 0 | J12: =(J10-J11)/J10 -> 0 | K12: =(K10-K11)/K10 -> 0 | ... O12: =(O10-O11)/O10 -> 0
A13: ='Distribution Dashboard'!#REF! -> #REF!
A14: ='Distribution Dashboard'!A6 -> 0 | B14: ='Distribution Dashboard'!B6 -> REGIONAL NRW | C14: ='Distribution Dashboard'!C6 -> 0
A15: ='Distribution Dashboard'!A7 -> 100 | B15: ='Distribution Dashboard'!B7 -> WATER AVAILABLE FOR SALES- REGIONS | C15: ='Distribution Dashboard'!C7 -> m3 | D15: =D26+D35+D40 -> 214810.57 | E15: =E26+E35+E40 -> 215882.84 | F15: =F26+F35+F40 -> 217038.9 | G15: =G26+G35+G40 -> 220378.23 | H15: =H26+H35+H40 -> 223369.43 | I15: =I26+I35+I40 -> 226152.02 | J15: =J26+J35+J40 -> 228481.92 | K15: =K26+K35+K40 -> 230597.54 | ... Q15: =Q26+Q35+Q40 -> 0
A16: ='Distribution Dashboard'!A8 -> 128a | B16: ='Distribution Dashboard'!B8 -> VOLUME WATER BILLED(CUSTOMERS-M3) | C16: ='Distribution Dashboard'!C8 -> m3 | D16: =D27+D36+D41 -> 162967.74 | E16: =E27+E36+E41 -> 164996.23 | F16: =F27+F36+F41 -> 167133.61 | G16: =G27+G36+G41 -> 170794.25 | H16: =H27+H36+H41 -> 174251.4 | I16: =I27+I36+I41 -> 177638.11 | J16: =J27+J36+J41 -> 180823.44 | K16: =K27+K36+K41 -> 183888.91 | ... O16: =O27+O36+O41 -> 194059.96
A17: ='Distribution Dashboard'!A9 -> 128 | B17: ='Distribution Dashboard'!B9 -> GLOBAL NRW | C17: ='Distribution Dashboard'!C9 -> % | D17: =(D15-D16)/D15 -> 0.24134206 | E17: =(E15-E16)/E15 -> 0.23571401 | F17: =(F15-F16)/F15 -> 0.22993705 | G17: =(G15-G16)/G15 -> 0.22499491 | H17: =(H15-H16)/H15 -> 0.21989592 | I17: =(I15-I16)/I15 -> 0.21451902 | J17: =(J15-J16)/J15 -> 0.20858755 | K17: =(K15-K16)/K15 -> 0.20255476 | ... O17: =(O15-O16)/O15 -> 0.17638265
A18: ='Distribution Dashboard'!A10 -> 0 | B18: ='Distribution Dashboard'!B10 -> Number of Active water Connections | C18: ='Distribution Dashboard'!C10 -> NO.
A19: ='Distribution Dashboard'!A11 -> 0 | B19: ='Distribution Dashboard'!B11 -> Number of Active sewer Connections | C19: ='Distribution Dashboard'!C11 -> NO.
A20: ='Distribution Dashboard'!A12 -> 0 | B20: ='Distribution Dashboard'!B12 -> Number of In-active Sewer Connections | C20: ='Distribution Dashboard'!C12 -> NO.
A21: ='Distribution Dashboard'!A13 -> 0 | B21: ='Distribution Dashboard'!B13 -> Number of In-active Water Connections | C21: ='Distribution Dashboard'!C13 -> NO.
A22: ='Distribution Dashboard'!A14 -> 0 | B22: ='Distribution Dashboard'!B14 -> Number of Connections | C22: ='Distribution Dashboard'!C14 -> NO. | D22: =SUM(D18:D21) -> 0 | E22: =SUM(E18:E21) -> 0 | F22: =SUM(F18:F21) -> 0 | G22: =SUM(G18:G21) -> 0 | H22: =SUM(H18:H21) -> 0 | I22: =SUM(I18:I21) -> 0 | J22: =SUM(J18:J21) -> 0 | K22: =SUM(K18:K21) -> 0 | ... O22: =SUM(O18:O21) -> 0
A23: ='Distribution Dashboard'!A15 -> 0 | B23: ='Distribution Dashboard'!B15 -> Maintenance, repair and operational cost | C23: ='Distribution Dashboard'!C15 -> KES
A24: ='Distribution Dashboard'!#REF! -> #REF! | B24: ='Distribution Dashboard'!#REF! -> #REF! | C24: ='Distribution Dashboard'!#REF! -> #REF!
A25: ='Distribution Dashboard'!A16 -> 0 | B25: ='Distribution Dashboard'!B16 -> CENTRAL REGION: CBD,CCCR,KABATI,SITE,KIHOTO,LAKEVIEW | C25: ='Distribution Dashboard'!C16 -> 0
A26: ='Distribution Dashboard'!A17 -> RA | B26: ='Distribution Dashboard'!B17 -> Volume Water Supplied | C26: ='Distribution Dashboard'!C17 -> m3 | D26: =D45+D51+D57+D63+D69+D91+D75 -> 105295.52 | E26: =E45+E51+E57+E63+E69+E91+E75 -> 105074.89 | F26: =F45+F51+F57+F63+F69+F91+F75 -> 104857.33 | G26: =G45+G51+G57+G63+G69+G91+G75 -> 104642.77 | H26: =H45+H51+H57+H63+H69+H91+H75 -> 104431.15 | I26: =I45+I51+I57+I63+I69+I91+I75 -> 104222.41 | J26: =J45+J51+J57+J63+J69+J91+J75 -> 104016.48 | K26: =K45+K51+K57+K63+K69+K91+K75 -> 103813.31 | ... O26: =O45+O51+O57+O63+O69+O91+O75 -> 103027.06
A27: ='Distribution Dashboard'!A18 -> RA2 | B27: ='Distribution Dashboard'!B18 -> Volume Water Sold | C27: ='Distribution Dashboard'!C18 -> m3 | D27: =D46+D52+D58+D64+D70+D92+D76 -> 84480.117 | E27: =E46+E52+E58+E64+E70+E92+E76 -> 84961.98 | F27: =F46+F52+F58+F64+F70+F92+F76 -> 85443.842 | G27: =G46+G52+G58+G64+G70+G92+G76 -> 85925.704 | H27: =H46+H52+H58+H64+H70+H92+H76 -> 86407.566 | I27: =I46+I52+I58+I64+I70+I92+I76 -> 86889.428 | J27: =J46+J52+J58+J64+J70+J92+J76 -> 87371.291 | K27: =K46+K52+K58+K64+K70+K92+K76 -> 87853.153 | ... O27: =O46+O52+O58+O64+O70+O92+O76 -> 89780.602
A28: ='Distribution Dashboard'!A19 -> RA3 | B28: ='Distribution Dashboard'!B19 -> NRW | C28: ='Distribution Dashboard'!C19 -> m3 | D28: =D26-D27 -> 20815.406 | E28: =E26-E27 -> 20112.91 | F28: =F26-F27 -> 19413.486 | G28: =G26-G27 -> 18717.066 | H28: =H26-H27 -> 18023.586 | I28: =I26-I27 -> 17332.982 | J28: =J26-J27 -> 16645.193 | K28: =K26-K27 -> 15960.161 | ... O28: =O26-O27 -> 13246.463
A29: ='Distribution Dashboard'!A20 -> RA4 | B29: ='Distribution Dashboard'!B20 -> NRW | C29: ='Distribution Dashboard'!C20 -> % | D29: =D28/D26 -> 0.19768557 | E29: =E28/E26 -> 0.191415 | F29: =F28/F26 -> 0.18514191 | G29: =G28/G26 -> 0.17886631 | H29: =H28/H26 -> 0.17258821 | I29: =I28/I26 -> 0.16630763 | J29: =J28/J26 -> 0.16002457 | K29: =K28/K26 -> 0.15373905 | ... O29: =O28/O26 -> 0.12857265
A30: ='Distribution Dashboard'!A21 -> 0 | B30: ='Distribution Dashboard'!B21 -> Amount Billed Water | C30: ='Distribution Dashboard'!C21 -> KES
A31: ='Distribution Dashboard'!A22 -> 0 | B31: ='Distribution Dashboard'!B22 -> Amount Billed Sewer | C31: ='Distribution Dashboard'!C22 -> KES
A32: ='Distribution Dashboard'!A23 -> 0 | B32: ='Distribution Dashboard'!B23 -> Number of Active water Connections | C32: ='Distribution Dashboard'!C23 -> KES
A33: ='Distribution Dashboard'!A24 -> 0 | B33: ='Distribution Dashboard'!B24 -> Number of Active sewer Connections | C33: ='Distribution Dashboard'!C24 -> KES
A34: ='Distribution Dashboard'!A25 -> 0 | B34: ='Distribution Dashboard'!B25 -> SOUTHERN REGION: MAI MAHIU,KAMERE,HELLSGATE | C34: ='Distribution Dashboard'!C25 -> 0
A35: ='Distribution Dashboard'!A26 -> RA6 (B) | B35: ='Distribution Dashboard'!B26 -> Volume Water Supplied | C35: ='Distribution Dashboard'!C26 -> m3 | D35: =D79+D85+D103+D121 -> 74168.145 | E35: =E79+E85+E103+E121 -> 75099.246 | F35: =F79+F85+F103+F121 -> 76156.75 | G35: =G79+G85+G103+G121 -> 79439.402 | H35: =H79+H85+H103+H121 -> 82374.058 | I35: =I79+I85+I103+I121 -> 85141.043 | J35: =J79+J85+J103+J121 -> 87280.37 | K35: =K79+K85+K103+K121 -> 89353.394 | ... O35: =O79+O85+O103+O121 -> 94360.159
A36: ='Distribution Dashboard'!A27 -> RB2 | B36: ='Distribution Dashboard'!B27 -> Volume Water Sold | C36: ='Distribution Dashboard'!C27 -> m3 | D36: =D80+D86+D104+D122 -> 49682.108 | E36: =E80+E86+E104+E122 -> 50812.796 | F36: =F80+F86+F104+F122 -> 52082.386 | G36: =G80+G86+G104+G122 -> 54905.225 | H36: =H80+H86+H104+H122 -> 57524.584 | I36: =I80+I86+I104+I122 -> 60103.499 | J36: =J80+J86+J104+J122 -> 62333.999 | K36: =K80+K86+K104+K122 -> 64564.498 | ... O36: =O80+O86+O104+O122 -> 71530.431
A37: ='Distribution Dashboard'!A28 -> RB3 (2) | B37: ='Distribution Dashboard'!B28 -> NRW | C37: ='Distribution Dashboard'!C28 -> m3 | D37: =D35-D36 -> 24486.037 | E37: =E35-E36 -> 24286.45 | F37: =F35-F36 -> 24074.365 | G37: =G35-G36 -> 24534.176 | H37: =H35-H36 -> 24849.474 | I37: =I35-I36 -> 25037.544 | J37: =J35-J36 -> 24946.372 | K37: =K35-K36 -> 24788.896 | ... O37: =O35-O36 -> 22829.728
A38: ='Distribution Dashboard'!A29 -> RB4 | B38: ='Distribution Dashboard'!B29 -> NRW | C38: ='Distribution Dashboard'!C29 -> % | D38: =D37/D35 -> 0.33014223 | E38: =E37/E35 -> 0.32339139 | F38: =F37/F35 -> 0.31611597 | G38: =G37/G35 -> 0.3088414 | H38: =H37/H35 -> 0.30166626 | I38: =I37/I35 -> 0.29407138 | J38: =J37/J35 -> 0.28581881 | K38: =K37/K35 -> 0.27742534 | ... O38: =O37/O35 -> 0.24194245
A39: ='Distribution Dashboard'!A30 -> 0 | B39: ='Distribution Dashboard'!B30 -> EASTERN REGION: KAYOLE,GONDI, KINUNGI,NJONJORO | C39: ='Distribution Dashboard'!C30 -> 0
A40: ='Distribution Dashboard'!A31 -> RA6 (B) (2) | B40: ='Distribution Dashboard'!B31 -> Volume Water Supplied | C40: ='Distribution Dashboard'!C31 -> m3 | D40: =D125+D97 -> 35346.901 | E40: =E125+E97 -> 35708.701 | F40: =F125+F97 -> 36024.819 | G40: =G125+G97 -> 36296.056 | H40: =H125+H97 -> 36564.217 | I40: =I125+I97 -> 36788.567 | J40: =J125+J97 -> 37185.07 | K40: =K125+K97 -> 37430.836 | ... O40: =O125+O97 -> 38231.852
...

Sheet Actuals2526
A1: ='Distribution Dashboard'!A1 -> NAIVAWASS DISTRIBUTION DASHBOARD - NON-REVENUE WATER & ZONAL PERFORMANCE | B1: ='Distribution Dashboard'!B1 -> 0 | C1: ='Distribution Dashboard'!D1 -> 0
A2: ='Distribution Dashboard'!A2 -> 0 | B2: ='Distribution Dashboard'!B2 -> 46054 | C2: ='Distribution Dashboard'!D2 -> 0
A3: ='Distribution Dashboard'!A3 -> 0 | B3: ='Distribution Dashboard'!B3 -> 0 | C3: ='Distribution Dashboard'!D3 -> Monthly
A4: ='Distribution Dashboard'!A4 -> 0 | C4: ='Distribution Dashboard'!C4 -> Unit | D4: 45839 | E4: 45870 | F4: 45901 | G4: 45931 | H4: 45962 | I4: 45992 | J4: 46023 | K4: 46054 | L4: 46082 | M4: 46113 | N4: 46143 | O4: 46174
A5: ='Distribution Dashboard'!#REF! -> #REF! | B5: ='Distribution Dashboard'!#REF! -> #REF! | C5: ='Distribution Dashboard'!#REF! -> #REF!
A6: ='Distribution Dashboard'!#REF! -> #REF! | B6: ='Distribution Dashboard'!#REF! -> #REF! | C6: ='Distribution Dashboard'!#REF! -> #REF! | D6: =D11 -> 203624 | E6: =E11 -> 229218 | F6: =F11 -> 194924 | G6: =G11 -> 247237 | H6: =H11 -> 181647 | I6: =I11 -> 180291 | J6: =J11 -> 258170 | K6: =K11 -> 222543 | ... O6: =O11 -> 0
A7: ='Distribution Dashboard'!#REF! -> #REF! | B7: ='Distribution Dashboard'!#REF! -> #REF! | C7: ='Distribution Dashboard'!#REF! -> #REF! | D7: =D16 -> 146435 | E7: =E16 -> 173295 | F7: =F16 -> 145984 | G7: =G16 -> 171125 | H7: =H16 -> 135132 | I7: =I16 -> 131036 | J7: =J16 -> 200570 | K7: =K16 -> 172266 | ... O7: =O16 -> 0
A8: ='Distribution Dashboard'!#REF! -> #REF! | B8: ='Distribution Dashboard'!#REF! -> #REF! | C8: ='Distribution Dashboard'!#REF! -> #REF! | D8: =(D6-D7)/D6 -> 0.28085589 | E8: =(E6-E7)/E6 -> 0.24397299 | F8: =(F6-F7)/F6 -> 0.25107221 | G8: =(G6-G7)/G6 -> 0.30785036 | H8: =(H6-H7)/H6 -> 0.25607359 | I8: =(I6-I7)/I6 -> 0.27319722 | J8: =(J6-J7)/J6 -> 0.2231088 | K8: =(K6-K7)/K6 -> 0.22592038 | ... O8: =(O6-O7)/O6 -> #DIV/0!
A9: ='Distribution Dashboard'!#REF! -> #REF!
A10: ='Distribution Dashboard'!#REF! -> #REF! | B10: ='Distribution Dashboard'!#REF! -> #REF! | C10: ='Distribution Dashboard'!#REF! -> #REF! | D10: =D6 -> 203624 | E10: =E6 -> 229218 | F10: =F6 -> 194924 | G10: =G6 -> 247237 | H10: =H6 -> 181647 | I10: =I6 -> 180291 | J10: =J6 -> 258170 | K10: =K6 -> 222543 | ... O10: =O6 -> 0
A11: ='Distribution Dashboard'!#REF! -> #REF! | B11: ='Distribution Dashboard'!#REF! -> #REF! | C11: ='Distribution Dashboard'!#REF! -> #REF! | D11: =D15 -> 203624 | E11: =E15 -> 229218 | F11: =F15 -> 194924 | G11: =G15 -> 247237 | H11: =H15 -> 181647 | I11: =I15 -> 180291 | J11: =J15 -> 258170 | K11: =K15 -> 222543 | ... O11: =O15 -> 0
A12: ='Distribution Dashboard'!#REF! -> #REF! | B12: ='Distribution Dashboard'!#REF! -> #REF! | C12: ='Distribution Dashboard'!#REF! -> #REF! | D12: =(D10-D11)/D10 -> 0 | E12: =(E10-E11)/E10 -> 0 | F12: =(F10-F11)/F10 -> 0 | G12: =(G10-G11)/G10 -> 0 | H12: =(H10-H11)/H10 -> 0 | I12: =(I10-I11)/I10 -> 0 | J12: =(J10-J11)/J10 -> 0 | K12: =(K10-K11)/K10 -> 0 | ... O12: =(O10-O11)/O10 -> #DIV/0!
A13: ='Distribution Dashboard'!#REF! -> #REF! | B13: ='Distribution Dashboard'!#REF! -> #REF! | C13: ='Distribution Dashboard'!#REF! -> #REF! | D13: =D10-D11 -> 0 | E13: =E10-E11 -> 0 | F13: =F10-F11 -> 0 | G13: =G10-G11 -> 0 | H13: =H10-H11 -> 0 | I13: =I10-I11 -> 0 | J13: =J10-J11 -> 0 | K13: =K10-K11 -> 0 | ... O13: =O10-O11 -> 0
A14: ='Distribution Dashboard'!A6 -> 0 | B14: ='Distribution Dashboard'!B6 -> REGIONAL NRW | C14: ='Distribution Dashboard'!C6 -> 0
A15: ='Distribution Dashboard'!A7 -> 100 | B15: ='Distribution Dashboard'!B7 -> WATER AVAILABLE FOR SALES- REGIONS | C15: ='Distribution Dashboard'!C7 -> m3 | D15: =D26+D35+D40 -> 203624 | E15: =E26+E35+E40 -> 229218 | F15: =F26+F35+F40 -> 194924 | G15: =G26+G35+G40 -> 247237 | H15: =H26+H35+H40 -> 181647 | I15: =I26+I35+I40 -> 180291 | J15: =J26+J35+J40 -> 258170 | K15: =K26+K35+K40 -> 222543 | ... O15: =O26+O35+O40 -> 0
A16: ='Distribution Dashboard'!A8 -> 128a | B16: ='Distribution Dashboard'!B8 -> VOLUME WATER BILLED(CUSTOMERS-M3) | C16: ='Distribution Dashboard'!C8 -> m3 | D16: =D27+D41+D36 -> 146435 | E16: =E27+E41+E36 -> 173295 | F16: =F27+F41+F36 -> 145984 | G16: =G27+G41+G36 -> 171125 | H16: =H27+H41+H36 -> 135132 | I16: =I27+I41+I36 -> 131036 | J16: =J27+J41+J36 -> 200570 | K16: =K27+K41+K36 -> 172266 | ... O16: =O27+O41+O36 -> 0
A17: ='Distribution Dashboard'!A9 -> 128 | B17: ='Distribution Dashboard'!B9 -> GLOBAL NRW | C17: ='Distribution Dashboard'!C9 -> % | D17: =(D15-D16)/D15 -> 0.28085589 | E17: =(E15-E16)/E15 -> 0.24397299 | F17: =(F15-F16)/F15 -> 0.25107221 | G17: =(G15-G16)/G15 -> 0.30785036 | H17: =(H15-H16)/H15 -> 0.25607359 | I17: =(I15-I16)/I15 -> 0.27319722 | J17: =(J15-J16)/J15 -> 0.2231088 | K17: =(K15-K16)/K15 -> 0.22592038 | ... O17: =(O15-O16)/O15 -> #DIV/0!
A18: ='Distribution Dashboard'!A10 -> 0 | B18: ='Distribution Dashboard'!B10 -> Number of Active water Connections | C18: ='Distribution Dashboard'!C10 -> NO. | D18: =D41+D32 -> 31567 | E18: =E41+E32 -> 30396 | F18: =F41+F32 -> 26239 | G18: =G41+G32 -> 28789 | H18: =H41+H32 -> 24966 | I18: =I41+I32 -> 26222 | J18: =J41+J32 -> 31253 | K18: =K41+K32 -> 33645 | ... O18: =O41+O32 -> 0
A19: ='Distribution Dashboard'!A11 -> 0 | B19: ='Distribution Dashboard'!B11 -> Number of Active sewer Connections | C19: ='Distribution Dashboard'!C11 -> NO. | D19: =D42+D33 -> 9642 | E19: =E42+E33 -> 9594 | F19: =F42+F33 -> 10486 | G19: =G42+G33 -> 20017 | H19: =H42+H33 -> 8560 | I19: =I42+I33 -> 8907 | J19: =J42+J33 -> 10970 | K19: =K42+K33 -> 9427 | ... O19: =O42+O33 -> 0
A20: ='Distribution Dashboard'!A12 -> 0 | B20: ='Distribution Dashboard'!B12 -> Number of In-active Sewer Connections | C20: ='Distribution Dashboard'!C12 -> NO.
A21: ='Distribution Dashboard'!A13 -> 0 | B21: ='Distribution Dashboard'!B13 -> Number of In-active Water Connections | C21: ='Distribution Dashboard'!C13 -> NO.
A22: ='Distribution Dashboard'!A14 -> 0 | B22: ='Distribution Dashboard'!B14 -> Number of Connections | C22: ='Distribution Dashboard'!C14 -> NO. | D22: =SUM(D18:D21) -> 41209 | E22: =SUM(E18:E21) -> 39990 | F22: =SUM(F18:F21) -> 36725 | G22: =SUM(G18:G21) -> 48806 | H22: =SUM(H18:H21) -> 33526 | I22: =SUM(I18:I21) -> 35129 | J22: =SUM(J18:J21) -> 42223 | K22: =SUM(K18:K21) -> 43072 | ... O22: =SUM(O18:O21) -> 0
A23: ='Distribution Dashboard'!A15 -> 0 | B23: ='Distribution Dashboard'!B15 -> Maintenance, repair and operational cost | C23: ='Distribution Dashboard'!C15 -> KES
A24: ='Distribution Dashboard'!#REF! -> #REF! | B24: ='Distribution Dashboard'!#REF! -> #REF! | C24: ='Distribution Dashboard'!#REF! -> #REF!
A25: ='Distribution Dashboard'!A16 -> 0 | B25: ='Distribution Dashboard'!B16 -> CENTRAL REGION: CBD,CCCR,KABATI,SITE,KIHOTO,LAKEVIEW | C25: ='Distribution Dashboard'!C16 -> 0
A26: ='Distribution Dashboard'!A17 -> RA | B26: ='Distribution Dashboard'!B17 -> Volume Water Supplied | C26: ='Distribution Dashboard'!C17 -> m3 | D26: =D45+D51+D57+D63+D69+D91+D75 -> 99588 | E26: =E45+E51+E57+E63+E69+E91+E75 -> 104217 | F26: =F45+F51+F57+F63+F69+F91+F75 -> 100946 | G26: =G45+G51+G57+G63+G69+G91+G75 -> 110522 | H26: =H45+H51+H57+H63+H69+H91+H75 -> 92662 | I26: =I45+I51+I57+I63+I69+I91+I75 -> 84151 | J26: =J45+J51+J57+J63+J69+J91+J75 -> 126366 | K26: =K45+K51+K57+K63+K69+K91+K75 -> 101836 | ... O26: =O45+O51+O57+O63+O69+O91+O75 -> 0
A27: ='Distribution Dashboard'!A18 -> RA2 | B27: ='Distribution Dashboard'!B18 -> Volume Water Sold | C27: ='Distribution Dashboard'!C18 -> m3 | D27: =D46+D52+D58+D64+D70+D92+D76 -> 72362 | E27: =E46+E52+E58+E64+E70+E92+E76 -> 84589 | F27: =F46+F52+F58+F64+F70+F92+F76 -> 79590 | G27: =G46+G52+G58+G64+G70+G92+G76 -> 86302 | H27: =H46+H52+H58+H64+H70+H92+H76 -> 71945 | I27: =I46+I52+I58+I64+I70+I92+I76 -> 63233 | J27: =J46+J52+J58+J64+J70+J92+J76 -> 105898 | K27: =K46+K52+K58+K64+K70+K92+K76 -> 83599 | ... O27: =O46+O52+O58+O64+O70+O92+O76 -> 0
A28: ='Distribution Dashboard'!A19 -> RA3 | B28: ='Distribution Dashboard'!B19 -> NRW | C28: ='Distribution Dashboard'!C19 -> m3 | D28: =D26-D27 -> 27226 | E28: =E26-E27 -> 19628 | F28: =F26-F27 -> 21356 | G28: =G26-G27 -> 24220 | H28: =H26-H27 -> 20717 | I28: =I26-I27 -> 20918 | J28: =J26-J27 -> 20468 | K28: =K26-K27 -> 18237 | ... O28: =O26-O27 -> 0
A29: ='Distribution Dashboard'!A20 -> RA4 | B29: ='Distribution Dashboard'!B20 -> NRW | C29: ='Distribution Dashboard'!C20 -> % | D29: =D28/D26 -> 0.27338635 | E29: =E28/E26 -> 0.1883378 | F29: =F28/F26 -> 0.21155866 | G29: =G28/G26 -> 0.21914189 | H29: =H28/H26 -> 0.22357601 | I29: =I28/I26 -> 0.24857696 | J29: =J28/J26 -> 0.16197395 | K29: =K28/K26 -> 0.17908205 | ... O29: =O28/O26 -> #DIV/0!
A30: ='Distribution Dashboard'!A21 -> 0 | B30: ='Distribution Dashboard'!B21 -> Amount Billed Water | C30: ='Distribution Dashboard'!C21 -> KES
A31: ='Distribution Dashboard'!A22 -> 0 | B31: ='Distribution Dashboard'!B22 -> Amount Billed Sewer | C31: ='Distribution Dashboard'!C22 -> KES
A32: ='Distribution Dashboard'!A23 -> 0 | B32: ='Distribution Dashboard'!B23 -> Number of Active water Connections | C32: ='Distribution Dashboard'!C23 -> KES
A33: ='Distribution Dashboard'!A24 -> 0 | B33: ='Distribution Dashboard'!B24 -> Number of Active sewer Connections | C33: ='Distribution Dashboard'!C24 -> KES
A34: ='Distribution Dashboard'!A25 -> 0 | B34: ='Distribution Dashboard'!B25 -> SOUTHERN REGION: MAI MAHIU,KAMERE,HELLSGATE | C34: ='Distribution Dashboard'!C25 -> 0
A35: ='Distribution Dashboard'!A26 -> RA6 (B) | B35: ='Distribution Dashboard'!B26 -> Volume Water Supplied | C35: ='Distribution Dashboard'!C26 -> m3 | D35: =D79+D85+D103+D121 -> 62827 | E35: =E79+E85+E103+E121 -> 85011 | F35: =F79+F85+F103+F121 -> 57253 | G35: =G79+G85+G103+G121 -> 87909 | H35: =H79+H85+H103+H121 -> 55459 | I35: =I79+I85+I103+I121 -> 61011 | J35: =J79+J85+J103+J121 -> 89581 | K35: =K79+K85+K103+K121 -> 77635 | ... O35: =O79+O85+O103+O121 -> 0
A36: ='Distribution Dashboard'!A27 -> RB2 | B36: ='Distribution Dashboard'!B27 -> Volume Water Sold | C36: ='Distribution Dashboard'!C27 -> m3 | D36: =D80+D86+D104+D122 -> 42506 | E36: =E80+E86+E104+E122 -> 58310 | F36: =F80+F86+F104+F122 -> 40155 | G36: =G80+G86+G104+G122 -> 56034 | H36: =H80+H86+H104+H122 -> 38221 | I36: =I80+I86+I104+I122 -> 41581 | J36: =J80+J86+J104+J122 -> 63419 | K36: =K80+K86+K104+K122 -> 55022 | ... O36: =O80+O86+O104+O122 -> 0
A37: ='Distribution Dashboard'!A28 -> RB3 (2) | B37: ='Distribution Dashboard'!B28 -> NRW | C37: ='Distribution Dashboard'!C28 -> m3 | D37: =D35-D36 -> 20321 | E37: =E35-E36 -> 26701 | F37: =F35-F36 -> 17098 | G37: =G35-G36 -> 31875 | H37: =H35-H36 -> 17238 | I37: =I35-I36 -> 19430 | J37: =J35-J36 -> 26162 | K37: =K35-K36 -> 22613 | ... O37: =O35-O36 -> 0
A38: ='Distribution Dashboard'!A29 -> RB4 | B38: ='Distribution Dashboard'!B29 -> NRW | C38: ='Distribution Dashboard'!C29 -> % | D38: =D37/D35 -> 0.32344374 | E38: =E37/E35 -> 0.31408876 | F38: =F37/F35 -> 0.29863937 | G38: =G37/G35 -> 0.36259086 | H38: =H37/H35 -> 0.31082421 | I38: =I37/I35 -> 0.31846716 | J38: =J37/J35 -> 0.29204854 | K38: =K37/K35 -> 0.29127327 | ... O38: =O37/O35 -> #DIV/0!
A39: ='Distribution Dashboard'!A30 -> 0 | B39: ='Distribution Dashboard'!B30 -> EASTERN REGION: KAYOLE,GONDI, KINUNGI,NJONJORO | C39: ='Distribution Dashboard'!C30 -> 0
A40: ='Distribution Dashboard'!A31 -> RA6 (B) (2) | B40: ='Distribution Dashboard'!B31 -> Volume Water Supplied | C40: ='Distribution Dashboard'!C31 -> m3 | D40: =D97+D125 -> 41209 | E40: =E97+E125 -> 39990 | F40: =F97+F125 -> 36725 | G40: =G97+G125 -> 48806 | H40: =H97+H125 -> 33526 | I40: =I97+I125 -> 35129 | J40: =J97+J125 -> 42223 | K40: =K97+K125 -> 43072 | ... O40: =O97+O125 -> 0
...

Sheet Actuals2425
A1: ='Distribution Dashboard'!A1 -> NAIVAWASS DISTRIBUTION DASHBOARD - NON-REVENUE WATER & ZONAL PERFORMANCE | B1: ='Distribution Dashboard'!B1 -> 0 | C1: ='Distribution Dashboard'!D1 -> 0
A2: ='Distribution Dashboard'!A2 -> 0 | B2: ='Distribution Dashboard'!B2 -> 46054 | C2: ='Distribution Dashboard'!D2 -> 0
A3: ='Distribution Dashboard'!A3 -> 0 | B3: ='Distribution Dashboard'!B3 -> 0 | C3: ='Distribution Dashboard'!D3 -> Monthly
A4: ='Distribution Dashboard'!A4 -> 0 | C4: ='Distribution Dashboard'!C4 -> Unit | D4: 45474 | E4: 45505 | F4: 45536 | G4: 45566 | H4: 45597 | I4: 45627 | J4: 45658 | K4: 45689 | L4: 45717 | M4: 45748 | N4: 45778 | O4: 45809
A5: ='Distribution Dashboard'!#REF! -> #REF! | B5: ='Distribution Dashboard'!#REF! -> #REF! | C5: ='Distribution Dashboard'!#REF! -> #REF!
A6: ='Distribution Dashboard'!#REF! -> #REF! | B6: ='Distribution Dashboard'!#REF! -> #REF! | C6: ='Distribution Dashboard'!#REF! -> #REF! | D6: 199192.12 | E6: 229211 | F6: 219157 | G6: 226434 | H6: 232327 | I6: 162567 | J6: 280545 | K6: 236218 | L6: 234258 | M6: 176008 | N6: 222024 | O6: 228197
A7: ='Distribution Dashboard'!#REF! -> #REF! | B7: ='Distribution Dashboard'!#REF! -> #REF! | C7: ='Distribution Dashboard'!#REF! -> #REF! | D7: =D16 -> 141416 | E7: =E16 -> 168508 | F7: =F16 -> 163668 | G7: =G16 -> 160893 | H7: =H16 -> 179892 | I7: =I16 -> 116560 | J7: =J16 -> 184451 | K7: =K16 -> 165475 | ... O7: =O16 -> 164911
A8: ='Distribution Dashboard'!#REF! -> #REF! | B8: ='Distribution Dashboard'!#REF! -> #REF! | C8: ='Distribution Dashboard'!#REF! -> #REF! | D8: =(D6-D7)/D6 -> 0.29005224 | E8: =(E6-E7)/E6 -> 0.26483458 | F8: =(F6-F7)/F6 -> 0.25319292 | G8: =(G6-G7)/G6 -> 0.28944858 | H8: =(H6-H7)/H6 -> 0.22569482 | I8: =(I6-I7)/I6 -> 0.28300332 | J8: =(J6-J7)/J6 -> 0.34252615 | K8: =(K6-K7)/K6 -> 0.29948183 | ... O8: =(O6-O7)/O6 -> 0.27733055
A9: ='Distribution Dashboard'!#REF! -> #REF!
A10: ='Distribution Dashboard'!#REF! -> #REF! | B10: ='Distribution Dashboard'!#REF! -> #REF! | C10: ='Distribution Dashboard'!#REF! -> #REF! | D10: =D6 -> 199192.12 | E10: =E6 -> 229211 | F10: =F6 -> 219157 | G10: =G6 -> 226434 | H10: =H6 -> 232327 | I10: =I6 -> 162567 | J10: =J6 -> 280545 | K10: =K6 -> 236218 | ... O10: =O6 -> 228197
A11: ='Distribution Dashboard'!#REF! -> #REF! | B11: ='Distribution Dashboard'!#REF! -> #REF! | C11: ='Distribution Dashboard'!#REF! -> #REF! | D11: =D15 -> 179812 | E11: =E15 -> 218591 | F11: =F15 -> 206801 | G11: =G15 -> 217593 | H11: =H15 -> 230368 | I11: =I15 -> 151401 | J11: =J15 -> 267445 | K11: =K15 -> 216809 | ... O11: =O15 -> 224235
A12: ='Distribution Dashboard'!#REF! -> #REF! | B12: ='Distribution Dashboard'!#REF! -> #REF! | C12: ='Distribution Dashboard'!#REF! -> #REF! | D12: =(D10-D11)/D10 -> 0.097293608 | E12: =(E10-E11)/E10 -> 0.046332855 | F12: =(F10-F11)/F10 -> 0.056379673 | G12: =(G10-G11)/G10 -> 0.03904449 | H12: =(H10-H11)/H10 -> 0.0084320806 | I12: =(I10-I11)/I10 -> 0.068685527 | J12: =(J10-J11)/J10 -> 0.046694826 | K12: =(K10-K11)/K10 -> 0.082165627 | ... O12: =(O10-O11)/O10 -> 0.017362191
A13: ='Distribution Dashboard'!#REF! -> #REF! | B13: ='Distribution Dashboard'!#REF! -> #REF! | C13: ='Distribution Dashboard'!#REF! -> #REF! | D13: =D10-D11 -> 19380.12 | E13: =E10-E11 -> 10620 | F13: =F10-F11 -> 12356 | G13: =G10-G11 -> 8841 | H13: =H10-H11 -> 1959 | I13: =I10-I11 -> 11166 | J13: =J10-J11 -> 13100 | K13: =K10-K11 -> 19409 | ... O13: =O10-O11 -> 3962
A14: ='Distribution Dashboard'!A6 -> 0 | B14: ='Distribution Dashboard'!B6 -> REGIONAL NRW | C14: ='Distribution Dashboard'!C6 -> 0
A15: ='Distribution Dashboard'!A7 -> 100 | B15: ='Distribution Dashboard'!B7 -> WATER AVAILABLE FOR SALES- REGIONS | C15: ='Distribution Dashboard'!C7 -> m3 | D15: =D26+D35+D40 -> 179812 | E15: =E26+E35+E40 -> 218591 | F15: =F26+F35+F40 -> 206801 | G15: =G26+G35+G40 -> 217593 | H15: =H26+H35+H40 -> 230368 | I15: =I26+I35+I40 -> 151401 | J15: =J26+J35+J40 -> 267445 | K15: =K26+K35+K40 -> 216809 | ... Q15: =Q26+Q35+Q40 -> 0
A16: ='Distribution Dashboard'!A8 -> 128a | B16: ='Distribution Dashboard'!B8 -> VOLUME WATER BILLED(CUSTOMERS-M3) | C16: ='Distribution Dashboard'!C8 -> m3 | D16: =D27+D41+D36 -> 141416 | E16: =E27+E41+E36 -> 168508 | F16: =F27+F41+F36 -> 163668 | G16: =G27+G41+G36 -> 160893 | H16: =H27+H41+H36 -> 179892 | I16: =I27+I41+I36 -> 116560 | J16: =J27+J41+J36 -> 184451 | K16: =K27+K41+K36 -> 165475 | ... O16: =O27+O41+O36 -> 164911
A17: ='Distribution Dashboard'!A9 -> 128 | B17: ='Distribution Dashboard'!B9 -> GLOBAL NRW | C17: ='Distribution Dashboard'!C9 -> % | D17: =(D15-D16)/D15 -> 0.21353414 | E17: =(E15-E16)/E15 -> 0.22911739 | F17: =(F15-F16)/F15 -> 0.20857249 | G17: =(G15-G16)/G15 -> 0.26057824 | H17: =(H15-H16)/H15 -> 0.21911029 | I17: =(I15-I16)/I15 -> 0.23012398 | J17: =(J15-J16)/J15 -> 0.31032175 | K17: =(K15-K16)/K15 -> 0.23677061 | ... O17: =(O15-O16)/O15 -> 0.26456173
A18: ='Distribution Dashboard'!A10 -> 0 | B18: ='Distribution Dashboard'!B10 -> Number of Active water Connections | C18: ='Distribution Dashboard'!C10 -> NO. | D18: =D41+D32 -> 26497 | E18: =E41+E32 -> 29718 | F18: =F41+F32 -> 32245 | G18: =G41+G32 -> 30200 | H18: =H41+H32 -> 32349 | I18: =I41+I32 -> 24184 | J18: =J41+J32 -> 29173 | K18: =K41+K32 -> 28120 | ... O18: =O41+O32 -> 30668
A19: ='Distribution Dashboard'!A11 -> 0 | B19: ='Distribution Dashboard'!B11 -> Number of Active sewer Connections | C19: ='Distribution Dashboard'!C11 -> NO. | D19: =D42+D33 -> 6559 | E19: =E42+E33 -> 10191 | F19: =F42+F33 -> 3039 | G19: =G42+G33 -> 7923 | H19: =H42+H33 -> 6667 | I19: =I42+I33 -> 5375 | J19: =J42+J33 -> 10605 | K19: =K42+K33 -> 8769 | ... O19: =O42+O33 -> 16572
A20: ='Distribution Dashboard'!A12 -> 0 | B20: ='Distribution Dashboard'!B12 -> Number of In-active Sewer Connections | C20: ='Distribution Dashboard'!C12 -> NO.
A21: ='Distribution Dashboard'!A13 -> 0 | B21: ='Distribution Dashboard'!B13 -> Number of In-active Water Connections | C21: ='Distribution Dashboard'!C13 -> NO.
A22: ='Distribution Dashboard'!A14 -> 0 | B22: ='Distribution Dashboard'!B14 -> Number of Connections | C22: ='Distribution Dashboard'!C14 -> NO. | D22: =SUM(D18:D21) -> 33056 | E22: =SUM(E18:E21) -> 39909 | F22: =SUM(F18:F21) -> 35284 | G22: =SUM(G18:G21) -> 38123 | H22: =SUM(H18:H21) -> 39016 | I22: =SUM(I18:I21) -> 29559 | J22: =SUM(J18:J21) -> 39778 | K22: =SUM(K18:K21) -> 36889 | ... O22: =SUM(O18:O21) -> 47240
A23: ='Distribution Dashboard'!A15 -> 0 | B23: ='Distribution Dashboard'!B15 -> Maintenance, repair and operational cost | C23: ='Distribution Dashboard'!C15 -> KES
A24: ='Distribution Dashboard'!#REF! -> #REF! | B24: ='Distribution Dashboard'!#REF! -> #REF! | C24: ='Distribution Dashboard'!#REF! -> #REF!
A25: ='Distribution Dashboard'!A16 -> 0 | B25: ='Distribution Dashboard'!B16 -> CENTRAL REGION: CBD,CCCR,KABATI,SITE,KIHOTO,LAKEVIEW | C25: ='Distribution Dashboard'!C16 -> 0
A26: ='Distribution Dashboard'!A17 -> RA | B26: ='Distribution Dashboard'!B17 -> Volume Water Supplied | C26: ='Distribution Dashboard'!C17 -> m3 | D26: =D45+D51+D57+D63+D69+D91+D75 -> 92367 | E26: =E45+E51+E57+E63+E69+E91+E75 -> 114426 | F26: =F45+F51+F57+F63+F69+F91+F75 -> 101553 | G26: =G45+G51+G57+G63+G69+G91+G75 -> 107597 | H26: =H45+H51+H57+H63+H69+H91+H75 -> 106133 | I26: =I45+I51+I57+I63+I69+I91+I75 -> 74176 | J26: =J45+J51+J57+J63+J69+J91+J75 -> 141121 | K26: =K45+K51+K57+K63+K69+K91+K75 -> 105690 | ... O26: =O45+O51+O57+O63+O69+O91+O75 -> 108927
A27: ='Distribution Dashboard'!A18 -> RA2 | B27: ='Distribution Dashboard'!B18 -> Volume Water Sold | C27: ='Distribution Dashboard'!C18 -> m3 | D27: =D46+D52+D58+D64+D70+D92+D76 -> 73301 | E27: =E46+E52+E58+E64+E70+E92+E76 -> 93670 | F27: =F46+F52+F58+F64+F70+F92+F76 -> 81216 | G27: =G46+G52+G58+G64+G70+G92+G76 -> 82720 | H27: =H46+H52+H58+H64+H70+H92+H76 -> 87303 | I27: =I46+I52+I58+I64+I70+I92+I76 -> 59040 | J27: =J46+J52+J58+J64+J70+J92+J76 -> 102175 | K27: =K46+K52+K58+K64+K70+K92+K76 -> 87481 | ... O27: =O46+O52+O58+O64+O70+O92+O76 -> 86204
A28: ='Distribution Dashboard'!A19 -> RA3 | B28: ='Distribution Dashboard'!B19 -> NRW | C28: ='Distribution Dashboard'!C19 -> m3 | D28: =D26-D27 -> 19066 | E28: =E26-E27 -> 20756 | F28: =F26-F27 -> 20337 | G28: =G26-G27 -> 24877 | H28: =H26-H27 -> 18830 | I28: =I26-I27 -> 15136 | J28: =J26-J27 -> 38946 | K28: =K26-K27 -> 18209 | ... O28: =O26-O27 -> 22723
A29: ='Distribution Dashboard'!A20 -> RA4 | B29: ='Distribution Dashboard'!B20 -> NRW | C29: ='Distribution Dashboard'!C20 -> % | D29: =D28/D26 -> 0.20641571 | E29: =E28/E26 -> 0.18139234 | F29: =F28/F26 -> 0.20025996 | G29: =G28/G26 -> 0.23120533 | H29: =H28/H26 -> 0.1774189 | I29: =I28/I26 -> 0.20405522 | J29: =J28/J26 -> 0.27597594 | K29: =K28/K26 -> 0.17228688 | ... O29: =O28/O26 -> 0.2086076
A30: ='Distribution Dashboard'!A21 -> 0 | B30: ='Distribution Dashboard'!B21 -> Amount Billed Water | C30: ='Distribution Dashboard'!C21 -> KES
A31: ='Distribution Dashboard'!A22 -> 0 | B31: ='Distribution Dashboard'!B22 -> Amount Billed Sewer | C31: ='Distribution Dashboard'!C22 -> KES
A32: ='Distribution Dashboard'!A23 -> 0 | B32: ='Distribution Dashboard'!B23 -> Number of Active water Connections | C32: ='Distribution Dashboard'!C23 -> KES
A33: ='Distribution Dashboard'!A24 -> 0 | B33: ='Distribution Dashboard'!B24 -> Number of Active sewer Connections | C33: ='Distribution Dashboard'!C24 -> KES
A34: ='Distribution Dashboard'!A25 -> 0 | B34: ='Distribution Dashboard'!B25 -> SOUTHERN REGION: MAI MAHIU,KAMERE,HELLSGATE | C34: ='Distribution Dashboard'!C25 -> 0
A35: ='Distribution Dashboard'!A26 -> RA6 (B) | B35: ='Distribution Dashboard'!B26 -> Volume Water Supplied | C35: ='Distribution Dashboard'!C26 -> m3 | D35: =D79+D85+D103+D121 -> 54389 | E35: =E79+E85+E103+E121 -> 64256 | F35: =F79+F85+F103+F121 -> 69964 | G35: =G79+G85+G103+G121 -> 71873 | H35: =H79+H85+H103+H121 -> 85219 | I35: =I79+I85+I103+I121 -> 47666 | J35: =J79+J85+J103+J121 -> 86546 | K35: =K79+K85+K103+K121 -> 74230 | ... O35: =O79+O85+O103+O121 -> 68068
A36: ='Distribution Dashboard'!A27 -> RB2 | B36: ='Distribution Dashboard'!B27 -> Volume Water Sold | C36: ='Distribution Dashboard'!C27 -> m3 | D36: =D80+D86+D104+D122 -> 41618 | E36: =E80+E86+E104+E122 -> 45120 | F36: =F80+F86+F104+F122 -> 50207 | G36: =G80+G86+G104+G122 -> 47973 | H36: =H80+H86+H104+H122 -> 60240 | I36: =I80+I86+I104+I122 -> 33336 | J36: =J80+J86+J104+J122 -> 53103 | K36: =K80+K86+K104+K122 -> 49874 | ... O36: =O80+O86+O104+O122 -> 48039
A37: ='Distribution Dashboard'!A28 -> RB3 (2) | B37: ='Distribution Dashboard'!B28 -> NRW | C37: ='Distribution Dashboard'!C28 -> m3 | D37: =D35-D36 -> 12771 | E37: =E35-E36 -> 19136 | F37: =F35-F36 -> 19757 | G37: =G35-G36 -> 23900 | H37: =H35-H36 -> 24979 | I37: =I35-I36 -> 14330 | J37: =J35-J36 -> 33443 | K37: =K35-K36 -> 24356 | ... O37: =O35-O36 -> 20029
A38: ='Distribution Dashboard'!A29 -> RB4 | B38: ='Distribution Dashboard'!B29 -> NRW | C38: ='Distribution Dashboard'!C29 -> % | D38: =D37/D35 -> 0.23480851 | E38: =E37/E35 -> 0.29780876 | F38: =F37/F35 -> 0.28238809 | G38: =G37/G35 -> 0.33253099 | H38: =H37/H35 -> 0.29311539 | I38: =I37/I35 -> 0.30063358 | J38: =J37/J35 -> 0.38641878 | K38: =K37/K35 -> 0.32811532 | ... O38: =O37/O35 -> 0.29424987
A39: ='Distribution Dashboard'!A30 -> 0 | B39: ='Distribution Dashboard'!B30 -> EASTERN REGION: KAYOLE,GONDI, KINUNGI,NJONJORO | C39: ='Distribution Dashboard'!C30 -> 0
A40: ='Distribution Dashboard'!A31 -> RA6 (B) (2) | B40: ='Distribution Dashboard'!B31 -> Volume Water Supplied | C40: ='Distribution Dashboard'!C31 -> m3 | D40: =D97+D125 -> 33056 | E40: =E97+E125 -> 39909 | F40: =F97+F125 -> 35284 | G40: =G97+G125 -> 38123 | H40: =H97+H125 -> 39016 | I40: =I97+I125 -> 29559 | J40: =J97+J125 -> 39778 | K40: =K97+K125 -> 36889 | ... O40: =O97+O125 -> 47240
...

Sheet Actual2223
A1: ='Distribution Dashboard'!A1 -> NAIVAWASS DISTRIBUTION DASHBOARD - NON-REVENUE WATER & ZONAL PERFORMANCE | B1: ='Distribution Dashboard'!B1 -> 0 | C1: ='Distribution Dashboard'!D1 -> 0
A2: ='Distribution Dashboard'!A2 -> 0 | B2: ='Distribution Dashboard'!B2 -> 46054 | C2: ='Distribution Dashboard'!D2 -> 0
A3: ='Distribution Dashboard'!A3 -> 0 | B3: ='Distribution Dashboard'!B3 -> 0 | C3: ='Distribution Dashboard'!D3 -> Monthly
A4: ='Distribution Dashboard'!A4 -> 0 | C4: ='Distribution Dashboard'!C4 -> Unit | D4: 44743 | E4: 44774 | F4: 44805 | G4: 44835 | H4: 44866 | I4: 44896 | J4: 44927 | K4: 44958 | L4: 44986 | M4: 45017 | N4: 45047 | O4: 45078
A5: ='Distribution Dashboard'!A6 -> 0 | B5: ='Distribution Dashboard'!B6 -> REGIONAL NRW | C5: ='Distribution Dashboard'!C6 -> 0
A6: ='Distribution Dashboard'!A7 -> 100 | B6: ='Distribution Dashboard'!B7 -> WATER AVAILABLE FOR SALES- REGIONS | C6: ='Distribution Dashboard'!C7 -> m3 | D6: =D17+D26+D27 -> 202300 | E6: =E17+E26+E27 -> 205466 | F6: =F17+F26+F31 -> 211119 | G6: =G17+G26+G31 -> 159438 | H6: =H17+H26+H31 -> 176489 | I6: =I17+I26+I31 -> 173351 | J6: =J17+J26+J31 -> 187922 | K6: =K17+K26+K31 -> 216999 | L6: =L17+L26+L31 -> 215601 | M6: =M17+M26+M31 -> 200611 | ... O6: =O17+O26+O31 -> 185559
A7: ='Distribution Dashboard'!A8 -> 128a | B7: ='Distribution Dashboard'!B8 -> VOLUME WATER BILLED(CUSTOMERS-M3) | C7: ='Distribution Dashboard'!C8 -> m3 | D7: =D18+D27+D31 -> 152162 | E7: =E18+E27+E31 -> 157614 | F7: =F18+F27+F32 -> 139547 | G7: =G18+G27+G32 -> 120836 | H7: =H18+H27+H32 -> 123996 | I7: =I18+I27+I32 -> 130054 | J7: =J18+J27+J32 -> 138635 | K7: =K18+K27+K32 -> 153470 | L7: =L18+L27+L32 -> 163824 | M7: =M18+M27+M32 -> 145291 | ... O7: =O18+O27+O32 -> 137010
A8: ='Distribution Dashboard'!A9 -> 128 | B8: ='Distribution Dashboard'!B9 -> GLOBAL NRW | C8: ='Distribution Dashboard'!C9 -> % | D8: =(D6-D7)/D6 -> 0.24783984 | E8: =(E6-E7)/E6 -> 0.23289498 | F8: =(F6-F7)/F6 -> 0.33901259 | G8: =(G6-G7)/G6 -> 0.24211292 | H8: =(H6-H7)/H6 -> 0.2974293 | I8: =(I6-I7)/I6 -> 0.24976493 | J8: =(J6-J7)/J6 -> 0.26227371 | K8: =(K6-K7)/K6 -> 0.29276172 | ... O8: =(O6-O7)/O6 -> 0.26163646
A9: ='Distribution Dashboard'!A10 -> 0 | B9: ='Distribution Dashboard'!B10 -> Number of Active water Connections | C9: ='Distribution Dashboard'!C10 -> NO. | D9: =D32+D23 -> 23761 | E9: =E32+E23 -> 27125 | F9: =F32+F23 -> 16098 | G9: =G32+G23 -> 19707 | H9: =H32+H23 -> 21640 | I9: =I32+I23 -> 20144 | J9: =J32+J23 -> 22923 | K9: =K32+K23 -> 24955 | ... O9: =O32+O23 -> 22371
A10: ='Distribution Dashboard'!A11 -> 0 | B10: ='Distribution Dashboard'!B11 -> Number of Active sewer Connections | C10: ='Distribution Dashboard'!C11 -> NO. | D10: =D33+D24 -> 7326 | E10: =E33+E24 -> 5299 | F10: =F33+F24 -> 8296 | G10: =G33+G24 -> 3219 | H10: =H33+H24 -> 8027 | I10: =I33+I24 -> 5516 | J10: =J33+J24 -> 6620 | K10: =K33+K24 -> 8110 | ... O10: =O33+O24 -> 7283
A11: ='Distribution Dashboard'!A12 -> 0 | B11: ='Distribution Dashboard'!B12 -> Number of In-active Sewer Connections | C11: ='Distribution Dashboard'!C12 -> NO.
A12: ='Distribution Dashboard'!A13 -> 0 | B12: ='Distribution Dashboard'!B13 -> Number of In-active Water Connections | C12: ='Distribution Dashboard'!C13 -> NO.
A13: ='Distribution Dashboard'!A14 -> 0 | B13: ='Distribution Dashboard'!B14 -> Number of Connections | C13: ='Distribution Dashboard'!C14 -> NO. | D13: =SUM(D9:D12) -> 31087 | E13: =SUM(E9:E12) -> 32424 | F13: =SUM(F9:F12) -> 24394 | G13: =SUM(G9:G12) -> 22926 | H13: =SUM(H9:H12) -> 29667 | I13: =SUM(I9:I12) -> 25660 | J13: =SUM(J9:J12) -> 29543 | K13: =SUM(K9:K12) -> 33065 | ... O13: =SUM(O9:O12) -> 29654
A14: ='Distribution Dashboard'!A15 -> 0 | B14: ='Distribution Dashboard'!B15 -> Maintenance, repair and operational cost | C14: ='Distribution Dashboard'!C15 -> KES
A15: ='Distribution Dashboard'!#REF! -> #REF! | B15: ='Distribution Dashboard'!#REF! -> #REF! | C15: ='Distribution Dashboard'!#REF! -> #REF!
A16: ='Distribution Dashboard'!A16 -> 0 | B16: ='Distribution Dashboard'!B16 -> CENTRAL REGION: CBD,CCCR,KABATI,SITE,KIHOTO,LAKEVIEW | C16: ='Distribution Dashboard'!C16 -> 0
A17: ='Distribution Dashboard'!A17 -> RA | B17: ='Distribution Dashboard'!B17 -> Volume Water Supplied | C17: ='Distribution Dashboard'!C17 -> m3 | D17: =D36+D42+D48+D54+D60+D78 -> 130641 | E17: =E36+E42+E48+E54+E60+E78 -> 128120 | F17: =F36+F42+F48+F54+F60+F78 -> 139029 | G17: =G36+G42+G48+G54+G60+G78 -> 95119 | H17: =H36+H42+H48+H54+H60+H78 -> 100181 | I17: =I36+I42+I48+I54+I60+I78 -> 108449 | J17: =J36+J42+J48+J54+J60+J78 -> 106481 | K17: =K36+K42+K48+K54+K60+K78 -> 125827 | ... O17: =O36+O42+O48+O54+O60+O78 -> 108257
A18: ='Distribution Dashboard'!A18 -> RA2 | B18: ='Distribution Dashboard'!B18 -> Volume Water Sold | C18: ='Distribution Dashboard'!C18 -> m3 | D18: =D37+D43+D49+D55+D61+D79 -> 90624 | E18: =E37+E43+E49+E55+E61+E79 -> 92447 | F18: =F37+F43+F49+F55+F61+F79 -> 91237 | G18: =G37+G43+G49+G55+G61+G79 -> 70936 | H18: =H37+H43+H49+H55+H61+H79 -> 71901 | I18: =I37+I43+I49+I55+I61+I79 -> 80684 | J18: =J37+J43+J49+J55+J61+J79 -> 82616 | K18: =K37+K43+K49+K55+K61+K79 -> 91234 | ... O18: =O37+O43+O49+O55+O61+O79 -> 81174
A19: ='Distribution Dashboard'!A19 -> RA3 | B19: ='Distribution Dashboard'!B19 -> NRW | C19: ='Distribution Dashboard'!C19 -> m3 | D19: =D17-D18 -> 40017 | E19: =E17-E18 -> 35673 | F19: =F17-F18 -> 47792 | G19: =G17-G18 -> 24183 | H19: =H17-H18 -> 28280 | I19: =I17-I18 -> 27765 | J19: =J17-J18 -> 23865 | K19: =K17-K18 -> 34593 | ... O19: =O17-O18 -> 27083
A20: ='Distribution Dashboard'!A20 -> RA4 | B20: ='Distribution Dashboard'!B20 -> NRW | C20: ='Distribution Dashboard'!C20 -> % | D20: =D19/D17 -> 0.30631272 | E20: =E19/E17 -> 0.27843428 | F20: =F19/F17 -> 0.34375562 | G20: =G19/G17 -> 0.25423943 | H20: =H19/H17 -> 0.28228906 | I20: =I19/I17 -> 0.25601896 | J20: =J19/J17 -> 0.22412449 | K20: =K19/K17 -> 0.2749251 | ... O20: =O19/O17 -> 0.2501732
A21: ='Distribution Dashboard'!A21 -> 0 | B21: ='Distribution Dashboard'!B21 -> Amount Billed Water | C21: ='Distribution Dashboard'!C21 -> KES
A22: ='Distribution Dashboard'!A22 -> 0 | B22: ='Distribution Dashboard'!B22 -> Amount Billed Sewer | C22: ='Distribution Dashboard'!C22 -> KES
A23: ='Distribution Dashboard'!A23 -> 0 | B23: ='Distribution Dashboard'!B23 -> Number of Active water Connections | C23: ='Distribution Dashboard'!C23 -> KES
A24: ='Distribution Dashboard'!A24 -> 0 | B24: ='Distribution Dashboard'!B24 -> Number of Active sewer Connections | C24: ='Distribution Dashboard'!C24 -> KES
A25: ='Distribution Dashboard'!A25 -> 0 | B25: ='Distribution Dashboard'!B25 -> SOUTHERN REGION: MAI MAHIU,KAMERE,HELLSGATE | C25: ='Distribution Dashboard'!C25 -> 0
A26: ='Distribution Dashboard'!A26 -> RA6 (B) | B26: ='Distribution Dashboard'!B26 -> Volume Water Supplied | C26: ='Distribution Dashboard'!C26 -> m3 | D26: =D66+D72+D90 -> 41208 | E26: =E66+E72+E90 -> 44603 | F26: =F66+F72+F90 -> 47696 | G26: =G66+G72+G90 -> 41393 | H26: =H66+H72+H90 -> 46641 | I26: =I66+I72+I90 -> 39242 | J26: =J66+J72+J90 -> 51898 | K26: =K66+K72+K90 -> 58107 | ... O26: =O66+O72+O90 -> 47648
A27: ='Distribution Dashboard'!A27 -> RB2 | B27: ='Distribution Dashboard'!B27 -> Volume Water Sold | C27: ='Distribution Dashboard'!C27 -> m3 | D27: =D67+D73+D91 -> 30451 | E27: =E67+E73+E91 -> 32743 | F27: =F67+F73+F91 -> 32212 | G27: =G67+G73+G91 -> 30193 | H27: =H67+H73+H91 -> 30455 | I27: =I67+I73+I91 -> 29226 | J27: =J67+J73+J91 -> 33096 | K27: =K67+K73+K91 -> 37281 | ... O27: =O67+O73+O91 -> 33465
A28: ='Distribution Dashboard'!A28 -> RB3 (2) | B28: ='Distribution Dashboard'!B28 -> NRW | C28: ='Distribution Dashboard'!C28 -> m3 | D28: =D26-D27 -> 10757 | E28: =E26-E27 -> 11860 | F28: =F26-F27 -> 15484 | G28: =G26-G27 -> 11200 | H28: =H26-H27 -> 16186 | I28: =I26-I27 -> 10016 | J28: =J26-J27 -> 18802 | K28: =K26-K27 -> 20826 | ... O28: =O26-O27 -> 14183
A29: ='Distribution Dashboard'!A29 -> RB4 | B29: ='Distribution Dashboard'!B29 -> NRW | C29: ='Distribution Dashboard'!C29 -> % | D29: =D28/D26 -> 0.26104155 | E29: =E28/E26 -> 0.2659014 | F29: =F28/F26 -> 0.32463938 | G29: =G28/G26 -> 0.27057715 | H29: =H28/H26 -> 0.34703373 | I29: =I28/I26 -> 0.25523674 | J29: =J28/J26 -> 0.36228756 | K29: =K28/K26 -> 0.35840776 | ... O29: =O28/O26 -> 0.29766202
A30: ='Distribution Dashboard'!A30 -> 0 | B30: ='Distribution Dashboard'!B30 -> EASTERN REGION: KAYOLE,GONDI, KINUNGI,NJONJORO | C30: ='Distribution Dashboard'!C30 -> 0
A31: ='Distribution Dashboard'!A31 -> RA6 (B) (2) | B31: ='Distribution Dashboard'!B31 -> Volume Water Supplied | C31: ='Distribution Dashboard'!C31 -> m3 | D31: =D84+D96+D100+D104 -> 31087 | E31: =E84+E96+E100+E104 -> 32424 | F31: =F84+F96+F100+F104 -> 24394 | G31: =G84+G96+G100+G104 -> 22926 | H31: =H84+H96+H100+H104 -> 29667 | I31: =I84+I96+I100+I104 -> 25660 | J31: =J84+J96+J100+J104 -> 29543 | K31: =K84+K96+K100+K104 -> 33065 | ... O31: =O84+O96+O100+O104 -> 29654
