Workbook
Name Actual_month: General!$B$3

Sheet Dashboard
A1: FINANCE DASHBOARD
B2: =INDEX('KPI 1'!$E18:$P18,Actual_month) -> 46082
D3: Monthly | J3: Cumulative | R3: 0.9
C4: Unit | G4: Target | H4: Actual | I4: % real. | M4: Target | N4: Actual | O4: % real.
A5: BILLING DASHBOARD - SUMMARY | Q5: monthly | R5: cumluative
A6: 1 | B6: Total Water Sales (Ksh) | C6: Ksh | D6: l | E6: l | F6: l | G6: =IFERROR(INDEX('KPI 1'!E$19:P$19,Actual_month),) -> 18825128 | H6: =IFERROR(INDEX('KPI 1'!$E$20:$P$20,Actual_month),) -> 18351480 | I6: =IFERROR(H6/G6,"") -> 0.9748396 | J6: l | K6: l | L6: l | M6: =IFERROR(INDEX('KPI 1'!$E$26:$P$26,Actual_month),) -> 161020690 | N6: =IFERROR(INDEX('KPI 1'!$E$27:$P$27,Actual_month),) -> 179809530 | O6: =IFERROR(N6/M6,"") -> 1.1166859 | P6: details | Q6: =G6*$R$3 -> 16942615 | R6: =M6*$R$3 -> 144918621 | S6: H | T6: v
A7: 2 | B7: Total Sewerage Sales (Ksh) | C7: Ksh | D7: l | E7: l | F7: l | G7: =IFERROR(INDEX('KPI 2'!E$19:P$19,Actual_month),) -> 5264966.7 | H7: =IFERROR(INDEX('KPI 2'!$E$20:$P$20,Actual_month),) -> 5950166 | I7: =IFERROR(H7/G7,"") -> 1.1301431 | J7: l | K7: l | L7: l | M7: =IFERROR(INDEX('KPI 2'!$E$26:$P$26,Actual_month),) -> 46508629 | N7: =IFERROR(INDEX('KPI 2'!$E$27:$P$27,Actual_month),) -> 52285082 | O7: =IFERROR(N7/M7,"") -> 1.1242017 | P7: details | Q7: =G7*$R$3 -> 4738470.1 | R7: =M7*$R$3 -> 41857766 | S7: H | T7: v
A8: 3 | B8: Bulk water | C8: Ksh | D8: l | E8: l | F8: l | G8: =IFERROR(INDEX('KPI a'!E$19:P$19,Actual_month),) -> 64130 | H8: =IFERROR(INDEX('KPI a'!$E$20:$P$20,Actual_month),) -> 30290 | I8: =IFERROR(H8/G8,"") -> 0.47232185 | J8: l | K8: l | L8: l | M8: =IFERROR(INDEX('KPI a'!$E$26:$P$26,Actual_month),) -> 577170 | N8: =IFERROR(INDEX('KPI a'!$E$27:$P$27,Actual_month),) -> 1096030 | O8: =IFERROR(N8/M8,"") -> 1.8989726 | P8: details | Q8: =G8*$R$3 -> 57717 | R8: =M8*$R$3 -> 519453 | S8: H | T8: v
A9: 4 | B9: Sanitation | C9: Ksh | D9: l | E9: l | F9: l | G9: =IFERROR(INDEX('KPI b1'!E$19:P$19,Actual_month),) -> 936756.39 | H9: =IFERROR(INDEX('KPI b1'!$E$20:$P$20,Actual_month),) -> 917568.5 | I9: =IFERROR(H9/G9,"") -> 0.97951667 | J9: l | K9: l | L9: l | M9: =IFERROR(INDEX('KPI b1'!$E$26:$P$26,Actual_month),) -> 8010534.5 | N9: =IFERROR(INDEX('KPI b1'!$E$27:$P$27,Actual_month),) -> 8990471 | O9: =IFERROR(N9/M9,"") -> 1.122331 | P9: details | Q9: =G9*$R$3 -> 843080.75 | R9: =M9*$R$3 -> 7209481 | S9: H | T9: v
A10: 5 | B10: new connection fee water | C10: Ksh | D10: l | E10: l | F10: l | G10: =IFERROR(INDEX('KPI c'!E$19:P$19,Actual_month),) -> 475000 | H10: =IFERROR(INDEX('KPI c'!$E$20:$P$20,Actual_month),) -> 147500 | I10: =IFERROR(H10/G10,"") -> 0.31052632 | J10: l | K10: l | L10: l | M10: =IFERROR(INDEX('KPI c'!$E$26:$P$26,Actual_month),) -> 4500000 | N10: =IFERROR(INDEX('KPI c'!$E$27:$P$27,Actual_month),) -> 3002500 | O10: =IFERROR(N10/M10,"") -> 0.66722222 | P10: details | Q10: =G10*$R$3 -> 427500 | R10: =M10*$R$3 -> 4050000 | S10: H | T10: v
A11: 6 | B11: new connection fee sewer | C11: Ksh | D11: l | E11: l | F11: l | G11: =IFERROR(INDEX('KPI e'!E$19:P$19,Actual_month),) -> 75000 | H11: =IFERROR(INDEX('KPI e'!$E$20:$P$20,Actual_month),) -> 0 | I11: =IFERROR(H11/G11,"") -> 0 | J11: l | K11: l | L11: l | M11: =IFERROR(INDEX('KPI e'!$E$26:$P$26,Actual_month),) -> 680000 | N11: =IFERROR(INDEX('KPI e'!$E$27:$P$27,Actual_month),) -> 142500 | O11: =IFERROR(N11/M11,"") -> 0.20955882 | P11: details | Q11: =G11*$R$3 -> 67500 | R11: =M11*$R$3 -> 612000 | S11: H | T11: v
A12: 7 | B12: reconnection fee (water+sewer) | C12: Ksh | D12: l | E12: l | F12: l | G12: =IFERROR(INDEX('KPI k'!E$19:P$19,Actual_month),) -> 582500 | H12: =IFERROR(INDEX('KPI k'!$E$20:$P$20,Actual_month),) -> 157500 | I12: =IFERROR(H12/G12,"") -> 0.27038627 | J12: l | K12: l | L12: l | M12: =IFERROR(INDEX('KPI k'!$E$26:$P$26,Actual_month),) -> 5242500 | N12: =IFERROR(INDEX('KPI k'!$E$27:$P$27,Actual_month),) -> 1335000 | O12: =IFERROR(N12/M12,"") -> 0.2546495 | P12: details | Q12: =G12*$R$3 -> 524250 | R12: =M12*$R$3 -> 4718250 | S12: H | T12: v
A13: 8 | B13: Prepaid kiosk | C13: Ksh | D13: l | E13: l | F13: l | G13: =IFERROR(INDEX('KPI y'!E$19:P$19,Actual_month),) -> 90000 | H13: =IFERROR(INDEX('KPI y'!$E$20:$P$20,Actual_month),) -> 61500 | I13: =IFERROR(H13/G13,"") -> 0.68333333 | J13: l | K13: l | L13: l | M13: =IFERROR(INDEX('KPI y'!$E$26:$P$26,Actual_month),) -> 810000 | N13: =IFERROR(INDEX('KPI y'!$E$27:$P$27,Actual_month),) -> 708200 | O13: =IFERROR(N13/M13,"") -> 0.87432099 | P13: details | Q13: =G13*$R$3 -> 81000 | R13: =M13*$R$3 -> 729000 | S13: H | T13: v
A14: 9 | B14: misc income-printing fee,CA,meter replacement fee,meter testing | C14: Ksh | D14: l | E14: l | F14: l | G14: =IFERROR(INDEX('KPI w'!E$19:P$19,Actual_month),) -> 112050 | H14: =IFERROR(INDEX('KPI w'!$E$20:$P$20,Actual_month),) -> 2454300 | I14: =IFERROR(H14/G14,"") -> 21.903614 | J14: l | K14: l | L14: l | M14: =IFERROR(INDEX('KPI w'!$E$26:$P$26,Actual_month),) -> 1008450 | N14: =IFERROR(INDEX('KPI w'!$E$27:$P$27,Actual_month),) -> 2918450 | O14: =IFERROR(N14/M14,"") -> 2.8939957 | P14: details | Q14: =G14*$R$3 -> 100845 | R14: =M14*$R$3 -> 907605 | S14: H | T14: v
A15: 10 | B15: sewer unblocking fee | C15: Ksh | D15: l | E15: l | F15: l | G15: =IFERROR(INDEX('KPI z'!E$19:P$19,Actual_month),) -> 2500 | H15: =IFERROR(INDEX('KPI z'!$E$20:$P$20,Actual_month),) -> 0 | I15: =IFERROR(H15/G15,"") -> 0 | J15: l | K15: l | L15: l | M15: =IFERROR(INDEX('KPI z'!$E$26:$P$26,Actual_month),) -> 22500 | N15: =IFERROR(INDEX('KPI z'!$E$27:$P$27,Actual_month),) -> 45000 | O15: =IFERROR(N15/M15,"") -> 2 | P15: details | Q15: =G15*$R$3 -> 2250 | R15: =M15*$R$3 -> 20250 | S15: H | T15: v
A16: 11 | B16: penalties (water+sewer) | C16: Ksh | D16: l | E16: l | F16: l | G16: =IFERROR(INDEX('KPI j'!E$19:P$19,Actual_month),) -> 190001 | H16: =IFERROR(INDEX('KPI j'!$E$20:$P$20,Actual_month),) -> 155000 | I16: =IFERROR(H16/G16,"") -> 0.81578518 | J16: l | K16: l | L16: l | M16: =IFERROR(INDEX('KPI j'!$E$26:$P$26,Actual_month),) -> 1710009 | N16: =IFERROR(INDEX('KPI j'!$E$27:$P$27,Actual_month),) -> 865000 | O16: =IFERROR(N16/M16,"") -> 0.50584529 | P16: details | Q16: =G16*$R$3 -> 171000.9 | R16: =M16*$R$3 -> 1539008.1 | S16: H | T16: v
A17: 12 | B17: Company exhauster | C17: Ksh | D17: l | E17: l | F17: l | G17: =IFERROR(INDEX('KPI 4(i)'!E$19:P$19,Actual_month),) -> 0 | H17: =IFERROR(INDEX('KPI 4(i)'!$E$20:$P$20,Actual_month),) -> 0 | I17: =IFERROR(H17/G17,"") | J17: l | K17: l | L17: l | M17: =IFERROR(INDEX('KPI 4(i)'!$E$26:$P$26,Actual_month),) -> 0 | N17: =IFERROR(INDEX('KPI 4(i)'!$E$27:$P$27,Actual_month),) -> 0 | O17: =IFERROR(N17/M17,"") | P17: details | Q17: =G17*$R$3 -> 0 | R17: =M17*$R$3 -> 0 | S17: H | T17: v
A18: 12 | B18: Customer exhauster | C18: Ksh | D18: l | E18: l | F18: l | G18: =IFERROR(INDEX('KPI 4 (ii)'!E$19:P$19,Actual_month),) -> 210000 | H18: =IFERROR(INDEX('KPI 4 (ii)'!$E$20:$P$20,Actual_month),) -> 180000 | I18: =IFERROR(H18/G18,"") -> 0.85714286 | J18: l | K18: l | L18: l | M18: =IFERROR(INDEX('KPI 4 (ii)'!$E$26:$P$26,Actual_month),) -> 1890000 | N18: =IFERROR(INDEX('KPI 4 (ii)'!$E$27:$P$27,Actual_month),) -> 1770000 | O18: =IFERROR(N18/M18,"") -> 0.93650794 | P18: details | Q18: =G18*$R$3 -> 189000 | R18: =M18*$R$3 -> 1701000 | S18: H | T18: v
A19: 13 | B19: Total billed (Ksh) | C19: Ksh | D19: l | E19: l | F19: l | G19: =IFERROR(INDEX('KPI 5'!E$19:P$19,Actual_month),) -> 26673902 | H19: =IFERROR(INDEX('KPI 5'!$E$20:$P$20,Actual_month),) -> 28313514 | I19: =IFERROR(H19/G19,"") -> 1.0614688 | J19: l | K19: l | L19: l | M19: =IFERROR(INDEX('KPI 5'!$E$26:$P$26,Actual_month),) -> 2.3059331e+08 | N19: =IFERROR(INDEX('KPI 5'!$E$27:$P$27,Actual_month),) -> 2.5116353e+08 | O19: =IFERROR(N19/M19,"") -> 1.0892056 | P19: details | Q19: =G19*$R$3 -> 24006512 | R19: =M19*$R$3 -> 2.0753398e+08 | S19: H | T19: v
A21: A | B21: Eastern Region | C21: DATE | D21: l | E21: l | F21: l | G21: =IFERROR(INDEX('KPI g'!E$19:P$19,Actual_month),) -> 0 | H21: =IFERROR(INDEX('KPI g'!$E$20:$P$20,Actual_month),) -> 10TH | I21: =IFERROR(H21/G21,"") | J21: l | K21: l | L21: l | M21: =IFERROR(INDEX('KPI g'!$E$26:$P$26,Actual_month),) -> 0 | N21: =H21 -> 10TH | O21: =IFERROR(N21/M21,"") | P21: details | R21: =M21*$R$3 -> 0 | S21: H | T21: v
A22: B | B22: Southern Region | C22: DATE | D22: l | E22: l | F22: l | G22: =IFERROR(INDEX('KPI x'!E$19:P$19,Actual_month),) -> 0 | H22: =IFERROR(INDEX('KPI x'!$E$20:$P$20,Actual_month),) -> 24TH | I22: =IFERROR(H22/G22,"") | J22: l | K22: l | L22: l | M22: =IFERROR(INDEX('KPI x'!$E$26:$P$26,Actual_month),) -> 0 | N22: =H22 -> 24TH | O22: =IFERROR(N22/M22,"") | P22: details | R22: =M22*$R$3 -> 0 | S22: H | T22: v
A23: C | B23: Central Region | C23: DATE | D23: l | E23: l | F23: l | G23: =IFERROR(INDEX('KPI x (2)'!E$19:P$19,Actual_month),) -> 0 | H23: =IFERROR(INDEX('KPI x (2)'!$E$20:$P$20,Actual_month),) -> 31ST | I23: =IFERROR(H23/G23,"") | J23: l | K23: l | L23: l | M23: =IFERROR(INDEX('KPI x (2)'!$E$26:$P$26,Actual_month),) -> 0 | N23: =H23 -> 31ST | O23: =IFERROR(N23/M23,"") | P23: details | R23: =M23*$R$3 -> 0 | S23: H | T23: v
A24: COLLECTION EFFICIENCY
A25: D | B25: Total accounts disconnected-water | C25: NO | D25: l | E25: l | F25: l | G25: =IFERROR(INDEX('KPI qi'!E$19:P$19,Actual_month),) -> 500 | H25: =IFERROR(INDEX('KPI qi'!$E$20:$P$20,Actual_month),) -> 148 | I25: =IFERROR(H25/G25,"") -> 0.296 | J25: l | K25: l | L25: l | M25: =IFERROR(INDEX('KPI qi'!$E$26:$P$26,Actual_month),) -> 4500 | N25: =IFERROR(INDEX('KPI qi'!$E$27:$P$27,Actual_month),) -> 1158 | O25: =IFERROR(N25/M25,"") -> 0.25733333 | P25: details | Q25: =G25*$R$3 -> 450 | R25: =M25*$R$3 -> 4050 | S25: H | T25: v
A26: E | B26: Total accounts disconnected-sewer | C26: NO | D26: l | E26: l | F26: l | G26: =IFERROR(INDEX('KPI h'!E$19:P$19,Actual_month),) -> 55 | H26: =IFERROR(INDEX('KPI h'!$E$20:$P$20,Actual_month),) -> 1 | I26: =IFERROR(H26/G26,"") -> 0.018181818 | J26: l | K26: l | L26: l | M26: =IFERROR(INDEX('KPI h'!$E$26:$P$26,Actual_month),) -> 495 | N26: =IFERROR(INDEX('KPI h'!$E$27:$P$27,Actual_month),) -> 30 | O26: =IFERROR(N26/M26,"") -> 0.060606061 | P26: details | Q26: =G26*$R$3 -> 49.5 | R26: =M26*$R$3 -> 445.5 | S26: H | T26: v
A27: 14 | B27: Total Collection for the month | C27: Ksh | D27: l | E27: l | F27: l | G27: =IFERROR(INDEX('KPI 6'!E$19:P$19,Actual_month),) -> 27944610 | H27: =IFERROR(INDEX('KPI 6'!$E$20:$P$20,Actual_month),) -> 31993098 | I27: =IFERROR(H27/G27,"") -> 1.1448754 | J27: l | K27: l | L27: l | M27: =IFERROR(INDEX('KPI 6'!$E$26:$P$26,Actual_month),) -> 2.4209576e+08 | N27: =IFERROR(INDEX('KPI 6'!$E$27:$P$27,Actual_month),) -> 2.345866e+08 | O27: =IFERROR(N27/M27,"") -> 0.9689827 | P27: details | Q27: =G27*$R$3 -> 25150149 | R27: =M27*$R$3 -> 2.1788619e+08 | S27: H | T27: v
A28: 7 | B28: Total Collection- Related Sales | C28: Ksh | D28: l | E28: l | F28: l | G28: =IFERROR(INDEX('KPI j'!E$19:P$19,Actual_month),) -> 190001 | H28: =IFERROR(INDEX('KPI j'!$E$20:$P$20,Actual_month),) -> 155000 | I28: =IFERROR(H28/G28,"") -> 0.81578518 | J28: l | K28: l | L28: l | M28: =IFERROR(INDEX('KPI j'!$E$26:$P$26,Actual_month),) -> 1710009 | N28: =IFERROR(INDEX('KPI j'!$E$27:$P$27,Actual_month),) -> 865000 | O28: =IFERROR(N28/M28,"") -> 0.50584529 | P28: details
A29: 15 | B29: Collection Efficiency - in % of billing | C29: % | D29: l | E29: l | F29: l | G29: =IFERROR(INDEX('KPI 9'!E$19:P$19,Actual_month),) -> 1.0476386 | H29: =IFERROR(INDEX('KPI 9'!$E$20:$P$20,Actual_month),) -> 1.0860913 | I29: =IFERROR(H29/G29,"") -> 1.0367041 | J29: l | K29: l | L29: l | M29: =IFERROR(INDEX('KPI 9'!$E$26:$P$26,Actual_month),) -> 1.0476386 | N29: =IFERROR(INDEX('KPI 9'!$E$27:$P$27,Actual_month),) -> 0.94457038 | O29: =IFERROR(N29/M29,"") -> 0.9016185 | P29: details | Q29: =G29*$R$3 -> 0.94287477 | R29: =M29*$R$3 -> 0.94287477 | S29: H | T29: v
A30: REGIONAL PERFORMANCE
A31: CENTRAL REGION: CBD,CCCR,KABATI,SITE,KIHOTO,LAKEVIEW,HOPEWELL
A32: 16a | B32: Amount Billed Water-Central | C32: Ksh. | D32: l | E32: l | F32: l | G32: =IFERROR(INDEX('KPI 10'!E$19:P$19,Actual_month),) -> 9044300 | H32: =IFERROR(INDEX('KPI 10'!$E$20:$P$20,Actual_month),) -> 10195970 | I32: =IFERROR(H32/G32,"") -> 1.1273366 | J32: l | K32: l | L32: l | M32: =IFERROR(INDEX('KPI 10'!$E$26:$P$26,Actual_month),) -> 81187895 | N32: =IFERROR(INDEX('KPI 10'!$E$27:$P$27,Actual_month),) -> 93178050 | O32: =IFERROR(N32/M32,"") -> 1.147684 | P32: details | Q32: =G32*$R$3 -> 8139870 | R32: =M32*$R$3 -> 73069106 | S32: H
A33: 17a | B33: Amount Billed Sewer-Central | C33: Ksh. | D33: l | E33: l | F33: l | G33: =IFERROR(INDEX('KPI 11'!E$19:P$19,Actual_month),) -> 5161165.8 | H33: =IFERROR(INDEX('KPI 11'!$E$20:$P$20,Actual_month),) -> 5821018.5 | I33: =IFERROR(H33/G33,"") -> 1.1278495 | J33: l | K33: l | L33: l | M33: =IFERROR(INDEX('KPI 11'!$E$26:$P$26,Actual_month),) -> 45605872 | N33: =IFERROR(INDEX('KPI 11'!$E$27:$P$27,Actual_month),) -> 51180684 | O33: =IFERROR(N33/M33,"") -> 1.1222389 | P33: details | Q33: =G33*$R$3 -> 4645049.2 | R33: =M33*$R$3 -> 41045285 | S33: H
A34: 18a | B34: othersales | C34: Ksh. | D34: l | E34: l | F34: l | G34: =IFERROR(INDEX('KPI 11a'!E$19:P$19,Actual_month),) -> 0 | H34: =IFERROR(INDEX('KPI 11a'!$E$20:$P$20,Actual_month),) -> 509798.5 | I34: =IFERROR(H34/G34,"") | J34: l | K34: l | L34: l | M34: =IFERROR(INDEX('KPI 11a'!$E$26:$P$26,Actual_month),) -> 0 | N34: =IFERROR(INDEX('KPI 11a'!$E$27:$P$27,Actual_month),) -> 7916502.5 | O34: =IFERROR(N34/M34,"") | P34: details | Q34: =G34*$R$3 -> 0 | R34: =M34*$R$3 -> 0 | S34: H
A35: 19a | B35: Amount Billed Water & Sewer-othersales-Central | C35: Ksh. | D35: l | E35: l | F35: l | G35: =IFERROR(INDEX('KPI 12'!E$19:P$19,Actual_month),) -> 14205466 | H35: =IFERROR(INDEX('KPI 12'!$E$20:$P$20,Actual_month),) -> 16526787 | I35: =IFERROR(H35/G35,"") -> 1.1634104 | J35: l | K35: l | L35: l | M35: =IFERROR(INDEX('KPI 12'!$E$26:$P$26,Actual_month),) -> 1.2679377e+08 | N35: =IFERROR(INDEX('KPI 12'!$E$27:$P$27,Actual_month),) -> 1.5227524e+08 | O35: =IFERROR(N35/M35,"") -> 1.2009678 | P35: details | Q35: =G35*$R$3 -> 12784919 | R35: =M35*$R$3 -> 1.1411439e+08 | S35: H
A36: 14a | B36: Amount Collected-Central | C36: Ksh. | D36: l | E36: l | F36: l | G36: =IFERROR(INDEX('KPI 13'!E$19:P$19,Actual_month),) -> 14915739 | H36: =IFERROR(INDEX('KPI 13'!$E$20:$P$20,Actual_month),) -> 22532132 | I36: =IFERROR(H36/G36,"") -> 1.5106279 | J36: l | K36: l | L36: l | M36: =IFERROR(INDEX('KPI 13'!$E$26:$P$26,Actual_month),) -> 1.3313346e+08 | N36: =IFERROR(INDEX('KPI 13'!$E$27:$P$27,Actual_month),) -> 1.4782438e+08 | O36: =IFERROR(N36/M36,"") -> 1.1103474 | P36: details | Q36: =G36*$R$3 -> 13424165 | R36: =M36*$R$3 -> 1.1982011e+08 | S36: H
A37: 15a | B37: Collection Efficiency-Central | C37: % | D37: l | E37: l | F37: l | G37: =IFERROR(INDEX('KPI 14'!E$19:P$19,Actual_month),) -> 1.05 | H37: =IFERROR(INDEX('KPI 14'!$E$20:$P$20,Actual_month),) -> 1.2996422 | I37: =IFERROR(H37/G37,"") -> 1.2377545 | J37: l | K37: l | L37: l | M37: =IFERROR(INDEX('KPI 14'!$E$26:$P$26,Actual_month),) -> 1.05 | N37: =IFERROR(INDEX('KPI 14'!$E$27:$P$27,Actual_month),) -> 0.97001417 | O37: =IFERROR(N37/M37,"") -> 0.92382302 | P37: details | Q37: =G37*$R$3 -> 0.945 | R37: =M37*$R$3 -> 0.945 | S37: H
A38: SOUTHERN REGION: HELLSGATE,KAMERE, MAI MAHIU,LONGONOT
A39: 16b | B39: Amount Billed Water-Southern | C39: Ksh. | D39: l | E39: l | F39: l | G39: =IFERROR(INDEX('KPI 15'!E$19:P$19,Actual_month),) -> 6650863.9 | H39: =IFERROR(INDEX('KPI 15'!$E$20:$P$20,Actual_month),) -> 4890400 | I39: =IFERROR(H39/G39,"") -> 0.73530298 | J39: l | K39: l | L39: l | M39: =IFERROR(INDEX('KPI 15'!$E$26:$P$26,Actual_month),) -> 52436203 | N39: =IFERROR(INDEX('KPI 15'!$E$27:$P$27,Actual_month),) -> 54746640 | O39: =IFERROR(N39/M39,"") -> 1.0440619 | P39: details | Q39: =G39*$R$3 -> 5985777.5 | R39: =M39*$R$3 -> 47192583 | S39: H
A40: 17b | B40: Amount Billed Sewer-Southern | C40: Ksh. | D40: l | E40: l | F40: l | G40: =IFERROR(INDEX('KPI 16'!E$19:P$19,Actual_month),) -> 0 | H40: =IFERROR(INDEX('KPI 16'!$E$20:$P$20,Actual_month),) -> 0 | I40: =IFERROR(H40/G40,"") | J40: l | K40: l | L40: l | M40: =IFERROR(INDEX('KPI 16'!$E$26:$P$26,Actual_month),) -> 0 | N40: =IFERROR(INDEX('KPI 16'!$E$27:$P$27,Actual_month),) -> 0 | O40: =IFERROR(N40/M40,"") | P40: details | Q40: =G40*$R$3 -> 0 | R40: =M40*$R$3 -> 0 | S40: H
A41: 18b | B41: othersales | C41: Ksh. | D41: l | E41: l | F41: l | G41: =IFERROR(INDEX('KPI 16A'!E$19:P$19,Actual_month),) -> 0 | H41: =IFERROR(INDEX('KPI 16A'!$E$20:$P$20,Actual_month),) -> 244520 | I41: =IFERROR(H41/G41,"") | J41: l | K41: l | L41: l | M41: =IFERROR(INDEX('KPI 16A'!$E$26:$P$26,Actual_month),) -> 0 | N41: =IFERROR(INDEX('KPI 16A'!$E$27:$P$27,Actual_month),) -> 4946482 | O41: =IFERROR(N41/M41,"") | P41: details | Q41: =G41*$R$3 -> 0 | R41: =M41*$R$3 -> 0 | S41: H
...

Sheet BUDGET2526
A1: =Dashboard!A1 -> FINANCE DASHBOARD
B4: MONTH | C4: UNIT | D4: JUL | E4: AUG | F4: SEP | G4: OCT | H4: NOV | I4: DEC | J4: JAN | K4: FEB | L4: MAR | M4: APR | N4: MAY | O4: JUN
A5: =Dashboard!A5 -> BILLING DASHBOARD - SUMMARY
A6: =Dashboard!A6 -> 1 | B6: =Dashboard!B6 -> Total Water Sales (Ksh) | C6: =Dashboard!C6 -> Ksh | D6: 16944468 | E6: 17161528 | F6: 17381828 | G6: 17650728 | H6: 17903428 | I6: 18139928 | J6: 18392628 | K6: 18621028 | L6: 18825128 | M6: 19013028 | N6: 19200928 | O6: 19385588
A7: =Dashboard!A7 -> 2 | B7: =Dashboard!B7 -> Total Sewerage Sales (Ksh) | C7: =Dashboard!C7 -> Ksh | D7: 5070284.1 | E7: 5094619.4 | F7: 5118954.8 | G7: 5143290.1 | H7: 5167625.4 | I7: 5191960.8 | J7: 5216296.1 | K7: 5240631.4 | L7: 5264966.7 | M7: 5289302.1 | N7: 5313637.4 | O7: 5337972.7
A8: =Dashboard!A8 -> 3 | B8: =Dashboard!B8 -> Bulk water | D8: 64130 | E8: 64130 | F8: 64130 | G8: 64130 | H8: 64130 | I8: 64130 | J8: 64130 | K8: 64130 | L8: 64130 | M8: 64130 | N8: 64130 | O8: 64130
A9: =Dashboard!#REF! -> #REF! | B9: =Dashboard!#REF! -> #REF!
A10: =Dashboard!A9 -> 4 | B10: =Dashboard!B9 -> Sanitation | D10: 842723.39 | E10: 853576.39 | F10: 864591.39 | G10: 878036.39 | H10: 890671.39 | I10: 902496.39 | J10: 915131.39 | K10: 926551.39 | L10: 936756.39 | M10: 946151.39 | N10: 955546.39 | O10: 964779.39
A11: =Dashboard!A10 -> 5 | B11: =Dashboard!B10 -> new connection fee water | D11: 455000 | E11: 407500 | F11: 412500 | G11: 587500 | H11: 562500 | I11: 537500 | J11: 550000 | K11: 512500 | L11: 475000 | M11: 425000 | N11: 425000 | O11: 420000
A12: =Dashboard!A11 -> 6 | B12: =Dashboard!B11 -> new connection fee sewer | D12: 80000 | E12: 75000 | F12: 75000 | G12: 75000 | H12: 75000 | I12: 75000 | J12: 75000 | K12: 75000 | L12: 75000 | M12: 75000 | N12: 75000 | O12: 75000
A13: =Dashboard!A12 -> 7 | B13: =Dashboard!B12 -> reconnection fee (water+sewer) | D13: 582500 | E13: 582500 | F13: 582500 | G13: 582500 | H13: 582500 | I13: 582500 | J13: 582500 | K13: 582500 | L13: 582500 | M13: 582500 | N13: 582500 | O13: 582500
A14: =Dashboard!A13 -> 8 | B14: =Dashboard!B13 -> Prepaid kiosk | C14: =Dashboard!C8 -> Ksh | D14: 90000 | E14: 90000 | F14: 90000 | G14: 90000 | H14: 90000 | I14: 90000 | J14: 90000 | K14: 90000 | L14: 90000 | M14: 90000 | N14: 90000 | O14: 90000
A15: =Dashboard!A14 -> 9 | B15: =Dashboard!B14 -> misc income-printing fee,CA,meter replacement fee,meter testing | C15: =Dashboard!C10 -> Ksh | D15: 112050 | E15: 112050 | F15: 112050 | G15: 112050 | H15: 112050 | I15: 112050 | J15: 112050 | K15: 112050 | L15: 112050 | M15: 112050 | N15: 112050 | O15: 112050
A16: =Dashboard!A15 -> 10 | B16: =Dashboard!B15 -> sewer unblocking fee | C16: =Dashboard!C11 -> Ksh | D16: 2500 | E16: 2500 | F16: 2500 | G16: 2500 | H16: 2500 | I16: 2500 | J16: 2500 | K16: 2500 | L16: 2500 | M16: 2500 | N16: 2500 | O16: 2500
A17: =Dashboard!A16 -> 11 | B17: =Dashboard!B16 -> penalties (water+sewer) | C17: =Dashboard!C12 -> Ksh | D17: 110001 | E17: 260001 | F17: 220001 | G17: 150001 | H17: 160001 | I17: 240001 | J17: 190001 | K17: 190001 | L17: 190001 | M17: 160001 | N17: 110001 | O17: 120001
A18: =Dashboard!#REF! -> #REF! | B18: =Dashboard!#REF! -> #REF! | C18: =Dashboard!C13 -> Ksh
A19: =Dashboard!A17 -> 12 | B19: =Dashboard!B17 -> Company exhauster | C19: =Dashboard!C14 -> Ksh | D19: 0 | E19: 0 | F19: 0 | G19: 0 | H19: 0 | I19: 0 | J19: 0 | K19: 0 | L19: 0 | M19: 0 | N19: 0 | O19: 0
A20: =Dashboard!A18 -> 12 | B20: =Dashboard!B18 -> Customer exhauster | C20: =Dashboard!C15 -> Ksh | D20: 210000 | E20: 210000 | F20: 210000 | G20: 210000 | H20: 210000 | I20: 210000 | J20: 210000 | K20: 210000 | L20: 210000 | M20: 210000 | N20: 210000 | O20: 210000
A21: =Dashboard!A19 -> 13 | B21: =Dashboard!B19 -> Total billed (Ksh) | C21: =Dashboard!C17 -> Ksh | D21: =D6+D7+D9+D11+D12+D13+D14+D16+D17+D20+D10+D15-D14 -> 24409526 | E21: =E6+E7+E9+E11+E12+E13+E14+E16+E17+E20+E10+E15-E14 -> 24759275 | F21: =F6+F7+F9+F11+F12+F13+F14+F16+F17+F20+F10+F15-F14 -> 24979925 | G21: =G6+G7+G9+G11+G12+G13+G14+G16+G17+G20+G10+G15-G14 -> 25391605 | H21: =H6+H7+H9+H11+H12+H13+H14+H16+H17+H20+H10+H15-H14 -> 25666276 | I21: =I6+I7+I9+I11+I12+I13+I14+I16+I17+I20+I10+I15-I14 -> 25993936 | J21: =J6+J7+J9+J11+J12+J13+J14+J16+J17+J20+J10+J15-J14 -> 26246106 | K21: =K6+K7+K9+K11+K12+K13+K14+K16+K17+K20+K10+K15-K14 -> 26472762 | ... O21: =O6+O7+O9+O11+O12+O13+O14+O16+O17+O20+O10+O15-O14 -> 27210391
A22: =Dashboard!A20 -> 0 | B22: =Dashboard!B20 -> 0
A23: =Dashboard!A21 -> A | B23: =Dashboard!B21 -> Eastern Region | C23: =Dashboard!C21 -> DATE
A24: =Dashboard!A22 -> B | B24: =Dashboard!B22 -> Southern Region | C24: =Dashboard!C22 -> DATE
A25: =Dashboard!A23 -> C | B25: =Dashboard!B23 -> Central Region | C25: =Dashboard!C23 -> DATE
A26: =Dashboard!A24 -> COLLECTION EFFICIENCY | B26: =Dashboard!B24 -> 0
A27: =Dashboard!A25 -> D | B27: =Dashboard!B25 -> Total accounts disconnected-water | C27: =Dashboard!C25 -> NO | D27: 500 | E27: 500 | F27: 500 | G27: 500 | H27: 500 | I27: 500 | J27: 500 | K27: 500 | L27: 500 | M27: 500 | N27: 500 | O27: 500
A28: =Dashboard!A26 -> E | B28: =Dashboard!B26 -> Total accounts disconnected-sewer | C28: =Dashboard!C26 -> NO | D28: 55 | E28: 55 | F28: 55 | G28: 55 | H28: 55 | I28: 55 | J28: 55 | K28: 55 | L28: 55 | M28: 55 | N28: 55 | O28: 55
A29: =Dashboard!A27 -> 14 | B29: =Dashboard!B27 -> Total Collection for the month | C29: =Dashboard!C27 -> Ksh | D29: =D21*D31 -> 25630003 | E29: =E21*E31 -> 25997238 | F29: =F21*F31 -> 26228921 | G29: =G21*G31 -> 26723339 | H29: =H21*H31 -> 26984968 | I29: =I21*I31 -> 27296721 | J29: =J21*J31 -> 27537000 | K29: =K21*K31 -> 27752961 | ... O29: =O21*O31 -> 28455822
A30: =Dashboard!A28 -> 7 | B30: =Dashboard!B28 -> Total Collection- Related Sales | C30: =Dashboard!C28 -> Ksh | E30: =D21/E29 -> 0.93892766 | F30: =E21/F29 -> 0.94396847 | G30: =F21/G29 -> 0.93476064 | H30: =G21/H29 -> 0.94095368 | I30: =H21/I29 -> 0.94026954 | J30: =I21/J29 -> 0.94396398 | K30: =J21/K29 -> 0.9457047 | L30: =K21/L29 -> 0.94732979 | ... O30: =N21/O29 -> 0.94838809
A31: =Dashboard!A29 -> 15 | B31: =Dashboard!B29 -> Collection Efficiency - in % of billing | C31: =Dashboard!C29 -> % | D31: 1.05 | E31: 1.05 | F31: 1.05 | G31: 1.0524478 | H31: 1.0513784 | I31: 1.0501188 | J31: 1.0491842 | K31: 1.0483591 | L31: 1.0476386 | M31: 1.0471458 | N31: 1.0465479 | O31: 1.0457704
A32: =Dashboard!A31 -> CENTRAL REGION: CBD,CCCR,KABATI,SITE,KIHOTO,LAKEVIEW,HOPEWELL
A33: =Dashboard!A32 -> 16a | B33: =Dashboard!B32 -> Amount Billed Water-Central | C33: =Dashboard!C32 -> Ksh. | D33: 8942465.9 | E33: 8996210.7 | F33: 9045864.1 | G33: 9035851.2 | H33: 9029894.1 | I33: 9020852.3 | J33: 9032887.4 | K33: 9039569.4 | L33: 9044300 | M33: 9063999.3 | N33: 9084168.1 | O33: 9104601.9
A34: =Dashboard!A33 -> 17a | B34: =Dashboard!B33 -> Amount Billed Sewer-Central | C34: =Dashboard!C33 -> Ksh. | D34: 4973474.6 | E34: 4996935.2 | F34: 5020396 | G34: 5043857.1 | H34: 5067318.4 | I34: 5090779.9 | J34: 5114241.6 | K34: 5137703.6 | L34: 5161165.8 | M34: 5184628.2 | N34: 5208090.8 | O34: 5231553.6
A35: =Dashboard!A34 -> 18a | B35: =Dashboard!B34 -> othersales | C35: =Dashboard!C34 -> Ksh.
A36: =Dashboard!A35 -> 19a | B36: =Dashboard!B35 -> Amount Billed Water & Sewer-othersales-Central | C36: =Dashboard!C35 -> Ksh. | D36: =D33+D34+D35 -> 13915941 | E36: =E33+E34+E35 -> 13993146 | F36: =F33+F34+F35 -> 14066260 | G36: =G33+G34+G35 -> 14079708 | H36: =H33+H34+H35 -> 14097212 | I36: =I33+I34+I35 -> 14111632 | J36: =J33+J34+J35 -> 14147129 | K36: =K33+K34+K35 -> 14177273 | ... O36: =O33+O34+O35 -> 14336156
A37: =Dashboard!A36 -> 14a | B37: =Dashboard!B36 -> Amount Collected-Central | C37: =Dashboard!C36 -> Ksh. | D37: =D38*D36 -> 14611738 | E37: =E38*E36 -> 14692803 | F37: =F38*F36 -> 14769573 | G37: =G38*G36 -> 14783694 | H37: =H38*H36 -> 14802073 | I37: =I38*I36 -> 14817214 | J37: =J38*J36 -> 14854486 | K37: =K38*K36 -> 14886137 | ... O37: =O38*O36 -> 15052963
A38: =Dashboard!A37 -> 15a | B38: =Dashboard!B37 -> Collection Efficiency-Central | C38: =Dashboard!C37 -> % | D38: 1.05 | E38: 1.05 | F38: 1.05 | G38: 1.05 | H38: 1.05 | I38: 1.05 | J38: 1.05 | K38: 1.05 | L38: 1.05 | M38: 1.05 | N38: 1.05 | O38: 1.05
A39: =Dashboard!A38 -> SOUTHERN REGION: HELLSGATE,KAMERE, MAI MAHIU,LONGONOT
A40: =Dashboard!A39 -> 16b | B40: =Dashboard!B39 -> Amount Billed Water-Southern | C40: =Dashboard!C39 -> Ksh. | D40: 5065118.2 | E40: 5186854 | F40: 5320133 | G40: 5584553.7 | H40: 5827594.1 | I40: 6061586.4 | J40: 6268878.1 | K40: 6470621.6 | L40: 6650863.9 | M40: 6799132.4 | N40: 6946856.2 | O40: 7091067.9
A41: =Dashboard!A40 -> 17b | B41: =Dashboard!B40 -> Amount Billed Sewer-Southern | C41: =Dashboard!C40 -> Ksh. | D41: 0 | E41: 0 | F41: 0 | G41: 0 | H41: 0 | I41: 0 | J41: 0 | K41: 0 | L41: 0 | M41: 0 | N41: 0 | O41: 0
A42: =Dashboard!A41 -> 18b | B42: =Dashboard!B41 -> othersales | C42: =Dashboard!C41 -> Ksh.
...

Sheet ACTUAL 2526
A1: =Dashboard!A1 -> FINANCE DASHBOARD
B4: MONTH | C4: UNIT | E4: JUL | F4: AUG | G4: SEP | H4: OCT | I4: NOV | J4: DEC | K4: JAN | L4: FEB | M4: MAR | N4: APR | O4: MAY | P4: JUN
A5: =Dashboard!A5 -> BILLING DASHBOARD - SUMMARY
A6: =Dashboard!A6 -> 1 | B6: =Dashboard!B6 -> Total Water Sales (Ksh) | C6: =Dashboard!C6 -> Ksh | E6: 18389070 | F6: 22070060 | G6: =18397090+440 -> 18397530 | H6: 21684080 | I6: =17026640+10140 -> 17036780 | J6: 16441310 | K6: 25608070 | L6: 21831150 | M6: 18351480
A7: =Dashboard!A7 -> 2 | B7: =Dashboard!B7 -> Total Sewerage Sales (Ksh) | C7: =Dashboard!C7 -> Ksh | E7: 5703321 | F7: 6046366 | G7: =5665420.8+55465.2-350 -> 5720536 | H7: 5831421 | I7: =5336003.5+7130 -> 5343133.5 | J7: 4905403.8 | K7: 6958143.5 | L7: 5826591 | M7: 5950166
A8: =Dashboard!A8 -> 3 | B8: =Dashboard!B8 -> Bulk water | C8: =Dashboard!C8 -> Ksh | E8: 185510 | F8: 166400 | G8: 165100 | H8: 164840 | I8: 126750 | J8: 122200 | K8: 46020 | L8: 88920 | M8: 30290
C9: =Dashboard!C9 -> Ksh
A10: =Dashboard!A9 -> 4 | B10: =Dashboard!B9 -> Sanitation | C10: =Dashboard!C10 -> Ksh | E10: 919453.5 | F10: 1103503 | G10: =919854.5+22 -> 919876.5 | H10: 1084204 | I10: =851332+507 -> 851839 | J10: 822065.5 | K10: 1280403.5 | L10: 1091557.5 | M10: 917568.5
A11: =Dashboard!A10 -> 5 | B11: =Dashboard!B10 -> new connection fee water | C11: =Dashboard!C11 -> Ksh | E11: 385000 | F11: 455000 | G11: 345000 | H11: 422500 | I11: 255000 | J11: 360000 | K11: 440000 | L11: 192500 | M11: 147500
A12: =Dashboard!A11 -> 6 | B12: =Dashboard!B11 -> new connection fee sewer | C12: =Dashboard!C12 -> Ksh | E12: 0 | F12: 22500 | G12: 22500 | H12: 20000 | I12: 27500 | J12: 0 | K12: 22500 | L12: 27500 | M12: 0
A13: =Dashboard!A12 -> 7 | B13: =Dashboard!B12 -> reconnection fee (water+sewer) | C13: =Dashboard!C13 -> Ksh | E13: 165000 | F13: 261500 | G13: 120500 | H13: 67500 | I13: 114000 | J13: 101000 | K13: 162000 | L13: 186000 | M13: 157500
A14: =Dashboard!A13 -> 8 | B14: =Dashboard!B13 -> Prepaid kiosk | C14: =Dashboard!C8 -> Ksh | E14: 78800 | F14: 82100 | G14: 74600 | H14: 84300 | I14: 67100 | J14: 62600 | K14: 116200 | L14: 81000 | M14: 61500
A15: =Dashboard!A14 -> 9 | B15: =Dashboard!B14 -> misc income-printing fee,CA,meter replacement fee,meter testing | C15: =Dashboard!C10 -> Ksh | E15: 115100 | F15: 30900 | G15: 49000 | H15: 44200 | I15: 68950 | J15: 21500 | K15: =90200-K16 -> 57700 | L15: 76800 | M15: 2454300
A16: =Dashboard!A15 -> 10 | B16: =Dashboard!B15 -> sewer unblocking fee | C16: =Dashboard!C11 -> Ksh | E16: 2500 | F16: 5000 | G16: 5000 | H16: 0 | I16: 0 | J16: 0 | K16: 32500 | L16: 0 | M16: 0
A17: =Dashboard!A16 -> 11 | B17: =Dashboard!B16 -> penalties (water+sewer) | C17: =Dashboard!C12 -> Ksh | E17: 40000 | F17: 0 | G17: 280000 | H17: 90000 | I17: 0 | J17: 0 | K17: 285000 | L17: 15000 | M17: 155000
A18: =Dashboard!#REF! -> #REF! | B18: =Dashboard!#REF! -> #REF! | C18: =Dashboard!C13 -> Ksh
A19: =Dashboard!A17 -> 12 | B19: =Dashboard!B17 -> Company exhauster | C19: =Dashboard!C14 -> Ksh | E19: 0 | F19: 0 | I19: 0 | J19: 0 | K19: 0 | L19: 0 | M19: 0
A20: =Dashboard!A18 -> 12 | B20: =Dashboard!B18 -> Customer exhauster | C20: =Dashboard!C15 -> Ksh | E20: 180000 | F20: 180000 | G20: 210000 | H20: 210000 | I20: 195000 | J20: 195000 | K20: 210000 | L20: 210000 | M20: 180000
A21: =Dashboard!A19 -> 13 | B21: =Dashboard!B19 -> Total billed (Ksh) | C21: =Dashboard!C17 -> Ksh | D21: ='Actual 202425'!P21 -> 28905832 | E21: =SUM(E6:E20)-(E14+E8) -> 25899444 | F21: =SUM(F6:F20)-(F14+F8) -> 30174829 | G21: =SUM(G6:G20)-(G14+G8) -> 26069942 | H21: =SUM(H6:H20)-(H14+H8) -> 29453905 | I21: =SUM(I6:I20)-(I14+I8) -> 23892202 | J21: =SUM(J6:J20)-(J14+J8) -> 22846279 | K21: =SUM(K6:K20)-(K14+K8) -> 35056317 | L21: =SUM(L6:L20)-(L14+L8) -> 29457098 | ... P21: =SUM(P6:P20)-(P14+P8) -> 0
A22: =Dashboard!A20 -> 0 | B22: =Dashboard!B20 -> 0 | C22: =Dashboard!C18 -> Ksh
A23: =Dashboard!A21 -> A | B23: =Dashboard!B21 -> Eastern Region | C23: =Dashboard!C21 -> DATE | E23: 9TH | F23: 12th | G23: 8th | H23: 9TH | I23: 13TH | J23: 12TH | K23: 15TH | L23: 10TH | M23: 10TH
A24: =Dashboard!A22 -> B | B24: =Dashboard!B22 -> Southern Region | C24: =Dashboard!C22 -> DATE | E24: 17TH | F24: 15th | G24: 15th | H24: 22nd | I24: 18TH | J24: 23RD | K24: 30TH | L24: 25TH | M24: 24TH
A25: =Dashboard!A23 -> C | B25: =Dashboard!B23 -> Central Region | C25: =Dashboard!C23 -> DATE | E25: 31ST | F25: 30th | G25: 29th | H25: 31st | I25: 28TH | J25: 23RD | K25: 30TH | L25: 27TH | M25: 31ST
A26: =Dashboard!A24 -> COLLECTION EFFICIENCY | B26: =Dashboard!B24 -> 0 | C26: =Dashboard!C20 -> 0
A27: =Dashboard!A25 -> D | B27: =Dashboard!B25 -> Total accounts disconnected-water | C27: =Dashboard!C25 -> NO | E27: 152 | F27: 229 | G27: 112 | H27: 42 | I27: 99 | J27: 101 | K27: 142 | L27: 133 | M27: 148
A28: =Dashboard!A26 -> E | B28: =Dashboard!B26 -> Total accounts disconnected-sewer | C28: =Dashboard!C26 -> NO | E28: 6 | F28: 3 | G28: 3 | H28: 1 | I28: 2 | J28: 0 | K28: 0 | L28: 14 | M28: 1
A29: =Dashboard!A27 -> 14 | B29: =Dashboard!B27 -> Total Collection for the month | C29: =Dashboard!C27 -> Ksh | E29: 25396691 | F29: 22000368 | G29: 23442340 | H29: 29982819 | I29: 22433751 | J29: 27037162 | K29: 24586578 | L29: 27713797 | M29: 31993098
A30: =Dashboard!A28 -> 7 | B30: =Dashboard!B28 -> Total Collection- Related Sales | C30: =Dashboard!C18 -> Ksh
A31: =Dashboard!A29 -> 15 | B31: =Dashboard!B29 -> Collection Efficiency - in % of billing | E31: =E29/D21 -> 0.87860095 | F31: =F29/E21 -> 0.84945328 | G31: =G29/F21 -> 0.77688392 | H31: =H29/G21 -> 1.1500915 | I31: =I29/H21 -> 0.76165626 | J31: =J29/I21 -> 1.1316312 | K31: =K29/J21 -> 1.0761743 | L31: =L29/K21 -> 0.79055073 | ... P31: =P29/O21 -> #DIV/0!
A32: =Dashboard!A31 -> CENTRAL REGION: CBD,CCCR,KABATI,SITE,KIHOTO,LAKEVIEW,HOPEWELL
A33: =Dashboard!A32 -> 16a | B33: =Dashboard!B32 -> Amount Billed Water-Central | C33: =Dashboard!C32 -> Ksh. | E33: 9210800 | F33: 10871060 | G33: 10150080 | H33: 11059010 | I33: =9178550+10140 -> 9188690 | J33: 8043560 | K33: 13738330 | L33: 10720550 | M33: 10195970
A34: =Dashboard!A33 -> 17a | B34: =Dashboard!B33 -> Amount Billed Sewer-Central | C34: =Dashboard!C33 -> Ksh. | E34: 5560946 | F34: 5918138.5 | G34: =5553915.8+55465.2-350 -> 5609031 | H34: 5721311 | I34: =5236748.5+7130 -> 5243878.5 | J34: 4788131.3 | K34: 6824426 | L34: 5693803.5 | M34: 5821018.5
A35: =Dashboard!A34 -> 18a | B35: =Dashboard!B34 -> othersales | C35: =Dashboard!C34 -> Ksh. | E35: 871940 | F35: 904453 | G35: 904154 | H35: 1010650.5 | I35: =811077.5+507 -> 811584.5 | J35: 696178 | K35: 1284916.5 | L35: 922827.5 | M35: 509798.5
A36: =Dashboard!A35 -> 19a | B36: =Dashboard!B35 -> Amount Billed Water & Sewer-othersales-Central | C36: =Dashboard!C35 -> Ksh. | D36: ='Actual 202425'!P36 -> 18208520 | E36: =E33+E34+E35 -> 15643686 | F36: =F33+F34+F35 -> 17693652 | G36: =G33+G34+G35 -> 16663265 | H36: =H33+H34+H35 -> 17790972 | I36: =I33+I34+I35 -> 15244153 | J36: =J33+J34+J35 -> 13527869 | K36: =K33+K34+K35 -> 21847672 | L36: =L33+L34+L35 -> 17337181 | ... P36: =P33+P34+P35 -> 0
A37: =Dashboard!A36 -> 14a | B37: =Dashboard!B36 -> Amount Collected-Central | C37: =Dashboard!C36 -> Ksh. | E37: 15973822 | F37: 13044625 | G37: 14430304 | H37: =19726476.6+15000 -> 19741477 | I37: 14374630 | J37: 18112068 | K37: 13052148 | L37: 16563178 | M37: 22532132
A38: =Dashboard!A37 -> 15a | B38: =Dashboard!B37 -> Collection Efficiency-Central | C38: =Dashboard!C37 -> % | E38: =E37/D36 -> 0.87727187 | F38: =F37/E36 -> 0.83385878 | G38: =G37/F36 -> 0.81556393 | H38: =H37/G36 -> 1.1847304 | I38: =I37/H36 -> 0.80797333 | J38: =J37/I36 -> 1.1881322 | K38: =K37/J36 -> 0.96483394 | L38: =L37/K36 -> 0.75812092 | ... P38: =P37/O36 -> #DIV/0!
A39: =Dashboard!A38 -> SOUTHERN REGION: HELLSGATE,KAMERE, MAI MAHIU,LONGONOT
A40: =Dashboard!A39 -> 16b | B40: =Dashboard!B39 -> Amount Billed Water-Southern | C40: =Dashboard!C39 -> Ksh. | E40: 5272370 | F40: 7465830 | G40: 5039430 | H40: 7076450 | I40: 4791020 | J40: 5179850 | K40: 8044460 | L40: 6986830 | M40: 4890400
A41: =Dashboard!A40 -> 17b | B41: =Dashboard!B40 -> Amount Billed Sewer-Southern | C41: =Dashboard!C40 -> Ksh. | E41: 0 | F41: 0 | G41: 0 | H41: 0 | I41: 0 | J41: 0 | K41: 0 | L41: 0 | M41: 0
A42: =Dashboard!A41 -> 18b | B42: =Dashboard!B41 -> othersales | C42: =Dashboard!C41 -> Ksh. | E42: 630818.5 | F42: 696791.5 | G42: 547121.5 | H42: 633322.5 | I42: 416851 | J42: 500992.5 | K42: 746723 | L42: 529341.5 | M42: 244520
...

Sheet Actual 202425
A1: =Dashboard!A1 -> FINANCE DASHBOARD
B4: MONTH | C4: UNIT | E4: JUL | F4: AUG | G4: SEP | H4: OCT | I4: NOV | J4: DEC | K4: JAN | L4: FEB | M4: MAR | N4: APR | O4: MAY | P4: JUN
A5: =Dashboard!A5 -> BILLING DASHBOARD - SUMMARY
A6: =Dashboard!A6 -> 1 | B6: =Dashboard!B6 -> Total Water Sales (Ksh) | C6: =Dashboard!C6 -> Ksh | E6: 11183420 | F6: 13918957 | G6: 13018249 | H6: 12608519 | I6: 14174994 | J6: 8977679 | K6: 14767948 | L6: 13060906 | M6: 13951180 | N6: 13956857 | O6: 19515330 | P6: 20899160
A7: =Dashboard!A7 -> 2 | B7: =Dashboard!B7 -> Total Sewerage Sales (Ksh) | C7: =Dashboard!C7 -> Ksh | E7: 4109000.4 | F7: 5060354.7 | G7: 4299927.7 | H7: 4437132.7 | I7: 4483043.5 | J7: 3764102.7 | K7: =5424626.2+350 -> 5424976.2 | L7: 4666903.2 | M7: 4963782.5 | N7: 5710578.7 | O7: 6133011 | P7: 6224363.5
A8: =Dashboard!A8 -> 3 | B8: =Dashboard!B8 -> Bulk water | E8: 22320 | F8: 28370 | G8: 64720 | H8: 22800 | I8: 40480 | J8: 25520 | K8: 51520 | L8: 59520 | M8: 104400 | N8: 73540 | O8: 63440 | P8: 165230
A9: =Dashboard!#REF! -> #REF! | B9: =Dashboard!#REF! -> #REF! | E9: 491000 | F9: 494150 | G9: 496750 | H9: 498550 | I9: 498350 | J9: 501650 | K9: =502600+800 -> 503400 | L9: 507750 | M9: 510500 | N9: 281750 | O9: 0 | P9: 0
A10: =Dashboard!A9 -> 4 | B10: =Dashboard!B9 -> Sanitation | N10: 456894.5 | O10: 975766.5 | P10: 1044958
A11: =Dashboard!A10 -> 5 | B11: =Dashboard!B10 -> new connection fee water | E11: 327500 | F11: 172500 | G11: 90000 | H11: 35000 | I11: 102500 | J11: 145000 | K11: 377500 | L11: 225000 | M11: 245000 | N11: 417500 | O11: 187500 | P11: 265000
A12: =Dashboard!A11 -> 6 | B12: =Dashboard!B11 -> new connection fee sewer | E12: 50000 | F12: 30000 | G12: 37500 | H12: 12500 | I12: 0 | J12: 25000 | K12: 10500 | L12: 60000 | M12: 22500 | N12: 17500 | O12: 0 | P12: 20000
A13: =Dashboard!A12 -> 7 | B13: =Dashboard!B12 -> reconnection fee (water+sewer) | E13: 714000 | F13: 279000 | G13: 192500 | H13: 270000 | I13: 176500 | J13: =150500+4500 -> 155000 | K13: 268500 | L13: 165000 | M13: 243500 | N13: 122500 | O13: 151000 | P13: 127000
A14: =Dashboard!A13 -> 8 | B14: =Dashboard!B13 -> Prepaid kiosk | C14: =Dashboard!C8 -> Ksh | E14: 77900 | F14: 100000 | G14: 107100 | H14: 99700 | I14: 100900 | J14: 57800 | K14: 124500 | L14: 96800 | M14: 100800 | N14: 67500 | O14: 86800 | P14: 124600
A15: =Dashboard!A14 -> 9 | B15: =Dashboard!B14 -> misc income-printing fee,CA,meter replacement fee,meter testing | C15: =Dashboard!C10 -> Ksh | E15: 75850 | F15: 51400 | G15: 133100 | H15: 165000 | I15: 46900 | J15: 80800 | K15: 147500 | L15: 100950 | M15: 163400 | N15: 295950 | O15: 143650 | P15: 90350
A16: =Dashboard!A15 -> 10 | B16: =Dashboard!B15 -> sewer unblocking fee | C16: =Dashboard!C11 -> Ksh | J16: 2500 | O16: 2500
A17: =Dashboard!A16 -> 11 | B17: =Dashboard!B16 -> penalties (water+sewer) | C17: =Dashboard!C12 -> Ksh | E17: 87556 | F17: 16152 | G17: 55750 | H17: 51350 | I17: 0 | K17: 39580 | L17: 7592 | M17: 30000 | N17: 285362 | O17: 40000 | P17: 10000
A18: =Dashboard!#REF! -> #REF! | B18: =Dashboard!#REF! -> #REF! | C18: =Dashboard!C13 -> Ksh
A19: =Dashboard!A17 -> 12 | B19: =Dashboard!B17 -> Company exhauster | C19: =Dashboard!C14 -> Ksh | E19: 0 | F19: 0 | G19: 0
A20: =Dashboard!A18 -> 12 | B20: =Dashboard!B18 -> Customer exhauster | C20: =Dashboard!C15 -> Ksh | E20: 135000 | F20: 135000 | G20: 135000 | H20: 135000 | I20: 135000 | J20: 135000 | K20: 135000 | L20: 165000 | M20: 217500 | N20: 195000 | O20: 195000 | P20: 225000
A21: =Dashboard!A19 -> 13 | B21: =Dashboard!B19 -> Total billed (Ksh) | C21: =Dashboard!C17 -> Ksh | D21: 17945234 | E21: =SUM(E6:E20)-(E14+E8) -> 17173326 | F21: =SUM(F6:F20)-(F14+F8) -> 20157514 | G21: =SUM(G6:G20)-(G14+G8) -> 18458777 | H21: =SUM(H6:H20)-(H14+H8) -> 18213052 | I21: =SUM(I6:I20)-(I14+I8) -> 19617288 | J21: =SUM(J6:J20)-(J14+J8) -> 13786732 | K21: =SUM(K6:K20)-(K14+K8) -> 21674904 | L21: =SUM(L6:L20)-(L14+L8) -> 18959101 | ... P21: =SUM(P6:P20)-(P14+P8) -> 28905832
A22: =Dashboard!A20 -> 0 | B22: =Dashboard!B20 -> 0 | C22: =Dashboard!C18 -> Ksh
A23: =Dashboard!A21 -> A | B23: =Dashboard!B21 -> Eastern Region | C23: =Dashboard!#REF! -> #REF! | E23: 12th &15th | F23: 14th | G23: 12th | H23: 7th | I23: 14th | J23: 11th | K23: 6th | L23: 7th | M23: 14th | N23: 14th | O23: 13th | P23: 19th
A24: =Dashboard!A22 -> B | B24: =Dashboard!B22 -> Southern Region | C24: =Dashboard!#REF! -> #REF! | E24: 15th | F24: 16th | G24: 17th | H24: 15th | I24: 15th | J24: 11th | K24: 20th | L24: 17th | M24: 20th | N24: 19th | O24: 16th | P24: 23rd
A25: =Dashboard!A23 -> C | B25: =Dashboard!B23 -> Central Region | C25: =Dashboard!C19 -> Ksh | E25: 31st | F25: 30th | G25: 30th | H25: 31st | I25: 29th | J25: 20th | K25: 29th | L25: 28th | M25: 30th | N25: 30th | O25: 29th | P25: 30th
A26: =Dashboard!A24 -> COLLECTION EFFICIENCY | B26: =Dashboard!B24 -> 0 | C26: =Dashboard!C20 -> 0
A27: =Dashboard!A25 -> D | B27: =Dashboard!B25 -> Total accounts disconnected-water | C27: =Dashboard!C21 -> DATE | E27: 606 | F27: 270 | G27: 119 | H27: 172 | I27: 166 | J27: 149 | K27: 197 | L27: 144 | M27: 227 | N27: 111 | O27: 123 | P27: 111
A28: =Dashboard!A26 -> E | B28: =Dashboard!B26 -> Total accounts disconnected-sewer | C28: =Dashboard!C16 -> Ksh | E28: 72 | F28: 2 | G28: 20 | H28: 44 | I28: 7 | J28: 4 | K28: 13 | L28: 14 | M28: 3 | N28: 5 | O28: 0 | P28: 0
A29: =Dashboard!A27 -> 14 | B29: =Dashboard!B27 -> Total Collection for the month | C29: =Dashboard!C17 -> Ksh | E29: 22802982 | F29: 15064900 | G29: 17788417 | H29: 18047891 | I29: 20883741 | J29: 15030214 | K29: 21271032 | L29: 18078019 | M29: 16601930 | N29: 23335361 | O29: 22039395 | P29: 28927934
A30: =Dashboard!A28 -> 7 | B30: =Dashboard!B28 -> Total Collection- Related Sales | C30: =Dashboard!C18 -> Ksh
A31: =Dashboard!A29 -> 15 | B31: =Dashboard!B29 -> Collection Efficiency - in % of billing | E31: =E29/D21 -> 1.2706985 | F31: =F29/E21 -> 0.87722668 | G31: =G29/F21 -> 0.8824708 | H31: =H29/G21 -> 0.97774036 | I31: =I29/H21 -> 1.146636 | J31: =J29/I21 -> 0.76617189 | K31: =K29/J21 -> 1.5428625 | L31: =L29/K21 -> 0.83405302 | ... P31: =P29/O21 -> 1.0579356
A32: =Dashboard!A31 -> CENTRAL REGION: CBD,CCCR,KABATI,SITE,KIHOTO,LAKEVIEW,HOPEWELL
A33: =Dashboard!A32 -> 16a | B33: =Dashboard!B32 -> Amount Billed Water-Central | C33: =Dashboard!C32 -> Ksh. | E33: 5843053 | F33: 7922759 | G33: 6574586 | H33: 6654857 | I33: 7074189 | J33: 4685457 | K33: 8536944 | L33: 7146065 | M33: 7724897 | N33: 9123070 | O33: 10708050 | P33: 11093770
A34: =Dashboard!A33 -> 17a | B34: =Dashboard!B33 -> Amount Billed Sewer-Central | C34: =Dashboard!C33 -> Ksh. | E34: 4056872.9 | F34: =4997329.65-1417.5 -> 4995912.2 | G34: 4239319.5 | H34: 4378066.2 | I34: 4413150 | J34: 3714209.2 | K34: =5355862.7+350 -> 5356212.7 | L34: 4592749 | M34: 4885077 | N34: 5635043.5 | O34: 6022758.5 | P34: 6114211
A35: =Dashboard!A34 -> 18a | B35: =Dashboard!B34 -> othersales | C35: =Dashboard!C34 -> Ksh. | E35: 794951 | F35: =491850+135000 -> 626850 | G35: 607950 | H35: 713100 | I35: 489600 | J35: 523900 | K35: =703980+800 -> 704780 | L35: 670850 | M35: 755350 | N35: 1189107.5 | O35: 1026152.5 | P35: 1000538.5
A36: =Dashboard!A35 -> 19a | B36: =Dashboard!B35 -> Amount Billed Water & Sewer-othersales-Central | C36: =Dashboard!C35 -> Ksh. | D36: 12356391 | E36: =E33+E34+E35 -> 10694877 | F36: =F33+F34+F35 -> 13545521 | G36: =G33+G34+G35 -> 11421855 | H36: =H33+H34+H35 -> 11746023 | I36: =I33+I34+I35 -> 11976939 | J36: =J33+J34+J35 -> 8923566.2 | K36: =K33+K34+K35 -> 14597937 | L36: =L33+L34+L35 -> 12409664 | ... P36: =P33+P34+P35 -> 18208520
A37: =Dashboard!A36 -> 14a | B37: =Dashboard!B36 -> Amount Collected-Central | C37: =Dashboard!C36 -> Ksh. | E37: 15577991 | F37: 8917003.1 | G37: 11509367 | H37: 11550709 | I37: 15277870 | J37: 9681321.2 | K37: 14304090 | L37: 12007999 | M37: 10866768 | N37: 16977535 | O37: 15080180 | P37: 19747968
A38: =Dashboard!A37 -> 15a | B38: =Dashboard!B37 -> Collection Efficiency-Central | C38: =Dashboard!C37 -> % | E38: =E37/D36 -> 1.2607234 | F38: =F37/E36 -> 0.83376397 | G38: =G37/F36 -> 0.84968065 | H38: =H37/G36 -> 1.0112813 | I38: =I37/H36 -> 1.3006845 | J38: =J37/I36 -> 0.80833018 | K38: =K37/J36 -> 1.6029566 | L38: =L37/K36 -> 0.82258194 | ... P38: =P37/O36 -> 1.1121254
A39: =Dashboard!A38 -> SOUTHERN REGION: HELLSGATE,KAMERE, MAI MAHIU,LONGONOT
A40: =Dashboard!A39 -> 16b | B40: =Dashboard!B39 -> Amount Billed Water-Southern | C40: =Dashboard!C39 -> Ksh. | E40: 3209469 | F40: 3501347 | G40: 3856856 | H40: 3641147 | I40: 4692660 | J40: 2552870 | K40: 4084599 | L40: 3854228 | M40: 4053585 | N40: 2884277 | O40: 5352660 | P40: 5996360
A41: =Dashboard!A40 -> 17b | B41: =Dashboard!B40 -> Amount Billed Sewer-Southern | C41: =Dashboard!C40 -> Ksh. | E41: 0
A42: =Dashboard!A41 -> 18b | B42: =Dashboard!B41 -> othersales | C42: =Dashboard!C41 -> Ksh. | E42: 467850 | F42: 324100 | G42: 254600 | H42: 227600 | I42: 234950 | J42: 338950 | K42: 495150 | L42: 284992 | M42: 370600 | N42: 539558 | O42: 443033 | P42: 469818
...

Sheet Actual2223
A1: =Dashboard!A1 -> FINANCE DASHBOARD
B4: MONTH | C4: UNIT | D4: JUL | E4: AUG | F4: SEP | G4: OCT | H4: NOV | I4: DEC | J4: JAN | K4: FEB | L4: MAR | M4: APR | N4: MAY | O4: JUN
A5: =Dashboard!A5 -> BILLING DASHBOARD - SUMMARY
A6: =Dashboard!A6 -> 1 | B6: =Dashboard!B6 -> Total Water Sales (Ksh) | C6: =Dashboard!C6 -> Ksh | D6: 12199740 | E6: 12735676 | F6: 11968928 | G6: 9537854 | H6: 10102428 | I6: 10986262 | J6: 11599157 | K6: 12676005 | L6: 13715682 | M6: 12172674 | N6: 10015215 | O6: 11728511
A7: =Dashboard!A7 -> 2 | B7: =Dashboard!B7 -> Total Sewerage Sales (Ksh) | C7: =Dashboard!C7 -> Ksh | D7: 5163189.6 | E7: 5115963.4 | F7: 5069596.2 | G7: 5067979.4 | H7: 5605456.5 | I7: 5780301.4 | J7: 5899284.4 | K7: 5160014.7 | L7: 5301013.9 | M7: 5146079.4 | N7: 4942473.3 | O7: 5141457.9
A8: =Dashboard!A8 -> 3 | B8: =Dashboard!B8 -> Bulk water | D8: 24880 | E8: 40130 | F8: 77090 | G8: 22080 | H8: 14000 | I8: 6240 | J8: 16480 | K8: 41840 | L8: 92880 | M8: 37120 | N8: 5040 | O8: 32560
A9: =Dashboard!#REF! -> #REF! | B9: =Dashboard!#REF! -> #REF! | D9: 392600 | E9: 394950 | F9: 409650 | G9: 414850 | H9: 417300 | I9: 422000 | J9: 424700 | K9: 428050 | L9: 434200 | M9: 439000 | N9: 442900 | O9: 445100
A10: =Dashboard!A10 -> 5 | B10: =Dashboard!B10 -> new connection fee water | D10: 130000 | E10: 276000 | F10: 307500 | G10: 199000 | H10: 209000 | I10: 140000 | J10: 207500 | K10: 430000 | L10: 588500 | M10: 305000 | N10: 175000 | O10: 232500
A11: =Dashboard!A11 -> 6 | B11: =Dashboard!B11 -> new connection fee sewer | D11: 0 | E11: 0 | F11: 22500 | G11: 20000 | H11: 30000 | I11: 30000 | J11: 25000 | K11: 5000 | L11: 45000 | M11: 80000 | N11: 27500 | O11: 5000
A12: =Dashboard!A12 -> 7 | B12: =Dashboard!B12 -> reconnection fee (water+sewer) | D12: 385000 | E12: 423000 | F12: 393500 | G12: 328000 | H12: 287500 | I12: 256000 | J12: 374500 | K12: 266500 | L12: 350500 | M12: 183500 | N12: 295800 | O12: 254500
A13: =Dashboard!A13 -> 8 | B13: =Dashboard!B13 -> Prepaid kiosk | C13: =Dashboard!C8 -> Ksh | D13: 86850 | E13: 84450 | F13: 56450 | G13: 97020 | H13: 61350 | I13: 68250 | J13: 83100 | K13: 90450 | L13: 76200 | M13: 61950 | N13: 26000 | O13: 28100
A14: =Dashboard!A14 -> 9 | B14: =Dashboard!B14 -> misc income-printing fee,CA,meter replacement fee,meter testing | C14: =Dashboard!C10 -> Ksh | D14: 4900 | E14: 8300 | F14: 12500 | G14: 19100 | H14: 292967.35 | I14: 7000 | J14: 19300 | K14: 21200 | L14: 136300 | M14: 759310 | N14: 253900 | O14: 99600
A15: =Dashboard!A15 -> 10 | B15: =Dashboard!B15 -> sewer unblocking fee | C15: =Dashboard!C11 -> Ksh | D15: 2500 | E15: 2500 | F15: 0 | G15: 0 | H15: 0 | I15: 0 | J15: 0 | K15: 0 | L15: 2500 | M15: 0 | N15: 0
A16: =Dashboard!A16 -> 11 | B16: =Dashboard!B16 -> penalties (water+sewer) | C16: =Dashboard!C12 -> Ksh | D16: 38033 | E16: 0 | F16: 169318 | G16: 0 | H16: 0 | I16: 0 | J16: 40000 | K16: 69783 | L16: 315642 | M16: 87169 | N16: 0 | O16: 13000
A17: =Dashboard!#REF! -> #REF! | B17: =Dashboard!#REF! -> #REF! | C17: =Dashboard!C13 -> Ksh
A18: =Dashboard!A17 -> 12 | B18: =Dashboard!B17 -> Company exhauster | C18: =Dashboard!C14 -> Ksh | D18: 155500 | E18: 121000 | F18: 115000 | G18: 112500 | H18: 173050 | I18: 140500 | J18: 288000 | K18: 253000 | L18: 78000 | M18: 107500 | N18: 130000 | O18: 148500
A19: =Dashboard!A18 -> 12 | B19: =Dashboard!B18 -> Customer exhauster | C19: =Dashboard!C15 -> Ksh | D19: 165000 | E19: 150000 | F19: 165000 | G19: 165000 | H19: 165000 | I19: 150000 | J19: 150000 | K19: 150000 | L19: 135000 | M19: 135000 | N19: 135000 | O19: 135000
A20: =Dashboard!A19 -> 13 | B20: =Dashboard!B19 -> Total billed (Ksh) | C20: =Dashboard!C17 -> Ksh | D20: =SUM(D6:D19)-(D13+D8) -> 18636463 | E20: =SUM(E6:E19)-(E13+E8) -> 19227389 | F20: =SUM(F6:F19)-(F13+F8) -> 18633492 | G20: =SUM(G6:G19)-(G13+G8) -> 15864283 | H20: =SUM(H6:H19)-(H13+H8) -> 17282702 | I20: =SUM(I6:I19)-(I13+I8) -> 17912063 | J20: =SUM(J6:J19)-(J13+J8) -> 19027441 | K20: =SUM(K6:K19)-(K13+K8) -> 19459553 | ... O20: =SUM(O6:O19)-(O13+O8) -> 18203169
A21: =Dashboard!A20 -> 0 | B21: =Dashboard!B20 -> 0 | C21: =Dashboard!C18 -> Ksh
A22: =Dashboard!A21 -> A | B22: =Dashboard!B21 -> Eastern Region | C22: =Dashboard!#REF! -> #REF! | D22: 17th | E22: 18th | F22: 16th | G22: 14th | H22: 15th | I22: 16th | J22: 14th | K22: 14th | L22: 16th | M22: 14th | N22: 15th | O22: 15th
A23: =Dashboard!A22 -> B | B23: =Dashboard!B22 -> Southern Region | C23: =Dashboard!#REF! -> #REF! | D23: 17th | E23: 18th | F23: 16th | G23: 14th | H23: 15th | I23: 21st | J23: 18th | K23: 14th | L23: 16th | M23: 20th | N23: 15th | O23: 15th
A24: =Dashboard!A23 -> C | B24: =Dashboard!B23 -> Central Region | C24: =Dashboard!C19 -> Ksh | D24: 29th | E24: 31st | F24: 30th | G24: 31st | H24: 30th | I24: 30th | J24: 31st | K24: 28th | L24: 31st | M24: 28th | N24: 31st | O24: 30th
A25: =Dashboard!A24 -> COLLECTION EFFICIENCY | B25: =Dashboard!B24 -> 0 | C25: =Dashboard!C20 -> 0
A26: =Dashboard!A25 -> D | B26: =Dashboard!B25 -> Total accounts disconnected-water | C26: =Dashboard!C21 -> DATE | D26: 364 | E26: 344 | F26: 323 | G26: 240 | H26: 241 | I26: 186 | J26: 305 | K26: 184 | L26: 313 | M26: 149 | N26: 210 | O26: 176
A27: =Dashboard!A26 -> E | B27: =Dashboard!B26 -> Total accounts disconnected-sewer | C27: =Dashboard!C16 -> Ksh | D27: 10 | E27: 54 | F27: 46 | G27: 58 | H27: 31 | I27: 48 | J27: 39 | K27: 47 | L27: 25 | M27: 23 | N27: 55 | O27: 49
A28: =Dashboard!A27 -> 14 | B28: =Dashboard!B27 -> Total Collection for the month | C28: =Dashboard!C17 -> Ksh | D28: 17553946 | E28: 14640444 | F28: 13485525 | G28: 13714992 | H28: 18534525 | I28: 12470759 | J28: 17312881 | K28: 14901865 | L28: 15605609 | M28: 15079990 | N28: 15346663 | O28: 17393617
A29: =Dashboard!A28 -> 7 | B29: =Dashboard!B28 -> Total Collection- Related Sales | C29: =Dashboard!C18 -> Ksh
A30: =Dashboard!A29 -> 15 | B30: =Dashboard!B29 -> Collection Efficiency - in % of billing | D30: =D28/ACTUAL2122!O22 -> 1.1308867 | E30: =E28/D20 -> 0.78558063 | F30: =F28/E20 -> 0.70137058 | G30: =G28/F20 -> 0.7360398 | H30: =H28/G20 -> 1.1683178 | I30: =I28/H20 -> 0.72157462 | J30: =J28/I20 -> 0.96654865 | K30: =K28/J20 -> 0.78317755 | L30: =L28/K20 -> 0.80195107 | ... O30: =O28/N20 -> 1.0594373
A31: =Dashboard!A31 -> CENTRAL REGION: CBD,CCCR,KABATI,SITE,KIHOTO,LAKEVIEW,HOPEWELL
A32: =Dashboard!A32 -> 16a | B32: =Dashboard!B32 -> Amount Billed Water-Central | C32: =Dashboard!C32 -> Ksh. | D32: 7447916 | E32: 8369605 | F32: 8367806 | G32: 5890041 | H32: 6272475 | I32: 7265076 | J32: 7408161 | K32: 8041476 | L32: 8363946 | M32: 7639624 | N32: 6614595 | O32: 7133367
A33: =Dashboard!A33 -> 17a | B33: =Dashboard!B33 -> Amount Billed Sewer-Central | C33: =Dashboard!C33 -> Ksh. | D33: 4699648.6 | E33: 5075106.4 | F33: 4844721.9 | G33: 4846991.4 | H33: 5367743.8 | I33: 5547386.9 | J33: 5661177.4 | K33: 5114256.4 | L33: 5275456.9 | M33: 5122146.4 | N33: 4916428.8 | O33: 5107057.7
A34: =Dashboard!A34 -> 18a | B34: =Dashboard!B34 -> othersales | C34: =Dashboard!C34 -> Ksh. | D34: 600350 | E34: 778951 | F34: 987568 | G34: 779550 | H34: 1085517.4 | I34: 721900 | J34: 987050 | K34: 908200 | L34: 1050852 | M34: 1456946 | N34: 914650 | O34: 784150
A35: =Dashboard!A35 -> 19a | B35: =Dashboard!B35 -> Amount Billed Water & Sewer-othersales-Central | C35: =Dashboard!C35 -> Ksh. | D35: =D32+D33+D34 -> 12747915 | E35: =E32+E33+E34 -> 14223662 | F35: =F32+F33+F34 -> 14200096 | G35: =G32+G33+G34 -> 11516582 | H35: =H32+H33+H34 -> 12725736 | I35: =I32+I33+I34 -> 13534363 | J35: =J32+J33+J34 -> 14056388 | K35: =K32+K33+K34 -> 14063932 | ... O35: =O32+O33+O34 -> 13024575
A36: =Dashboard!A36 -> 14a | B36: =Dashboard!B36 -> Amount Collected-Central | C36: =Dashboard!C36 -> Ksh. | D36: 13369388 | E36: 10007080 | F36: 9399206.2 | G36: 9447431.8 | H36: 14164924 | I36: 8428642 | J36: 12701452 | K36: 10226755 | L36: 10461453 | M36: 10578929 | N36: 10173620 | O36: 13145367
A37: =Dashboard!A37 -> 15a | B37: =Dashboard!B37 -> Collection Efficiency-Central | C37: =Dashboard!C37 -> % | D37: =D36/ACTUAL2122!O33 -> 1.4269497 | E37: =E36/D35 -> 0.78499742 | F37: =F36/E35 -> 0.66081477 | G37: =G36/F35 -> 0.6653076 | H37: =H36/G35 -> 1.229959 | I37: =I36/H35 -> 0.66233041 | J37: =J36/I35 -> 0.93845956 | K37: =K36/J35 -> 0.72755211 | L37: =L36/K35 -> 0.74384976 | ... O37: =O36/N35 -> 1.0562198
A38: =Dashboard!A38 -> SOUTHERN REGION: HELLSGATE,KAMERE, MAI MAHIU,LONGONOT
A39: =Dashboard!A39 -> 16b | B39: =Dashboard!B39 -> Amount Billed Water-Southern | C39: =Dashboard!C39 -> Ksh. | D39: 2236041 | E39: 2367557 | F39: 2476585 | G39: 2221226 | H39: 2275040 | I39: 2238025 | J39: 2440191 | K39: 2770961 | L39: 3105853 | M39: 2709503 | N39: 1569252 | O39: 2754587
A40: =Dashboard!A40 -> 17b | B40: =Dashboard!B40 -> Amount Billed Sewer-Southern | C40: =Dashboard!C40 -> Ksh. | D40: 0 | E40: 0 | F40: 0 | G40: 0 | H40: 0 | I40: 0 | J40: 0 | K40: 0 | L40: 0 | M40: 0 | N40: 0 | O40: 0
A41: =Dashboard!A41 -> 18b | B41: =Dashboard!B41 -> othersales | C41: =Dashboard!C41 -> Ksh. | D41: 207933 | E41: 309550 | F41: 359250 | G41: 260500 | H41: 288650 | I41: 181250 | J41: 243100 | K41: 491183 | L41: 598700 | M41: 368550 | N41: 280550 | O41: 281550
A42: =Dashboard!A42 -> 19b | B42: =Dashboard!B42 -> Amount Billed Water & Sewer-OTHER SALES-Southern | C42: =Dashboard!C42 -> Ksh. | D42: =D39+D40+D41 -> 2443974 | E42: =E39+E40+E41 -> 2677107 | F42: =F39+F40+F41 -> 2835835 | G42: =G39+G40+G41 -> 2481726 | H42: =H39+H40+H41 -> 2563690 | I42: =I39+I40+I41 -> 2419275 | J42: =J39+J40+J41 -> 2683291 | K42: =K39+K40+K41 -> 3262144 | ... O42: =O39+O40+O41 -> 3036137
...

Sheet ACTUAL2122
A1: =[1]Dashboard!A1 -> FINANCE DASHBOARD
B4: MONTH | C4: UNIT | D4: JUL | E4: AUG | F4: SEP | G4: OCT | H4: NOV | I4: DEC | J4: JAN | K4: FEB | L4: MAR | M4: APR | N4: MAY | O4: JUN
A5: =[1]Dashboard!A5 -> SALES DASHBOARD - SUMMARY
A6: =[1]Dashboard!A6 -> 1 | B6: =[1]Dashboard!B6 -> Total Water Sales (Ksh) | C6: =[1]Dashboard!C6 -> Ksh | D6: 9816920 | E6: 9629542 | F6: 9990578.3 | G6: 10323025 | H6: 10434355 | I6: 10257770 | J6: 11956646 | K6: 12122204 | L6: 10549503 | M6: 12370653 | N6: 9949935 | O6: 9227442
A7: =[1]Dashboard!A7 -> 2 | B7: =[1]Dashboard!B7 -> Total Sewerage Sales (Ksh) | C7: =[1]Dashboard!C7 -> Ksh | D7: 4382887.2 | E7: 4351383.3 | F7: 4538576.5 | G7: 4545154.2 | H7: 5077368.6 | I7: 4348279 | J7: 4560939.5 | K7: 4812019.1 | L7: 4291621 | M7: 4771105.9 | N7: 4515160.5 | O7: 4714692.6
B8: bulk
B9: meter rent | D9: 331100 | E9: 336400 | F9: 340300 | G9: 343400 | H9: 349350 | I9: 355250 | J9: 361150 | K9: 365900 | L9: 369600 | M9: 380850 | N9: 383800 | O9: 387050
B10: new connection fee-water | D10: 120000 | E10: 108000 | F10: 164000 | G10: 334500 | H10: 192000 | I10: 234000 | J10: 128500 | K10: 264500 | L10: 319000 | M10: 202000 | N10: 143500 | O10: 310000
B11: reconnection fee-water | D11: 91500 | E11: 77000 | F11: 68000 | G11: 65500 | H11: 64000 | I11: 66000 | J11: 45500 | K11: 40500 | L11: 279000 | M11: 199000 | N11: 509500 | O11: 457000
B12: OTHER SALES CA,METER TESTING,PRINTING | D12: 7000 | E12: 5800 | F12: 12500 | G12: 5100 | H12: 4800 | I12: 3900 | J12: 7600 | K12: 7200 | L12: 8300 | M12: 22300 | N12: 20200 | O12: 9600
B13: penalties-water | D13: 178060 | E13: 147985 | F13: 169420 | G13: 76210 | H13: 8000 | I13: 17495 | J13: 16000 | K13: 39884 | L13: 233517 | M13: 12000 | N13: 8400
A14: =[1]Dashboard!A8 -> 3 | B14: =[1]Dashboard!B8 -> Total Water Related Sales | C14: =[1]Dashboard!C8 -> Ksh | D14: =SUM(D9:D13) -> 727660 | E14: =SUM(E9:E13) -> 675185 | F14: =SUM(F9:F13) -> 754220 | G14: =SUM(G9:G13) -> 824710 | H14: =SUM(H9:H13) -> 618150 | I14: =SUM(I9:I13) -> 676645 | J14: =SUM(J9:J13) -> 558750 | K14: =SUM(K9:K13) -> 717984 | ... O14: =SUM(O9:O13) -> 1163650
A15: =[1]Dashboard!A9 -> 4(i) | B15: =[1]Dashboard!B9 -> Company exhauster | C15: =[1]Dashboard!C9 -> Ksh | D15: 140000 | E15: 130000 | F15: 150500 | G15: 142500 | H15: 147500 | I15: 114000 | J15: 150000 | K15: 142500 | L15: 15000 | M15: 152500 | N15: 149000 | O15: 193000
A16: =[1]Dashboard!A10 -> 4(ii) | B16: =[1]Dashboard!B10 -> Customer exhauster | C16: =[1]Dashboard!C10 -> Ksh | D16: 180000 | E16: 180000 | F16: 165000 | G16: 150000 | H16: 150000 | I16: 150000 | J16: 165000 | K16: 150000 | L16: 158500 | M16: 150000 | N16: 150000 | O16: 150000
B17: unblockage fee | G17: 0 | H17: 0 | I17: 0 | J17: 0 | L17: 7500 | M17: 2500 | N17: 0 | O17: 5000
B18: new connection-sewer | D18: 27500 | E18: 38000 | F18: 10500 | G18: 19000 | H18: 87500 | I18: 27500 | J18: 28000 | K18: 60000 | L18: 25000 | M18: 15000 | N18: 44500 | O18: 55000
B19: reconnection fee-sewer | D19: =0+D13 -> 178060 | E19: =3000+E13 -> 150985 | F19: =3000+F13 -> 172420 | G19: 9000 | H19: 3000 | I19: 1500 | J19: 13500 | K19: 96000 | L19: 34500 | M19: 9000 | N19: 19500 | O19: 13500
B20: penalties-sewer | D20: 48000 | G20: 0 | H20: 0 | I20: 0 | L20: 35000 | M20: 0 | N20: 0
A21: =[1]Dashboard!A11 -> 4 | B21: =[1]Dashboard!B11 -> Total Sewerage Related Sales | C21: =[1]Dashboard!C11 -> Ksh | D21: =SUM(D15:D20) -> 573560 | E21: =SUM(E15:E20) -> 498985 | F21: =SUM(F15:F20) -> 498420 | G21: =SUM(G15:G20) -> 320500 | H21: =SUM(H15:H20) -> 388000 | I21: =SUM(I15:I20) -> 293000 | J21: =SUM(J15:J20) -> 356500 | K21: =SUM(K15:K20) -> 448500 | ... O21: =SUM(O15:O20) -> 416500
A22: =[1]Dashboard!A12 -> 5 | B22: =[1]Dashboard!B12 -> Total Water/Sewerage and Related Sales (Ksh) | C22: =[1]Dashboard!C12 -> Ksh | D22: =D6+D7+D14+D21 -> 15501027 | E22: =E6+E7+E14+E21 -> 15155095 | F22: =F6+F7+F14+F21 -> 15781795 | G22: =G6+G7+G14+G21 -> 16013389 | H22: =H6+H7+H14+H21 -> 16517874 | I22: =I6+I7+I14+I21 -> 15575694 | J22: =J6+J7+J14+J21 -> 17432835 | K22: =K6+K7+K14+K21 -> 18100707 | ... O22: =O6+O7+O14+O21 -> 15522285
A23: =[1]Dashboard!A13 -> COLLECTION EFFICIENCY
A24: =[1]Dashboard!A14 -> 6 | B24: =[1]Dashboard!B14 -> Total Collection, Water and Sewer Revenues and other sales | C24: =[1]Dashboard!C14 -> Ksh | D24: 15131038 | E24: 12356990 | F24: 12415042 | G24: 13167328 | H24: 18704966 | I24: 11339412 | J24: 19291963 | K24: 11507178 | L24: 13785470 | M24: 11337951 | N24: 19240363 | O24: 14508155
A25: =[1]Dashboard!A15 -> 7 | B25: =[1]Dashboard!B15 -> Total Collection- Related Sales | C25: =[1]Dashboard!C15 -> Ksh | D25: 729278.67 | E25: 957093.79 | F25: 900865.9 | G25: 817252.59 | H25: 852098.27 | I25: 837820.69 | J25: 954038.3 | K25: 808090.65 | L25: 970913.67 | M25: 852667.86 | N25: 1017770.8 | O25: 1299989.5
A26: =[1]Dashboard!A16 -> 8 | B26: =[1]Dashboard!B16 -> Collection Efficiency - in % of budget | C26: =[1]Dashboard!C16 -> % | D26: =D24/[1]BUDGET!D23 -> 1 | E26: =E24/[1]BUDGET!E23 -> 1 | F26: =F24/[1]BUDGET!F23 -> 1 | G26: =G24/[1]BUDGET!G23 -> 1 | H26: =H24/[1]BUDGET!H23 -> 1 | I26: =I24/[1]BUDGET!I23 -> 1 | J26: =J24/[2]BUDGET!J23 -> 0.94795962 | K26: =K24/[1]BUDGET!K23 -> 1 | L26: =L24/[1]BUDGET!L23 -> 1 | M26: =M24/[1]BUDGET!M23 -> 1 | N26: =N24/[1]BUDGET!N23 -> 1 | O26: =O24/[1]BUDGET!O23 -> 1
A27: =[1]Dashboard!A17 -> 9 | B27: =[1]Dashboard!B17 -> Collection Efficiency - in % of billing | C27: =[1]Dashboard!C17 -> % | D27: =(D24+D25)/[1]ACTUAL2021!O21 -> 1.0130564 | E27: =E24/D22 -> 0.79717236 | F27: =F24/E22 -> 0.81919923 | G27: =G24/F22 -> 0.83433653 | H27: =H24/G22 -> 1.1680829 | I27: =I24/H22 -> 0.68649345 | J27: =J24/I22 -> 1.2385941 | K27: =K24/J22 -> 0.66008642 | L27: =L24/K22 -> 0.7615984 | ... O27: =O24/N22 -> 0.91283599
A28: =[1]Dashboard!A18 -> REGIONAL PERFORMANCE
A29: =[1]Dashboard!A19 -> DTI REGION: CBD,CCCR,KABATI,SITE,KIHOTO
A30: =[1]Dashboard!A20 -> 10 | B30: =[1]Dashboard!B20 -> Amount Billed Water-DTI | C30: =[1]Dashboard!C20 -> Ksh. | D30: 5277990 | E30: 4887807 | F30: 5455618.3 | G30: 5416695 | H30: 5791785 | I30: 5819845 | J30: 6294944 | K30: 6986878 | L30: 5892852 | M30: 6078802 | N30: 5301001 | O30: 4569022
A31: =[1]Dashboard!A21 -> 11 | B31: =[1]Dashboard!B21 -> Amount Billed Sewer-DTI | C31: =[1]Dashboard!C21 -> Ksh. | D31: 3270777.8 | E31: 3201537.7 | F31: 3456698.4 | G31: 3443299.1 | H31: 3601247.2 | I31: 3830623.7 | J31: 4098101.7 | K31: 4386863.2 | L31: 3916586.6 | M31: 4089032.2 | N31: 3907537.3 | O31: 4054135.2
A32: =[1]Dashboard!A22 -> 11a | B32: =[1]Dashboard!B22 -> othersales | C32: =[1]Dashboard!C22 -> Ksh. | D32: 682500 | E32: 293235 | F32: 389800 | G32: 585810 | H32: 545200 | I32: 353296 | J32: 540100 | K32: 716700 | L32: 698850 | M32: 599500 | N32: 712900 | O32: 746050
