Workbook

Sheet WEEKLY REPORT
A1: SITE | B1: TARGETS | C1: WEEKLY TARGETS | D1: WEEKLY PRODUCTION | E1: DEFICIT ON TARGET | F1: REASONS FOR UNDER TARGET | G1: REMARKS
A2: DCK | B2: 287 | C2: =B2*7 -> 2009 | D2: =production!#REF!+production!#REF!+production!#REF!+production!#REF!+production!#REF!+production!#REF!+production!#REF!+production!#REF! -> #REF! | E2: =D2-C2 -> #REF! | F2: Burst on main line
A3: WWS | B3: 660 | C3: =B3*7 -> 4620 | D3: =production!#REF!+production!#REF!+production!#REF!+production!#REF!+production!#REF!+production!#REF!+production!#REF! -> #REF! | E3: =D3-C3 -> #REF! | F3: power failure and BH2 Tripping
A4: Mai Mahiu | B4: 360 | C4: =B4*7 -> 2520 | D4: =production!#REF!+production!#REF!+production!#REF!+production!#REF!+production!#REF!+production!#REF!+production!#REF! -> #REF! | E4: =D4-C4 -> #REF! | F4: power failure
A5: Ngondi | B5: 15 | C5: =B5*7 -> 105 | D5: =production!#REF! -> #REF! | E5: =D5-C5 -> #REF!
A6: NIP | B6: 194 | C6: =B6*7 -> 1358 | D6: =production!#REF! -> #REF! | E6: =D6-C6 -> #REF!
A7: KARATI | B7: 3135 | C7: =B7*7 -> 21945 | D7: =production!#REF!+production!#REF!+production!#REF!+production!#REF!+production!#REF!+production!#REF!+production!#REF! -> #REF! | E7: =D7-C7 -> #REF! | F7: Max Daily-2760(weekly- 19320) | G7: Change of bulk meters
A8: Kinungi BH | B8: 5 | C8: =B8*7 -> 35 | D8: 0 | E8: =D8-C8 -> -35 | F8: not operational
A9: Nyonjoro | B9: 7 | C9: =B9*7 -> 49 | D9: =production!#REF! -> #REF! | E9: =D9-C9 -> #REF! | F9: ok
A10: Karati PP | B10: 3 | C10: =B10*7 -> 21 | D10: =production!#REF! -> #REF! | E10: =D10-C10 -> #REF! | F10: ok
A11: Ihindu | B11: 8 | C11: =B11*7 -> 56 | D11: 0 | E11: =D11-C11 -> -56 | F11: not yet handed over
C12: ='WEEKLY REPORT'!M152 -> 0
A14: SITE | B14: TARGETS | C14: WEEKLY TARGETS | D14: WEEKLY PRODUCTION | E14: DEFICIT ON TARGET | F14: REASONS FOR UNDER TARGET | G14: REMARKS
A15: DCK | B15: 287 | C15: =B15*7 -> 2009 | D15: =production!#REF! -> #REF! | E15: =D15-C15 -> #REF! | F15: indicated low water by control panel | G15: Rehabilitate the BH
A16: WWS | B16: 660 | C16: =B16*7 -> 4620 | D16: =production!#REF! -> #REF! | E16: =D16-C16 -> #REF! | F16: power failure and BH2 Tripping | I16: =0.8*38 -> 30.4
A17: Mai Mahiu | B17: 360 | C17: =B17*7 -> 2520 | D17: =production!#REF! -> #REF! | E17: =D17-C17 -> #REF! | F17: power failure ,weather change
A18: Ngondi | B18: 15 | C18: =B18*7 -> 105 | D18: =production!#REF! -> #REF! | E18: =D18-C18 -> #REF! | F18: weather change
A19: NIP | B19: 194 | C19: =B19*7 -> 1358 | D19: =production!#REF! -> #REF! | E19: =D19-C19 -> #REF! | F19: we have leakages on the rising main line
A20: KARATI | B20: 3135 | C20: =B20*7 -> 21945 | D20: =production!#REF! -> #REF! | E20: =D20-C20 -> #REF! | F20: Max Daily-2760(weekly- 19320)/Weather | G20: Change of bulk meters
A21: Kinungi BH | B21: 5 | C21: =B21*7 -> 35 | D21: =production!#REF! -> #REF! | E21: =D21-C21 -> #REF! | F21: not operational
A22: Nyonjoro | B22: 7 | C22: =B22*7 -> 49 | D22: =production!#REF! -> #REF! | E22: =D22-C22 -> #REF! | F22: change of weather
A23: Karati PP | B23: 3 | C23: =B23*7 -> 21 | D23: =production!#REF! -> #REF! | E23: =D23-C23 -> #REF! | F23: ok
A24: Ihindu | B24: 8 | C24: =B24*7 -> 56 | D24: 0 | E24: =D24-C24 -> -56 | F24: not yet handed over
A27: SITE | B27: TARGETS | C27: WEEKLY TARGETS | D27: WEEKLY PRODUCTION | E27: DEFICIT ON TARGET | F27: REASONS FOR UNDER TARGET | G27: REMARKS
A28: DCK | B28: 287 | C28: =B28*7 -> 2009 | D28: =production!#REF! -> #REF! | E28: =D28-C28 -> #REF! | F28: low Demand | G28: Rehabilitate the BH
A29: WWS | B29: 660 | C29: =B29*7 -> 4620 | D29: =production!#REF! -> #REF! | E29: =D29-C29 -> #REF! | F29: low Demand
A30: Mai Mahiu | B30: 360 | C30: =B30*7 -> 2520 | D30: =production!#REF! -> #REF! | E30: =D30-C30 -> #REF! | F30: low Demand/Power Failure
A31: Ngondi | B31: 15 | C31: =B31*7 -> 105 | D31: =production!#REF! -> #REF! | E31: =D31-C31 -> #REF! | F31: low Demand
A32: NIP | B32: 194 | C32: =B32*7 -> 1358 | D32: =production!#REF! -> #REF! | E32: =D32-C32 -> #REF! | F32: 0k
A33: KARATI | B33: 3135 | C33: =B33*7 -> 21945 | D33: =production!#REF! -> #REF! | E33: =D33-C33 -> #REF! | F33: low Demand | G33: Change of bulk meters
A34: Kinungi BH | B34: 5 | C34: =B34*7 -> 35 | D34: =production!#REF! -> #REF! | E34: =D34-C34 -> #REF! | F34: not operational
A35: Nyonjoro | B35: 7 | C35: =B35*7 -> 49 | D35: =production!#REF! -> #REF! | E35: =D35-C35 -> #REF! | F35: low Demand
A36: Karati PP | B36: 3 | C36: =B36*7 -> 21 | D36: =production!#REF! -> #REF! | E36: =D36-C36 -> #REF! | F36: ok
A37: Ihindu | B37: 8 | C37: =B37*7 -> 56 | E37: =D37-C37 -> -56 | F37: not yet handed over
A40: SITE | B40: TARGETS | C40: WEEKLY TARGETS | D40: WEEKLY PRODUCTION | E40: DEFICIT ON TARGET | F40: REASONS FOR UNDER TARGET | G40: REMARKS
A41: DCK | B41: 287 | C41: =B41*7 -> 2009 | D41: =production!#REF! -> #REF! | E41: =D41-C41 -> #REF! | F41: low Demand | G41: Rehabilitate the BH
A42: WWS | B42: 660 | C42: =B42*7 -> 4620 | D42: =production!#REF! -> #REF! | E42: =D42-C42 -> #REF! | F42: low Demand
A43: Mai Mahiu | B43: 360 | C43: =B43*7 -> 2520 | D43: =production!#REF! -> #REF! | E43: =D43-C43 -> #REF! | F43: low Demand/Power Failure
A44: Ngondi | B44: 15 | C44: =B44*7 -> 105 | D44: =production!#REF! -> #REF! | E44: =D44-C44 -> #REF! | F44: low Demand
A45: NIP | B45: 194 | C45: =B45*7 -> 1358 | D45: =production!#REF! -> #REF! | E45: =D45-C45 -> #REF! | F45: 0k
...

Sheet production
A1: Daily production sheet
A2: Site/Date | B2: 29th December | C2: 30th December | D2: 31st December | E2: 1st Jan | F2: 2nd Jan | G2: 3rd Jan | H2: 4th Jan | I2: week 1 Total | J2: 5th Jan | K2: 6th Jan | L2: 7th Jan | M2: 8th Jan | N2: 9th Jan | O2: 10th Jan | P2: 11th Jan | Q2: week 2 Total
A3: DCK | B3: 291 | C3: 244 | D3: 300 | E3: 223 | F3: 172 | G3: 161 | H3: 201 | I3: =SUM(B3:H3) -> 1592 | J3: 189 | K3: 169 | L3: 233 | M3: 213 | N3: 138 | O3: 208 | P3: 103 | Q3: =SUM(J3:P3) -> 1253 | S3: =133646-133512 -> 134
A4: WWS | B4: 606 | C4: 685 | D4: 689 | E4: 661 | F4: 625 | G4: 672 | H4: 643 | I4: =SUM(B4:H4) -> 4581 | J4: 656 | K4: 689 | L4: 654 | M4: 643 | N4: 650 | O4: 598 | P4: 658 | Q4: =SUM(J4:P4) -> 4548 | S4: =200130-200050 -> 80
A5: Mai Mahiu | B5: 130 | C5: 147 | D5: 149 | E5: 90 | F5: 144 | G5: 51 | H5: 181 | I5: =SUM(B5:H5) -> 892 | J5: 122 | K5: 155 | L5: 124 | M5: 145 | N5: 134 | O5: 69 | P5: 175 | Q5: =SUM(J5:P5) -> 924
A6: Ngondi | B6: 0 | C6: 0 | D6: 0 | E6: 0 | F6: 0 | G6: 0 | H6: 108 | I6: =SUM(B6:H6) -> 108 | J6: 0 | K6: 0 | L6: 0 | M6: 0 | N6: 0 | O6: 0 | P6: 28 | Q6: =SUM(J6:P6) -> 28
A7: NIP | B7: 0 | C7: 0 | D7: 0 | E7: 0 | F7: 0 | G7: 2296 | H7: 0 | I7: =SUM(B7:H7) -> 2296 | J7: 0 | K7: 0 | L7: 0 | M7: 0 | N7: 2190 | O7: 1150 | P7: 0 | Q7: =SUM(J7:P7) -> 3340
A8: Sub-Total | B8: =SUM(B3:B7) -> 1027 | C8: =SUM(C3:C7) -> 1076 | D8: =SUM(D3:D7) -> 1138 | E8: =SUM(E3:E7) -> 974 | F8: =SUM(F3:F7) -> 941 | G8: =SUM(G3:G7) -> 3180 | H8: =SUM(H3:H7) -> 1133 | I8: =SUM(I3:I7) -> 9469 | ... Q8: =SUM(Q3:Q7) -> 10093
A9: KARATI | B9: 2562 | C9: 2547 | D9: 2656 | E9: 2636 | F9: 2253 | G9: 2396 | H9: 2120 | I9: =SUM(B9:H9) -> 17170 | J9: 2349 | K9: 2605 | L9: 2495 | M9: 2715 | N9: 2689 | O9: 2196 | P9: 2208 | Q9: =SUM(J9:P9) -> 17257
A10: Kinungi BH | B10: 0 | C10: 0 | D10: 0 | E10: 0 | F10: 0 | G10: 0 | H10: 0 | I10: =SUM(B10:H10) -> 0 | J10: 0 | K10: 0 | L10: 0 | M10: 0 | N10: 0 | O10: 0 | P10: 0 | Q10: =SUM(J10:P10) -> 0
A11: Nyonjoro | B11: 0 | C11: 0 | D11: 0 | E11: 0 | F11: 0 | G11: 0 | H11: 27 | I11: =SUM(B11:H11) -> 27 | J11: 0 | K11: 0 | L11: 0 | M11: 0 | N11: 0 | O11: 0 | P11: 29 | Q11: =SUM(J11:P11) -> 29
A12: Karati PP | B12: 0 | C12: 0 | D12: 0 | E12: 0 | F12: 0 | G12: 0 | H12: 78 | I12: =SUM(B12:H12) -> 78 | J12: 0 | K12: 0 | L12: 0 | M12: 0 | N12: 0 | O12: 0 | P12: 45 | Q12: =SUM(J12:P12) -> 45
A13: Sub-Total | B13: =SUM(B9:B10) -> 2562 | C13: =SUM(C9:C12) -> 2547 | D13: =SUM(D9:D10) -> 2656 | E13: =SUM(E9:E12) -> 2636 | F13: =SUM(F9:F12) -> 2253 | G13: =SUM(G9:G12) -> 2396 | H13: =SUM(H9:H12) -> 2225 | I13: =SUM(I9:I12) -> 17275 | J13: =SUM(J9:J11) -> 2349 | K13: =SUM(K9:K12) -> 2605 | L13: =SUM(L9:L12) -> 2495 | M13: =SUM(M9:M11) -> 2715 | N13: =SUM(N9:N11) -> 2689 | O13: =SUM(O9:O11) -> 2196 | P13: =SUM(P9:P11) -> 2237 | Q13: =SUM(Q9:Q12) -> 17331
A14: AIC | B14: 693 | C14: 986 | D14: 952 | E14: 888 | F14: 307 | G14: 143 | H14: 180 | I14: =SUM(B14:H14) -> 4149 | J14: 184 | K14: 179 | L14: 785 | M14: 864 | N14: 301 | O14: 215 | P14: 239 | Q14: =SUM(J14:P14) -> 2767
A15: DTI | B15: 1700 | C15: 1264 | D15: 1870 | E15: 2069 | F15: 1496 | G15: 1630 | H15: 1669 | I15: =SUM(B15:H15) -> 11698 | J15: 1552 | K15: 1795 | L15: 1830 | M15: 1690 | N15: 1822 | O15: 1895 | P15: 1607 | Q15: =SUM(J15:P15) -> 12191
A16: Police Line | B16: 700 | C16: 710 | D16: 700 | E16: 600 | F16: 650 | G16: 750 | H16: 650 | I16: =SUM(B16:H16) -> 4760 | J16: 700 | K16: 700 | L16: 650 | M16: 400 | N16: 200 | O16: 250 | P16: 250 | Q16: =SUM(J16:P16) -> 3150
A17: Sub-Total | B17: =SUM(B14:B16) -> 3093 | C17: =SUM(C14:C16) -> 2960 | D17: =SUM(D14:D16) -> 3522 | E17: =SUM(E14:E16) -> 3557 | F17: =SUM(F14:F16) -> 2453 | G17: =SUM(G14:G16) -> 2523 | H17: =SUM(H14:H16) -> 2499 | I17: =SUM(I14:I16) -> 20607 | ... Q17: =SUM(Q14:Q16) -> 18108
A18: TOTAL | B18: =B8+B17+B13 -> 6682 | C18: =C8+C17+C13 -> 6583 | D18: =D8+D17+D13 -> 7316 | E18: =E8+E17+E13 -> 7167 | F18: =F8+F17+F13 -> 5647 | G18: =G8+G17+G13 -> 8099 | H18: =H8+H17+H13 -> 5857 | I18: =I8+I17+I13 -> 47351 | ... Q18: =Q8+Q17+Q13 -> 45532
A20: Daily production sheet
A21: Site/Date | B21: 12th Jan | C21: 13th Jan | D21: 14th Jan | E21: 15th Jan | F21: 16th Jan | G21: 17th Jan | H21: 18th Jan | I21: week 3 Total | J21: 19th Jan | K21: 20th Jan | L21: 21st Jan | M21: 22nd Jan | N21: 23rd Jan | O21: 24th Jan | P21: 25th Jan | Q21: week 4 Total
A22: DCK | B22: 140 | C22: 174 | D22: 203 | E22: 73 | F22: 210 | G22: 181 | H22: 203 | I22: =SUM(B22:H22) -> 1184 | J22: 80 | K22: 151 | L22: 240 | M22: 315 | N22: 308 | O22: 168 | P22: 289 | Q22: =SUM(J22:P22) -> 1551
A23: WWS | B23: 636 | C23: 623 | D23: 635 | E23: 677 | F23: 655 | G23: 599 | H23: 617 | I23: =SUM(B23:H23) -> 4442 | J23: 646 | K23: 691 | L23: 667 | M23: 698 | N23: 680 | O23: 650 | P23: 667 | Q23: =SUM(J23:P23) -> 4699
A24: Mai Mahiu | B24: 139 | C24: 57 | D24: 179 | E24: 156 | F24: 125 | G24: 157 | H24: 98 | I24: =SUM(B24:H24) -> 911 | J24: 147 | K24: 181 | L24: 130 | M24: 2 | N24: 0 | O24: 231 | P24: 79 | Q24: =SUM(J24:P24) -> 770
A25: Ngondi | B25: 0 | C25: 0 | D25: 0 | E25: 0 | F25: 0 | G25: 0 | H25: 14 | I25: =SUM(B25:H25) -> 14 | J25: 0 | K25: 0 | L25: 0 | M25: 0 | N25: 0 | O25: 0 | P25: 39 | Q25: =SUM(J25:P25) -> 39
A26: NIP | B26: 0 | C26: 0 | D26: 0 | E26: 0 | F26: 0 | G26: 0 | H26: 0 | I26: =SUM(B26:H26) -> 0 | J26: 0 | K26: 0 | L26: 0 | M26: 0 | N26: 2008 | O26: 1392 | P26: 0 | Q26: =SUM(J26:P26) -> 3400
A27: Sub-Total | B27: =SUM(B22:B26) -> 915 | C27: =SUM(C22:C26) -> 854 | D27: 0 | E27: =SUM(E22:E26) -> 906 | F27: =SUM(F22:F26) -> 990 | G27: =SUM(G22:G26) -> 937 | H27: =SUM(H22:H26) -> 932 | I27: =SUM(I22:I26) -> 6551 | J27: =SUM(J22:J26) -> 873 | K27: =SUM(K22:K26) -> 1023 | L27: =SUM(L22:L26) -> 1037 | ... Q27: =SUM(Q22:Q26) -> 10459
A28: KARATI | B28: 1923 | C28: 2145 | D28: 1977 | E28: 1819 | F28: 2127 | G28: 2370 | H28: 1979 | I28: =SUM(B28:H28) -> 14340 | J28: 2187 | K28: 2682 | L28: 1503 | M28: 847 | N28: 1644 | O28: 2858 | P28: 2795 | Q28: =SUM(J28:P28) -> 14516
A29: Kinungi BH | B29: 0 | C29: 0 | D29: 0 | E29: 0 | F29: 0 | G29: 0 | H29: 0 | I29: =SUM(B29:H29) -> 0 | J29: 0 | K29: 0 | L29: 0 | M29: 0 | N29: 0 | O29: 0 | P29: 0 | Q29: =SUM(J29:P29) -> 0
A30: Nyonjoro | B30: 0 | C30: 0 | D30: 0 | E30: 0 | F30: 0 | G30: 0 | H30: 39 | I30: =SUM(B30:H30) -> 39 | J30: 0 | K30: 0 | L30: 0 | M30: 0 | N30: 0 | O30: 0 | P30: 55 | Q30: =SUM(J30:P30) -> 55
A31: Karati PP | C31: 0 | D31: 0 | E31: 0 | F31: 0 | G31: 0 | H31: 33 | I31: =SUM(C31:H31) -> 33 | J31: 0 | K31: 0 | L31: 0 | M31: 0 | N31: 0 | O31: 0 | P31: 58 | Q31: =SUM(J31:P31) -> 58
A32: Sub-Total | B32: =SUM(B28:B31) -> 1923 | C32: =SUM(C28:C31) -> 2145 | D32: =SUM(D28:D29) -> 1977 | E32: =SUM(E28:E31) -> 1819 | F32: =SUM(F28:F31) -> 2127 | G32: =SUM(G28:G31) -> 2370 | H32: =SUM(H28:H31) -> 2051 | I32: =SUM(I28:I31) -> 14412 | J32: =SUM(J28:J30) -> 2187 | K32: =SUM(K28:K31) -> 2682 | L32: =SUM(L28:L31) -> 1503 | M32: =SUM(M28:M30) -> 847 | N32: =SUM(N28:N30) -> 1644 | O32: =SUM(O28:O30) -> 2858 | P32: =SUM(P28:P30) -> 2850 | Q32: =SUM(Q28:Q31) -> 14629
A33: AIC | B33: 169 | C33: 165 | D33: 164 | E33: 154 | F33: 180 | G33: 205 | H33: 141 | I33: =SUM(B33:H33) -> 1178 | J33: 178 | K33: 147 | L33: 155 | M33: 234 | N33: 221 | O33: 177 | P33: 217 | Q33: =SUM(J33:P33) -> 1329
A34: DTI | B34: 1860 | C34: 1829 | D34: 1380 | E34: 1997 | F34: 1228 | G34: 1658 | H34: 1787 | I34: =SUM(B34:H34) -> 11739 | J34: 1880 | K34: 1968 | L34: 1542 | M34: 1782 | N34: 1703 | O34: 1879 | P34: 1888 | Q34: =SUM(J34:P34) -> 12642
A35: Police Line | B35: 550 | C35: 600 | D35: 581 | E35: 703 | F35: 761 | G35: 700 | H35: 700 | I35: =SUM(B35:H35) -> 4595 | J35: 700 | K35: 700 | L35: 600 | M35: 750 | N35: 700 | O35: 550 | P35: 600 | Q35: =SUM(J35:P35) -> 4600
A36: Sub-Total | B36: =SUM(B33:B35) -> 2579 | C36: =SUM(C33:C35) -> 2594 | D36: =SUM(D33:D35) -> 2125 | E36: =SUM(E33:E35) -> 2854 | F36: =SUM(F33:F35) -> 2169 | G36: =SUM(G33:G35) -> 2563 | H36: =SUM(H33:H35) -> 2628 | I36: =SUM(I33:I35) -> 17512 | ... Q36: =SUM(Q33:Q35) -> 18571
A37: TOTAL | B37: =B27+B36+B32 -> 5417 | C37: =C27+C36+C32 -> 5593 | D37: =D27+D36+D32 -> 4102 | E37: =E27+E36+E32 -> 5579 | F37: =F27+F36+F32 -> 5286 | G37: =G27+G36+G32 -> 5870 | H37: =H27+H36+H32 -> 5611 | I37: =I27+I36+I32 -> 38475 | ... P37: =P27+P36+P32 -> 6629 | Q37: =A20:Q37+RQ4041+Q32 -> #VALUE!
A39: Daily production sheet
A40: Site/Date | B40: 26th Jan | C40: 27th Jan | D40: 28th Jan | E40: 29th Jan | F40: 30th Jan | G40: 31st Jan | H40: 1ST Feb | I40: week 5 Total | J40: 2nd Feb | K40: 3rd Feb | L40: 4th Feb | M40: 5th Feb | N40: 6th Feb | O40: 7th Feb | P40: 8th Feb | Q40: week 6 Total
A41: DCK | B41: 302 | C41: 274 | D41: 274 | E41: 259 | F41: 276 | G41: 198 | H41: 236 | I41: =SUM(B41:H41) -> 1819 | J41: 287 | K41: 329 | L41: 248 | M41: 255 | N41: 257 | O41: 252 | P41: 288 | Q41: =SUM(J41:P41) -> 1916
A42: WWS | B42: 621 | C42: 633 | D42: 633 | E42: 653 | F42: 656 | G42: 678 | H42: 653 | I42: =SUM(B42:H42) -> 4527 | J42: 593 | K42: 590 | L42: 655 | M42: 604 | N42: 639 | O42: 645 | P42: 629 | Q42: =SUM(J42:P42) -> 4355
...

Sheet Regions
A1: Daily production sheet
A2: Site/Date | B2: 29th December | C2: 30th December | D2: 31st December | E2: 1st Jan | F2: 2nd Jan | G2: 3rd Jan | H2: 4th Jan | I2: week 1 Total | J2: 5th Jan | K2: 6th Jan | L2: 7th Jan | M2: 8th Jan | N2: 9th Jan | O2: 10th Jan | P2: 11th Jan | Q2: week 2 Total
A3: DCK | B3: 291 | C3: 244 | D3: 300 | E3: 223 | F3: 172 | G3: 161 | H3: 201 | I3: =SUM(B3:H3) -> 1592 | J3: 189 | K3: 169 | L3: 233 | M3: 213 | N3: 138 | O3: 208 | P3: 103 | Q3: =SUM(J3:P3) -> 1253
A4: WWS+Karati (Mirera) | B4: 724 | C4: 915 | D4: 1132 | E4: 936 | F4: 927 | G4: 1004 | H4: 982 | I4: =SUM(B4:H4) -> 6620 | J4: 789 | K4: 1130 | L4: 1118 | M4: 945 | N4: 935 | O4: 942 | P4: 700 | Q4: =SUM(J4:P4) -> 6559
A5: Mai Mahiu | B5: 130 | C5: 147 | D5: 149 | E5: 90 | F5: 144 | G5: 51 | H5: 181 | I5: =SUM(B5:H5) -> 892 | J5: 122 | K5: 155 | L5: 124 | M5: 145 | N5: 134 | O5: 69 | P5: 175 | Q5: =SUM(J5:P5) -> 924
A6: Ngondi | B6: 0 | C6: 0 | D6: 0 | E6: 0 | F6: 0 | G6: 0 | H6: 108 | I6: =SUM(B6:H6) -> 108 | J6: 0 | K6: 0 | L6: 0 | M6: 0 | N6: 0 | O6: 0 | P6: 28 | Q6: =SUM(J6:P6) -> 28
A7: NIP | B7: 0 | C7: 0 | D7: 0 | E7: 0 | F7: 0 | G7: 2296 | H7: 0 | I7: =SUM(B7:H7) -> 2296 | J7: 0 | K7: 0 | L7: 0 | M7: 0 | N7: 0 | O7: 1150 | P7: 0 | Q7: =SUM(J7:P7) -> 1150
A8: Southern | B8: =B5+B4+B3+B7 -> 1145 | C8: =C5+C4+C3+C7 -> 1306 | D8: =D5+D4+D3+D7 -> 1581 | E8: =E5+E4+E3+E7 -> 1249 | F8: =F5+F4+F3+F7 -> 1243 | G8: =G5+G4+G3+G7 -> 3512 | H8: =H5+H4+H3+H7 -> 1364 | I8: =SUM(B8:H8) -> 11400 | J8: =SUM(J3:J7) -> 1100 | K8: =SUM(K3:K7) -> 1454 | L8: =SUM(L3:L7) -> 1475 | M8: =SUM(M3:M7) -> 1303 | N8: =SUM(N3:N7) -> 1207 | O8: =SUM(O3:O7) -> 2369 | P8: =SUM(P3:P7) -> 1006 | Q8: =SUM(J8:P8) -> 9914
A9: WWS+KARATI( Kayole) | B9: 1178 | C9: 1257 | D9: 1082 | E9: 1076 | F9: 997 | G9: 1075 | H9: 994 | I9: =SUM(B9:H9) -> 7659 | J9: 1060 | K9: 1136 | L9: 1127 | M9: 1282 | N9: 928 | O9: 1017 | P9: 1001 | Q9: =SUM(J9:P9) -> 7551
A10: Kinungi BH | B10: 0 | C10: 0 | D10: 0 | E10: 0 | F10: 0 | G10: 0 | H10: 0 | I10: =SUM(B10:H10) -> 0 | J10: 0 | K10: 0 | L10: 0 | M10: 0 | N10: 0 | O10: 0 | P10: 0 | Q10: =SUM(J10:P10) -> 0
A11: Nyonjoro | B11: 0 | C11: 0 | D11: 0 | E11: 0 | F11: 0 | G11: 0 | H11: 27 | I11: =SUM(B11:H11) -> 27 | J11: 0 | K11: 0 | L11: 0 | M11: 0 | N11: 0 | O11: 0 | P11: 29 | Q11: =SUM(J11:P11) -> 29
A12: Karati PP | B12: 0 | C12: 0 | D12: 0 | E12: 0 | F12: 0 | G12: 0 | H12: 78 | I12: =SUM(B12:H12) -> 78 | J12: 0 | K12: 0 | L12: 0 | M12: 0 | N12: 0 | O12: 0 | P12: 45 | Q12: =SUM(J12:P12) -> 45
A13: Eastern | B13: =SUM(B9:B11) -> 1178 | C13: =SUM(C9:C11) -> 1257 | D13: =SUM(D9:D11) -> 1082 | E13: =SUM(E9:E11) -> 1076 | F13: =SUM(F9:F11) -> 997 | G13: =G9 -> 1075 | H13: =H12+H11+H9 -> 1099 | I13: =SUM(I9:I11) -> 7686 | J13: =SUM(J9:J11) -> 1060 | K13: =SUM(K9:K11) -> 1136 | L13: =SUM(L9:L11) -> 1127 | M13: =SUM(M9:M11) -> 1282 | N13: =SUM(N9:N11) -> 928 | O13: =SUM(O9:O11) -> 1017 | P13: =SUM(P9:P11) -> 1030 | Q13: =SUM(Q9:Q11) -> 7580
A14: AIC | B14: 693 | C14: 986 | D14: 952 | E14: 888 | F14: 307 | G14: 143 | H14: 180 | I14: =SUM(B14:H14) -> 4149 | J14: 184 | K14: 179 | L14: 785 | M14: 864 | N14: 301 | O14: 215 | P14: 239 | Q14: =SUM(J14:P14) -> 2767
A15: DTI | B15: 1700 | C15: 1264 | D15: 1870 | E15: 2069 | F15: 1496 | G15: 1630 | H15: 1669 | I15: =SUM(B15:H15) -> 11698 | J15: 1552 | K15: 1795 | L15: 1830 | M15: 1690 | N15: 1822 | O15: 1895 | P15: 1607 | Q15: =SUM(J15:P15) -> 12191
A16: Police Line | B16: 700 | C16: 710 | D16: 700 | E16: 600 | F16: 650 | G16: 750 | H16: 650 | I16: =SUM(B16:H16) -> 4760 | J16: 700 | K16: 700 | L16: 700 | M16: 400 | N16: 200 | O16: 250 | P16: 250 | Q16: =SUM(J16:P16) -> 3200
A17: WWS+Karati (L.V) | B17: 1240 | C17: 953 | D17: 1092 | E17: 1063 | F17: 986 | G17: 893 | H17: 869 | I17: =SUM(B17:H17) -> 7096 | J17: 942 | K17: 920 | L17: 888 | M17: 989 | N17: 950 | O17: 940 | P17: 886 | Q17: =SUM(J17:P17) -> 6515
A18: Central BL | B18: =SUM(B14:B17) -> 4333 | C18: =SUM(C14:C17) -> 3913 | D18: =SUM(D14:D17) -> 4614 | E18: =SUM(E14:E17) -> 4620 | F18: =SUM(F14:F17) -> 3439 | G18: =G17+G16+G15+G14 -> 3416 | H18: =SUM(H14:H17) -> 3368 | I18: =SUM(I14:I17) -> 27703 | J18: =SUM(J14:J17) -> 3378 | K18: =SUM(K14:K17) -> 3594 | L18: =SUM(L14:L17) -> 4203 | M18: =SUM(M14:M17) -> 3943 | N18: =SUM(N14:N17) -> 3273 | O18: =SUM(O14:O17) -> 3300 | ... Q18: =SUM(Q14:Q17) -> 24673
B19: =B8+B13+B18 -> 6656 | C19: =C8+C13+C18 -> 6476 | D19: =D8+D13+D18 -> 7277 | E19: =E8+E13+E18 -> 6945 | F19: =F8+F13+F18 -> 5679 | G19: =G8+G13+G18 -> 8003 | H19: =H8+H13+H18 -> 5831 | I19: =I8+I13+I18 -> 46789 | ... Q19: =Q8+Q13+Q18 -> 42167
B20: =production!B18 -> 6682 | C20: =production!C18 -> 6583 | D20: =production!D18 -> 7316 | E20: =production!E18 -> 7167 | F20: =production!F18 -> 5647 | G20: =production!G18 -> 8099 | H20: =production!H18 -> 5857 | I20: =SUM(B20:H20) -> 47351 | J20: =production!J24 -> 147 | K20: =production!K24 -> 181 | L20: =production!L24 -> 130 | M20: =production!M24 -> 2 | N20: =production!N24 -> 0 | O20: =production!O24 -> 231 | P20: =production!P24 -> 79 | Q20: =production!Q24 -> 770
B21: =B20-B19 -> 26 | C21: =C20-C19 -> 107 | D21: =D20-D19 -> 39 | E21: =E20-E19 -> 222 | F21: =F20-F19 -> -32 | G21: =G20-G19 -> 96 | H21: =H20-H19 -> 26 | I21: =I20-I19 -> 562 | ... Q21: =Q20-Q19 -> -41397
A23: Daily production sheet
A24: Site/Date | B24: 12th Jan | C24: 13th Jan | D24: 14th Jan | E24: 15th Jan | F24: 16th Jan | G24: 17th Jan | H24: 18th Jan | I24: week 3 Total | J24: 19th Jan | K24: 20th Jan | L24: 21st Jan | M24: 22nd Jan | N24: 23rd Jan | O24: 24th Jan | P24: 25th Jan | Q24: week 4 Total
A25: DCK | B25: 140 | C25: 174 | D25: 203 | E25: 73 | F25: 210 | G25: 181 | H25: 203 | I25: =SUM(B25:H25) -> 1184 | J25: 80 | K25: 151 | L25: 240 | M25: 315 | N25: 308 | O25: 168 | P25: 289 | Q25: =SUM(J25:P25) -> 1551
A26: WWS+Karati (Mirera) | B26: 775 | C26: 765 | D26: 728 | E26: 706 | F26: 827 | G26: 857 | H26: 747 | I26: =SUM(B26:H26) -> 5405 | J26: 885 | K26: 917 | L26: 747 | M26: 39 | N26: 365 | O26: 1224 | P26: 1077 | Q26: =SUM(J26:P26) -> 5254
A27: Mai Mahiu | B27: 139 | C27: 57 | D27: 179 | E27: 156 | F27: 125 | G27: 157 | H27: 98 | I27: =SUM(B27:H27) -> 911 | J27: 147 | K27: 181 | L27: 130 | M27: 2 | N27: 0 | O27: 231 | P27: 79 | Q27: =SUM(J27:P27) -> 770
A28: Ngondi | G28: 0 | H28: 14 | I28: =SUM(B28:H28) -> 14 | J28: 0 | K28: 0 | L28: 0 | M28: 0 | N28: 0 | O28: 0 | P28: 39 | Q28: =SUM(J28:P28) -> 39
A29: NIP | G29: 0 | H29: 0 | I29: =SUM(B29:H29) -> 0 | J29: 0 | K29: 0 | L29: 0 | M29: 0 | N29: 2008 | O29: 1392 | P29: 0 | Q29: =SUM(J29:P29) -> 3400
A30: Southern | B30: =B27+B26+B25+B29 -> 1054 | C30: =C27+C26+C25+C29 -> 996 | D30: =D27+D26+D25+D29 -> 1110 | E30: =E27+E26+E25+E29 -> 935 | F30: =F27+F26+F25+F29 -> 1162 | G30: =G27+G26+G25+G29 -> 1195 | H30: =H27+H26+H25+H29 -> 1048 | I30: =SUM(B30:H30) -> 7500 | J30: =SUM(J25:J29) -> 1112 | K30: =SUM(K25:K29) -> 1249 | L30: =SUM(L25:L29) -> 1117 | M30: =SUM(M25:M29) -> 356 | N30: =SUM(N25:N29) -> 2681 | O30: =SUM(O25:O29) -> 3015 | P30: =SUM(P25:P29) -> 1484 | Q30: =SUM(J30:P30) -> 11014
A31: WWS+KARATI( Kayole) | B31: 1042 | C31: 822 | D31: 1040 | E31: 948 | F31: 1046 | G31: 957 | H31: 1088 | I31: =SUM(B31:H31) -> 6943 | J31: 952 | K31: 1129 | L31: 720 | M31: 397 | N31: 568 | O31: 1304 | P31: 1387 | Q31: =SUM(J31:P31) -> 6457
A32: Kinungi BH | G32: 0 | H32: 0 | I32: =SUM(B32:H32) -> 0 | J32: 0 | K32: 0 | L32: 0 | M32: 0 | N32: 0 | O32: 0 | P32: 0 | Q32: =SUM(J32:P32) -> 0
A33: Nyonjoro | G33: 0 | H33: 39 | I33: =SUM(B33:H33) -> 39 | J33: 0 | K33: 0 | L33: 0 | M33: 0 | N33: 0 | O33: 0 | P33: 55 | Q33: =SUM(J33:P33) -> 55
A34: Karati PP | G34: 0 | H34: 33 | I34: =SUM(B34:H34) -> 33 | J34: 0 | K34: 0 | L34: 0 | M34: 0 | N34: 0 | O34: 0 | P34: 58 | Q34: =SUM(J34:P34) -> 58
A35: Eastern | B35: =SUM(B31:B33) -> 1042 | C35: =SUM(C31:C33) -> 822 | D35: =SUM(D31:D33) -> 1040 | E35: =SUM(E31:E33) -> 948 | F35: =SUM(F31:F33) -> 1046 | G35: =G31 -> 957 | H35: =H34+H33+H31 -> 1160 | I35: =SUM(I31:I33) -> 6982 | J35: =SUM(J31:J33) -> 952 | K35: =SUM(K31:K33) -> 1129 | L35: =SUM(L31:L33) -> 720 | M35: =SUM(M31:M33) -> 397 | N35: =SUM(N31:N33) -> 568 | O35: =SUM(O31:O33) -> 1304 | P35: =SUM(P31:P33) -> 1442 | Q35: =SUM(Q31:Q33) -> 6512
A36: AIC | B36: 169 | C36: 165 | D36: 164 | E36: 154 | F36: 180 | G36: 205 | H36: 141 | I36: =SUM(B36:H36) -> 1178 | J36: 178 | K36: 147 | L36: 155 | M36: 234 | N36: 221 | O36: 177 | P36: 217 | Q36: =SUM(J36:P36) -> 1329
A37: DTI | B37: 1860 | C37: 1829 | D37: 1380 | E37: 1997 | F37: 1228 | G37: 1658 | H37: 1787 | I37: =SUM(B37:H37) -> 11739 | J37: 1880 | K37: 1968 | L37: 1542 | M37: 1882 | N37: 1703 | O37: 1879 | P37: 1888 | Q37: =SUM(J37:P37) -> 12742
A38: Police Line | B38: 550 | C38: 600 | D38: 581 | E38: 703 | F38: 761 | G38: 700 | H38: 700 | I38: =SUM(B38:H38) -> 4595 | J38: 700 | K38: 700 | L38: 600 | M38: 750 | N38: 700 | O38: 550 | P38: 600 | Q38: =SUM(J38:P38) -> 4600
A39: WWS+Karati (L.V) | B39: 826 | C39: 832 | D39: 850 | E39: 877 | F39: 825 | G39: 903 | H39: 802 | I39: =SUM(B39:H39) -> 5915 | J39: 987 | K39: 1085 | L39: 830 | M39: 907 | N39: 762 | O39: 1038 | P39: 1028 | Q39: =SUM(J39:P39) -> 6637
A40: Central BL | B40: =SUM(B36:B39) -> 3405 | C40: =SUM(C36:C39) -> 3426 | D40: =SUM(D36:D39) -> 2975 | E40: =SUM(E36:E39) -> 3731 | F40: =SUM(F36:F39) -> 2994 | G40: =G39+G38+G37+G36 -> 3466 | H40: =SUM(H36:H39) -> 3430 | I40: =SUM(I36:I39) -> 23427 | J40: =SUM(J36:J39) -> 3745 | K40: =SUM(K36:K39) -> 3900 | L40: =SUM(L36:L39) -> 3127 | M40: =SUM(M36:M39) -> 3773 | N40: =SUM(N36:N39) -> 3386 | O40: =SUM(O36:O39) -> 3644 | ... Q40: =SUM(Q36:Q39) -> 25308
B41: =B30+B35+B40 -> 5501 | C41: =C30+C35+C40 -> 5244 | D41: =D30+D35+D40 -> 5125 | E41: =E30+E35+E40 -> 5614 | F41: =F30+F35+F40 -> 5202 | G41: =G30+G35+G40 -> 5618 | H41: =H30+H35+H40 -> 5638 | I41: =I30+I35+I40 -> 37909 | ... Q41: =Q30+Q35+Q40 -> 42834
...

Sheet Karate
A1: Site/Date | B1: 29th December | C1: 30th December | D1: 31st December | E1: 1st Jan | F1: 2nd Jan | G1: 3rd Jan | H1: 4th Jan | I1: week 1 Total | J1: 5th Jan | K1: 6th Jan | L1: 7th Jan | M1: 8th Jan | N1: 9th Jan | O1: 10th Jan | P1: 11th Jan | Q1: week 2Total
A2: KARATI | B2: =production!B9 -> 2562 | C2: =production!C9 -> 2547 | D2: =production!D9 -> 2656 | E2: =production!E9 -> 2636 | F2: =production!F9 -> 2253 | G2: =production!G9 -> 2396 | H2: =production!H9 -> 2120 | I2: =SUM(B2:H2) -> 17170 | J2: =production!J9 -> 2349 | K2: =production!K9 -> 2605 | L2: =production!L9 -> 2495 | M2: =production!M9 -> 2715 | N2: 2118 | O2: =production!O9 -> 2196 | P2: =production!P9 -> 2208 | Q2: =SUM(J2:P2) -> 16686
A3: KAR Supply | B3: =Supply!O12 -> 2562 | C3: =Supply!T12 -> 2547 | D3: =Supply!Y12 -> 2656 | E3: =Supply!E35 -> 2636 | F3: =Supply!J35 -> 2253 | G3: =Supply!O35 -> 2396 | H3: =Supply!T35 -> 2120 | I3: =SUM(B3:H3) -> 17170 | J3: =Supply!Y35 -> 2349 | K3: =Supply!E58 -> 2605 | L3: =Supply!J58 -> 2495 | M3: =Supply!O58 -> 2715 | N3: 2118 | O3: =Supply!T58 -> 2196 | P3: =Supply!E81 -> 2208 | Q3: =SUM(J3:P3) -> 16686
A4: Daily production sheet | B4: =B2-B3 -> 0 | C4: =C2-C3 -> 0 | D4: =D2-D3 -> 0 | E4: =E2-E3 -> 0 | F4: =F2-F3 -> 0 | G4: =G2-G3 -> 0 | H4: =H2-H3 -> 0 | I4: =SUM(B4:H4) -> 0 | J4: =J2-J3 -> 0 | K4: =K2-K3 -> 0 | L4: =L2-L3 -> 0 | M4: =M2-M3 -> 0 | N4: =T3 -> 0 | O4: =O2-O3 -> 0 | P4: =P2-P3 -> 0 | Q4: =SUM(J4:P4) -> 0
A6: Site/Date | B6: 12th Jan | C6: 13th Jan | D6: 14th Jan | E6: 15th Jan | F6: 16th Jan | G6: 17th Jan | H6: 18th Jan | I6: week 3 Total | J6: 19th Jan | K6: 20th Jan | L6: 21st Jan | M6: 22nd Jan | N6: 23rd Jan | O6: 24th Jan | P6: 25th Jan | Q6: week 4 Total
A7: KARATI | B7: =production!B28 -> 1923 | C7: =production!C28 -> 2145 | D7: =production!D28 -> 1977 | E7: 1819 | F7: 2127 | G7: =production!G28 -> 2370 | H7: =production!H28 -> 1979 | I7: =SUM(B7:H7) -> 14340 | J7: =production!J28 -> 2187 | K7: =production!K28 -> 2682 | L7: =production!L28 -> 1503 | M7: =production!M28 -> 847 | N7: =production!N28 -> 1644 | O7: 2858 | P7: =production!P28 -> 2795 | Q7: =SUM(J7:P7) -> 14516
A8: KAR Supply | B8: =Supply!J81 -> 1923 | C8: =Supply!O81 -> 2145 | D8: =Supply!T81 -> 1977 | E8: 1819 | F8: 2127 | G8: =Supply!AI81 -> 2370 | H8: =Supply!AN81 -> 1979 | I8: =SUM(B8:H8) -> 14340 | J8: =Supply!E104 -> 2187 | K8: =Supply!J104 -> 2682 | L8: =Supply!O104 -> 1503 | M8: =Supply!T104 -> 847 | N8: =Supply!Y104 -> 1639 | O8: =Supply!AD104 -> 2858 | P8: =Supply!AI104 -> 2795 | Q8: =SUM(J8:P8) -> 14511
A9: Daily production sheet | B9: =B7-B8 -> 0 | C9: =C7-C8 -> 0 | D9: =D7-D8 -> 0 | E9: =E7-E8 -> 0 | F9: =F7-F8 -> 0 | G9: =G7-G8 -> 0 | H9: =H7-H8 -> 0 | I9: =SUM(B9:H9) -> 0 | J9: =J7-J8 -> 0 | K9: =K7-K8 -> 0 | L9: =L7-L8 -> 0 | M9: =M7-M8 -> 0 | N9: =N7-N8 -> 5 | O9: =O7-O8 -> 0 | P9: =P7-P8 -> 0 | Q9: =SUM(J9:P9) -> 5
A11: Site/Date | B11: 26th Jan | C11: 27th Jan | D11: 28th Jan | E11: 29th Jan | F11: 30th Jan | G11: 31st Jan | H11: 1st Feb | I11: week 5 Total | J11: 2nd Feb | K11: 3rd Feb | L11: 4th Feb | M11: 5th Feb | N11: 6th Feb | O11: 7th Feb | P11: 8th Feb | Q11: week 6 Total
A12: KARATI | B12: =production!B47 -> 2709 | C12: 2859 | D12: =production!D47 -> 2841 | E12: =production!E47 -> 1948 | F12: 1777 | G12: 2079 | H12: 1509 | I12: =SUM(B12:H12) -> 15722 | J12: 2564 | K12: 2660 | L12: 2963 | M12: 3035 | N12: 2532 | O12: 2422 | P12: 2854 | Q12: =SUM(L12:P12) -> 13806
A13: KAR Supply | B13: =Supply!AN104 -> 2643 | C13: 2859 | D13: =Supply!J127 -> 2841 | E13: =Supply!O127 -> 1902 | F13: 1777 | G13: 2079 | H13: 1505 | I13: =SUM(B13:H13) -> 15606 | J13: 2564 | K13: 2589 | L13: 2967 | M13: 3116 | N13: 2507 | O13: 2342 | P13: 2890 | Q13: =SUM(L13:P13) -> 13822
A14: Daily production sheet | B14: =B12-B13 -> 66 | C14: =C12-C13 -> 0 | D14: =D12-D13 -> 0 | E14: =E12-E13 -> 46 | F14: =F12-F13 -> 0 | H14: =H12-H13 -> 4 | I14: =SUM(B14:H14) -> 116 | J14: =L12-L13 -> -4 | K14: =K12-K13 -> 71 | L14: =L12-L13 -> -4 | M14: =M12-M13 -> -81 | N14: =N12-N13 -> 25 | O14: =O12-O13 -> 80 | P14: =P12-P13 -> -36 | Q14: =Q12-Q13 -> -16
A16: Site/Date | B16: 9th feb | C16: 10th | D16: 11th | E16: 12th | F16: 13th | G16: 14th | H16: 15th | I16: week 7 total | J16: 16th feb | K16: 17th feb | L16: 18th feb | M16: 19th feb | N16: 20th feb | O16: 21st feb | P16: 22nd feb | Q16: week 8 total
A17: KARATI | B17: 2840 | C17: 2840 | D17: 2650 | E17: 2643 | F17: 2853 | G17: 2761 | H17: 2940 | I17: =SUM(B17:H17) -> 19527 | J17: 2962 | K17: 3043 | L17: 2865 | M17: =production!$M$67 -> 1829 | N17: =production!N67 -> 2602 | O17: =production!$O$67 -> 2858 | P17: =production!$P$67 -> 2166 | Q17: =SUM(J17:P17) -> 18325
A18: KAR Supply | B18: 2818 | C18: 2820 | D18: 2556 | E18: 2650 | F18: 2871 | G18: 2789 | H18: 2933 | I18: =SUM(B18:H18) -> 19437 | J18: 2940 | K18: 3080 | L18: 2831 | M18: =Supply!AN173 -> 1829 | N18: =Supply!E196 -> 2527 | O18: =Supply!J196 -> 3058 | P18: =Supply!O196 -> 2159 | Q18: =SUM(J18:P18) -> 18424
A19: Daily production sheet | B19: =B17-B18 -> 22 | C19: =C17-C18 -> 20 | D19: =D17-D18 -> 94 | E19: =E17-E18 -> -7 | F19: =F17-F18 -> -18 | G19: =G17-G18 -> -28 | H19: =H17-H18 -> 7 | I19: =I17-I18 -> 90 | ... Q19: =Q17-Q18 -> -99
A21: Site/Date | B21: 23rd Feb | C21: 24th Feb | D21: 25th Feb | E21: 26th Feb | F21: 27th Feb | G21: 28th Feb | H21: 29th Feb | I21: week 9total | J21: 1st March | K21: 2nd March | L21: 3rd March | M21: 4th March | N21: 5th March | O21: 6th March | P21: 7th March | Q21: week 10 total
A22: KARATI | B22: =production!$B$86 -> 2850 | C22: =production!$C$86 -> 1874 | D22: =production!$D$86 -> 2911 | E22: =production!$E$86 -> 2937 | F22: =production!F86 -> 2709 | G22: =production!$G$86 -> 2579 | H22: =production!$H$86 -> 2249 | I22: =SUM(B22:H22) -> 18109 | J22: 2938 | K22: 2716 | L22: =production!$L$86 -> 2763 | M22: =production!M86 -> 2810 | N22: =production!$N$86 -> 2881 | O22: =production!O86 -> 2176 | P22: =production!P86 -> 2548 | Q22: =SUM(J22:P22) -> 18832
A23: KAR Supply | B23: =Supply!T196 -> 2940 | C23: =Supply!Y196 -> 1827 | D23: =Supply!AD196 -> 2972 | E23: =Supply!AI196 -> 2899 | F23: =Supply!AN196 -> 2764 | G23: =Supply!E219 -> 2661 | H23: =Supply!J219 -> 2188 | I23: =SUM(B23:H23) -> 18251 | J23: 2693 | K23: 2638 | L23: =Supply!Y219 -> 2683 | M23: =Supply!AD219 -> 2843 | N23: =Supply!AI219 -> 2868 | O23: =Supply!AN219 -> 2156 | P23: =Supply!E242 -> 2527 | Q23: =SUM(J23:P23) -> 18408
A24: Daily production sheet | B24: =B22-B23 -> -90 | C24: =C22-C23 -> 47 | D24: =D22-D23 -> -61 | E24: =E22-E23 -> 38 | F24: =F22-F23 -> -55 | G24: =G22-G23 -> -82 | H24: =H22-H23 -> 61 | I24: =I22-I23 -> -142 | ... Q24: =Q22-Q23 -> 424
A26: Site/Date | B26: 8th March | C26: 9th March | D26: 10th March | E26: 11th March | F26: 12th March | G26: 13th March | H26: 14th March | I26: week 11total | J26: 15th March | K26: 16th March | L26: 17th March | M26: 18th March | N26: 19th March | O26: 20th March | P26: 21st March | Q26: week 12 total
A27: KARATI | B27: =production!B105 -> 2491 | C27: =production!$C$105 -> 2288 | D27: =production!$D$105 -> 2270 | E27: =production!E105 -> 2771 | F27: =production!$F$105 -> 2642 | G27: =production!$G$105 -> 2673 | H27: =production!$H$105 -> 2678 | I27: =SUM(B27:H27) -> 17813 | J27: =production!$J$105 -> 2742 | K27: =production!$K$105 -> 2720 | L27: =production!$L$105 -> 2357 | M27: =production!M105 -> 2949 | N27: =production!N105 -> 2160 | O27: =production!O105 -> 2536 | P27: =production!P105 -> 2692 | Q27: =SUM(J27:P27) -> 18156
A28: KAR Supply | B28: =Supply!J242 -> 2253 | C28: =Supply!O242 -> 2280 | D28: =Supply!T242 -> 2224 | E28: =Supply!Y242 -> 2739 | F28: =Supply!AD242 -> 2698 | G28: =Supply!AI242 -> 2567 | H28: =Supply!AN242 -> 2709 | I28: =SUM(B28:H28) -> 17470 | J28: =Supply!E265 -> 2744 | K28: =Supply!J265 -> 2738 | L28: =Supply!O265 -> 2342 | M28: =Supply!T265 -> 2858 | N28: =Supply!Y265 -> 2207 | O28: =Supply!AD265 -> 2479 | P28: =Supply!AI265 -> 2835 | Q28: =SUM(J28:P28) -> 18203
A29: Daily production sheet | B29: =B27-B28 -> 238 | C29: =C27-C28 -> 8 | D29: =D27-D28 -> 46 | E29: =E27-E28 -> 32 | F29: =F27-F28 -> -56 | G29: =G27-G28 -> 106 | H29: =H27-H28 -> -31 | I29: =I27-I28 -> 343 | ... Q29: =Q27-Q28 -> -47
A31: Site/Date | B31: 22nd March | C31: 23rd March | D31: 24th March | E31: 25th March | F31: 26th March | G31: 27th March | H31: 28th March | I31: week 13total | J31: 29th March | K31: 30th March | L31: 31st March | M31: 1st April | N31: 2nd April | O31: 3rd April | P31: 4th April | Q31: week 14 total
A32: KARATI | B32: =production!B124 -> 2240 | C32: =production!C124 -> 2796 | D32: =production!D124 -> 2625 | E32: =production!$E$124 -> 2609 | F32: =production!F124 -> 2841 | G32: =production!$G$124 -> 2921 | H32: =production!H124 -> 2941 | I32: =SUM(B32:H32) -> 18973 | J32: =production!$J$124 -> 2870 | K32: =production!$K$124 -> 2677 | L32: =production!$L$124 -> 2916 | M32: =production!$M$124 -> 2875 | N32: =production!$N$124 -> 2625 | O32: 2674 | P32: =production!$P$124 -> 2350 | Q32: =SUM(J32:P32) -> 18987
A33: KAR Supply | B33: =Supply!AN265 -> 1995 | C33: =Supply!E288 -> 2890 | D33: =Supply!J288 -> 2666 | E33: =Supply!O288 -> 2582 | F33: =Supply!T288 -> 2829 | G33: =Supply!Y288 -> 2890 | H33: =Supply!AD288 -> 2893 | I33: =SUM(B33:H33) -> 18745 | J33: =Supply!AI288 -> 2878 | K33: =Supply!AN288 -> 2652 | L33: =Supply!E311 -> 2951 | M33: =Supply!J311 -> 2883 | N33: =Supply!O311 -> 2597 | O33: 2679 | P33: =Supply!Y311 -> 2251 | Q33: =SUM(J33:P33) -> 18891
A34: Daily production sheet | B34: =B32-B33 -> 245 | C34: =C32-C33 -> -94 | D34: =D32-D33 -> -41 | E34: =E32-E33 -> 27 | F34: =F32-F33 -> 12 | G34: =G32-G33 -> 31 | H34: =H32-H33 -> 48 | I34: =I32-I33 -> 228 | ... Q34: =Q32-Q33 -> 96
A36: Site/Date | B36: 5th April | C36: 6th April | D36: 7th April | E36: 8th April | F36: 9th April | G36: 10th April | H36: 11th April | I36: week 15total | J36: 12th April | K36: 13th April | L36: 14th April | M36: 15th April | N36: 16th April | O36: 17th April | P36: 18th April | Q36: week 16 total
A37: KARATI | B37: =production!$B$143 -> 2233 | C37: =production!$C$143 -> 2584 | D37: =production!$D$143 -> 2406 | E37: =production!$E$143 -> 2425 | F37: =production!$F$143 -> 1873 | G37: =production!$G$143 -> 2552 | H37: =production!$H$143 -> 1874 | I37: =SUM(B37:H37) -> 15947 | J37: =production!J143 -> 246 | K37: =production!K143 -> 1965 | L37: =production!L143 -> 2180 | M37: =production!$M$143 -> 2630 | N37: =production!N143 -> 2513 | O37: 2689 | P37: =production!$P$143 -> 2006 | Q37: =SUM(J37:P37) -> 14229
A38: KAR Supply | B38: =Supply!AD311 -> 2298 | C38: =Supply!AI311 -> 2515 | D38: =Supply!AN311 -> 2400 | E38: =Supply!E334 -> 2405 | F38: =Supply!J334 -> 1801 | G38: =Supply!O334 -> 2573 | H38: =Supply!T334 -> 1892 | I38: =SUM(B38:H38) -> 15884 | J38: =Supply!Y334 -> 229 | K38: =Supply!AD334 -> 2034 | L38: =Supply!AI334 -> 2173 | M38: =Supply!AN334 -> 2541 | N38: =Supply!E357 -> 2626 | O38: 2679 | P38: =Supply!O357 -> 1859 | Q38: =SUM(J38:P38) -> 14141
A39: Daily production sheet | B39: =B37-B38 -> -65 | C39: =C37-C38 -> 69 | D39: =D37-D38 -> 6 | E39: =E37-E38 -> 20 | F39: =F37-F38 -> 72 | G39: =G37-G38 -> -21 | H39: =H37-H38 -> -18 | I39: =I37-I38 -> 63 | ... Q39: =Q37-Q38 -> 88
A41: Site/Date | B41: 19th April | C41: 20th April | D41: 21st April | E41: 22nd April | F41: 23rd April | G41: 24th April | H41: 25th April | I41: week 17total | J41: 26th April | K41: 27th April | L41: 28th April | M41: 29th April | N41: 30th April | O41: 1st May | P41: 2nd May | Q41: week 18 total
A42: KARATI | B42: =production!$B$162 -> 2289 | C42: =production!$C$162 -> 2257 | D42: =production!$D$162 -> 2411 | E42: =production!E162 -> 2168 | F42: =production!$F$162 -> 1965 | G42: =production!G162 -> 2090 | H42: =production!H162 -> 2470 | I42: =SUM(B42:H42) -> 15650 | J42: =production!$J$162 -> 2487 | K42: =production!$K$162 -> 1973 | L42: =production!$L$162 -> 2076 | M42: =production!$M$162 -> 1972 | N42: =production!N162 -> 2145 | O42: =production!O162 -> 1793 | P42: =production!$P$162 -> 1285 | Q42: =SUM(J42:P42) -> 13731
A43: KAR Supply | B43: =Supply!T357 -> 2300 | C43: =Supply!Y357 -> 2245 | D43: =Supply!AD357 -> 2189 | E43: =Supply!AI357 -> 2132 | F43: =Supply!AN357 -> 1955 | G43: =Supply!E380 -> 2352 | H43: =Supply!J380 -> 2037 | I43: =SUM(B43:H43) -> 15210 | J43: =Supply!O380 -> 2353 | K43: =Supply!T380 -> 1932 | L43: =Supply!Y380 -> 2444 | M43: =Supply!AD380 -> 1819 | N43: =Supply!AI380 -> 2086 | O43: =Supply!AN380 -> 1869 | P43: =Supply!E403 -> 1238 | Q43: =SUM(J43:P43) -> 13741
A44: Daily production sheet | B44: =B42-B43 -> -11 | C44: =C42-C43 -> 12 | D44: =D42-D43 -> 222 | E44: =E42-E43 -> 36 | F44: =F42-F43 -> 10 | G44: =G42-G43 -> -262 | H44: =H42-H43 -> 433 | I44: =I42-I43 -> 440 | ... Q44: =Q42-Q43 -> -10
A46: Site/Date | B46: 3rd May | C46: 4th May | D46: 5th May | E46: 6th May | F46: 7th May | G46: 8th May | H46: 9th May | I46: week 19total | J46: 10th May | K46: 11th May | L46: 12th May | M46: 13th May | N46: 14th May | O46: 15th May | P46: 16th May | Q46: week 20 total
A47: KARATI | B47: =production!$B$181 -> 2359 | C47: =production!$C$181 -> 1884 | D47: =production!$D$181 -> 1806 | E47: =production!$E$181 -> 2105 | F47: =production!F181 -> 1855 | G47: =production!G181 -> 2196 | H47: =production!H181 -> 2322 | I47: =SUM(B47:H47) -> 14527 | J47: =production!J181 -> 2452 | K47: =production!K181 -> 2766 | L47: =production!L181 -> 2392 | M47: =production!M181 -> 2010 | N47: =production!N181 -> 2025 | O47: =production!$O$181 -> 2231 | P47: =production!P181 -> 2479 | Q47: =SUM(J47:P47) -> 16355
A48: KAR Supply | B48: =Supply!J403 -> 2040 | C48: =Supply!O403 -> 1795 | D48: =Supply!T403 -> 1718 | E48: =Supply!Y403 -> 2430 | F48: =Supply!AD403 -> 1964 | G48: =Supply!AI403 -> 2507 | H48: =Supply!AN403 -> 2473 | I48: =SUM(B48:H48) -> 14927 | J48: =Supply!E426 -> 2403 | K48: =Supply!J426 -> 2667 | L48: =Supply!O426 -> 2329 | M48: =Supply!T426 -> 1932 | N48: =Supply!Y426 -> 2039 | O48: =Supply!X443 -> 330243 | P48: =Supply!AI426 -> 2454 | Q48: =SUM(J48:P48) -> 344067
A49: Daily production sheet | B49: =B47-B48 -> 319 | C49: =C47-C48 -> 89 | D49: =D47-D48 -> 88 | E49: =E47-E48 -> -325 | F49: =F47-F48 -> -109 | G49: =G47-G48 -> -311 | H49: =H47-H48 -> -151 | I49: =I47-I48 -> -400 | ... Q49: =Q47-Q48 -> -327712
...

Sheet DTI
B1: Site/Date | C1: 29th December | D1: 30th December | E1: 31st December | F1: 1st Jan | G1: 2nd Jan | H1: 3rd Jan | I1: 4th Jan | J1: week 1Total | K1: 5th Jan | L1: 6th Jan | M1: 7th Jan | N1: 8th Jan | O1: 9th Jan | P1: 10th Jan | Q1: 11th Jan | R1: week 2 Total
B2: DTI | C2: =production!B15 -> 1700 | D2: =production!C15 -> 1264 | E2: =production!D15 -> 1870 | F2: =production!E15 -> 2069 | G2: =production!F15 -> 1496 | H2: =production!G15 -> 1630 | I2: =production!H15 -> 1669 | J2: =SUM(C2:I2) -> 11698 | K2: =production!J15 -> 1552 | L2: =production!K15 -> 1795 | M2: =production!L15 -> 1830 | N2: =production!M15 -> 1690 | O2: 1822 | P2: =production!O15 -> 1895 | Q2: =production!P15 -> 1607 | R2: =SUM(K2:Q2) -> 12191
B3: DTI Supply | C3: =Supply!O3 -> 1700 | D3: =Supply!T3 -> 1260 | E3: =Supply!Y3 -> 1870 | F3: =Supply!E26 -> 1990 | G3: =Supply!J26 -> 1440 | H3: =Supply!O26 -> 1630 | I3: =Supply!T26 -> 1640 | J3: =SUM(C3:I3) -> 11530 | K3: =Supply!Y26 -> 1480 | L3: =Supply!E49 -> 1710 | M3: =Supply!J49 -> 1830 | N3: =Supply!O49 -> 1500 | O3: 1822 | P3: =Supply!T49 -> 1670 | Q3: =Supply!E72 -> 1580 | R3: =SUM(K3:Q3) -> 11592
B4: Daily production sheet | C4: =C2-C3 -> 0 | D4: =D2-D3 -> 4 | E4: =E2-E3 -> 0 | F4: =F2-F3 -> 79 | G4: =G2-G3 -> 56 | H4: =H2-H3 -> 0 | I4: =I2-I3 -> 29 | J4: =SUM(C4:I4) -> 168 | K4: =K2-K3 -> 72 | L4: =L2-L3 -> 85 | M4: =M2-M3 -> 0 | N4: =N2-N3 -> 190 | O4: =O2-O3 -> 0 | P4: =P2-P3 -> 225 | Q4: =Q2-Q3 -> 27 | R4: =SUM(K4:Q4) -> 599
B6: Site/Date | C6: 12th Jan | D6: 13th Jan | E6: 14th Jan | F6: 15th Jan | G6: 16th Jan | H6: 17th Jan | I6: 18th Jan | J6: week 3 Total | K6: 19th Jan | L6: 20th Jan | M6: 21st Jan | N6: 22nd Jan | O6: 23rd Jan | P6: 24th Jan | Q6: 25th Jan | R6: week 4 Total
B7: DTI | C7: =production!B34 -> 1860 | D7: =production!C34 -> 1829 | E7: =production!D34 -> 1380 | F7: 1997 | G7: 1228 | H7: =production!G34 -> 1658 | I7: =production!H34 -> 1787 | J7: =SUM(C7:I7) -> 11739 | K7: =production!J34 -> 1880 | L7: =production!K34 -> 1968 | M7: =production!L34 -> 1542 | N7: =production!M34 -> 1782 | O7: =production!N34 -> 1703 | P7: =production!O34 -> 1879 | Q7: =production!P34 -> 1888 | R7: =SUM(K7:Q7) -> 12642
B8: DTI Supply | C8: =Supply!J72 -> 1770 | D8: =Supply!O72 -> 1710 | E8: =Supply!T72 -> 1290 | F8: 1830 | G8: 1070 | H8: =Supply!AI72 -> 1490 | I8: =Supply!AN72 -> 1780 | J8: =SUM(C8:I8) -> 10940 | K8: =Supply!E95 -> 1680 | L8: =Supply!J95 -> 1850 | M8: =Supply!O95 -> 1420 | N8: =Supply!T95 -> 1830 | O8: =Supply!Y95 -> 1610 | P8: =Supply!AD95 -> 1840 | Q8: =Supply!AI95 -> 1830 | R8: =SUM(K8:Q8) -> 12060
B9: Daily production sheet | C9: =C7-C8 -> 90 | D9: =D7-D8 -> 119 | E9: =E7-E8 -> 90 | F9: =F7-F8 -> 167 | G9: =G7-G8 -> 158 | H9: =H7-H8 -> 168 | I9: =I7-I8 -> 7 | J9: =SUM(C9:I9) -> 799 | K9: =K7-K8 -> 200 | L9: =L7-L8 -> 118 | M9: =M7-M8 -> 122 | N9: =N7-N8 -> -48 | O9: =O7-O8 -> 93 | P9: =P7-P8 -> 39 | Q9: =Q7-Q8 -> 58 | R9: =SUM(K9:Q9) -> 582
B12: Site/Date | C12: 26th Jan | D12: 27th Jan | E12: 28th Jan | F12: 29th Jan | G12: 30th Jan | H12: 31st Jan | I12: 1st Feb | J12: week 5 Total | K12: 2nd Feb | L12: 3rd Feb | M12: 4th Feb | N12: 5th Feb | O12: 6th Feb | P12: 7th Feb | Q12: 8th Feb | R12: week 6 Total
B13: DTI | C13: =production!B53 -> 1826 | D13: 1554 | E13: =production!D53 -> 1870 | F13: =production!E53 -> 2005 | G13: 1214 | H13: 1429 | I13: 1634 | J13: =SUM(C13:I13) -> 11532 | K13: 1780 | L13: 1779 | M13: 1797 | N13: 1824 | O13: 1867 | P13: 1702 | Q13: 2076 | R13: =SUM(K13:Q13) -> 12825
B14: DTI Supply | C14: =Supply!AN95 -> 1670 | D14: 1470 | E14: =Supply!J118 -> 1870 | F14: =Supply!O118 -> 1850 | G14: 1140 | H14: 1420 | I14: 1470 | J14: =SUM(C14:I14) -> 10890 | K14: 1761 | L14: 1640 | M14: 1760 | N14: 1760 | O14: 1720 | P14: 1440 | Q14: 1870 | R14: =SUM(K14:Q14) -> 11951
B16: Site/Date | C16: 9th feb | D16: 10th feb | E16: 11th feb | F16: 12th feb | G16: 13th feb | H16: 14th feb | I16: 15th feb | J16: week 7 | K16: 16th feb | L16: 17th feb | M16: 18th feb | N16: 19th feb | O16: 20th feb | P16: 21st feb | Q16: 22nd feb | R16: week 8
B17: DTI | C17: 1146 | D17: 1920 | E17: 2390 | F17: 1680 | G17: 1738 | H17: 1437 | I17: 1872 | J17: =SUM(C17:I17) -> 12183 | K17: 1786 | L17: 1677 | M17: 1672 | N17: =production!$M$73 -> 1815 | O17: =production!N73 -> 1821 | P17: =production!O73 -> 1681 | Q17: =production!$P$73 -> 1855 | R17: =SUM(K17:Q17) -> 12307
B18: DTI Supply | C18: 960 | D18: 1880 | E18: 1670 | F18: 1660 | G18: 1600 | H18: 1210 | I18: 1820 | J18: =SUM(C18:I18) -> 10800 | K18: 1730 | L18: 1450 | M18: 1630 | N18: =Supply!AN164 -> 1710 | O18: =Supply!E187 -> 1720 | P18: =Supply!J187 -> 1600 | Q18: =Supply!O187 -> 1720 | R18: =SUM(K18:Q18) -> 11560
B19: Daily production sheet | C19: =C17-C18 -> 186 | D19: =D17-D18 -> 40 | E19: =E17-E18 -> 720 | F19: =F17-F18 -> 20 | G19: =G17-G18 -> 138 | H19: =H17-H18 -> 227 | I19: =I17-I18 -> 52 | J19: =J17-J18 -> 1383 | ... R19: =R17-R18 -> 747
B21: Site/Date | C21: 23rd feb | D21: 24th feb | E21: 25th feb | F21: 26th feb | G21: 27th feb | H21: 28th feb | I21: 29th feb | J21: week 9 | K21: 1st March | L21: 2nd March | M21: 3rd March | N21: 4th March | O21: 5th March | P21: 6th March | Q21: 7th March | R21: week 10
B22: DTI | C22: =production!$B$92 -> 1350 | D22: =production!$C$92 -> 1048 | E22: =production!$D$92 -> 1150 | F22: =production!$E$92 -> 940 | G22: =production!F92 -> 830 | H22: =production!$G$92 -> 920 | I22: =production!$H$92 -> 1050 | J22: =SUM(C22:I22) -> 7288 | K22: 1023 | L22: 1524 | M22: =production!$L$92 -> 1460 | N22: =production!M92 -> 1669 | O22: =production!$N$92 -> 2121 | P22: =production!O92 -> 1380 | Q22: =production!P92 -> 2107 | R22: =SUM(K22:Q22) -> 11284
B23: DTI Supply | C23: =Supply!T187 -> 1350 | D23: =Supply!Y187 -> 1040 | E23: =Supply!AD187 -> 1150 | F23: =Supply!AI187 -> 1120 | G23: =Supply!AN187 -> 830 | H23: =Supply!E210 -> 920 | I23: =Supply!J210 -> 1050 | J23: =SUM(C23:I23) -> 7460 | K23: 1090 | L23: 1480 | M23: =Supply!Y210 -> 1460 | N23: =Supply!AD210 -> 1600 | O23: =Supply!AI210 -> 1870 | P23: =Supply!AN210 -> 1380 | Q23: =Supply!E233 -> 1930 | R23: =SUM(K23:Q23) -> 10810
B24: Daily production sheet | C24: =C22-C23 -> 0 | D24: =D22-D23 -> 8 | E24: =E22-E23 -> 0 | F24: =F22-F23 -> -180 | G24: =G22-G23 -> 0 | H24: =H22-H23 -> 0 | I24: =I22-I23 -> 0 | J24: =J22-J23 -> -172 | ... R24: =R22-R23 -> 474
B26: Site/Date | C26: 8th March | D26: 9th March | E26: 10th March | F26: 11th March | G26: 12th March | H26: 13th March | I26: 14th March | J26: week 11 | K26: 15th March | L26: 16th March | M26: 17th March | N26: 18th March | O26: 19th March | P26: 20th March | Q26: 21st March | R26: week 12
B27: DTI | C27: =production!I111 -> 12405 | D27: 1630 | E27: =production!$D$111 -> 1682 | F27: =production!E111 -> 1872 | G27: =production!$F$111 -> 1678 | H27: =production!$G$111 -> 1760 | I27: =production!$H$111 -> 1770 | J27: =SUM(C27:I27) -> 22797 | K27: =production!$J$111 -> 1786 | L27: =production!$K$111 -> 1745 | M27: =production!$L$111 -> 1648 | N27: =production!M111 -> 1831 | O27: =production!N111 -> 1606 | P27: =production!O111 -> 1705 | Q27: =production!P111 -> 1855 | R27: =SUM(K27:Q27) -> 12176
B28: DTI Supply | C28: =Supply!J233 -> 1920 | D28: 1590 | E28: =Supply!T233 -> 1600 | F28: =Supply!Y233 -> 1710 | G28: =Supply!AD233 -> 1590 | H28: =Supply!AI233 -> 1740 | I28: =Supply!AN233 -> 1670 | J28: =SUM(C28:I28) -> 11820 | K28: =Supply!E256 -> 1740 | L28: =Supply!J256 -> 1700 | M28: =Supply!O256 -> 1560 | N28: =Supply!T256 -> 1740 | O28: =Supply!Y256 -> 1410 | P28: =Supply!AD256 -> 1650 | Q28: =Supply!AI256 -> 1730 | R28: =SUM(K28:Q28) -> 11530
B29: Daily production sheet | C29: =C27-C28 -> 10485 | D29: =D27-D28 -> 40 | E29: =E27-E28 -> 82 | F29: =F27-F28 -> 162 | G29: =G27-G28 -> 88 | H29: =H27-H28 -> 20 | I29: =I27-I28 -> 100 | J29: =J27-J28 -> 10977 | ... R29: =R27-R28 -> 646
B31: Site/Date | C31: 22nd March | D31: 23rd March | E31: 24th March | F31: 25th March | G31: 26th March | H31: 27th March | I31: 28th March | J31: week 13 week | K31: 29th March | L31: 30th March | M31: 31st March | N31: 1st April | O31: 2nd April | P31: 3rd April | Q31: 4th April | R31: week 14 week
B32: DTI | C32: =production!B130 -> 1875 | D32: =production!C130 -> 1828 | E32: =production!D130 -> 1851 | F32: =production!$E$130 -> 1928 | G32: =production!F130 -> 1774 | H32: =production!$G$130 -> 1695 | I32: =production!H130 -> 1650 | J32: =SUM(C32:I32) -> 12601 | K32: =production!J130 -> 1758 | L32: =production!K130 -> 1674 | M32: =production!L130 -> 1488 | N32: =production!$M$130 -> 1252 | O32: =production!$N$130 -> 1253 | P32: 1289 | Q32: =production!$P$130 -> 1249 | R32: =SUM(K32:Q32) -> 9963
B33: DTI Supply | C33: =Supply!AN256 -> 1810 | D33: =Supply!E279 -> 1740 | E33: =Supply!J279 -> 1750 | F33: =Supply!O279 -> 1770 | G33: =Supply!T279 -> 1690 | H33: =Supply!Y279 -> 1560 | I33: =Supply!AD279 -> 1650 | J33: =SUM(C33:I33) -> 11970 | K33: =Supply!AI279 -> 1660 | L33: =Supply!AN279 -> 1510 | M33: =Supply!E302 -> 1310 | N33: =Supply!J302 -> 1240 | O33: =Supply!O302 -> 1200 | P33: 1080 | Q33: =Supply!Y302 -> 1090 | R33: =SUM(K33:Q33) -> 9090
B34: Daily production sheet | C34: =C32-C33 -> 65 | D34: =D32-D33 -> 88 | E34: =E32-E33 -> 101 | F34: =F32-F33 -> 158 | G34: =G32-G33 -> 84 | H34: =H32-H33 -> 135 | I34: =I32-I33 -> 0 | J34: =J32-J33 -> 631 | ... R34: =R32-R33 -> 873
B36: Site/Date | C36: 5th April | D36: 6th April | E36: 7th April | F36: 8th April | G36: 9th April | H36: 10th April | I36: 11th April | J36: week 15 week | K36: 12th April | L36: 13th April | M36: 14th April | N36: 15th April | O36: 16th April | P36: 17th April | Q36: 18th April | R36: week 16week
B37: DTI | C37: =production!$B$149 -> 1570 | D37: =production!$C$149 -> 1595 | E37: =production!$D$149 -> 1399 | F37: =production!$E$149 -> 1560 | G37: =production!$F$149 -> 1893 | H37: =production!$G$149 -> 1780 | I37: =production!$H$149 -> 1961 | J37: =SUM(C37:I37) -> 11758 | K37: =production!J149 -> 1920 | L37: =production!K149 -> 1747 | M37: =production!L149 -> 1590 | N37: =production!$M$149 -> 1829 | O37: =production!N149 -> 1938 | P37: =production!$O$149 -> 1913 | Q37: =production!$P$149 -> 1764 | R37: =SUM(K37:Q37) -> 12701
B38: DTI Supply | C38: =Supply!AD302 -> 1570 | D38: =Supply!AI302 -> 1520 | E38: =Supply!AN302 -> 1350 | F38: =Supply!E325 -> 1470 | G38: =Supply!J325 -> 1830 | H38: =Supply!O325 -> 1700 | I38: =Supply!T325 -> 1760 | J38: =SUM(C38:I38) -> 11200 | K38: =Supply!Y325 -> 1920 | L38: =Supply!AD325 -> 1590 | M38: =Supply!AI325 -> 1610 | N38: =Supply!AN325 -> 1750 | O38: =Supply!E348 -> 1870 | P38: =Supply!J348 -> 1700 | Q38: =Supply!O348 -> 1680 | R38: =SUM(K38:Q38) -> 12120
B39: Daily production sheet | C39: =C37-C38 -> 0 | D39: =D37-D38 -> 75 | E39: =E37-E38 -> 49 | F39: =F37-F38 -> 90 | G39: =G37-G38 -> 63 | H39: =H37-H38 -> 80 | I39: =I37-I38 -> 201 | J39: =J37-J38 -> 558 | ... R39: =R37-R38 -> 581
B41: Site/Date | C41: 19th April | D41: 20th April | E41: 21st April | F41: 22nd April | G41: 23rd April | H41: 24th April | I41: 25th April | J41: week 17 week | K41: 26th April | L41: 27th April | M41: 28th April | N41: 29th April | O41: 30th April | P41: 1st May | Q41: 2nd May | R41: week 18week
B42: DTI | C42: =production!$B$168 -> 1813 | D42: =production!$C$168 -> 1805 | E42: =production!$D$168 -> 1840 | F42: 1870 | G42: =production!$F$168 -> 130 | H42: =production!G168 -> 390 | I42: =production!H168 -> 390 | J42: =SUM(C42:I42) -> 8238 | K42: =production!$J$168 -> 420 | L42: =production!$K$168 -> 1594 | M42: =production!$L$168 -> 1461 | N42: =production!$M$168 -> 1557 | O42: =production!N168 -> 1655 | P42: =production!O168 -> 1558 | Q42: =production!$P$168 -> 1480 | R42: =SUM(K42:Q42) -> 9725
B43: DTI Supply | C43: =Supply!T348 -> 1690 | D43: =Supply!Y348 -> 1790 | E43: =Supply!AD348 -> 1710 | F43: =Supply!AI348 -> 1810 | G43: =Supply!AN348 -> 130 | H43: =Supply!E371 -> 390 | I43: =Supply!J371 -> 0 | J43: =SUM(C43:I43) -> 7520 | K43: =Supply!O371 -> 570 | L43: =Supply!T371 -> 1160 | M43: =Supply!Y371 -> 1280 | N43: =Supply!AD371 -> 1350 | O43: =Supply!AI371 -> 1810 | P43: =Supply!AN371 -> 1260 | Q43: =Supply!E394 -> 1200 | R43: =SUM(K43:Q43) -> 8630
B44: Daily production sheet | C44: =C42-C43 -> 123 | D44: =D42-D43 -> 15 | E44: =E42-E43 -> 130 | F44: =F42-F43 -> 60 | G44: =G42-G43 -> 0 | H44: =H42-H43 -> 0 | I44: =I42-I43 -> 390 | J44: =J42-J43 -> 718 | ... R44: =R42-R43 -> 1095
B46: Site/Date | C46: 3rd May | D46: 4th May | E46: 5th May | F46: 6th May | G46: 7th May | H46: 8th May | I46: 9th May | J46: week19week | K46: 10th May | L46: 11th May | M46: 12th May | N46: 13th May | O46: 14th May | P46: 15th May | Q46: 16th May | R46: week 20week
B47: DTI | C47: =production!$B$187 -> 1649 | D47: 490 | E47: =production!$D$187 -> 0 | F47: =production!$E$187 -> 524 | G47: =production!F187 -> 1245 | H47: =production!G187 -> 1540 | I47: =production!H187 -> 1821 | J47: =SUM(C47:I47) -> 7269 | K47: =production!J187 -> 1925 | L47: =production!K187 -> 965 | M47: =production!L187 -> 1602 | N47: =production!M187 -> 1600 | O47: =production!N187 -> 2040 | P47: =production!$O$187 -> 2087 | Q47: =production!P187 -> 2410 | R47: =SUM(K47:Q47) -> 12629
B48: DTI Supply | C48: =Supply!J394 -> 1400 | D48: =Supply!O394 -> 490 | E48: =Supply!T394 -> 0 | F48: =Supply!Y394 -> 440 | G48: =Supply!AD394 -> 1180 | H48: =Supply!AI394 -> 1810 | I48: =Supply!AN394 -> 1570 | J48: =SUM(C48:I48) -> 6890 | K48: =Supply!E417 -> 1690 | L48: =Supply!J417 -> 890 | M48: =Supply!O417 -> 1390 | N48: =Supply!T417 -> 1600 | O48: =Supply!Y417 -> 2040 | P48: =Supply!AD417 -> 2050 | Q48: =Supply!AI417 -> 2410 | R48: =SUM(K48:Q48) -> 12070
B49: Daily production sheet | C49: =C47-C48 -> 249 | D49: =D47-D48 -> 0 | E49: =E47-E48 -> 0 | F49: =F47-F48 -> 84 | G49: =G47-G48 -> 65 | H49: =H47-H48 -> -270 | I49: =I47-I48 -> 251 | J49: =J47-J48 -> 379 | ... R49: =R47-R48 -> 559
B51: Site/Date | C51: 17th May | D51: 18th May | E51: 19th May | F51: 20th May | G51: 21st May | H51: 22nd May | I51: 23rd May | J51: week21week | K51: 24th May | L51: 25th May | M51: 26th May | N51: 27th May | O51: 28th May | P51: 29th May | Q51: 30th May | R51: week 22week
...

Sheet Kwh
A1: Daily production sheet
A2: Site/Date | B2: 29th December | C2: 30th December | D2: 31st December | E2: 1st Jan | F2: 2nd Jan | G2: 3rd Jan | H2: 4th Jan | I2: week 1 Total | J2: 5th Jan | K2: 6th Jan | L2: 7th Jan | M2: 8th Jan | N2: 9th Jan | O2: 10th Jan | P2: 11th Jan | Q2: week 2 Total
A3: DCK | B3: 385 | C3: 294 | D3: 380 | E3: 308 | F3: 216 | G3: 201 | H3: 262 | I3: =SUM(B3:H3) -> 2046 | J3: 258 | K3: 202 | L3: 309 | M3: 285 | N3: 346 | O3: 255 | P3: 152 | Q3: =SUM(J3:P3) -> 1807 | R3: =181+165 -> 346
A4: WWS | B4: 1074 | C4: 1166 | D4: 996 | E4: 1048 | F4: 1028 | G4: 1089 | H4: 958 | I4: =SUM(B4:H4) -> 7359 | J4: 1041 | K4: 1127 | L4: 654 | M4: 1184 | N4: 1071 | O4: 895 | P4: 990 | Q4: =SUM(J4:P4) -> 6962
A5: Mai Mahiu | B5: 168 | C5: 7 | D5: 90 | E5: 46 | F5: 79 | G5: 29 | H5: 88 | I5: =SUM(B5:H5) -> 507 | J5: 70 | K5: 105 | L5: 124 | M5: 85 | N5: 80 | O5: 40 | P5: 108 | Q5: =SUM(J5:P5) -> 612
A6: Ngondi | B6: 0 | C6: 0 | D6: 0 | E6: 0 | F6: 0 | G6: 0 | H6: 0 | I6: =SUM(B6:H6) -> 0 | J6: 0 | K6: 0 | L6: 0 | M6: 0 | N6: 0 | O6: 0 | P6: 0 | Q6: =SUM(J6:P6) -> 0
A7: NIP | B7: 0 | C7: 0 | D7: 0 | E7: 0 | F7: 0 | G7: 2869 | H7: 0 | I7: =SUM(B7:H7) -> 2869 | J7: 0 | K7: 0 | L7: 0 | M7: 0 | N7: 1823 | O7: 0 | P7: 0 | Q7: =SUM(J7:P7) -> 1823 | S7: =269461-269459 -> 2
A8: Southern | B8: =SUM(B3:B7) -> 1627 | C8: =SUM(C3:C7) -> 1467 | D8: =SUM(D3:D7) -> 1466 | E8: =SUM(E3:E7) -> 1402 | F8: =SUM(F3:F7) -> 1323 | G8: =G5+G4+G3 -> 1319 | H8: =SUM(H3:H7) -> 1308 | I8: =SUM(I3:I7) -> 12781 | J8: =SUM(J3:J5) -> 1369 | K8: =SUM(K3:K5) -> 1434 | L8: =SUM(L3:L7) -> 1087 | M8: =SUM(M3:M4) -> 1469 | N8: =SUM(N3:N7) -> 3320 | O8: =SUM(O3:O5) -> 1190 | P8: =SUM(P3:P5) -> 1250 | Q8: =SUM(Q3:Q5) -> 9381
A9: KARATI | B9: 2418 | C9: 2420 | D9: 2473 | E9: 2533 | F9: 2142 | G9: 2266 | H9: 2012 | I9: =SUM(B9:H9) -> 16264 | J9: 2241 | K9: 2425 | L9: 2415 | M9: 2580 | N9: 2038 | O9: 1993 | P9: 2114 | Q9: =SUM(J9:P9) -> 15806
A10: Kinungi BH | B10: 0 | C10: 0 | D10: 0 | E10: 0 | F10: 0 | G10: 0 | H10: 0 | I10: =SUM(B10:H10) -> 0 | J10: 0 | K10: 0 | L10: 0 | M10: 0 | N10: 0 | O10: 0 | P10: 0 | Q10: =SUM(J10:P10) -> 0
A11: Karati PP | B11: 0 | C11: 0 | D11: 0 | E11: 0 | F11: 0 | G11: 0 | H11: 67 | I11: =SUM(B11:H11) -> 67 | J11: 0 | K11: 0 | L11: 0 | M11: 0 | N11: 0 | O11: 0 | P11: 40 | Q11: =SUM(J11:P11) -> 40
A12: Eastern | B12: =SUM(B9:B11) -> 2418 | C12: =SUM(C9:C11) -> 2420 | D12: =SUM(D9:D11) -> 2473 | E12: =SUM(E9:E11) -> 2533 | F12: =SUM(F9:F11) -> 2142 | G12: =G9 -> 2266 | H12: =SUM(H9:H11) -> 2079 | I12: =SUM(I9:I11) -> 16331 | J12: =SUM(J9:J11) -> 2241 | K12: =SUM(K9:K11) -> 2425 | L12: =SUM(L9:L11) -> 2415 | M12: =SUM(M9:M11) -> 2580 | N12: =SUM(N9:N11) -> 2038 | O12: =SUM(O9:O11) -> 1993 | ... Q12: =SUM(Q9:Q11) -> 15846
A13: AIC | B13: 321 | C13: 477 | D13: 488 | E13: 478 | F13: 161 | G13: 143 | H13: 93 | I13: =SUM(B13:H13) -> 2161 | J13: 96 | K13: 93 | L13: 430 | M13: 481 | N13: 155 | O13: 115 | P13: 126 | Q13: =SUM(J13:P13) -> 1496
A14: DTI | B14: 864 | C14: 652 | D14: 952 | E14: 1014 | F14: 736 | G14: 838 | H14: 830 | I14: =SUM(B14:H14) -> 5886 | J14: 773 | K14: 870 | L14: 927 | M14: 768 | N14: 849 | O14: 949 | P14: 808 | Q14: =SUM(J14:P14) -> 5944
A15: Police Line | B15: 390 | C15: 409 | D15: 353 | E15: 310 | F15: 347 | G15: 420 | H15: 327 | I15: =SUM(B15:H15) -> 2556 | J15: 401 | K15: 410 | L15: 415 | M15: 206 | N15: 2 | O15: 140 | P15: 154 | Q15: =SUM(J15:P15) -> 1728
A16: Central BL | B16: =SUM(B13:B15) -> 1575 | C16: =SUM(C13:C15) -> 1538 | D16: =SUM(D13:D15) -> 1793 | E16: =SUM(E13:E15) -> 1802 | F16: =SUM(F13:F15) -> 1244 | G16: =G15+G14+G13 -> 1401 | H16: =SUM(H13:H15) -> 1250 | I16: =SUM(I13:I15) -> 10603 | J16: =SUM(J13:J15) -> 1270 | K16: =SUM(K13:K15) -> 1373 | L16: =SUM(L13:L15) -> 1772 | M16: =SUM(M13:M15) -> 1455 | N16: =SUM(N13:N15) -> 1006 | O16: =SUM(O13:O15) -> 1204 | ... Q16: =SUM(Q13:Q15) -> 9168
A17: TOTALS | B17: =B8+B16+B12 -> 5620 | C17: =C8+C16+C12 -> 5425 | D17: =D8+D16+D12 -> 5732 | E17: =E8+E16+E12 -> 5737 | F17: =F8+F16+F12 -> 4709 | G17: =G16+G12+G8 -> 4986 | H17: =H8+H16+H12 -> 4637 | I17: =I8+I16+I12 -> 39715 | J17: =J8+J16+J12 -> 4880 | K17: =K8+K16+K12 -> 5232 | L17: =L8+L16+L12 -> 5274 | M17: =M8+M16+M12 -> 5504 | N17: =N8+N16+N12 -> 6364 | O17: =O8+O16+O12 -> 4387 | ... Q17: =Q8+Q16+Q12 -> 34395
A19: Daily production sheet
A20: Site/Date | B20: 12th Jan | C20: 13th Jan | D20: 14th Jan | E20: 15th Jan | F20: 16th Jan | G20: 17th Jan | H20: 18th Jan | I20: week 3 Total | J20: 19th Jan | K20: 20th Jan | L20: 21st Jan | M20: 22nd Jan | N20: 23rd Jan | O20: 24th Jan | P20: 25th Jan | Q20: week 4 Total
A21: DCK | B21: 199 | C21: 233 | D21: 254 | E21: 92 | F21: 266 | G21: 243 | H21: 256 | I21: =SUM(B21:H21) -> 1543 | J21: 130 | K21: 207 | L21: 298 | M21: 388 | N21: 415 | O21: 239 | P21: 361 | Q21: =SUM(J21:P21) -> 2038
A22: WWS | B22: 1028 | C22: 971 | D22: 967 | E22: 895 | F22: 998 | G22: 974 | H22: 1061 | I22: =SUM(B22:H22) -> 6894 | J22: 967 | K22: 1098 | L22: 808 | M22: 731 | N22: 891 | O22: 1061 | P22: 1199 | Q22: =SUM(J22:P22) -> 6755
A23: Mai Mahiu | B23: 79 | C23: 34 | D23: 126 | E23: 90 | F23: 73 | G23: 93 | H23: 50 | I23: =SUM(B23:H23) -> 545 | J23: 164 | K23: 229 | L23: 80 | M23: 0 | N23: 0 | O23: 96 | P23: 49 | Q23: =SUM(J23:P23) -> 618
A24: Ngondi | G24: 0 | H24: 0 | I24: =SUM(B24:H24) -> 0 | J24: 0 | K24: 0 | L24: 0 | M24: 0 | N24: 0 | O24: 0 | P24: 0 | Q24: =SUM(J24:P24) -> 0
A25: NIP | G25: 0 | H25: 0 | I25: =SUM(B25:H25) -> 0 | J25: 0 | K25: 0 | L25: 0 | M25: 0 | N25: 2505 | O25: 1700 | P25: 0 | Q25: =SUM(J25:P25) -> 4205
A26: Southern | B26: =SUM(B21:B25) -> 1306 | C26: =SUM(C21:C25) -> 1238 | D26: =SUM(D21:D25) -> 1347 | E26: =SUM(E21:E25) -> 1077 | F26: =SUM(F21:F25) -> 1337 | G26: =G23+G22+G21 -> 1310 | H26: =SUM(H21:H25) -> 1367 | I26: =SUM(I21:I25) -> 8982 | J26: =SUM(J21:J23) -> 1261 | K26: =SUM(K21:K23) -> 1534 | L26: =SUM(L21:L25) -> 1186 | M26: =SUM(M21:M22) -> 1119 | N26: =SUM(N21:N25) -> 3811 | O26: =SUM(O21:O23) -> 1396 | P26: =SUM(P21:P23) -> 1609 | Q26: =SUM(Q21:Q23) -> 9411
A27: KARATI | B27: 1785 | C27: 2146 | D27: 1746 | E27: 1730 | F27: 1988 | G27: 2205 | H27: 1814 | I27: =SUM(B27:H27) -> 13414 | J27: 1952 | K27: 2557 | L27: 1377 | M27: 757 | N27: 1657 | O27: 2688 | P27: 2595 | Q27: =SUM(J27:P27) -> 13583
A28: Kinungi BH | G28: 0 | H28: 0 | I28: =SUM(B28:H28) -> 0 | J28: 0 | K28: 0 | L28: 0 | M28: 0 | N28: 0 | O28: 0 | P28: 0 | Q28: =SUM(J28:P28) -> 0
A29: Karati PP | G29: 0 | H29: 30 | I29: =SUM(B29:H29) -> 30 | J29: 0 | K29: 0 | L29: 0 | M29: 0 | N29: 0 | O29: 0 | P29: 50 | Q29: =SUM(J29:P29) -> 50
A30: Eastern | B30: =SUM(B27:B29) -> 1785 | C30: =SUM(C27:C29) -> 2146 | D30: =SUM(D27:D29) -> 1746 | E30: =SUM(E27:E29) -> 1730 | F30: =SUM(F27:F29) -> 1988 | G30: =G27 -> 2205 | H30: =SUM(H27:H29) -> 1844 | I30: =SUM(I27:I29) -> 13444 | J30: =SUM(J27:J29) -> 1952 | K30: =SUM(K27:K29) -> 2557 | L30: =SUM(L27:L29) -> 1377 | M30: =SUM(M27:M29) -> 757 | N30: =SUM(N27:N29) -> 1657 | O30: =SUM(O27:O29) -> 2688 | ... Q30: =SUM(Q27:Q29) -> 13633
