Workbook
Name Actual_month: General!$B$3

Sheet Dashboard Production Quality
A1: TECHNICAL DASHBOARD PRODUCTION AND WATER QUALITY
B2: =INDEX('KPI 1a'!E$18:P$18,Actual_month) -> 46054
D3: Monthly | J3: Cumulative | R3: 0.9
C4: Unit | G4: Target | H4: Actual | I4: % real. | M4: Target | N4: Actual | O4: % real.
A5: DASHBOARD - VOLUMES PRODUCED - NON-REVENUE WATER
A6: 1 | B6: DTI PRODUCTION SITE
A7: 1a | B7: Water Volume Abstracted | C7: M3 | D7: l | E7: l | F7: l | G7: =INDEX('KPI 1a'!$E$19:$P$19,Actual_month) -> 43020 | H7: =INDEX('KPI 1a'!E$20:P$20,Actual_month) -> 34037 | I7: =IFERROR(H7/G7,"") -> 0.79119014 | J7: l | K7: l | L7: l | M7: =INDEX('KPI 1a'!$E$26:$P$26,Actual_month) -> 330640 | N7: =INDEX('KPI 1a'!$E$27:$P$27,Actual_month) -> 345878 | O7: =IFERROR(N7/M7,"") -> 1.0460864 | P7: details | Q7: =G7*$R$3 -> 38718 | R7: =M7*$R$3 -> 297576 | S7: H | T7: v
A8: 1b | B8: Water Volume Supplied | C8: M3 | D8: l | E8: l | F8: l | G8: =INDEX('KPI 1b'!$E$19:$P$19,Actual_month) -> 42159.6 | H8: =INDEX('KPI 1b'!E$20:P$20,Actual_month) -> 34037 | I8: =IFERROR(H8/G8,"") -> 0.80733688 | J8: l | K8: l | L8: l | M8: =INDEX('KPI 1b'!$E$26:$P$26,Actual_month) -> 324027.2 | N8: =INDEX('KPI 1b'!$E$27:$P$27,Actual_month) -> 345878 | O8: =IFERROR(N8/M8,"") -> 1.0674351 | P8: details | Q8: =G8*$R$3 -> 37943.64 | R8: =M8*$R$3 -> 291624.48 | S8: H | T8: v
A9: 1c | B9: Power Grid | C9: KWH | D9: l | E9: l | F9: l | G9: =INDEX('KPI 1c'!$E$19:$P$19,Actual_month) -> 50298.261 | H9: =INDEX('KPI 1c'!$E$20:$P$20,Actual_month) -> 48514.887 | I9: =IFERROR(H9/G9,"") -> 0.96454403 | J9: l | K9: l | L9: l | M9: =INDEX('KPI 1c'!$E$26:$P$26,Actual_month) -> 402386.09 | N9: =INDEX('KPI 1c'!E$27:P$27,Actual_month) -> 431553.89 | O9: =IFERROR(N9/M9,"") -> 1.0724871 | P9: details | Q9: =G9/$R$3 -> 55886.957 | R9: =M9/$R$3 -> 447095.65 | S9: L | T9: v
A10: 1d | B10: Power Solar | C10: KWH | D10: l | E10: l | F10: l | G10: =INDEX('KPI 1d'!$E$19:$P$19,Actual_month) -> 15534.791 | H10: =INDEX('KPI 1d'!E$20:P$20,Actual_month) -> 9920 | I10: =IFERROR(H10/G10,"") -> 0.63856667 | J10: l | K10: l | L10: l | M10: =INDEX('KPI 1d'!$E$26:$P$26,Actual_month) -> 124278.33 | N10: =INDEX('KPI 1d'!$E$27:$P$27,Actual_month) -> 96199.16 | O10: =IFERROR(N10/M10,"") -> 0.77406222 | P10: details | Q10: =G10*$R$3 -> 13981.312 | R10: =M10*$R$3 -> 111850.5 | S10: H | T10: v
A11: 1e | B11: Total Power Consumption | C11: KWH | D11: l | E11: l | F11: l | G11: =INDEX('KPI 1e'!$E$19:$P$19,Actual_month) -> 65833.052 | H11: =INDEX('KPI 1e'!E$20:P$20,Actual_month) -> 58434.887 | I11: =IFERROR(H11/G11,"") -> 0.88762233 | J11: l | K11: l | L11: l | M11: =INDEX('KPI 1e'!$E$26:$P$26,Actual_month) -> 526664.42 | N11: =INDEX('KPI 1e'!$E$27:$P$27,Actual_month) -> 527753.05 | O11: =IFERROR(N11/M11,"") -> 1.002067 | P11: details | Q11: =G11*$R$3 -> 59249.747 | R11: =M11*$R$3 -> 473997.98 | S11: H | T11: v
A12: 1f | B12: % Solar | C12: % | D12: l | E12: l | F12: l | G12: =INDEX('KPI 1f'!$E$19:$P$19,Actual_month) -> 0.23597252 | H12: =INDEX('KPI 1f'!E$20:P$20,Actual_month) -> 0.1697616 | I12: =IFERROR(H12/G12,"") -> 0.71941259 | J12: l | K12: l | L12: l | M12: =INDEX('KPI 1f'!$E$26:$P$26,Actual_month) -> 0.23597252 | N12: =INDEX('KPI 1f'!$E$27:$P$27,Actual_month) -> 0.18247408 | O12: =IFERROR(N12/M12,"") -> 0.7732853 | P12: details | Q12: =G12*$R$3 -> 0.21237527 | R12: =M12*$R$3 -> 0.21237527 | S12: H | T12: v
A13: 1g | B13: Power Efficiency | C13: KWH/M3 | D13: l | E13: l | F13: l | G13: =INDEX('KPI 1g'!$E$19:$P$19,Actual_month) -> 1.5302895 | H13: =IFERROR(INDEX('KPI 1g'!E$20:P$20,Actual_month),) -> 1.7168049 | I13: =IFERROR(G13/H13,"") -> 0.89135899 | J13: l | K13: l | L13: l | M13: =INDEX('KPI 1g'!$E$26:$P$26,Actual_month) -> 1.5939116 | N13: =IFERROR(INDEX('KPI 1g'!E$27:P$27,Actual_month),) -> 1.5501161 | O13: =IFERROR(M13/N13,"") -> 1.028253 | P13: details | Q13: =G13/$R$3 -> 1.7003216 | R13: =M13/$R$3 -> 1.7710128 | S13: L | T13: v
A14: 1h | B14: Production Loss | C14: M3 | D14: l | E14: l | F14: l | G14: =INDEX('KPI 1h'!E$19:P$19,Actual_month) -> 860.4 | H14: =INDEX('KPI 1h'!E$20:P$20,Actual_month) -> 1053 | I14: =IFERROR(G14/H14,"") -> 0.81709402 | J14: l | K14: l | L14: l | M14: =INDEX('KPI 1h'!$E$26:$P$26,Actual_month) -> 6612.8 | N14: =INDEX('KPI 1h'!E$27:P$27,Actual_month) -> 17779 | O14: =IFERROR(M14/N14,"") -> 0.37194443 | P14: details | Q14: =G14/$R$3 -> 956 | R14: =M14/$R$3 -> 7347.5556 | S14: L | T14: v
A16: 2 | B16: WATERWORKS PRODUCTION SITE
A17: 2a | B17: Water Volume Abstracted | C17: M3 | D17: l | E17: l | F17: l | G17: =INDEX('KPI 2a'!E$19:P$19,Actual_month) -> 19550 | H17: =INDEX('KPI 2a'!E$20:Q$20,Actual_month) -> 28759 | I17: =IFERROR(H17/G17,"") -> 1.4710486 | J17: l | K17: l | L17: l | M17: =INDEX('KPI 2a'!$E$26:$P$26,Actual_month) -> 155000 | N17: =INDEX('KPI 2a'!$E$27:$P$27,Actual_month) -> 176227 | O17: =IFERROR(N17/M17,"") -> 1.1369484 | P17: details | Q17: =G17*$R$3 -> 17595 | R17: =M17*$R$3 -> 139500 | S17: H | T17: v
A18: 2b | B18: Water Volume Supplied | C18: M3 | D18: l | E18: l | F18: l | G18: =INDEX('KPI 2b'!E$19:P$19,Actual_month) -> 19159 | H18: =INDEX('KPI 2b'!E$20:Q$20,Actual_month) -> 28759 | I18: =IFERROR(H18/G18,"") -> 1.50107 | J18: l | K18: l | L18: l | M18: =INDEX('KPI 2b'!$E$26:$P$26,Actual_month) -> 151900 | N18: =INDEX('KPI 2b'!$E$27:$P$27,Actual_month) -> 176227 | O18: =IFERROR(N18/M18,"") -> 1.1601514 | P18: details | Q18: =G18*$R$3 -> 17243.1 | R18: =M18*$R$3 -> 136710 | S18: H | T18: v
A19: 2c | B19: Power Grid | C19: KWH | D19: l | E19: l | F19: l | G19: =INDEX('KPI 2c'!E$19:P$19,Actual_month) -> 32877.705 | H19: =INDEX('KPI 2c'!E$20:P$20,Actual_month) -> 34188 | I19: =IFERROR(H19/G19,"") -> 1.0398536 | J19: l | K19: l | L19: l | M19: =INDEX('KPI 2c'!$E$26:$P$26,Actual_month) -> 263021.64 | N19: =INDEX('KPI 2c'!$E$27:$P$27,Actual_month) -> 283549 | O19: =IFERROR(N19/M19,"") -> 1.0780444 | P19: details | Q19: =G19/$R$3 -> 36530.783 | R19: =M19/$R$3 -> 292246.27 | S19: L | T19: v
A20: 2d | B20: Power solar | C20: KWH | D20: l | E20: l | F20: l | G20: =INDEX('KPI 2d'!E$19:O$19,Actual_month) -> 10118.458 | H20: =INDEX('KPI 2d'!E$20:P$20,Actual_month) -> 6981 | I20: =IFERROR(H20/G20,"") -> 0.68992723 | J20: l | K20: l | L20: l | M20: =INDEX('KPI 2d'!$E$26:$P$26,Actual_month) -> 80947.667 | N20: =INDEX('KPI 2d'!$E$27:$P$27,Actual_month) -> 95906.92 | O20: =IFERROR(N20/M20,"") -> 1.1848015 | P20: details | Q20: =G20*$R$3 -> 9106.6125 | R20: =M20*$R$3 -> 72852.9 | S20: H | T20: v
A21: 2e | B21: Total Power Consumption | C21: KWH | E21: l | F21: l | G21: =INDEX('KPI 2e'!E$19:P$19,Actual_month) -> 42996.163 | H21: =INDEX('KPI 2e'!E$20:P$20,Actual_month) -> 41169 | I21: =IFERROR(H21/G21,"") -> 0.95750404 | L21: l | M21: =INDEX('KPI 2e'!$E$26:$P$26,Actual_month) -> 343969.31 | N21: =INDEX('KPI 2e'!$E$27:$P$27,Actual_month) -> 379455.92 | O21: =IFERROR(N21/M21,"") -> 1.103168 | P21: details | Q21: =G21*$R$3 -> 38696.547 | R21: =M21*$R$3 -> 309572.38 | S21: H | T21: v
A22: 2f | B22: % Solar | C22: % | D22: l | E22: l | F22: l | G22: =INDEX('KPI 2f'!E$19:P$19,Actual_month) -> 0.23533398 | H22: =INDEX('KPI 2f'!E$20:P$20,Actual_month) -> 0.16956934 | I22: =IFERROR(H22/G22,"") -> 0.7205476 | J22: l | K22: l | L22: l | M22: =INDEX('KPI 2f'!$E$26:$P$26,Actual_month) -> 0.23533398 | N22: =INDEX('KPI 2f'!$E$27:$P$27,Actual_month) -> 0.24979114 | O22: =IFERROR(N22/M22,"") -> 1.0614325 | P22: details | Q22: =G22*$R$3 -> 0.21180058 | R22: =M22*$R$3 -> 0.21180058 | S22: H | T22: v
A23: 2g | B23: Power Efficiency | C23: KWH/M3 | D23: l | E23: l | F23: l | G23: =INDEX('KPI 2g'!E$19:P$19,Actual_month) -> 2.1992922 | H23: =IFERROR(INDEX('KPI 2g'!E$20:P$20,Actual_month),) -> 1.4315171 | I23: =IFERROR(G23/H23,"") -> 1.5363367 | J23: l | K23: l | L23: l | M23: =INDEX('KPI 2g'!$E$26:$P$26,Actual_month) -> 2.2192344 | N23: =IFERROR(INDEX('KPI 2g'!$E$27:$P$27,Actual_month),) -> 2.2106639 | O23: =IFERROR(M23/N23,"") -> 1.0038769 | P23: details | Q23: =G23/$R$3 -> 2.443658 | R23: =M23/$R$3 -> 2.465816 | S23: L | T23: v
A24: 2h | B24: Production Loss | C24: M3 | D24: l | E24: l | F24: l | G24: =INDEX('KPI 2h'!E$19:P$19,Actual_month) -> 391 | H24: =INDEX('KPI 2h'!E$20:P$20,Actual_month) -> 1962 | I24: =IFERROR(G24/H24,"") -> 0.19928644 | J24: l | K24: l | L24: l | M24: =INDEX('KPI 2h'!$E$26:$P$26,Actual_month) -> 3100 | N24: =INDEX('KPI 2h'!$E$27:$P$27,Actual_month) -> 12032.9 | O24: =IFERROR(M24/N24,"") -> 0.25762701 | P24: details | Q24: =G24/$R$3 -> 434.44444 | R24: =M24/$R$3 -> 3444.4444 | S24: L | T24: v
A26: 3 | B26: A.I.C PRODUCTION SITE
A27: 3a | B27: Water Volume Abstracted | C27: M3 | D27: l | E27: l | F27: l | G27: =INDEX('KPI 3a'!E$19:P$19,Actual_month) -> 9220 | H27: =INDEX('KPI 3a'!E$20:P$20,Actual_month) -> 16841 | I27: =IFERROR(H27/G27,"") -> 1.8265727 | J27: l | K27: l | L27: l | M27: =INDEX('KPI 3a'!$E$26:$P$26,Actual_month) -> 68340 | N27: =INDEX('KPI 3a'!$E$27:$P$27,Actual_month) -> 92061 | O27: =IFERROR(N27/M27,"") -> 1.3471027 | P27: details | Q27: =G27*$R$3 -> 8298 | R27: =M27*$R$3 -> 61506 | S27: H | T27: v
A28: 3b | B28: Water Volume Supplied | C28: M3 | G28: =INDEX('KPI 3b'!E$19:P$19,Actual_month) -> 9035.6 | H28: =INDEX('KPI 3b'!E$20:P$20,Actual_month) -> 16763 | I28: =IFERROR(H28/G28,"") -> 1.8552171 | J28: l | K28: l | L28: l | M28: =INDEX('KPI 3b'!$E$26:$P$26,Actual_month) -> 66973.2 | N28: =INDEX('KPI 3b'!$E$27:$P$27,Actual_month) -> 91311 | O28: =IFERROR(N28/M28,"") -> 1.3633961 | P28: details | Q28: =G28*$R$3 -> 8132.04 | R28: =M28*$R$3 -> 60275.88 | S28: H | T28: v
A29: 3c | B29: Power Consumption | C29: KWH | D29: l | E29: l | F29: l | G29: =INDEX('KPI 3c'!E$19:P$19,Actual_month) -> 4699.8333 | H29: =INDEX('KPI 3c'!E$20:P$20,Actual_month) -> 10709.556 | I29: =IFERROR(G29/H29,"") -> 0.43884485 | J29: l | K29: l | L29: l | M29: =INDEX('KPI 3c'!$E$26:$P$26,Actual_month) -> 37598.667 | N29: =INDEX('KPI 3c'!$E$27:$P$27,Actual_month) -> 50629.556 | O29: =IFERROR(M29/N29,"") -> 0.74262289 | P29: details | Q29: =G29/$R$3 -> 5222.037 | R29: =M29/$R$3 -> 41776.296 | S29: L | T29: v
A30: 3d | B30: Power Efficiency | C30: KWH/M3 | D30: l | E30: l | F30: l | G30: =INDEX('KPI 3d'!E$19:P$19,Actual_month) -> 0.50974331 | H30: =INDEX('KPI 3d'!E$20:P$20,Actual_month) -> 0.63592159 | I30: =IFERROR(G30/H30,"") -> 0.80158202 | J30: l | K30: l | L30: l | M30: =INDEX('KPI 3d'!$E$26:$P$26,Actual_month) -> 0.55153731 | N30: =INDEX('KPI 3d'!$E$27:$P$27,Actual_month) -> 0.53925494 | O30: =IFERROR(M30/N30,"") -> 1.0227766 | P30: details | Q30: =G30/$R$3 -> 0.56638146 | R30: =M30/$R$3 -> 0.61281924 | S30: L | T30: v
A31: 3e | B31: Production Loss | C31: M3 | D31: l | E31: l | F31: l | G31: =INDEX('KPI 3e'!E$19:P$19,Actual_month) -> 184.4 | H31: =INDEX('KPI 3e'!E$20:P$20,Actual_month) -> 78 | I31: =IFERROR(G31/H31,"") -> 2.3641026 | J31: l | K31: l | L31: l | M31: =INDEX('KPI 3e'!$E$26:$P$26,Actual_month) -> 1366.8 | N31: =INDEX('KPI 3e'!$E$27:$P$27,Actual_month) -> 750 | O31: =IFERROR(M31/N31,"") -> 1.8224 | P31: details | Q31: =G31/$R$3 -> 204.88889 | R31: =M31/$R$3 -> 1518.6667 | S31: L | T31: v
A33: 4 | B33: KARATI PRODUCTION SITE
A34: 4a | B34: Water Volume Abstracted | C34: M3 | D34: l | E34: l | F34: l | G34: =INDEX('KPI 4a'!E$19:P$19,Actual_month) -> 60680 | H34: =INDEX('KPI 4a'!E$20:P$20,Actual_month) -> 55641 | I34: =IFERROR(H34/G34,"") -> 0.91695781 | J34: l | K34: l | L34: l | M34: =INDEX('KPI 4a'!$E$26:$P$26,Actual_month) -> 483530 | N34: =INDEX('KPI 4a'!$E$27:$P$27,Actual_month) -> 438286.74 | O34: =IFERROR(N34/M34,"") -> 0.90643133 | P34: details | Q34: =G34*$R$3 -> 54612 | R34: =M34*$R$3 -> 435177 | S34: H | T34: v
A35: 4b | B35: Water Volume Supplied | C35: M3 | D35: l | E35: l | F35: l | G35: =INDEX('KPI 4b'!E$19:P$19,Actual_month) -> 53435.444 | H35: =INDEX('KPI 4b'!E$20:P$20,Actual_month) -> 52879 | I35: =IFERROR(H35/G35,"") -> 0.98958662 | J35: l | K35: l | L35: l | M35: =INDEX('KPI 4b'!$E$26:$P$26,Actual_month) -> 449891.85 | N35: =INDEX('KPI 4b'!$E$27:$P$27,Actual_month) -> 410352.7 | O35: =IFERROR(N35/M35,"") -> 0.91211411 | P35: details | Q35: =G35*$R$3 -> 48091.899 | R35: =M35*$R$3 -> 404902.66 | S35: H | T35: v
A36: 4c | B36: Power Grid | C36: KWH | D36: l | E36: l | F36: l | G36: =INDEX('KPI 4c'!E$19:P$19,Actual_month) -> 55514.06 | H36: =INDEX('KPI 4c'!E$20:P$20,Actual_month) -> 41487 | I36: =IFERROR(H36/G36,"") -> 0.74732419 | J36: l | K36: l | L36: l | M36: =INDEX('KPI 4c'!$E$26:$P$26,Actual_month) -> 444112.48 | N36: =INDEX('KPI 4c'!$E$27:$P$27,Actual_month) -> 323923 | O36: =IFERROR(N36/M36,"") -> 0.72937153 | P36: details | Q36: =G36/$R$3 -> 61682.289 | R36: =M36/$R$3 -> 493458.31 | S36: L | T36: v
A37: 4d | B37: Power Solar | C37: KWH | D37: l | E37: l | F37: l | G37: =INDEX('KPI 4d'!E$19:P$19,Actual_month) -> 10113.154 | H37: =INDEX('KPI 4d'!E$20:P$20,Actual_month) -> 36723 | I37: =IFERROR(H37/G37,"") -> 3.6312115 | J37: l | K37: l | L37: l | M37: =INDEX('KPI 4d'!$E$26:$P$26,Actual_month) -> 80905.229 | N37: =INDEX('KPI 4d'!$E$27:$P$27,Actual_month) -> 129122.95 | O37: =IFERROR(N37/M37,"") -> 1.5959778 | P37: details | Q37: =G37*$R$3 -> 9101.8383 | R37: =M37*$R$3 -> 72814.706 | S37: H | T37: v
A38: 4e | B38: Total Power Consumption | C38: KWH | D38: l | E38: l | F38: l | G38: =INDEX('KPI 4e'!E$19:P$19,Actual_month) -> 65627.214 | H38: =INDEX('KPI 4e'!E$20:P$20,Actual_month) -> 78210 | I38: =IFERROR(H38/G38,"") -> 1.1917312 | J38: l | K38: l | L38: l | M38: =INDEX('KPI 4e'!$E$26:$P$26,Actual_month) -> 525017.71 | N38: =INDEX('KPI 4e'!$E$27:$P$27,Actual_month) -> 453045.95 | O38: =IFERROR(N38/M38,"") -> 0.86291556 | P38: details | Q38: =G38*$R$3 -> 59064.492 | R38: =M38*$R$3 -> 472515.94 | S38: H | T38: v
A39: 4f | B39: % Solar | C39: % | D39: l | E39: l | F39: l | G39: =INDEX('KPI 4f'!E$19:P$19,Actual_month) -> 0.1541 | H39: =INDEX('KPI 4f'!E$20:P$20,Actual_month) -> 0.46954354 | I39: =IFERROR(H39/G39,"") -> 3.0470054 | J39: l | K39: l | L39: l | M39: =INDEX('KPI 4f'!$E$26:$P$26,Actual_month) -> 0.1541 | N39: =INDEX('KPI 4f'!$E$27:$P$27,Actual_month) -> 0.27365874 | O39: =IFERROR(N39/M39,"") -> 1.7758517 | P39: details | Q39: =G39*$R$3 -> 0.13869 | R39: =M39*$R$3 -> 0.13869 | S39: H | T39: v
A40: 4g | B40: Power Efficiency | C40: KWH/M3 | D40: l | E40: l | F40: l | G40: =INDEX('KPI 4g'!E$19:P$19,Actual_month) -> 0.11938952 | H40: =INDEX('KPI 4g'!E$20:P$20,Actual_month) -> 1.4056182 | I40: =IFERROR(G40/H40,"") -> 0.084937379 | J40: l | K40: l | L40: l | M40: =INDEX('KPI 4g'!$E$26:$P$26,Actual_month) -> 0.06948763 | N40: =INDEX('KPI 4g'!$E$27:$P$27,Actual_month) -> 1.0281053 | O40: =IFERROR(M40/N40,"") -> 0.067588051 | P40: details | Q40: =G40/$R$3 -> 0.13265502 | R40: =M40/$R$3 -> 0.077208478 | S40: L | T40: v
A41: 4h | B41: Production Loss | C41: M3 | D41: l | E41: l | F41: l | G41: =INDEX('KPI 4h'!E$19:P$19,Actual_month) -> 7244.5562 | H41: =INDEX('KPI 4h'!E$20:P$20,Actual_month) -> 2762 | I41: =IFERROR(G41/H41,"") -> 2.6229385 | J41: l | K41: l | L41: l | M41: =INDEX('KPI 4h'!$E$26:$P$26,Actual_month) -> 33638.153 | N41: =INDEX('KPI 4h'!$E$27:$P$27,Actual_month) -> 27934.037 | O41: =IFERROR(M41/N41,"") -> 1.2041995 | P41: details | Q41: =G41/$R$3 -> 8049.5069 | R41: =M41/$R$3 -> 37375.726 | S41: L | T41: v
A43: 5 | B43: DCK PRODUCTION SITE
A44: 5a | B44: Water Volume Abstracted | C44: M3 | D44: l | E44: l | F44: l | G44: =INDEX('KPI 5a'!E$19:P$19,Actual_month) -> 9600 | H44: =INDEX('KPI 5a'!E$20:P$20,Actual_month) -> 8683 | I44: =IFERROR(H44/G44,"") -> 0.90447917 | J44: l | K44: l | L44: l | M44: =INDEX('KPI 5a'!$E$25:$P$25,Actual_month) -> 62500 | N44: =INDEX('KPI 5a'!$E$26:$P$26,Actual_month) -> 62998 | O44: =IFERROR(N44/M44,"") -> 1.007968 | P44: details | Q44: =G44*$R$3 -> 8640 | R44: =M44*$R$3 -> 56250 | S44: H | T44: v
...

Sheet Budget2526
B1: ='Dashboard Production Quality'!B1 -> 0 | C1: ='Dashboard Production Quality'!C1 -> 0 | E1: 13.4
B2: ='Dashboard Production Quality'!B2 -> 46054 | C2: ='Dashboard Production Quality'!C2 -> 0 | E2: 0.02
B3: ='Dashboard Production Quality'!B3 -> 0 | C3: ='Dashboard Production Quality'!C3 -> 0
A4: ='Dashboard Production Quality'!A4 -> 0 | C4: ='Dashboard Production Quality'!C4 -> Unit | E4: jul | F4: aug | G4: sep | H4: oct | I4: nov | J4: dec | K4: jan | L4: feb | M4: mar | N4: apr | O4: may | P4: jun
A5: ='Dashboard Production Quality'!A5 -> DASHBOARD - VOLUMES PRODUCED - NON-REVENUE WATER | B5: ='Dashboard Production Quality'!B5 -> 0 | C5: ='Dashboard Production Quality'!C5 -> 0
A6: ='Dashboard Production Quality'!A7 -> 1a | B6: ='Dashboard Production Quality'!B6 -> DTI PRODUCTION SITE | C6: ='Dashboard Production Quality'!C6 -> 0
A7: ='Dashboard Production Quality'!A7 -> 1a | B7: ='Dashboard Production Quality'!B7 -> Water Volume Abstracted | C7: ='Dashboard Production Quality'!C7 -> M3 | E7: 40000 | F7: 40020 | G7: 40520 | H7: 41020 | I7: 41520 | J7: 42020 | K7: 42520 | L7: 43020 | M7: 43520 | N7: 44020 | O7: 44520 | P7: 45020
A8: ='Dashboard Production Quality'!A8 -> 1b | B8: ='Dashboard Production Quality'!B8 -> Water Volume Supplied | C8: ='Dashboard Production Quality'!C8 -> M3 | E8: =E7-E14 -> 39200 | F8: =F7-F14 -> 39219.6 | G8: =G7-G14 -> 39709.6 | H8: =H7-H14 -> 40199.6 | I8: =I7-I14 -> 40689.6 | J8: =J7-J14 -> 41179.6 | K8: =K7-K14 -> 41669.6 | L8: =L7-L14 -> 42159.6 | ... P8: =P7-P14 -> 44119.6
A9: ='Dashboard Production Quality'!A9 -> 1c | B9: ='Dashboard Production Quality'!B9 -> Power Grid | C9: ='Dashboard Production Quality'!C9 -> KWH | E9: 50298.261 | F9: 50298.261 | G9: 50298.261 | H9: 50298.261 | I9: 50298.261 | J9: 50298.261 | K9: 50298.261 | L9: 50298.261 | M9: 50298.261 | N9: 50298.261 | O9: 50298.261 | P9: 50298.261
A10: ='Dashboard Production Quality'!A10 -> 1d | B10: ='Dashboard Production Quality'!B10 -> Power Solar | C10: ='Dashboard Production Quality'!C10 -> KWH | E10: 15534.791 | F10: 15534.791 | G10: 15534.791 | H10: 15534.791 | I10: 15534.791 | J10: 15534.791 | K10: 15534.791 | L10: 15534.791 | M10: 15534.791 | N10: 15534.791 | O10: 15534.791 | P10: 15534.791
A11: ='Dashboard Production Quality'!A11 -> 1e | B11: ='Dashboard Production Quality'!B11 -> Total Power Consumption | C11: ='Dashboard Production Quality'!C11 -> KWH | E11: =E10+E9 -> 65833.052 | F11: =F10+F9 -> 65833.052 | G11: =G10+G9 -> 65833.052 | H11: =H10+H9 -> 65833.052 | I11: =I10+I9 -> 65833.052 | J11: =J10+J9 -> 65833.052 | K11: =K10+K9 -> 65833.052 | L11: =L10+L9 -> 65833.052 | ... P11: =P10+P9 -> 65833.052
A12: ='Dashboard Production Quality'!A12 -> 1f | B12: ='Dashboard Production Quality'!B12 -> % Solar | C12: ='Dashboard Production Quality'!C12 -> % | E12: =E10/E11 -> 0.23597252 | F12: =F10/F11 -> 0.23597252 | G12: =G10/G11 -> 0.23597252 | H12: =H10/H11 -> 0.23597252 | I12: =I10/I11 -> 0.23597252 | J12: =J10/J11 -> 0.23597252 | K12: =K10/K11 -> 0.23597252 | L12: =L10/L11 -> 0.23597252 | ... P12: =P10/P11 -> 0.23597252
A13: ='Dashboard Production Quality'!A13 -> 1g | B13: ='Dashboard Production Quality'!B13 -> Power Efficiency | C13: ='Dashboard Production Quality'!C13 -> KWH/M3 | E13: =E11/E7 -> 1.6458263 | F13: =F11/F7 -> 1.6450038 | G13: =G11/G7 -> 1.6247051 | H13: =H11/H7 -> 1.6049013 | I13: =I11/I7 -> 1.5855745 | J13: =J11/J7 -> 1.5667076 | K13: =K11/K7 -> 1.5482844 | L13: =L11/L7 -> 1.5302895 | ... P13: =P11/P7 -> 1.4623068
A14: ='Dashboard Production Quality'!A14 -> 1h | B14: ='Dashboard Production Quality'!B14 -> Production Loss | C14: ='Dashboard Production Quality'!C14 -> M3 | E14: =$E$2*E7 -> 800 | F14: =$E$2*F7 -> 800.4 | G14: =$E$2*G7 -> 810.4 | H14: =$E$2*H7 -> 820.4 | I14: =$E$2*I7 -> 830.4 | J14: =$E$2*J7 -> 840.4 | K14: =$E$2*K7 -> 850.4 | L14: =$E$2*L7 -> 860.4 | ... P14: =$E$2*P7 -> 900.4
A15: ='Dashboard Production Quality'!A16 -> 2 | B15: ='Dashboard Production Quality'!B16 -> WATERWORKS PRODUCTION SITE | C15: ='Dashboard Production Quality'!C16 -> 0
A16: ='Dashboard Production Quality'!A17 -> 2a | B16: ='Dashboard Production Quality'!B17 -> Water Volume Abstracted | C16: ='Dashboard Production Quality'!C17 -> M3 | E16: 19200 | F16: 19250 | G16: 19300 | H16: 19350 | I16: 19400 | J16: 19450 | K16: 19500 | L16: 19550 | M16: 19600 | N16: 19650 | O16: 19700 | P16: 19750
A17: ='Dashboard Production Quality'!A18 -> 2b | B17: ='Dashboard Production Quality'!B18 -> Water Volume Supplied | C17: ='Dashboard Production Quality'!C18 -> M3 | E17: =E16-E23 -> 18816 | F17: =F16-F23 -> 18865 | G17: =G16-G23 -> 18914 | H17: =H16-H23 -> 18963 | I17: =I16-I23 -> 19012 | J17: =J16-J23 -> 19061 | K17: =K16-K23 -> 19110 | L17: =L16-L23 -> 19159 | ... P17: =P16-P23 -> 19355
A18: ='Dashboard Production Quality'!A19 -> 2c | B18: ='Dashboard Production Quality'!B19 -> Power Grid | C18: ='Dashboard Production Quality'!C19 -> KWH | E18: 32877.705 | F18: 32877.705 | G18: 32877.705 | H18: 32877.705 | I18: 32877.705 | J18: 32877.705 | K18: 32877.705 | L18: 32877.705 | M18: 32877.705 | N18: 32877.705 | O18: 32877.705 | P18: 32877.705
A19: ='Dashboard Production Quality'!A20 -> 2d | B19: ='Dashboard Production Quality'!B20 -> Power solar | C19: ='Dashboard Production Quality'!C20 -> KWH | E19: 10118.458 | F19: 10118.458 | G19: 10118.458 | H19: 10118.458 | I19: 10118.458 | J19: 10118.458 | K19: 10118.458 | L19: 10118.458 | M19: 10118.458 | N19: 10118.458 | O19: 10118.458 | P19: 10118.458
A20: ='Dashboard Production Quality'!A21 -> 2e | B20: ='Dashboard Production Quality'!B21 -> Total Power Consumption | C20: ='Dashboard Production Quality'!C21 -> KWH | E20: =E18+E19 -> 42996.163 | F20: =F18+F19 -> 42996.163 | G20: =G18+G19 -> 42996.163 | H20: =H18+H19 -> 42996.163 | I20: =I18+I19 -> 42996.163 | J20: =J18+J19 -> 42996.163 | K20: =K18+K19 -> 42996.163 | L20: =L18+L19 -> 42996.163 | ... P20: =P18+P19 -> 42996.163
A21: ='Dashboard Production Quality'!A22 -> 2f | B21: ='Dashboard Production Quality'!B22 -> % Solar | C21: ='Dashboard Production Quality'!C22 -> % | E21: =E19/E20 -> 0.23533398 | F21: =F19/F20 -> 0.23533398 | G21: =G19/G20 -> 0.23533398 | H21: =H19/H20 -> 0.23533398 | I21: =I19/I20 -> 0.23533398 | J21: =J19/J20 -> 0.23533398 | K21: =K19/K20 -> 0.23533398 | L21: =L19/L20 -> 0.23533398 | ... P21: =P19/P20 -> 0.23533398
A22: ='Dashboard Production Quality'!A23 -> 2g | B22: ='Dashboard Production Quality'!B23 -> Power Efficiency | C22: ='Dashboard Production Quality'!C23 -> KWH/M3 | E22: =E20/E16 -> 2.2393835 | F22: =F20/F16 -> 2.2335669 | G22: =G20/G16 -> 2.2277805 | H22: =H20/H16 -> 2.2220239 | I22: =I20/I16 -> 2.2162971 | J22: =J20/J16 -> 2.2105997 | K22: =K20/K16 -> 2.2049315 | L22: =L20/L16 -> 2.1992922 | ... P22: =P20/P16 -> 2.1770209
A23: ='Dashboard Production Quality'!A24 -> 2h | B23: ='Dashboard Production Quality'!B24 -> Production Loss | C23: ='Dashboard Production Quality'!C24 -> M3 | E23: =$E$2*E16 -> 384 | F23: =$E$2*F16 -> 385 | G23: =$E$2*G16 -> 386 | H23: =$E$2*H16 -> 387 | I23: =$E$2*I16 -> 388 | J23: =$E$2*J16 -> 389 | K23: =$E$2*K16 -> 390 | L23: =$E$2*L16 -> 391 | ... P23: =$E$2*P16 -> 395
A24: ='Dashboard Production Quality'!A26 -> 3 | B24: ='Dashboard Production Quality'!B26 -> A.I.C PRODUCTION SITE | C24: ='Dashboard Production Quality'!C26 -> 0
A25: ='Dashboard Production Quality'!A27 -> 3a | B25: ='Dashboard Production Quality'!B27 -> Water Volume Abstracted | C25: ='Dashboard Production Quality'!C27 -> M3 | E25: 8000 | F25: 8020 | G25: 8220 | H25: 8420 | I25: 8620 | J25: 8820 | K25: 9020 | L25: 9220 | M25: 9420 | N25: 9620 | O25: 9820 | P25: 10020
A26: ='Dashboard Production Quality'!A28 -> 3b | B26: ='Dashboard Production Quality'!B28 -> Water Volume Supplied | C26: ='Dashboard Production Quality'!C28 -> M3 | E26: =E25-E29 -> 7840 | F26: =F25-F29 -> 7859.6 | G26: =G25-G29 -> 8055.6 | H26: =H25-H29 -> 8251.6 | I26: =I25-I29 -> 8447.6 | J26: =J25-J29 -> 8643.6 | K26: =K25-K29 -> 8839.6 | L26: =L25-L29 -> 9035.6 | ... P26: =P25-P29 -> 9819.6
A27: ='Dashboard Production Quality'!A29 -> 3c | B27: ='Dashboard Production Quality'!B29 -> Power Consumption | C27: ='Dashboard Production Quality'!C29 -> KWH | E27: 4699.8333 | F27: 4699.8333 | G27: 4699.8333 | H27: 4699.8333 | I27: 4699.8333 | J27: 4699.8333 | K27: 4699.8333 | L27: 4699.8333 | M27: 4699.8333 | N27: 4699.8333 | O27: 4699.8333 | P27: 4699.8333
A28: ='Dashboard Production Quality'!A30 -> 3d | B28: ='Dashboard Production Quality'!B30 -> Power Efficiency | C28: ='Dashboard Production Quality'!C30 -> KWH/M3 | E28: =E27/E25 -> 0.58747917 | F28: =F27/F25 -> 0.58601413 | G28: =G27/G25 -> 0.57175588 | H28: =H27/H25 -> 0.55817498 | I28: =I27/I25 -> 0.54522428 | J28: =J27/J25 -> 0.53286092 | K28: =K27/K25 -> 0.52104582 | L28: =L27/L25 -> 0.50974331 | ... P28: =P27/P25 -> 0.46904524
A29: ='Dashboard Production Quality'!A31 -> 3e | B29: ='Dashboard Production Quality'!B31 -> Production Loss | C29: ='Dashboard Production Quality'!C31 -> M3 | E29: =E25*$E$2 -> 160 | F29: =F25*$E$2 -> 160.4 | G29: =G25*$E$2 -> 164.4 | H29: =H25*$E$2 -> 168.4 | I29: =I25*$E$2 -> 172.4 | J29: =J25*$E$2 -> 176.4 | K29: =K25*$E$2 -> 180.4 | L29: =L25*$E$2 -> 184.4 | ... P29: =P25*$E$2 -> 200.4
A30: ='Dashboard Production Quality'!A33 -> 4 | B30: ='Dashboard Production Quality'!B33 -> KARATI PRODUCTION SITE | C30: ='Dashboard Production Quality'!C33 -> 0
A31: ='Dashboard Production Quality'!A34 -> 4a | B31: ='Dashboard Production Quality'!B34 -> Water Volume Abstracted | C31: ='Dashboard Production Quality'!C34 -> M3 | E31: 60240 | F31: 60260 | G31: 60330 | H31: 60400 | I31: 60470 | J31: 60540 | K31: 60610 | L31: 60680 | M31: 60750 | N31: 60820 | O31: 60890 | P31: 60960
A32: ='Dashboard Production Quality'!A35 -> 4b | B32: ='Dashboard Production Quality'!B35 -> Water Volume Supplied | C32: ='Dashboard Production Quality'!C35 -> M3 | E32: =E31-E38 -> 58540.269 | F32: =F31-F38 -> 58357.137 | G32: =G31-G38 -> 57571.797 | H32: =H31-H38 -> 56911.728 | I32: =I31-I38 -> 56001.527 | J32: =J31-J38 -> 54832.721 | K32: =K31-K38 -> 54241.225 | L32: =L31-L38 -> 53435.444 | ... P32: =P31-P38 -> 49221.375
A33: ='Dashboard Production Quality'!A36 -> 4c | B33: ='Dashboard Production Quality'!B36 -> Power Grid | C33: ='Dashboard Production Quality'!C36 -> KWH | E33: 55514.06 | F33: 55514.06 | G33: 55514.06 | H33: 55514.06 | I33: 55514.06 | J33: 55514.06 | K33: 55514.06 | L33: 55514.06 | M33: 55514.06 | N33: 55514.06 | O33: 55514.06 | P33: 55514.06
A34: ='Dashboard Production Quality'!A37 -> 4d | B34: ='Dashboard Production Quality'!B37 -> Power Solar | C34: ='Dashboard Production Quality'!C37 -> KWH | E34: 10113.154 | F34: 10113.154 | G34: 10113.154 | H34: 10113.154 | I34: 10113.154 | J34: 10113.154 | K34: 10113.154 | L34: 10113.154 | M34: 10113.154 | N34: 10113.154 | O34: 10113.154 | P34: 10113.154
A35: ='Dashboard Production Quality'!A38 -> 4e | B35: ='Dashboard Production Quality'!B38 -> Total Power Consumption | C35: ='Dashboard Production Quality'!C38 -> KWH | E35: =E33+E34 -> 65627.214 | F35: =F33+F34 -> 65627.214 | G35: =G33+G34 -> 65627.214 | H35: =H33+H34 -> 65627.214 | I35: =I33+I34 -> 65627.214 | J35: =J33+J34 -> 65627.214 | K35: =K33+K34 -> 65627.214 | L35: =L33+L34 -> 65627.214 | ... P35: =P33+P34 -> 65627.214
A36: ='Dashboard Production Quality'!A39 -> 4f | B36: ='Dashboard Production Quality'!B39 -> % Solar | C36: ='Dashboard Production Quality'!C39 -> % | E36: =E34/E35 -> 0.1541 | F36: =F34/F35 -> 0.1541 | G36: =G34/G35 -> 0.1541 | H36: =H34/H35 -> 0.1541 | I36: =I34/I35 -> 0.1541 | J36: =J34/J35 -> 0.1541 | K36: =K34/K35 -> 0.1541 | L36: =L34/L35 -> 0.1541 | ... P36: =P34/P35 -> 0.1541
A37: ='Dashboard Production Quality'!A40 -> 4g | B37: ='Dashboard Production Quality'!B40 -> Power Efficiency | C37: ='Dashboard Production Quality'!C40 -> KWH/M3 | E37: =E38/E31 -> 0.028215984 | F37: =F38/F31 -> 0.031577553 | G37: =G38/G31 -> 0.045718599 | H37: =H38/H31 -> 0.057752851 | I37: =I38/I31 -> 0.073895702 | J37: =J38/J31 -> 0.094272866 | K37: =K38/K31 -> 0.10507796 | L37: =L38/L31 -> 0.11938952 | ... P37: =P38/P31 -> 0.19256275
A38: ='Dashboard Production Quality'!A41 -> 4h | B38: ='Dashboard Production Quality'!B41 -> Production Loss | C38: ='Dashboard Production Quality'!C41 -> M3 | E38: 1699.7309 | F38: 1902.8633 | G38: 2758.2031 | H38: 3488.2722 | I38: 4468.4731 | J38: 5707.2793 | K38: 6368.7754 | L38: 7244.5562 | M38: 8444.0638 | N38: 9336.4382 | O38: 10258.719 | P38: 11738.625
A39: ='Dashboard Production Quality'!A43 -> 5 | B39: ='Dashboard Production Quality'!B43 -> DCK PRODUCTION SITE | C39: ='Dashboard Production Quality'!C43 -> 0
A40: ='Dashboard Production Quality'!A44 -> 5a | B40: ='Dashboard Production Quality'!B44 -> Water Volume Abstracted | C40: ='Dashboard Production Quality'!C44 -> M3 | E40: 6000 | F40: 6500 | G40: 7000 | H40: 7600 | I40: 8100 | J40: 8600 | K40: 9100 | L40: 9600 | M40: 10100 | N40: 10600 | O40: 11100 | P40: 11600
...

Sheet ACTUAL 2526
B1: ='Dashboard Production Quality'!B1 -> 0 | C1: ='Dashboard Production Quality'!C1 -> 0
C2: ='Dashboard Production Quality'!C2 -> 0
B3: ='Dashboard Production Quality'!B3 -> 0 | C3: ='Dashboard Production Quality'!C3 -> 0
A4: ='Dashboard Production Quality'!A4 -> 0 | C4: ='Dashboard Production Quality'!C4 -> Unit | D4: jul | E4: aug | F4: sep | G4: oct | H4: nov | I4: dec | J4: jan | K4: feb | L4: mar | M4: apr | N4: may | O4: jun
A5: ='Dashboard Production Quality'!A5 -> DASHBOARD - VOLUMES PRODUCED - NON-REVENUE WATER | B5: ='Dashboard Production Quality'!B5 -> 0 | C5: ='Dashboard Production Quality'!C5 -> 0
A6: ='Dashboard Production Quality'!A6 -> 1 | B6: ='Dashboard Production Quality'!B6 -> DTI PRODUCTION SITE | C6: ='Dashboard Production Quality'!C6 -> 0
A7: ='Dashboard Production Quality'!A7 -> 1a | B7: ='Dashboard Production Quality'!B7 -> Water Volume Abstracted | C7: ='Dashboard Production Quality'!C7 -> M3 | D7: 45093 | E7: 50272 | F7: 38210 | G7: 45521 | H7: 38240 | I7: 37291 | J7: 57214 | K7: 34037
A8: ='Dashboard Production Quality'!A8 -> 1b | B8: ='Dashboard Production Quality'!B8 -> Water Volume Supplied | C8: ='Dashboard Production Quality'!C8 -> M3 | D8: =D7-D14 -> 44015 | E8: =E7-E14 -> 47210 | F8: =F7-F14 -> 35022 | G8: =G7-G14 -> 42660 | H8: =H7-H14 -> 35997 | I8: =I7-I14 -> 35997 | J8: =J7-J14 -> 54214 | K8: =K7-K14 -> 32984 | ... O8: =O7-O14 -> 0
A9: ='Dashboard Production Quality'!A9 -> 1c | B9: ='Dashboard Production Quality'!B9 -> Power Grid | C9: ='Dashboard Production Quality'!C9 -> KWH | D9: 54776 | E9: 55447 | F9: 56659 | G9: 56802 | H9: 42378 | I9: 53153 | J9: 63824 | K9: 48514.887
A10: ='Dashboard Production Quality'!A10 -> 1d | B10: ='Dashboard Production Quality'!B10 -> Power Solar | C10: ='Dashboard Production Quality'!C10 -> KWH | D10: 12533.16 | E10: 8129 | F10: 9469 | G10: 10170 | H10: 14386 | I10: 15791 | J10: 15801 | K10: 9920
A11: ='Dashboard Production Quality'!A11 -> 1e | B11: ='Dashboard Production Quality'!B11 -> Total Power Consumption | C11: ='Dashboard Production Quality'!C11 -> KWH | D11: =D9+D10 -> 67309.16 | E11: =E9+E10 -> 63576 | F11: =F9+F10 -> 66128 | G11: =G9+G10 -> 66972 | H11: =H9+H10 -> 56764 | I11: =I9+I10 -> 68944 | J11: =J9+J10 -> 79625 | K11: =K9+K10 -> 58434.887 | ... O11: =O9+O10 -> 0
A12: ='Dashboard Production Quality'!A12 -> 1f | B12: ='Dashboard Production Quality'!B12 -> % Solar | C12: ='Dashboard Production Quality'!C12 -> % | D12: =D10/D11 -> 0.18620289 | E12: =E10/E11 -> 0.12786272 | F12: =F10/F11 -> 0.14319199 | G12: =G10/G11 -> 0.15185451 | H12: =H10/H11 -> 0.25343528 | I12: =I10/I11 -> 0.22904096 | J12: =J10/J11 -> 0.1984427 | K12: =K10/K11 -> 0.1697616 | ... O12: =O10/O11 -> #DIV/0!
A13: ='Dashboard Production Quality'!A13 -> 1g | B13: ='Dashboard Production Quality'!B13 -> Power Efficiency | C13: ='Dashboard Production Quality'!C13 -> KWH/M3 | D13: =D11/D7 -> 1.4926743 | E13: =E11/E7 -> 1.2646404 | F13: =F11/F7 -> 1.7306464 | G13: =G11/G7 -> 1.4712331 | H13: =H11/H7 -> 1.4844142 | I13: =I11/I7 -> 1.8488107 | J13: =J11/J7 -> 1.3917048 | K13: =K11/K7 -> 1.7168049 | ... O13: =O11/O7 -> #DIV/0!
A14: ='Dashboard Production Quality'!A14 -> 1h | B14: ='Dashboard Production Quality'!B14 -> Production Loss | C14: ='Dashboard Production Quality'!C14 -> M3 | D14: 1078 | E14: 3062 | F14: 3188 | G14: 2861 | H14: 2243 | I14: 1294 | J14: 3000 | K14: 1053
A15: ='Dashboard Production Quality'!A16 -> 2 | B15: ='Dashboard Production Quality'!B16 -> WATERWORKS PRODUCTION SITE | C15: ='Dashboard Production Quality'!C16 -> 0
A16: ='Dashboard Production Quality'!A17 -> 2a | B16: ='Dashboard Production Quality'!B17 -> Water Volume Abstracted | C16: ='Dashboard Production Quality'!C17 -> M3 | D16: 19269 | E16: 21454 | F16: 20216 | G16: 24029 | H16: 18217 | I16: 17440 | J16: 26843 | K16: 28759
A17: ='Dashboard Production Quality'!A18 -> 2b | B17: ='Dashboard Production Quality'!B18 -> Water Volume Supplied | C17: ='Dashboard Production Quality'!C18 -> M3 | D17: =D16-D23 -> 17644 | E17: =E16-E23 -> 19463 | F17: =F16-F23 -> 19420.1 | G17: =G16-G23 -> 23533 | H17: =H16-H23 -> 16578 | I17: =I16-I23 -> 16578 | J17: =J16-J23 -> 24181 | K17: =K16-K23 -> 26797 | ... O17: =O16-O23 -> 0
