Workbook
Name Actual_month: General!$B$3

Sheet Dashboard
A1: SALES & CC DASHBOARD
B2: =INDEX('KPI 1'!$E18:$P18,Actual_month) -> 46054
D3: Monthly | J3: Cumulative | R3: 0.9
C4: Unit | G4: Target | H4: Actual | I4: % real. | M4: Target | N4: Actual | O4: % real.
A5: NEW CONNECTIONS WATER | Q5: monthly | R5: cumluative
A6: 1 | B6: CBD - NEW WATER | C6: No. | D6: l | E6: l | F6: l | G6: =IFERROR(INDEX('KPI 1'!E$19:P$19,Actual_month),) -> 1 | H6: =IFERROR(INDEX('KPI 1'!$E$20:$P$20,Actual_month),) -> 0 | I6: =IFERROR(H6/G6,"") -> 0 | J6: l | K6: l | L6: l | M6: =IFERROR(INDEX('KPI 1'!$E$26:$P$26,Actual_month),) -> 8 | N6: =IFERROR(INDEX('KPI 1'!$E$27:$P$27,Actual_month),) -> 2 | O6: =IFERROR(N6/M6,"") -> 0.25 | P6: details | Q6: =G6*$R$3 -> 0.9 | R6: =M6*$R$3 -> 7.2 | S6: H | T6: v
A7: 2 | B7: CCCR- NEW WATER | C7: No. | D7: l | E7: l | F7: l | G7: =IFERROR(INDEX('KPI 2'!E$19:P$19,Actual_month),) -> 10 | H7: =IFERROR(INDEX('KPI 2'!$E$20:$P$20,Actual_month),) -> 3 | I7: =IFERROR(H7/G7,"") -> 0.3 | J7: l | K7: l | L7: l | M7: =IFERROR(INDEX('KPI 2'!$E$26:$P$26,Actual_month),) -> 79 | N7: =IFERROR(INDEX('KPI 2'!$E$27:$P$27,Actual_month),) -> 20 | O7: =IFERROR(N7/M7,"") -> 0.25316456 | P7: details | Q7: =G7*$R$3 -> 9 | R7: =M7*$R$3 -> 71.1 | S7: H | T7: v
A8: 3 | B8: KABATI- NEW WATER | C8: No. | D8: l | E8: l | F8: l | G8: =IFERROR(INDEX('KPI 3'!E$19:P$19,Actual_month),) -> 4 | H8: =IFERROR(INDEX('KPI 3'!$E$20:$P$20,Actual_month),) -> 0 | I8: =IFERROR(H8/G8,"") -> 0 | J8: l | K8: l | L8: l | M8: =IFERROR(INDEX('KPI 3'!$E$26:$P$26,Actual_month),) -> 32 | N8: =IFERROR(INDEX('KPI 3'!$E$27:$P$27,Actual_month),) -> 10 | O8: =IFERROR(N8/M8,"") -> 0.3125 | P8: details | Q8: =G8*$R$3 -> 3.6 | R8: =M8*$R$3 -> 28.8 | S8: H | T8: v
A9: 4 | B9: SITE- NEW WATER | C9: No. | D9: l | E9: l | F9: l | G9: =IFERROR(INDEX('KPI 4'!E$19:P$19,Actual_month),) -> 1 | H9: =IFERROR(INDEX('KPI 4'!$E$20:$P$20,Actual_month),) -> 0 | I9: =IFERROR(H9/G9,"") -> 0 | J9: l | K9: l | L9: l | M9: =IFERROR(INDEX('KPI 4'!$E$26:$P$26,Actual_month),) -> 8 | N9: =IFERROR(INDEX('KPI 4'!$E$27:$P$27,Actual_month),) -> 7 | O9: =IFERROR(N9/M9,"") -> 0.875 | P9: details | Q9: =G9*$R$3 -> 0.9 | R9: =M9*$R$3 -> 7.2 | S9: H | T9: v
A10: 5 | B10: KIHOTO- NEW WATER | C10: No. | D10: l | E10: l | F10: l | G10: =IFERROR(INDEX('KPI 5'!E$19:P$19,Actual_month),) -> 1 | H10: =IFERROR(INDEX('KPI 5'!$E$20:$P$20,Actual_month),) -> 1 | I10: =IFERROR(H10/G10,"") -> 1 | J10: l | K10: l | L10: l | M10: =IFERROR(INDEX('KPI 5'!$E$26:$P$26,Actual_month),) -> 8 | N10: =IFERROR(INDEX('KPI 5'!$E$27:$P$27,Actual_month),) -> 3 | O10: =IFERROR(N10/M10,"") -> 0.375 | P10: details | Q10: =G10*$R$3 -> 0.9 | R10: =M10*$R$3 -> 7.2 | S10: H | T10: v
A11: 6 | B11: LAKEVIEW- NEW WATER | C11: No. | D11: l | E11: l | F11: l | G11: =IFERROR(INDEX('KPI 10'!E$19:P$19,Actual_month),) -> 2 | H11: =IFERROR(INDEX('KPI 10'!$E$20:$P$20,Actual_month),) -> 0 | I11: =IFERROR(H11/G11,"") -> 0 | J11: l | K11: l | L11: l | M11: =IFERROR(INDEX('KPI 10'!$E$26:$P$26,Actual_month),) -> 16 | N11: =IFERROR(INDEX('KPI 10'!$E$27:$P$27,Actual_month),) -> 14 | O11: =IFERROR(N11/M11,"") -> 0.875 | P11: details | Q11: =G11*$R$3 -> 1.8 | R11: =M11*$R$3 -> 14.4 | S11: H | T11: v
A12: 7 | B12: HOPEWELL- NEW WATER | C12: No. | D12: l | E12: l | F12: l | G12: =IFERROR(INDEX('KPI 10A'!E$19:P$19,Actual_month),) -> 2 | H12: =IFERROR(INDEX('KPI 10A'!$E$20:$P$20,Actual_month),) -> 3 | I12: =IFERROR(H12/G12,"") -> 1.5 | J12: l | K12: l | L12: l | M12: =IFERROR(INDEX('KPI 10A'!$E$26:$P$26,Actual_month),) -> 16 | N12: =IFERROR(INDEX('KPI 10A'!$E$27:$P$27,Actual_month),) -> 53 | O12: =IFERROR(N12/M12,"") -> 3.3125 | P12: details | Q12: =G12*$R$3 -> 1.8 | R12: =M12*$R$3 -> 14.4 | S12: H | T12: v
B13: TOTAL NEW WATER CONNECTIONS CENTRAL REGION | C13: No. | D13: l | E13: l | F13: l | G13: =IFERROR(INDEX('KPI 6'!E$19:P$19,Actual_month),) -> 21 | H13: =IFERROR(INDEX('KPI 6'!$E$20:$P$20,Actual_month),) -> 7 | I13: =IFERROR(H13/G13,"") -> 0.33333333 | J13: l | K13: l | L13: l | M13: =IFERROR(INDEX('KPI 6'!$E$26:$P$26,Actual_month),) -> 167 | N13: =IFERROR(INDEX('KPI 6'!$E$27:$P$27,Actual_month),) -> 109 | O13: =IFERROR(N13/M13,"") -> 0.65269461 | P13: details | Q13: =G13*$R$3 -> 18.9 | R13: =M13*$R$3 -> 150.3 | S13: H | T13: v
A14: 1 | B14: HELLSGATE- NEW WATER | C14: No. | D14: l | E14: l | F14: l | G14: =IFERROR(INDEX('KPI 7'!E$19:P$19,Actual_month),) -> 45 | H14: =IFERROR(INDEX('KPI 7'!$E$20:$P$20,Actual_month),) -> 14 | I14: =IFERROR(H14/G14,"") -> 0.31111111 | J14: l | K14: l | L14: l | M14: =IFERROR(INDEX('KPI 7'!$E$26:$P$26,Actual_month),) -> 276 | N14: =IFERROR(INDEX('KPI 7'!$E$27:$P$27,Actual_month),) -> 147 | O14: =IFERROR(N14/M14,"") -> 0.5326087 | P14: details | Q14: =G14*$R$3 -> 40.5 | R14: =M14*$R$3 -> 248.4 | S14: H | T14: v
A15: 2 | B15: KAMERE- NEW WATER | C15: No. | D15: l | E15: l | F15: l | G15: =IFERROR(INDEX('KPI 8'!E$19:P$19,Actual_month),) -> 11 | H15: =IFERROR(INDEX('KPI 8'!$E$20:$P$20,Actual_month),) -> 14 | I15: =IFERROR(H15/G15,"") -> 1.2727273 | J15: l | K15: l | L15: l | M15: =IFERROR(INDEX('KPI 8'!$E$26:$P$26,Actual_month),) -> 68 | N15: =IFERROR(INDEX('KPI 8'!$E$27:$P$27,Actual_month),) -> 147 | O15: =IFERROR(N15/M15,"") -> 2.1617647 | P15: details | Q15: =G15*$R$3 -> 9.9 | R15: =M15*$R$3 -> 61.2 | S15: H | T15: v
A16: 3 | B16: MAI-MAHIU- NEW WATER | C16: No. | D16: l | E16: l | F16: l | G16: =IFERROR(INDEX('KPI 11'!E$19:P$19,Actual_month),) -> 61 | H16: =IFERROR(INDEX('KPI 11'!$E$20:$P$20,Actual_month),) -> 33 | I16: =IFERROR(H16/G16,"") -> 0.54098361 | J16: l | K16: l | L16: l | M16: =IFERROR(INDEX('KPI 11'!$E$26:$P$26,Actual_month),) -> 478 | N16: =IFERROR(INDEX('KPI 11'!$E$27:$P$27,Actual_month),) -> 384 | O16: =IFERROR(N16/M16,"") -> 0.80334728 | P16: details | Q16: =G16*$R$3 -> 54.9 | R16: =M16*$R$3 -> 430.2 | S16: H | T16: v
A17: 4 | B17: LONGONOT- NEW WATER | C17: No. | D17: l | E17: l | F17: l | G17: =IFERROR(INDEX('KPI 11B'!E$19:P$19,Actual_month),) -> 10 | H17: =IFERROR(INDEX('KPI 11B'!$E$20:$P$20,Actual_month),) -> 2 | I17: =IFERROR(H17/G17,"") -> 0.2 | J17: l | K17: l | L17: l | M17: =IFERROR(INDEX('KPI 11B'!$E$26:$P$26,Actual_month),) -> 80 | N17: =IFERROR(INDEX('KPI 11B'!$E$27:$P$27,Actual_month),) -> 71 | O17: =IFERROR(N17/M17,"") -> 0.8875 | P17: details | Q17: =G17*$R$3 -> 9 | R17: =M17*$R$3 -> 72 | S17: H | T17: v
B18: TOTAL NEW WATER CONNECTION SOUTHERN REGION | C18: No. | D18: l | E18: l | F18: l | G18: =IFERROR(INDEX('KPI 12'!E$19:P$19,Actual_month),) -> 127 | H18: =IFERROR(INDEX('KPI 12'!$E$20:$P$20,Actual_month),) -> 51 | I18: =IFERROR(H18/G18,"") -> 0.4015748 | J18: l | K18: l | L18: l | M18: =IFERROR(INDEX('KPI 12'!$E$26:$P$26,Actual_month),) -> 902 | N18: =IFERROR(INDEX('KPI 12'!$E$27:$P$27,Actual_month),) -> 646 | O18: =IFERROR(N18/M18,"") -> 0.71618625 | P18: details | Q18: =G18*$R$3 -> 114.3 | R18: =M18*$R$3 -> 811.8 | S18: H | T18: v
A19: EASTERN REGION | Q19: monthly | R19: cumluative
A20: 1 | B20: KAYOLE- NEW WATER | C20: No. | D20: l | E20: l | F20: l | G20: =IFERROR(INDEX('KPI 9'!E$19:P$19,Actual_month),) -> 23 | H20: =IFERROR(INDEX('KPI 9'!$E$20:$P$20,Actual_month),) -> 17 | I20: =IFERROR(H20/G20,"") -> 0.73913043 | J20: l | K20: l | L20: l | M20: =IFERROR(INDEX('KPI 9'!$E$26:$P$26,Actual_month),) -> 184 | N20: =IFERROR(INDEX('KPI 9'!$E$27:$P$27,Actual_month),) -> 270 | O20: =IFERROR(N20/M20,"") -> 1.4673913 | P20: details | Q20: =G20*$R$3 -> 20.7 | R20: =M20*$R$3 -> 165.6 | S20: H | T20: v
A21: 2 | B21: IHINDU- NEW WATER | C21: No. | D21: l | E21: l | F21: l | G21: =IFERROR(INDEX('KPI 9B'!E$19:P$19,Actual_month),) -> 18 | H21: =IFERROR(INDEX('KPI 9B'!$E$20:$P$20,Actual_month),) -> 0 | I21: =IFERROR(H21/G21,"") -> 0 | J21: l | K21: l | L21: l | M21: =IFERROR(INDEX('KPI 9B'!$E$26:$P$26,Actual_month),) -> 229 | N21: =IFERROR(INDEX('KPI 9B'!$E$27:$P$27,Actual_month),) -> 4 | O21: =IFERROR(N21/M21,"") -> 0.017467249 | P21: details | Q21: =G21*$R$3 -> 16.2 | R21: =M21*$R$3 -> 206.1 | S21: H | T21: v
B22: TOTAL NEW W CONNECTION EASTERN REGION | C22: No. | D22: l | E22: l | F22: l | G22: =IFERROR(INDEX('KPI 12B'!E$19:P$19,Actual_month),) -> 41 | H22: =IFERROR(INDEX('KPI 12B'!$E$20:$P$20,Actual_month),) -> 17 | I22: =IFERROR(H22/G22,"") -> 0.41463415 | J22: l | K22: l | L22: l | M22: =IFERROR(INDEX('KPI 12B'!$E$26:$P$26,Actual_month),) -> 413 | N22: =IFERROR(INDEX('KPI 12B'!$E$27:$P$27,Actual_month),) -> 274 | O22: =IFERROR(N22/M22,"") -> 0.66343826 | P22: details | Q22: =G22*$R$3 -> 36.9 | R22: =M22*$R$3 -> 371.7 | S22: H | T22: v
A23: NEW CONNECTIONS SEWER | Q23: monthly | R23: cumluative
A24: 1 | B24: CBD- NEW SEWER | C24: No. | D24: l | E24: l | F24: l | G24: =IFERROR(INDEX('KPI 13'!E$19:P$19,Actual_month),) -> 1 | H24: =IFERROR(INDEX('KPI 13'!$E$20:$P$20,Actual_month),) -> 0 | I24: =IFERROR(H24/G24,"") -> 0 | J24: l | K24: l | L24: l | M24: =IFERROR(INDEX('KPI 13'!$E$26:$P$26,Actual_month),) -> 8 | N24: =IFERROR(INDEX('KPI 13'!$E$27:$P$27,Actual_month),) -> 0 | O24: =IFERROR(N24/M24,"") -> 0 | P24: details | Q24: =G24*$R$3 -> 0.9 | R24: =M24*$R$3 -> 7.2 | S24: H | T24: v
A25: 2 | B25: CCCR- NEW SEWER | C25: No. | D25: l | E25: l | F25: l | G25: =IFERROR(INDEX('KPI 14'!E$19:P$19,Actual_month),) -> 7 | H25: =IFERROR(INDEX('KPI 14'!$E$20:$P$20,Actual_month),) -> 2 | I25: =IFERROR(H25/G25,"") -> 0.28571429 | J25: l | K25: l | L25: l | M25: =IFERROR(INDEX('KPI 14'!$E$26:$P$26,Actual_month),) -> 56 | N25: =IFERROR(INDEX('KPI 14'!$E$27:$P$27,Actual_month),) -> 5 | O25: =IFERROR(N25/M25,"") -> 0.089285714 | P25: details | Q25: =G25*$R$3 -> 6.3 | R25: =M25*$R$3 -> 50.4 | S25: H | T25: v
A26: 3 | B26: KABATI- NEW SEWER | C26: No. | D26: l | E26: l | F26: l | G26: =IFERROR(INDEX('KPI 15'!E$19:P$19,Actual_month),) -> 3 | H26: =IFERROR(INDEX('KPI 15'!$E$20:$P$20,Actual_month),) -> 1 | I26: =IFERROR(H26/G26,"") -> 0.33333333 | J26: l | K26: l | L26: l | M26: =IFERROR(INDEX('KPI 15'!$E$26:$P$26,Actual_month),) -> 25 | N26: =IFERROR(INDEX('KPI 15'!$E$27:$P$27,Actual_month),) -> 6 | O26: =IFERROR(N26/M26,"") -> 0.24 | P26: details | Q26: =G26*$R$3 -> 2.7 | R26: =M26*$R$3 -> 22.5 | S26: H | T26: v
A27: 4 | B27: SITE- NEW SEWER | C27: No. | D27: l | E27: l | F27: l | G27: =IFERROR(INDEX('KPI 16'!E$19:P$19,Actual_month),) -> 1 | H27: =IFERROR(INDEX('KPI 16'!$E$20:$P$20,Actual_month),) -> 0 | I27: =IFERROR(H27/G27,"") -> 0 | J27: l | K27: l | L27: l | M27: =IFERROR(INDEX('KPI 16'!$E$26:$P$26,Actual_month),) -> 8 | N27: =IFERROR(INDEX('KPI 16'!$E$27:$P$27,Actual_month),) -> 1 | O27: =IFERROR(N27/M27,"") -> 0.125 | P27: details | Q27: =G27*$R$3 -> 0.9 | R27: =M27*$R$3 -> 7.2 | S27: H | T27: v
A28: 5 | B28: KIHOTO- NEW SEWER | C28: No. | D28: l | E28: l | F28: l | G28: =IFERROR(INDEX('KPI 17'!E$19:P$19,Actual_month),) -> 0 | H28: =IFERROR(INDEX('KPI 17'!$E$20:$P$20,Actual_month),) -> 0 | I28: =IFERROR(H28/G28,"") | J28: l | K28: l | L28: l | M28: =IFERROR(INDEX('KPI 17'!$E$26:$P$26,Actual_month),) -> 0 | N28: =IFERROR(INDEX('KPI 17'!$E$27:$P$27,Actual_month),) -> 0 | O28: =IFERROR(N28/M28,"") | P28: details | Q28: =G28*$R$3 -> 0 | R28: =M28*$R$3 -> 0 | S28: H | T28: v
A29: 6 | B29: LAKEVIEW- NEW SEWER | C29: No. | D29: l | E29: l | F29: l | G29: =IFERROR(INDEX('KPI 22'!E$19:P$19,Actual_month),) -> 1 | H29: =IFERROR(INDEX('KPI 22'!$E$20:$P$20,Actual_month),) -> 0 | I29: =IFERROR(H29/G29,"") -> 0 | J29: l | K29: l | L29: l | M29: =IFERROR(INDEX('KPI 22'!$E$26:$P$26,Actual_month),) -> 8 | N29: =IFERROR(INDEX('KPI 22'!$E$27:$P$27,Actual_month),) -> 3 | O29: =IFERROR(N29/M29,"") -> 0.375 | P29: details | Q29: =G29*$R$3 -> 0.9 | R29: =M29*$R$3 -> 7.2 | S29: H | T29: v
A30: 7 | B30: HOPEWELL- NEW SEWER | C30: No. | D30: l | E30: l | F30: l | G30: =IFERROR(INDEX('KPI 22A'!E$19:P$19,Actual_month),) -> 0 | H30: =IFERROR(INDEX('KPI 22A'!$E$20:$P$20,Actual_month),) -> 0 | I30: =IFERROR(H30/G30,"") | J30: l | K30: l | L30: l | M30: =IFERROR(INDEX('KPI 22A'!$E$26:$P$26,Actual_month),) -> 0 | N30: =IFERROR(INDEX('KPI 22A'!$E$27:$P$27,Actual_month),) -> 0 | O30: =IFERROR(N30/M30,"") | P30: details | Q30: =G30*$R$3 -> 0 | R30: =M30*$R$3 -> 0 | S30: H | T30: v
B31: TOTAL NEW SEWER CONNECTIONS CENTRAL REGION | C31: No. | D31: l | E31: l | F31: l | G31: =IFERROR(INDEX('KPI 18'!E$19:P$19,Actual_month),) -> 13 | H31: =IFERROR(INDEX('KPI 18'!$E$20:$P$20,Actual_month),) -> 3 | I31: =IFERROR(H31/G31,"") -> 0.23076923 | J31: l | K31: l | L31: l | M31: =IFERROR(INDEX('KPI 18'!$E$26:$P$26,Actual_month),) -> 105 | N31: =IFERROR(INDEX('KPI 18'!$E$27:$P$27,Actual_month),) -> 15 | O31: =IFERROR(N31/M31,"") -> 0.14285714 | P31: details | Q31: =G31*$R$3 -> 11.7 | R31: =M31*$R$3 -> 94.5 | S31: H | T31: v
A32: 1 | B32: HELLSGATE- NEW SEWER | C32: No. | D32: l | E32: l | F32: l | G32: =IFERROR(INDEX('KPI 19'!E$19:P$19,Actual_month),) -> 0 | H32: =IFERROR(INDEX('KPI 19'!$E$20:$P$20,Actual_month),) -> 0 | I32: =IFERROR(H32/G32,"") | J32: l | K32: l | L32: l | M32: =IFERROR(INDEX('KPI 19'!$E$26:$P$26,Actual_month),) -> 0 | N32: =IFERROR(INDEX('KPI 19'!$E$27:$P$27,Actual_month),) -> 0 | O32: =IFERROR(N32/M32,"") | P32: details | Q32: =G32*$R$3 -> 0 | R32: =M32*$R$3 -> 0 | S32: H | T32: v
A33: 2 | B33: KAMERE- NEW SEWER | C33: No. | D33: l | E33: l | F33: l | G33: =IFERROR(INDEX('KPI 20'!E$19:P$19,Actual_month),) -> 0 | H33: =IFERROR(INDEX('KPI 20'!$E$20:$P$20,Actual_month),) -> 0 | I33: =IFERROR(H33/G33,"") | J33: l | K33: l | L33: l | M33: =IFERROR(INDEX('KPI 20'!$E$26:$P$26,Actual_month),) -> 0 | N33: =IFERROR(INDEX('KPI 20'!$E$27:$P$27,Actual_month),) -> 0 | O33: =IFERROR(N33/M33,"") | P33: details | Q33: =G33*$R$3 -> 0 | R33: =M33*$R$3 -> 0 | S33: H | T33: v
A34: 3 | B34: MAI-MAHIU- NEW SEWER | C34: No. | D34: l | E34: l | F34: l | G34: =IFERROR(INDEX('KPI 23'!E$19:P$19,Actual_month),) -> 0 | H34: =IFERROR(INDEX('KPI 23'!$E$20:$P$20,Actual_month),) -> 0 | I34: =IFERROR(H34/G34,"") | J34: l | K34: l | L34: l | M34: =IFERROR(INDEX('KPI 23'!$E$26:$P$26,Actual_month),) -> 0 | N34: =IFERROR(INDEX('KPI 23'!$E$27:$P$27,Actual_month),) -> 0 | O34: =IFERROR(N34/M34,"") | P34: details | Q34: =G34*$R$3 -> 0 | R34: =M34*$R$3 -> 0 | S34: H | T34: v
B35: TOTAL NEW S CONNECTION SOUTHERN REGION | C35: No. | D35: l | E35: l | F35: l | G35: =IFERROR(INDEX('KPI 24'!E$19:P$19,Actual_month),) -> 0 | H35: =IFERROR(INDEX('KPI 24'!$E$20:$P$20,Actual_month),) -> 0 | I35: =IFERROR(H35/G35,"") | J35: l | K35: l | L35: l | M35: =IFERROR(INDEX('KPI 24'!$E$26:$P$26,Actual_month),) -> 0 | N35: =IFERROR(INDEX('KPI 24'!$E$27:$P$27,Actual_month),) -> 0 | O35: =IFERROR(N35/M35,"") | P35: details | Q35: =G35*$R$3 -> 0 | R35: =M35*$R$3 -> 0 | S35: H | T35: v
A36: EASTERN REGION | Q36: monthly | R36: cumluative
A37: 1 | B37: KAYOLE- NEW SEWER | C37: No. | D37: l | E37: l | F37: l | G37: =IFERROR(INDEX('KPI 21'!E$19:P$19,Actual_month),) -> 1 | H37: =IFERROR(INDEX('KPI 21'!$E$20:$P$20,Actual_month),) -> 2 | I37: =IFERROR(H37/G37,"") -> 2 | J37: l | K37: l | L37: l | M37: =IFERROR(INDEX('KPI 21'!$E$26:$P$26,Actual_month),) -> 8 | N37: =IFERROR(INDEX('KPI 21'!$E$27:$P$27,Actual_month),) -> 10 | O37: =IFERROR(N37/M37,"") -> 1.25 | P37: details | Q37: =G37*$R$3 -> 0.9 | R37: =M37*$R$3 -> 7.2 | S37: H | T37: v
A38: TOTAL CONNECTIONS-WATER | Q38: monthly | R38: cumluative
A39: 1 | B39: CBD- WATER | C39: No. | D39: l | E39: l | F39: l | G39: =IFERROR(INDEX('KPI 25'!E$19:P$19,Actual_month),) -> 798 | H39: =IFERROR(INDEX('KPI 25'!$E$20:$P$20,Actual_month),) -> 792 | I39: =IFERROR(H39/G39,"") -> 0.9924812 | J39: l | K39: l | L39: l | M39: =IFERROR(INDEX('KPI 25'!$E$26:$P$26,Actual_month),) -> 798 | N39: =IFERROR(INDEX('KPI 25'!$E$27:$P$27,Actual_month),) -> 792 | O39: =IFERROR(N39/M39,"") -> 0.9924812 | P39: details | Q39: =G39*$R$3 -> 718.2 | R39: =M39*$R$3 -> 718.2 | S39: H | T39: v
A40: 2 | B40: CCCR- WATER | C40: No. | D40: l | E40: l | F40: l | G40: =IFERROR(INDEX('KPI 26'!E$19:P$19,Actual_month),) -> 959 | H40: =IFERROR(INDEX('KPI 26'!$E$20:$P$20,Actual_month),) -> 898 | I40: =IFERROR(H40/G40,"") -> 0.93639208 | J40: l | K40: l | L40: l | M40: =IFERROR(INDEX('KPI 26'!$E$26:$P$26,Actual_month),) -> 959 | N40: =IFERROR(INDEX('KPI 26'!$E$27:$P$27,Actual_month),) -> 898 | O40: =IFERROR(N40/M40,"") -> 0.93639208 | P40: details | Q40: =G40*$R$3 -> 863.1 | R40: =M40*$R$3 -> 863.1 | S40: H | T40: v
...

Sheet budget 2025-26
A1: =Dashboard!A1 -> SALES & CC DASHBOARD
E2: 12 | F2: 48
B4: MONTH | C4: UNIT | D4: JUL | E4: AUG | F4: SEP | G4: OCT | H4: NOV | I4: DEC | J4: JAN | K4: FEB | L4: MAR | M4: APR | N4: MAY | O4: JUN
A5: =Dashboard!A5 -> NEW CONNECTIONS WATER
A6: =Dashboard!A6 -> 1 | B6: =Dashboard!B6 -> CBD - NEW WATER | C6: =Dashboard!C6 -> No. | D6: 1 | E6: 1 | F6: 1 | G6: 1 | H6: 1 | I6: 1 | J6: 1 | K6: 1 | L6: 1 | M6: 1 | N6: 1 | O6: 1
A7: =Dashboard!A7 -> 2 | B7: =Dashboard!B7 -> CCCR- NEW WATER | C7: =Dashboard!C7 -> No. | D7: 9 | E7: 10 | F7: 10 | G7: 10 | H7: 10 | I7: 10 | J7: 10 | K7: 10 | L7: 10 | M7: 10 | N7: 10 | O7: 10
A8: =Dashboard!A8 -> 3 | B8: =Dashboard!B8 -> KABATI- NEW WATER | C8: =Dashboard!C8 -> No. | D8: 4 | E8: 4 | F8: 4 | G8: 4 | H8: 4 | I8: 4 | J8: 4 | K8: 4 | L8: 4 | M8: 4 | N8: 4 | O8: 4
A9: =Dashboard!A9 -> 4 | B9: =Dashboard!B9 -> SITE- NEW WATER | C9: =Dashboard!C9 -> No. | D9: 1 | E9: 1 | F9: 1 | G9: 1 | H9: 1 | I9: 1 | J9: 1 | K9: 1 | L9: 1 | M9: 1 | N9: 1 | O9: 1
A10: =Dashboard!A10 -> 5 | B10: =Dashboard!B10 -> KIHOTO- NEW WATER | C10: =Dashboard!C10 -> No. | D10: 1 | E10: 1 | F10: 1 | G10: 1 | H10: 1 | I10: 1 | J10: 1 | K10: 1 | L10: 1 | M10: 1 | N10: 1 | O10: 1
A11: =Dashboard!A11 -> 6 | B11: =Dashboard!B11 -> LAKEVIEW- NEW WATER | C11: =Dashboard!C11 -> No. | D11: 2 | E11: 2 | F11: 2 | G11: 2 | H11: 2 | I11: 2 | J11: 2 | K11: 2 | L11: 2 | M11: 2 | N11: 2 | O11: 2
A12: =Dashboard!A12 -> 7 | B12: =Dashboard!B12 -> HOPEWELL- NEW WATER | C12: =Dashboard!C12 -> No. | D12: 2 | E12: 2 | F12: 2 | G12: 2 | H12: 2 | I12: 2 | J12: 2 | K12: 2 | L12: 2 | M12: 2 | N12: 2 | O12: 2
A13: =Dashboard!A13 -> 0 | B13: =Dashboard!B13 -> TOTAL NEW WATER CONNECTIONS CENTRAL REGION | C13: =Dashboard!C13 -> No. | D13: =SUM(D6:D12) -> 20 | E13: =SUM(E6:E12) -> 21 | F13: =SUM(F6:F12) -> 21 | G13: =SUM(G6:G12) -> 21 | H13: =SUM(H6:H12) -> 21 | I13: =SUM(I6:I12) -> 21 | J13: =SUM(J6:J12) -> 21 | K13: =SUM(K6:K12) -> 21 | ... O13: =SUM(O6:O12) -> 21
A14: =Dashboard!A14 -> 1 | B14: =Dashboard!B14 -> HELLSGATE- NEW WATER | C14: =Dashboard!C14 -> No. | D14: 8 | E14: 8 | F14: 20 | G14: 50 | H14: 50 | I14: 50 | J14: 45 | K14: 45 | L14: 35 | M14: 30 | N14: 30 | O14: 28
A15: =Dashboard!A15 -> 2 | B15: =Dashboard!B15 -> KAMERE- NEW WATER | C15: =Dashboard!C15 -> No. | D15: 1 | E15: 1 | F15: 1 | G15: 21 | H15: 11 | I15: 11 | J15: 11 | K15: 11 | L15: 11 | M15: 11 | N15: 11 | O15: 11
A16: =Dashboard!A16 -> 3 | B16: =Dashboard!B16 -> MAI-MAHIU- NEW WATER | C16: =Dashboard!C16 -> No. | D16: 51 | E16: 51 | F16: 46 | G16: 71 | H16: 71 | I16: 66 | J16: 61 | K16: 61 | L16: 56 | M16: 46 | N16: 46 | O16: 46
A17: =Dashboard!A17 -> 4 | B17: =Dashboard!B17 -> LONGONOT- NEW WATER | C17: =Dashboard!C17 -> No. | D17: 10 | E17: 10 | F17: 10 | G17: 10 | H17: 10 | I17: 10 | J17: 10 | K17: 10 | L17: 10 | M17: 10 | N17: 10 | O17: 10
A18: =Dashboard!A18 -> 0 | B18: =Dashboard!B18 -> TOTAL NEW WATER CONNECTION SOUTHERN REGION | C18: =Dashboard!C18 -> No. | D18: =SUM(D14:D17) -> 70 | E18: =SUM(E14:E17) -> 70 | F18: =SUM(F14:F17) -> 77 | G18: =SUM(G14:G17) -> 152 | H18: =SUM(H14:H17) -> 142 | I18: =SUM(I14:I17) -> 137 | J18: =SUM(J14:J17) -> 127 | K18: =SUM(K14:K17) -> 127 | ... O18: =SUM(O14:O17) -> 95
A19: =Dashboard!A20 -> 1 | B19: =Dashboard!B20 -> KAYOLE- NEW WATER | C19: =Dashboard!C20 -> No. | D19: 38 | E19: 18 | F19: 18 | G19: 18 | H19: 18 | I19: 18 | J19: 33 | K19: 23 | L19: 23 | M19: 18 | N19: 18 | O19: 18
A20: =Dashboard!A21 -> 2 | B20: =Dashboard!B21 -> IHINDU- NEW WATER | C20: =Dashboard!C21 -> No. | D20: 38 | E20: 38 | F20: 33 | G20: 28 | H20: 28 | I20: 23 | J20: 23 | K20: 18 | L20: 18 | M20: 18 | N20: 18 | O20: 18
B21: =Dashboard!B22 -> TOTAL NEW W CONNECTION EASTERN REGION | C21: =Dashboard!C22 -> No. | D21: =D19+D20 -> 76 | E21: =E19+E20 -> 56 | F21: =F19+F20 -> 51 | G21: =G19+G20 -> 46 | H21: =H19+H20 -> 46 | I21: =I19+I20 -> 41 | J21: =J19+J20 -> 56 | K21: =K19+K20 -> 41 | ... O21: =O19+O20 -> 36
A22: =Dashboard!A23 -> NEW CONNECTIONS SEWER
A23: =Dashboard!A24 -> 1 | B23: =Dashboard!B24 -> CBD- NEW SEWER | C23: =Dashboard!C24 -> No. | D23: 1 | E23: 1 | F23: 1 | G23: 1 | H23: 1 | I23: 1 | J23: 1 | K23: 1 | L23: 1 | M23: 1 | N23: 1 | O23: 1
A24: =Dashboard!A25 -> 2 | B24: =Dashboard!B25 -> CCCR- NEW SEWER | C24: =Dashboard!C25 -> No. | D24: 7 | E24: 7 | F24: 7 | G24: 7 | H24: 7 | I24: 7 | J24: 7 | K24: 7 | L24: 7 | M24: 7 | N24: 7 | O24: 7
A25: =Dashboard!A26 -> 3 | B25: =Dashboard!B26 -> KABATI- NEW SEWER | C25: =Dashboard!C26 -> No. | D25: 4 | E25: 3 | F25: 3 | G25: 3 | H25: 3 | I25: 3 | J25: 3 | K25: 3 | L25: 3 | M25: 3 | N25: 3 | O25: 3
A26: =Dashboard!A27 -> 4 | B26: =Dashboard!B27 -> SITE- NEW SEWER | C26: =Dashboard!C27 -> No. | D26: 1 | E26: 1 | F26: 1 | G26: 1 | H26: 1 | I26: 1 | J26: 1 | K26: 1 | L26: 1 | M26: 1 | N26: 1 | O26: 1
A27: =Dashboard!A28 -> 5 | B27: =Dashboard!B28 -> KIHOTO- NEW SEWER | C27: =Dashboard!C28 -> No.
A28: =Dashboard!A29 -> 6 | B28: =Dashboard!B29 -> LAKEVIEW- NEW SEWER | C28: =Dashboard!C29 -> No. | D28: 1 | E28: 1 | F28: 1 | G28: 1 | H28: 1 | I28: 1 | J28: 1 | K28: 1 | L28: 1 | M28: 1 | N28: 1 | O28: 1
A29: =Dashboard!A30 -> 7 | B29: =Dashboard!B30 -> HOPEWELL- NEW SEWER | C29: =Dashboard!C30 -> No.
A30: =Dashboard!A31 -> 0 | B30: =Dashboard!B31 -> TOTAL NEW SEWER CONNECTIONS CENTRAL REGION | C30: =Dashboard!C31 -> No. | D30: =SUM(D23:D29) -> 14 | E30: =SUM(E23:E29) -> 13 | F30: =SUM(F23:F29) -> 13 | G30: =SUM(G23:G29) -> 13 | H30: =SUM(H23:H29) -> 13 | I30: =SUM(I23:I29) -> 13 | J30: =SUM(J23:J29) -> 13 | K30: =SUM(K23:K29) -> 13 | ... O30: =SUM(O23:O29) -> 13
A31: =Dashboard!A32 -> 1 | B31: =Dashboard!B32 -> HELLSGATE- NEW SEWER | C31: =Dashboard!C32 -> No. | D31: 0 | E31: 0 | F31: 0 | G31: 0 | H31: 0 | I31: 0 | J31: 0 | K31: 0 | L31: 0 | M31: 0 | N31: 0 | O31: 0
A32: =Dashboard!A33 -> 2 | B32: =Dashboard!B33 -> KAMERE- NEW SEWER | C32: =Dashboard!C33 -> No. | D32: 0 | E32: 0 | F32: 0 | G32: 0 | H32: 0 | I32: 0 | J32: 0 | K32: 0 | L32: 0 | M32: 0 | N32: 0 | O32: 0
A33: =Dashboard!A34 -> 3 | B33: =Dashboard!B34 -> MAI-MAHIU- NEW SEWER | C33: =Dashboard!C34 -> No. | D33: 0 | E33: 0 | F33: 0 | G33: 0 | H33: 0 | I33: 0 | J33: 0 | K33: 0 | L33: 0 | M33: 0 | N33: 0 | O33: 0
A34: =Dashboard!A35 -> 0 | B34: =Dashboard!B35 -> TOTAL NEW S CONNECTION SOUTHERN REGION | C34: =Dashboard!C35 -> No. | D34: =SUM(D31:D33) -> 0 | E34: =SUM(E31:E33) -> 0 | F34: =SUM(F31:F33) -> 0 | G34: =SUM(G31:G33) -> 0 | H34: =SUM(H31:H33) -> 0 | I34: =SUM(I31:I33) -> 0 | J34: =SUM(J31:J33) -> 0 | K34: =SUM(K31:K33) -> 0 | ... O34: =SUM(O31:O33) -> 0
A35: =Dashboard!A37 -> 1 | B35: =Dashboard!B37 -> KAYOLE- NEW SEWER | C35: =Dashboard!C37 -> No. | D35: 1 | E35: 1 | F35: 1 | G35: 1 | H35: 1 | I35: 1 | J35: 1 | K35: 1 | L35: 1 | M35: 1 | N35: 1 | O35: 1
A36: =Dashboard!A38 -> TOTAL CONNECTIONS-WATER
A37: =Dashboard!A39 -> 1 | B37: =Dashboard!B39 -> CBD- WATER | C37: =Dashboard!C39 -> No. | D37: ='Input Actual2024-25'!P37+'budget 2025-26'!D6 -> 791 | E37: =D37+E6 -> 792 | F37: =E37+F6 -> 793 | G37: =F37+G6 -> 794 | H37: =G37+H6 -> 795 | I37: =H37+I6 -> 796 | J37: =I37+J6 -> 797 | K37: =J37+K6 -> 798 | L37: =K37+L6 -> 799 | ... O37: =N37+O6 -> 802
A38: =Dashboard!A40 -> 2 | B38: =Dashboard!B40 -> CCCR- WATER | C38: =Dashboard!C40 -> No. | D38: ='Input Actual2024-25'!P38+'budget 2025-26'!D7 -> 889 | E38: =D38+E7 -> 899 | F38: =E38+F7 -> 909 | G38: =F38+G7 -> 919 | H38: =G38+H7 -> 929 | I38: =H38+I7 -> 939 | J38: =I38+J7 -> 949 | K38: =J38+K7 -> 959 | L38: =K38+L7 -> 969 | ... O38: =N38+O7 -> 999
A39: =Dashboard!A41 -> 3 | B39: =Dashboard!B41 -> KABATI- WATER | C39: =Dashboard!C41 -> No. | D39: ='Input Actual2024-25'!P39+'budget 2025-26'!D8 -> 957 | E39: =D39+E8 -> 961 | F39: =E39+F8 -> 965 | G39: =F39+G8 -> 969 | H39: =G39+H8 -> 973 | I39: =H39+I8 -> 977 | J39: =I39+J8 -> 981 | K39: =J39+K8 -> 985 | L39: =K39+L8 -> 989 | ... O39: =N39+O8 -> 1001
A40: =Dashboard!A42 -> 4 | B40: =Dashboard!B42 -> SITE- WATER | C40: =Dashboard!C42 -> No. | D40: ='Input Actual2024-25'!P40+'budget 2025-26'!D9 -> 940 | E40: =D40+E9 -> 941 | F40: =E40+F9 -> 942 | G40: =F40+G9 -> 943 | H40: =G40+H9 -> 944 | I40: =H40+I9 -> 945 | J40: =I40+J9 -> 946 | K40: =J40+K9 -> 947 | L40: =K40+L9 -> 948 | ... O40: =N40+O9 -> 951
A41: =Dashboard!A43 -> 5 | B41: =Dashboard!B43 -> KIHOTO- WATER | C41: =Dashboard!C43 -> No. | D41: ='Input Actual2024-25'!P41+'budget 2025-26'!D10 -> 220 | E41: =D41+E10 -> 221 | F41: =E41+F10 -> 222 | G41: =F41+G10 -> 223 | H41: =G41+H10 -> 224 | I41: =H41+I10 -> 225 | J41: =I41+J10 -> 226 | K41: =J41+K10 -> 227 | L41: =K41+L10 -> 228 | ... O41: =N41+O10 -> 231
...

Sheet Input Actual2025-26
A1: =Dashboard!A1 -> SALES & CC DASHBOARD | E1: =E13+E18+E19 -> 136 | G1: =G13+G18+G19 -> 129 | H1: =H13+H18+H19 -> 149 | I1: =I13+I18+I19 -> 96 | J1: =J13+J18+J19 -> 134
E2: =E31+E35+E36 -> 0 | G2: =G31+G35+G36 -> 4 | H2: =H31+H35+H36 -> 3 | I2: =I31+I35+I36 -> 5 | J2: =J31+J35+J36 -> 0
B4: MONTH | C4: UNIT | E4: JUL | F4: AUG | G4: SEP | H4: OCT | I4: NOV | J4: DEC | K4: JAN | L4: FEB | M4: MAR | N4: APR | O4: MAY | P4: JUN
A5: =Dashboard!A5 -> NEW CONNECTIONS WATER
A6: =Dashboard!A6 -> 1 | B6: =Dashboard!B6 -> CBD - NEW WATER | C6: =Dashboard!C6 -> No. | D6: 8 | E6: 0 | F6: 0 | G6: 0 | H6: 1 | I6: 0 | J6: 0 | K6: 1 | L6: 0
A7: =Dashboard!A7 -> 2 | B7: =Dashboard!B7 -> CCCR- NEW WATER | C7: =Dashboard!C7 -> No. | D7: 14 | E7: 0 | F7: 3 | G7: 2 | H7: 2 | I7: 3 | J7: 2 | K7: 5 | L7: 3
A8: =Dashboard!A8 -> 3 | B8: =Dashboard!B8 -> KABATI- NEW WATER | C8: =Dashboard!C8 -> No. | D8: 4 | E8: 0 | F8: 0 | G8: 5 | H8: 1 | I8: 2 | J8: 0 | K8: 2 | L8: 0
A9: =Dashboard!A9 -> 4 | B9: =Dashboard!B9 -> SITE- NEW WATER | C9: =Dashboard!C9 -> No. | D9: 2 | E9: 0 | F9: 2 | G9: 0 | H9: 3 | I9: 0 | J9: 0 | K9: 2 | L9: 0
A10: =Dashboard!A10 -> 5 | B10: =Dashboard!B10 -> KIHOTO- NEW WATER | C10: =Dashboard!C10 -> No. | D10: 5 | E10: 2 | F10: 0 | G10: 0 | H10: 0 | I10: 0 | J10: 0 | K10: 0 | L10: 1
A11: =Dashboard!A11 -> 6 | B11: =Dashboard!B11 -> LAKEVIEW- NEW WATER | C11: =Dashboard!C11 -> No. | D11: 7 | E11: 2 | F11: 8 | G11: 0 | H11: 2 | I11: 0 | J11: 0 | K11: 2 | L11: 0
A12: =Dashboard!A12 -> 7 | B12: =Dashboard!B12 -> HOPEWELL- NEW WATER | C12: =Dashboard!C12 -> No. | D12: =Dashboard!D12 -> l | E12: 1 | F12: 0 | G12: 0 | H12: 14 | I12: 1 | J12: 12 | K12: 22 | L12: 3
A13: =Dashboard!A13 -> 0 | B13: =Dashboard!B13 -> TOTAL NEW WATER CONNECTIONS CENTRAL REGION | C13: =Dashboard!C13 -> No. | D13: 40 | E13: =SUM(E6:E12) -> 5 | F13: =SUM(F6:F12) -> 13 | G13: =SUM(G6:G12) -> 7 | H13: =SUM(H6:H12) -> 23 | I13: =SUM(I6:I12) -> 6 | J13: =SUM(J6:J12) -> 14 | K13: =SUM(K6:K12) -> 34 | L13: =SUM(L6:L12) -> 7 | ... P13: =SUM(P6:P12) -> 0
A14: =Dashboard!A14 -> 1 | B14: =Dashboard!B14 -> HELLSGATE- NEW WATER | C14: =Dashboard!C14 -> No. | D14: 24 | E14: 37 | F14: 18 | G14: 13 | H14: 11 | I14: 10 | J14: 10 | K14: 34 | L14: 14
A15: =Dashboard!A15 -> 2 | B15: =Dashboard!B15 -> KAMERE- NEW WATER | C15: =Dashboard!C15 -> No. | D15: 0 | E15: 0 | F15: 4 | G15: 14 | H15: 1 | I15: 15 | J15: 4 | K15: 4 | L15: 2
A16: =Dashboard!A16 -> 3 | B16: =Dashboard!B16 -> MAI-MAHIU- NEW WATER | C16: =Dashboard!C16 -> No. | D16: 24 | E16: 66 | F16: 59 | G16: 29 | H16: 73 | I16: 27 | J16: 66 | K16: 31 | L16: 33
A17: =Dashboard!A17 -> 4 | B17: =Dashboard!B17 -> LONGONOT- NEW WATER | C17: =Dashboard!C17 -> No. | D17: 24 | E17: 11 | F17: 20 | G17: 11 | H17: 11 | I17: 8 | J17: 2 | K17: 6 | L17: 2
A18: =Dashboard!A18 -> 0 | B18: =Dashboard!B18 -> TOTAL NEW WATER CONNECTION SOUTHERN REGION | C18: =Dashboard!C18 -> No. | D18: 48 | E18: =SUM(E14:E17) -> 114 | F18: =SUM(F14:F17) -> 101 | G18: =SUM(G14:G17) -> 67 | H18: =SUM(H14:H17) -> 96 | I18: =SUM(I14:I17) -> 60 | J18: =SUM(J14:J17) -> 82 | K18: =SUM(K14:K17) -> 75 | L18: =SUM(L14:L17) -> 51 | ... P18: =SUM(P14:P17) -> 0
A19: =Dashboard!A20 -> 1 | B19: =Dashboard!B20 -> KAYOLE- NEW WATER | C19: =Dashboard!C20 -> No. | D19: 25 | E19: 17 | F19: 40 | G19: 55 | H19: 30 | I19: 30 | J19: 38 | K19: 43 | L19: 17
A20: =Dashboard!A21 -> 2 | B20: =Dashboard!B21 -> IHINDU- NEW WATER | C20: =Dashboard!C21 -> No. | D20: =Dashboard!D21 -> l | E20: 1 | F20: 0 | G20: 1 | H20: 0 | I20: 0 | J20: 0 | K20: 2 | L20: 0
A21: =Dashboard!A22 -> 0 | B21: =Dashboard!B22 -> TOTAL NEW W CONNECTION EASTERN REGION | C21: =Dashboard!C22 -> No. | E21: =E20+E19 -> 18 | F21: =F20+F19 -> 40 | G21: =G20+G19 -> 56 | H21: =H20+H19 -> 30 | I21: =I20+I19 -> 30 | J21: =J20+J19 -> 38 | K21: =K20+K19 -> 45 | L21: =L20+L19 -> 17 | ... P21: =P20+P19 -> 0
B22: TOTAL NEW CONNECTIONS WATER | E22: =E21+E18+E13 -> 137 | F22: =F21+F18+F13 -> 154 | G22: =G21+G18+G13 -> 130 | H22: =H21+H18+H13 -> 149 | I22: =I21+I18+I13 -> 96 | J22: =J21+J18+J13 -> 134 | K22: =K21+K18+K13 -> 154 | L22: =L21+L18+L13 -> 75 | ... P22: =P21+P18+P13 -> 0
A23: =Dashboard!A23 -> NEW CONNECTIONS SEWER
A24: =Dashboard!A24 -> 1 | B24: =Dashboard!B24 -> CBD- NEW SEWER | C24: =Dashboard!C24 -> No. | D24: 0 | E24: 0 | F24: 0 | G24: 0 | H24: 0 | I24: 0 | J24: 0 | K24: 0 | L24: 0
A25: =Dashboard!A25 -> 2 | B25: =Dashboard!B25 -> CCCR- NEW SEWER | C25: =Dashboard!C25 -> No. | D25: 0 | E25: 0 | F25: 0 | G25: 0 | H25: 1 | I25: 1 | J25: 0 | K25: 1 | L25: 2
A26: =Dashboard!A26 -> 3 | B26: =Dashboard!B26 -> KABATI- NEW SEWER | C26: =Dashboard!C26 -> No. | D26: 0 | E26: 0 | F26: 1 | G26: 1 | H26: 0 | I26: 1 | J26: 0 | K26: 2 | L26: 1
A27: =Dashboard!A27 -> 4 | B27: =Dashboard!B27 -> SITE- NEW SEWER | C27: =Dashboard!C27 -> No. | D27: 0 | E27: 0 | F27: 0 | G27: 1 | H27: 0 | I27: 0 | J27: 0 | K27: 0 | L27: 0
A28: =Dashboard!A28 -> 5 | B28: =Dashboard!B28 -> KIHOTO- NEW SEWER | C28: =Dashboard!C28 -> No. | D28: 0 | E28: 0 | F28: 0 | G28: 0 | H28: 0 | I28: 0 | J28: 0 | K28: 0 | L28: 0
A29: =Dashboard!A29 -> 6 | B29: =Dashboard!B29 -> LAKEVIEW- NEW SEWER | C29: =Dashboard!C29 -> No. | D29: 2 | E29: 0 | F29: 1 | G29: 0 | H29: 1 | I29: 0 | J29: 0 | K29: 1 | L29: 0
A30: =Dashboard!A30 -> 7 | B30: =Dashboard!B30 -> HOPEWELL- NEW SEWER | C30: =Dashboard!C30 -> No. | D30: 2 | E30: 0 | F30: 0 | G30: 0 | H30: 0 | I30: 0 | J30: 0 | K30: 0 | L30: 0
A31: =Dashboard!A31 -> 0 | B31: =Dashboard!B31 -> TOTAL NEW SEWER CONNECTIONS CENTRAL REGION | C31: =Dashboard!C31 -> No. | D31: 2 | E31: =SUM(E24:E30) -> 0 | F31: =SUM(F24:F30) -> 2 | G31: =SUM(G24:G30) -> 2 | H31: =SUM(H24:H30) -> 2 | I31: =SUM(I24:I30) -> 2 | J31: =SUM(J24:J30) -> 0 | K31: =SUM(K24:K30) -> 4 | L31: =SUM(L24:L30) -> 3 | ... P31: =SUM(P24:P30) -> 0
A32: =Dashboard!A32 -> 1 | B32: =Dashboard!B32 -> HELLSGATE- NEW SEWER | C32: =Dashboard!C32 -> No. | E32: 0 | F32: =F64-E64 -> 0 | G32: =G64-F64 -> 0 | H32: =H64-G64 -> 0 | I32: =I64-H64 -> 0 | J32: =J64-I64 -> 0 | K32: =K64-J64 -> 0 | L32: =L64-K64 -> 0 | M32: =M64-L64 -> 0 | ... P32: =P64-O64 -> 0
A33: =Dashboard!A33 -> 2 | B33: =Dashboard!B33 -> KAMERE- NEW SEWER | C33: =Dashboard!C33 -> No. | E33: 0 | F33: =F65-E65 -> 0 | G33: =G65-F65 -> 0 | H33: =H65-G65 -> 0 | I33: =I65-H65 -> 0 | J33: =J65-I65 -> 0 | K33: =K65-J65 -> 0 | L33: =L65-K65 -> 0 | M33: =M65-L65 -> 0 | ... P33: =P65-O65 -> 0
A34: =Dashboard!A34 -> 3 | B34: =Dashboard!B34 -> MAI-MAHIU- NEW SEWER | C34: =Dashboard!C34 -> No. | E34: 0 | F34: =F66-E66 -> 0 | G34: =G66-F66 -> 0 | H34: =H66-G66 -> 0 | I34: =I66-H66 -> 0 | J34: =J66-I66 -> 0 | K34: =K66-J66 -> 0 | L34: =L66-K66 -> 0 | M34: =M66-L66 -> 0 | ... P34: =P66-O66 -> 0
A35: =Dashboard!A35 -> 0 | B35: =Dashboard!B35 -> TOTAL NEW S CONNECTION SOUTHERN REGION | C35: =Dashboard!C35 -> No. | D35: 0 | E35: =SUM(E32:E34) -> 0 | F35: =SUM(F32:F34) -> 0 | G35: =SUM(G32:G34) -> 0 | H35: =SUM(H32:H34) -> 0 | I35: =SUM(I32:I34) -> 0 | J35: =SUM(J32:J34) -> 0 | K35: =SUM(K32:K34) -> 0 | L35: =SUM(L32:L34) -> 0 | ... P35: =SUM(P32:P34) -> 0
A36: =Dashboard!A37 -> 1 | B36: =Dashboard!B37 -> KAYOLE- NEW SEWER | C36: =Dashboard!C37 -> No. | D36: 6 | E36: 0 | F36: 2 | G36: 2 | H36: 1 | I36: 3 | J36: 0 | K36: 0 | L36: 2
B37: TOTAL NEW CONNECTIONS -SEWER | D37: 8 | E37: =E36+E31 -> 0 | F37: =F36+F31 -> 4 | G37: =G36+G31 -> 4 | H37: =H36+H31 -> 3 | I37: =I36+I31 -> 5 | J37: =J36+J31 -> 0 | K37: =K36+K31 -> 4 | L37: =L36+L31 -> 5 | ... P37: =P36+P31 -> 0
A38: =Dashboard!A38 -> TOTAL CONNECTIONS-WATER
A39: =Dashboard!A39 -> 1 | B39: =Dashboard!B39 -> CBD- WATER | C39: =Dashboard!C39 -> No. | D39: 773 | E39: 790 | F39: 791 | G39: 791 | H39: 793 | I39: 793 | J39: 793 | K39: 792 | L39: 792
A40: =Dashboard!A40 -> 2 | B40: =Dashboard!B40 -> CCCR- WATER | C40: =Dashboard!C40 -> No. | D40: 779 | E40: 880 | F40: 883 | G40: 885 | H40: 886 | I40: 889 | J40: 890 | K40: 895 | L40: 898
A41: =Dashboard!A41 -> 3 | B41: =Dashboard!B41 -> KABATI- WATER | C41: =Dashboard!C41 -> No. | D41: 908 | E41: 953 | F41: 952 | G41: 956 | H41: 956 | I41: 957 | J41: 957 | K41: 959 | L41: 959
...

Sheet Input Actual2024-25
A1: =Dashboard!A1 -> SALES & CC DASHBOARD | E1: =E13+E18+E19 -> 78 | G1: =G13+G18+G19 -> 26 | H1: =H13+H18+H19 -> 10 | I1: =I13+I18+I19 -> 39 | J1: =J13+J18+J19 -> 56
E2: =E29+E33+E34 -> 3 | G2: =G29+G33+G34 -> 3 | H2: =H29+H33+H34 -> 2 | I2: =I29+I33+I34 -> 0 | J2: =J29+J33+J34 -> 4
B4: MONTH | C4: UNIT | E4: JUL | F4: AUG | G4: SEP | H4: OCT | I4: NOV | J4: DEC | K4: JAN | L4: FEB | M4: MAR | N4: APR | O4: MAY | P4: JUN
A5: =Dashboard!A5 -> NEW CONNECTIONS WATER
A6: =Dashboard!A6 -> 1 | B6: =Dashboard!B6 -> CBD - NEW WATER | C6: =Dashboard!C6 -> No. | D6: 8 | E6: 1 | F6: 1 | G6: 2 | H6: 0 | I6: 0 | J6: 0 | K6: 0 | L6: 0 | M6: 0 | N6: 1 | O6: 2 | P6: 2
A7: =Dashboard!A7 -> 2 | B7: =Dashboard!B7 -> CCCR- NEW WATER | C7: =Dashboard!C7 -> No. | D7: 14 | E7: 6 | F7: 1 | G7: 3 | H7: 0 | I7: 0 | J7: 0 | K7: 7 | L7: 2 | M7: 1 | N7: 3 | O7: 2 | P7: 4
A8: =Dashboard!A8 -> 3 | B8: =Dashboard!B8 -> KABATI- NEW WATER | C8: =Dashboard!C8 -> No. | D8: 4 | E8: 1 | F8: 4 | G8: 5 | H8: 0 | I8: 3 | J8: 0 | K8: 1 | L8: 4 | M8: 0 | N8: 2 | O8: 2 | P8: 0
A9: =Dashboard!A9 -> 4 | B9: =Dashboard!B9 -> SITE- NEW WATER | C9: =Dashboard!C9 -> No. | D9: 2 | E9: 1 | F9: 0 | G9: 0 | H9: 0 | I9: 0 | J9: 0 | K9: 1 | L9: 0 | M9: 0 | N9: 0 | O9: 0 | P9: 2
A10: =Dashboard!A10 -> 5 | B10: =Dashboard!B10 -> KIHOTO- NEW WATER | C10: =Dashboard!C10 -> No. | D10: 5 | E10: 0 | F10: 0 | G10: 0 | H10: 0 | I10: 0 | J10: 0 | K10: 1 | L10: 0 | M10: 0 | N10: 0 | O10: 0 | P10: 1
A11: =Dashboard!A11 -> 6 | B11: =Dashboard!B11 -> LAKEVIEW- NEW WATER | C11: =Dashboard!C11 -> No. | D11: 7 | E11: 7 | F11: 5 | G11: 0 | H11: 2 | I11: 0 | J11: 0 | K11: 2 | L11: 4 | M11: 2 | N11: 1 | O11: 2 | P11: 1
A12: =Dashboard!A12 -> 7 | B12: =Dashboard!B12 -> HOPEWELL- NEW WATER | C12: =Dashboard!C12 -> No. | D12: =Dashboard!D12 -> l | E12: 0 | F12: 0 | G12: 0 | H12: 0 | I12: 0 | J12: 0 | K12: 4 | L12: 0 | M12: 2 | N12: 0 | O12: 1 | P12: 2
A13: =Dashboard!A13 -> 0 | B13: =Dashboard!B13 -> TOTAL NEW WATER CONNECTIONS CENTRAL REGION | C13: =Dashboard!C13 -> No. | D13: 40 | E13: =SUM(E6:E12) -> 16 | F13: =SUM(F6:F12) -> 11 | G13: =SUM(G6:G12) -> 10 | H13: =SUM(H6:H12) -> 2 | I13: =SUM(I6:I12) -> 3 | J13: =SUM(J6:J12) -> 0 | K13: =SUM(K6:K12) -> 16 | L13: =SUM(L6:L12) -> 10 | ... P13: =SUM(P6:P12) -> 12
A14: =Dashboard!A14 -> 1 | B14: =Dashboard!B14 -> HELLSGATE- NEW WATER | C14: =Dashboard!C14 -> No. | D14: 24 | E14: 13 | F14: 8 | G14: -1 | H14: 0 | I14: 1 | J14: 1 | K14: 13 | L14: 12 | M14: 16 | N14: 16 | O14: 17 | P14: 16
A15: =Dashboard!A15 -> 2 | B15: =Dashboard!B15 -> KAMERE- NEW WATER | C15: =Dashboard!C15 -> No. | D15: 0 | E15: 4 | F15: 1 | G15: 0 | H15: 0 | I15: 0 | J15: 1 | K15: 1 | L15: 4 | M15: 0 | N15: 1 | O15: 1 | P15: 0
A16: =Dashboard!A16 -> 3 | B16: =Dashboard!B16 -> MAI-MAHIU- NEW WATER | C16: =Dashboard!C16 -> No. | D16: 24 | E16: 14 | F16: 22 | G16: 12 | H16: 2 | I16: 13 | J16: 53 | K16: 87 | L16: 17 | M16: 16 | N16: 75 | O16: 11 | P16: 24
A17: =Dashboard!A17 -> 4 | B17: =Dashboard!B17 -> LONGONOT- NEW WATER | C17: =Dashboard!C17 -> No. | D17: 24 | E17: 0 | F17: 0 | G17: 3 | H17: 0 | I17: 0 | J17: 1 | K17: 5 | L17: 6 | M17: 6 | N17: 5 | O17: 9 | P17: 10
A18: =Dashboard!A18 -> 0 | B18: =Dashboard!B18 -> TOTAL NEW WATER CONNECTION SOUTHERN REGION | C18: =Dashboard!C18 -> No. | D18: 48 | E18: =SUM(E14:E17) -> 31 | F18: =SUM(F14:F17) -> 31 | G18: =SUM(G14:G17) -> 14 | H18: =SUM(H14:H17) -> 2 | I18: =SUM(I14:I17) -> 14 | J18: =SUM(J14:J17) -> 56 | K18: =SUM(K14:K17) -> 106 | L18: =SUM(L14:L17) -> 39 | ... P18: =SUM(P14:P17) -> 50
A19: =Dashboard!A20 -> 1 | B19: =Dashboard!B20 -> KAYOLE- NEW WATER | C19: =Dashboard!C20 -> No. | D19: 25 | E19: 31 | F19: 9 | G19: 2 | H19: 6 | I19: 22 | J19: 0 | K19: 7 | L19: 37 | M19: 47 | N19: 55 | O19: 12 | P19: 25
B20: TOTAL NEW CONNECTIONS WATER | D20: 113 | E20: =E19+E18+E13 -> 78 | F20: =F19+F18+F13 -> 51 | G20: =G19+G18+G13 -> 26 | H20: =H19+H18+H13 -> 10 | I20: =I19+I18+I13 -> 39 | J20: =J19+J18+J13 -> 56 | K20: =K19+K18+K13 -> 129 | L20: =L19+L18+L13 -> 86 | ... P20: =P19+P18+P13 -> 87
A21: =Dashboard!A23 -> NEW CONNECTIONS SEWER
A22: =Dashboard!A24 -> 1 | B22: =Dashboard!B24 -> CBD- NEW SEWER | C22: =Dashboard!C24 -> No. | D22: 0 | E22: 0 | F22: 1 | G22: 0 | H22: 0 | I22: 0 | J22: 1 | K22: 1 | L22: 0 | M22: 0 | N22: 0 | O22: 0 | P22: 1
A23: =Dashboard!A25 -> 2 | B23: =Dashboard!B25 -> CCCR- NEW SEWER | C23: =Dashboard!C25 -> No. | D23: 0 | E23: 1 | F23: 2 | G23: -2 | H23: 0 | I23: 0 | J23: 0 | K23: 0 | L23: 0 | M23: 1 | N23: 1 | O23: 0 | P23: 0
A24: =Dashboard!A26 -> 3 | B24: =Dashboard!B26 -> KABATI- NEW SEWER | C24: =Dashboard!C26 -> No. | D24: 0 | E24: 0 | F24: 4 | G24: 0 | H24: 0 | I24: 0 | J24: 2 | K24: 0 | L24: 2 | M24: 0 | N24: 1 | O24: 0 | P24: 1
A25: =Dashboard!A27 -> 4 | B25: =Dashboard!B27 -> SITE- NEW SEWER | C25: =Dashboard!C27 -> No. | D25: 0 | E25: 1 | F25: 3 | G25: 1 | H25: 0 | I25: 0 | J25: 0 | K25: 0 | L25: 1 | M25: 0 | N25: 0 | O25: 0 | P25: 0
A26: =Dashboard!A28 -> 5 | B26: =Dashboard!B28 -> KIHOTO- NEW SEWER | C26: =Dashboard!C28 -> No. | D26: 0 | E26: 0 | F26: 0 | G26: 0 | H26: 0 | I26: 0 | J26: 0 | K26: 0 | L26: 0 | M26: 0 | N26: 0 | O26: 0 | P26: 0
A27: =Dashboard!A29 -> 6 | B27: =Dashboard!B29 -> LAKEVIEW- NEW SEWER | C27: =Dashboard!C29 -> No. | D27: 2 | E27: 0 | F27: 0 | G27: 2 | H27: 1 | I27: 0 | J27: 0 | K27: 0 | L27: 1 | M27: 1 | N27: 0 | O27: 0 | P27: 0
A28: =Dashboard!A30 -> 7 | B28: =Dashboard!B30 -> HOPEWELL- NEW SEWER | C28: =Dashboard!C30 -> No. | D28: 2 | E28: 0 | F28: 0 | G28: 0 | H28: 0 | I28: 0 | J28: 0 | K28: 0 | L28: 0 | M28: 0 | N28: 0 | O28: 0 | P28: 0
A29: =Dashboard!A31 -> 0 | B29: =Dashboard!B31 -> TOTAL NEW SEWER CONNECTIONS CENTRAL REGION | C29: =Dashboard!C31 -> No. | D29: 2 | E29: =SUM(E22:E28) -> 2 | F29: =SUM(F22:F28) -> 10 | G29: =SUM(G22:G28) -> 1 | H29: =SUM(H22:H28) -> 1 | I29: =SUM(I22:I28) -> 0 | J29: =SUM(J22:J28) -> 3 | K29: =SUM(K22:K28) -> 1 | L29: =SUM(L22:L28) -> 4 | ... P29: =SUM(P22:P28) -> 2
A30: =Dashboard!A32 -> 1 | B30: =Dashboard!B32 -> HELLSGATE- NEW SEWER | C30: =Dashboard!C32 -> No. | E30: 0 | F30: =F60-E60 -> 0 | G30: =G60-F60 -> 0 | H30: =H60-G60 -> 0 | I30: =I60-H60 -> 0 | J30: =J60-I60 -> 0 | K30: =K60-J60 -> 0 | L30: =L60-K60 -> 0 | M30: =M60-L60 -> 0 | ... P30: =P60-O60 -> 0
A31: =Dashboard!A33 -> 2 | B31: =Dashboard!B33 -> KAMERE- NEW SEWER | C31: =Dashboard!C33 -> No. | E31: 0 | F31: =F61-E61 -> 0 | G31: =G61-F61 -> 0 | H31: =H61-G61 -> 0 | I31: =I61-H61 -> 0 | J31: =J61-I61 -> 0 | K31: =K61-J61 -> 0 | L31: =L61-K61 -> 0 | M31: =M61-L61 -> 0 | ... P31: =P61-O61 -> 0
A32: =Dashboard!A34 -> 3 | B32: =Dashboard!B34 -> MAI-MAHIU- NEW SEWER | C32: =Dashboard!C34 -> No. | E32: 0 | F32: =F62-E62 -> 0 | G32: =G62-F62 -> 0 | H32: =H62-G62 -> 0 | I32: =I62-H62 -> 0 | J32: =J62-I62 -> 0 | K32: =K62-J62 -> 0 | L32: =L62-K62 -> 0 | M32: =M62-L62 -> 0 | ... P32: =P62-O62 -> 0
A33: =Dashboard!A35 -> 0 | B33: =Dashboard!B35 -> TOTAL NEW S CONNECTION SOUTHERN REGION | C33: =Dashboard!C35 -> No. | D33: 0 | E33: =SUM(E30:E32) -> 0 | F33: =SUM(F30:F32) -> 0 | G33: =SUM(G30:G32) -> 0 | H33: =SUM(H30:H32) -> 0 | I33: =SUM(I30:I32) -> 0 | J33: =SUM(J30:J32) -> 0 | K33: =SUM(K30:K32) -> 0 | L33: =SUM(L30:L32) -> 0 | ... P33: =SUM(P30:P32) -> 0
A34: =Dashboard!A37 -> 1 | B34: =Dashboard!B37 -> KAYOLE- NEW SEWER | C34: =Dashboard!C37 -> No. | D34: 6 | E34: 1 | F34: 0 | G34: 2 | H34: 1 | I34: 0 | J34: 1 | K34: 0 | L34: 2 | M34: 2 | N34: 1 | O34: 0 | P34: 1
B35: TOTAL NEW CONNECTIONS -SEWER | D35: 8 | E35: =E34+E29 -> 3 | F35: =F34+F29 -> 10 | G35: =G34+G29 -> 3 | H35: =H34+H29 -> 2 | I35: =I34+I29 -> 0 | J35: =J34+J29 -> 4 | K35: =K34+K29 -> 1 | L35: =L34+L29 -> 6 | ... P35: =P34+P29 -> 3
A36: =Dashboard!A38 -> TOTAL CONNECTIONS-WATER
A37: =Dashboard!A39 -> 1 | B37: =Dashboard!B39 -> CBD- WATER | C37: =Dashboard!C39 -> No. | D37: 773 | E37: 782 | F37: 783 | G37: 785 | H37: 786 | I37: 785 | J37: 786 | K37: 785 | L37: 785 | M37: 785 | N37: 786 | O37: 788 | P37: 790
A38: =Dashboard!A40 -> 2 | B38: =Dashboard!B40 -> CCCR- WATER | C38: =Dashboard!C40 -> No. | D38: 779 | E38: 857 | F38: 858 | G38: 861 | H38: 859 | I38: 861 | J38: 861 | K38: 869 | L38: 872 | M38: 873 | N38: 875 | O38: 876 | P38: 880
A39: =Dashboard!A41 -> 3 | B39: =Dashboard!B41 -> KABATI- WATER | C39: =Dashboard!C41 -> No. | D39: 908 | E39: 935 | F39: 939 | G39: 944 | H39: 944 | I39: 946 | J39: 945 | K39: 946 | L39: 950 | M39: 950 | N39: 951 | O39: 953 | P39: 953
A40: =Dashboard!A42 -> 4 | B40: =Dashboard!B42 -> SITE- WATER | C40: =Dashboard!C42 -> No. | D40: 921 | E40: 935 | F40: 935 | G40: 935 | H40: 935 | I40: 935 | J40: 935 | K40: 936 | L40: 937 | M40: 937 | N40: 937 | O40: 937 | P40: 939
A41: =Dashboard!A43 -> 5 | B41: =Dashboard!B43 -> KIHOTO- WATER | C41: =Dashboard!C43 -> No. | D41: 207 | E41: 217 | F41: 217 | G41: 217 | H41: 217 | I41: 217 | J41: 217 | K41: 218 | L41: 218 | M41: 218 | N41: 218 | O41: 218 | P41: 219
...

Sheet MARKETING PLAN
B1: MARKETING PLAN (QUARTERLY)
A2: In order to fully implement both the marketing and the sales plan, the section needs more staff
A3: AREA | B3: TARGET | C3: STRATEGY | D3: BUDGET | E3: TIMELINE | F3: LEVEL OF IMPLEMENTATION | G3: REMARKS
A4: Ihindu Marketing and target | B4: 300 | C4: · Door to door marketing, | E4: July-September 2024 | F4: 0 | G4: Pending project completion
C5: · Conduct water clinic. | D5: 29250 | F5: 0
C6: · Follow up with customers via phone | D6: Airtime -1,000 | F6: 0
C7: · Social marketer | D7: 200 per connection | F7: 0
C8: · Use of communication materials | F8: 0
C9: · Use of point man | F9: 1
A10: Kayole Sewer Marketing | B10: 400 | C10: · Door to door marketing | E10: July-September 2024 | F10: 0
C11: · Call customers on phone for follow up (customers with water connection | D11: Airtime -1,000 | F11: 0
C12: · PHO enforcement on customers reluctant to apply | F12: 1
C13: · Use of communication materials | F13: 0
C14: · Social marketer | D14: 200 per connection | F14: 0
C15: · Hold water clinic in the target areas | D15: 29250 | F15: 1
A16: Ngondi | B16: 300 | C16: · Door to door marketing | E16: July-September 2024 | F16: 0
C17: · Hold water clinic | D17: Water clinic-29,250 | F17: 0 | G17: Pending phase 2 clinics
C18: · Use of point man | F18: 1
C19: · Social marketer | D19: 200 per connection | F19: 0
C20: · Use of communication materials | F20: 0
C21: · Follow up with customers via phone | D21: Airtime -1,000 | F21: 0
C22: · Hold a community meeting | D22: Refreshments-50*100=5,000 | F22: 0
D23: Hiring of hall- 5,000 | F23: 0.5
A24: Karima, Rare and Kamucira | B24: 400 | C24: · Door to door marketing | E24: July-August 2024 | F24: 0.5
C25: · Use of communication materials | F25: 0
C26: · Hold water clinic | D26: Water clinic-29,250 | F26: 0 | G26: Pending phase 2 clinics
C27: · Follow up by calling customers | D27: Airtime -1,000 | F27: 0.8
C28: · Social marketers | D28: 200 per connection | F28: 1
C29: · Use of point man | F29: 0.5
A30: Kedong (Wachira line) | B30: 100 | C30: · Use of point man | E30: 45474 | F30: 0
C31: · Follow up by calling customers | D31: Airtime -1,000 | F31: 0
A32: Rwanyaga | B32: 150 | C32: · Hold a community meeting | D32: Refreshments-50*100=5,000 | E32: August - September 2024 | F32: 0
D33: Hiring of hall- 5,000 | F33: 0
C34: · Social marketers | D34: 200 per connection | F34: 0
C35: · Use of communication materials | F35: 0
C36: · Follow up with customers on pending payment and NAWC | D36: Airtime -1,000 | F36: 0
A37: Kabati sewer connection | B37: 100 | C37: · Hold a community meeting | D37: Refreshments-50*100=5,000 | E37: 45474 | F37: 0.333
D38: Hiring of hall- 5,000 | F38: 0
C39: · Social marketers | D39: 200 per connection | F39: 0
C40: · Use of communication materials | F40: 1
...

Sheet SALES PLAN
C1: Duration/Time required to complete a task/step and activity in days | D1: 45474 | H1: 45505 | L1: 45536 | P1: 45566 | T1: 45597 | X1: 45627 | AB1: 45658 | AF1: 45689 | AJ1: 45717 | AN1: 45748 | AR1: 45778 | AV1: 45809 | BA1: person Responsible | BB1: External support needed
B2: SALES SECTION | D2: W1 | E2: W2 | F2: W3 | G2: W4 | H2: W1 | I2: W2 | J2: W3 | K2: W4 | L2: W1 | M2: W2 | N2: W3 | O2: W4 | P2: W1 | Q2: W2 | R2: W3 | S2: W4 | T2: W1 | U2: W2 | V2: W3 | W2: W4 | X2: W1 | Y2: W2 | Z2: W3 | AA2: W4 | AB2: W1 | AC2: W2 | AD2: W3 | AE2: W4 | AF2: W1 | AG2: W2 | AH2: W3 | AI2: W4 | AJ2: W1 | AK2: W2 | AL2: W3 | AM2: W4 | AN2: W1 | AO2: W2 | AP2: W3 | AQ2: W4 | AR2: W1 | AS2: W2 | AT2: W3 | AU2: W4 | AV2: W1 | AW2: W2 | AX2: W3 | AY2: W4 | AZ2: Annual Targets
B3: ACTIVITIES
B4: INCREASE SALES | C4: =SUM(C5:C123) -> 8537 | BA4: SALES S.
B5: INCREASE SALES IN EASTERN REGION
B6: Water Extensions: Laketown(Bridge), Jumbo Estate, Solomon extension, Signture lane 2 & 7 | C6: Assessment done | BA6: Sales Supervisor
B7: Designing and Development of BoQs | C7: =5*4 -> 20 | BA7: Projects
B8: Approval for Extensions | C8: =5*4 -> 20 | BA8: DSM | BB8: 535000
B9: Implementation | C9: =5*4 -> 20 | BA9: Zonal Officer
B10: Customer registration & connection | C10: 180 | AZ10: 107 | BA10: Sales Supervisor | BB10: 50000
B11: Analysis of the inactive accounts | C11: (156)19.67% | BA11: Sales Supervisor
B13: Increase in sewer connections | C13: =12*22 -> 264 | BA13: Sales Supervisor | BB13: 50000
B15: INCREASE SALES IN SOUTHERN REGION
B16: Extensions: Dam1, Transit 1, 2 & 3, Silvester, Kedon( Kwa-Ngombe), Sanctuary,Part Island, Shalom & Musaka, Ngondi | C16: Assesment done | BA16: Sales Supervisor
B17: Designing and Development of BoQs | C17: 20 | BA17: Projects Engineer
B18: Approval for Extensions | C18: =5*4 -> 20 | BA18: DSM | BB18: 2642625
B19: Implementation | C19: =5*6 -> 30 | BA19: Zonal Officer
B20: Customer registration & connection | C20: 180 | AZ20: 200 | BA20: Sales Supervisor(Social Marketer) | BB20: 50000
B21: Analysis of the inactive accounts | C21: (793)22.76% | BA21: Sales Supervisor
B23: Increase water connections in Maai-Mahiu WFL | C23: =22*12 -> 264 | AZ23: 320 | BA23: Sales Supervisor
B25: INCREASE SALES IN CENTRAL REGION
B26: Extensions: Kihoto-Line 1 ,2, 7 & 8 Ziwa Drive,Catholic,Maziwa,Mulika Mwizi, and =ndegwa lane; Manera 1,2& 3, Banda line 1 and : ; Prison extension | C26: Assessment Done | BA26: Sales Supervisor
B27: Designing and Development of BoQs | C27: 10 | BA27: Projects Engineer
B28: Approval for Extensions | C28: 10 | BA28: DSM | BB28: 2225000
B29: Implementation | C29: =5*4 -> 20 | BA29: Zonal Officer
B30: Customer registration & connection | C30: 150 | AZ30: 445 | BA30: Sales Supervisor(Social Marketer) | BB30: 50000
B31: Analysis of the inactive accounts | C31: (1,160)15.98% | BA31: Sales Supervisor
B33: Increase in sewer connections | C33: =12*22 -> 264 | BA33: Sales Supervisor | BB33: 50000
B35: NEW PROJECT AREAS
B36: KINUNGI
B37: Community meeting | C37: 1 | BA37: SSS
B38: prioritization of extension | C38: =5*4 -> 20 | BA38: SSS
B39: Implementation | C39: =5*8 -> 40 | BA39: Zonal Officer
B40: Registration | C40: =10*22 -> 220 | AZ40: 300 | BA40: Sales Supervisor(Social Marketer) | BB40: 60000
B41: Customer connection | C41: =10*22 -> 220 | BA41: Zonal Officer
B43: GOVERNOR
B44: Commnity meeting | C44: 1 | BA44: Sales Supervisor(Social Marketer)
B45: prioritization of extension | C45: =5*3 -> 15 | BA45: SSS | BB45: 1000000
B46: Implementation | C46: =5*4 -> 20 | BA46: Zonal Officer
B47: Registration | C47: =11*22 -> 242 | BA47: Sales Supervisor(Social Marketer) | BB47: 60000
...

Sheet actual 2022-23
A1: =Dashboard!A1 -> SALES & CC DASHBOARD | D1: =D12+D16+D17 -> 44 | E1: =E12+E16+E17 -> 115 | F1: =F12+F16+F17 -> 155 | G1: =G12+G16+G17 -> 78 | H1: =H12+H16+H17 -> 80 | I1: =I12+I16+I17 -> 45
D2: =D26+D30+D31 -> 11 | E2: =E26+E30+E31 -> 2 | F2: =F26+F30+F31 -> 4 | G2: =G26+G30+G31 -> 16 | H2: =H26+H30+H31 -> 4 | I2: =I26+I30+I31 -> 5
B4: MONTH | C4: UNIT | D4: JUL | E4: AUG | F4: SEP | G4: OCT | H4: NOV | I4: DEC | J4: JAN | K4: FEB | L4: MAR | M4: APR | N4: MAY | O4: JUN
A5: =Dashboard!A5 -> NEW CONNECTIONS WATER
A6: =Dashboard!A6 -> 1 | B6: =Dashboard!B6 -> CBD - NEW WATER | C6: =Dashboard!C6 -> No. | D6: =D34-'actual 2021-22'!O32 -> 0 | E6: =E34-D34 -> 0 | F6: =F34-E34 -> 5 | G6: 0 | H6: =H34-G34 -> 3 | I6: =I34-H34 -> 1 | J6: =J34-I34 -> 2 | K6: =K34-J34 -> 3 | L6: =L34-K34 -> 4 | M6: 2 | N6: 3 | O6: 8
A7: =Dashboard!A7 -> 2 | B7: =Dashboard!B7 -> CCCR- NEW WATER | C7: =Dashboard!C7 -> No. | D7: =D35-'actual 2021-22'!O33 -> 4 | E7: =E35-D35 -> 6 | F7: =F35-E35 -> 8 | G7: =G35-F35 -> 15 | H7: =H35-G35 -> 5 | I7: =I35-H35 -> 1 | J7: =J35-I35 -> 6 | K7: =K35-J35 -> 5 | L7: =L35-K35 -> 6 | M7: 1 | N7: 0 | O7: 14
A8: =Dashboard!A8 -> 3 | B8: =Dashboard!B8 -> KABATI- NEW WATER | C8: =Dashboard!C8 -> No. | D8: =D36-'actual 2021-22'!O34 -> 4 | E8: =E36-D36 -> 10 | F8: =F36-E36 -> 4 | G8: 0 | H8: =H36-G36 -> 2 | I8: =I36-H36 -> 8 | J8: =J36-I36 -> 10 | K8: =K36-J36 -> 5 | L8: =L36-K36 -> 8 | M8: 4 | N8: 4 | O8: 4
A9: =Dashboard!A9 -> 4 | B9: =Dashboard!B9 -> SITE- NEW WATER | C9: =Dashboard!C9 -> No. | D9: =D37-'actual 2021-22'!O35 -> 4 | E9: =E37-D37 -> 3 | F9: =F37-E37 -> 1 | G9: =G37-F37 -> 0 | H9: =H37-G37 -> 1 | I9: =I37-H37 -> 0 | J9: =J37-I37 -> 1 | K9: =K37-J37 -> 3 | L9: =L37-K37 -> 2 | M9: 5 | N9: 3 | O9: 2
A10: =Dashboard!A10 -> 5 | B10: =Dashboard!B10 -> KIHOTO- NEW WATER | C10: =Dashboard!C10 -> No. | D10: =D38-'actual 2021-22'!O36 -> 3 | E10: =E38-D38 -> 2 | F10: =F38-E38 -> 0 | G10: =G38-F38 -> 0 | H10: =H38-G38 -> 3 | I10: =I38-H38 -> 2 | J10: =J38-I38 -> 1 | K10: =K38-J38 -> 0 | L10: =L38-K38 -> 0 | M10: 2 | N10: 0 | O10: 5
A11: =Dashboard!A11 -> 6 | B11: =Dashboard!B11 -> LAKEVIEW- NEW WATER | C11: =Dashboard!C11 -> No. | D11: =D39-'actual 2021-22'!O41 -> 2 | E11: =E39-D39 -> 6 | F11: =F39-E39 -> 2 | G11: 3 | H11: =H39-G39 -> 7 | I11: =I39-H39 -> 7 | J11: =J39-I39 -> 6 | K11: =K39-J39 -> 9 | L11: =L39-K39 -> 10 | M11: 4 | N11: 1 | O11: 7
A12: =Dashboard!A13 -> 0 | B12: =Dashboard!B13 -> TOTAL NEW WATER CONNECTIONS CENTRAL REGION | C12: =Dashboard!C13 -> No. | D12: =SUM(D6:D11) -> 17 | E12: =SUM(E6:E11) -> 27 | F12: =SUM(F6:F11) -> 20 | G12: =SUM(G6:G11) -> 18 | H12: =SUM(H6:H11) -> 21 | I12: =SUM(I6:I11) -> 19 | J12: =SUM(J6:J11) -> 26 | K12: =SUM(K6:K11) -> 25 | ... O12: =SUM(O6:O11) -> 40
A13: =Dashboard!A14 -> 1 | B13: =Dashboard!B14 -> HELLSGATE- NEW WATER | C13: =Dashboard!C14 -> No. | D13: =D41-'actual 2021-22'!O38 -> 6 | E13: =E41-D41 -> 22 | F13: =F41-E41 -> 13 | G13: =G41-F41 -> 29 | H13: =H41-G41 -> 16 | I13: =I41-H41 -> 12 | J13: =J41-I41 -> 10 | K13: =K41-J41 -> 31 | L13: =L41-K41 -> 29 | M13: 19 | N13: 19 | O13: 24
A14: =Dashboard!A15 -> 2 | B14: =Dashboard!B15 -> KAMERE- NEW WATER | C14: =Dashboard!C15 -> No. | D14: =D42-'actual 2021-22'!O39 -> 0 | E14: =E42-D42 -> 3 | F14: =F42-E42 -> 0 | G14: =G42-F42 -> 1 | H14: =H42-G42 -> 2 | I14: =I42-H42 -> 0 | J14: =J42-I42 -> 1 | K14: =K42-J42 -> 1 | L14: =L42-K42 -> 1 | M14: 1 | N14: 0 | O14: 0
A15: =Dashboard!A16 -> 3 | B15: =Dashboard!B16 -> MAI-MAHIU- NEW WATER | C15: =Dashboard!C16 -> No. | D15: =D43-'actual 2021-22'!O42 -> 8 | E15: =E43-D43 -> 31 | F15: =F43-E43 -> 110 | G15: =G43-F43 -> 14 | H15: =H43-G43 -> 27 | I15: =I43-H43 -> 5 | J15: =J43-I43 -> 19 | K15: =K43-J43 -> 81 | L15: =L43-K43 -> 114 | M15: 52 | N15: 22 | O15: 24
A16: =Dashboard!A18 -> 0 | B16: =Dashboard!B18 -> TOTAL NEW WATER CONNECTION SOUTHERN REGION | C16: =Dashboard!C18 -> No. | D16: =SUM(D13:D15) -> 14 | E16: =SUM(E13:E15) -> 56 | F16: =SUM(F13:F15) -> 123 | G16: =SUM(G13:G15) -> 44 | H16: =SUM(H13:H15) -> 45 | I16: =SUM(I13:I15) -> 17 | J16: =SUM(J13:J15) -> 30 | K16: =SUM(K13:K15) -> 113 | ... O16: =SUM(O13:O15) -> 48
A17: =Dashboard!A20 -> 1 | B17: =Dashboard!B20 -> KAYOLE- NEW WATER | C17: =Dashboard!C20 -> No. | D17: =D45-'actual 2021-22'!O40 -> 13 | E17: =E45-D45 -> 32 | F17: =F45-E45 -> 12 | G17: =G45-F45 -> 16 | H17: =H45-G45 -> 14 | I17: =I45-H45 -> 9 | J17: =J45-I45 -> 29 | K17: =K45-J45 -> 25 | L17: =L45-K45 -> 57 | M17: 25 | N17: 20 | O17: 25
B18: TOTAL NEW CONNECTIONS WATER | D18: =D17+D16+D12 -> 44 | E18: =E17+E16+E12 -> 115 | F18: =F17+F16+F12 -> 155 | G18: =G17+G16+G12 -> 78 | H18: =H17+H16+H12 -> 80 | I18: =I17+I16+I12 -> 45 | J18: =J17+J16+J12 -> 85 | K18: =K17+K16+K12 -> 163 | ... O18: =O17+O16+O12 -> 113
A19: =Dashboard!A23 -> NEW CONNECTIONS SEWER
A20: =Dashboard!A24 -> 1 | B20: =Dashboard!B24 -> CBD- NEW SEWER | C20: =Dashboard!C24 -> No. | D20: =D47-'actual 2021-22'!O45 -> 1 | E20: =E47-D47 -> 1 | F20: =F47-E47 -> 1 | G20: =G47-F47 -> 2 | H20: =H47-G47 -> 0 | I20: =I47-H47 -> 1 | J20: =J47-I47 -> 0 | K20: =K47-J47 -> 2 | L20: =L47-K47 -> 0 | M20: 1 | N20: 3 | O20: 0
A21: =Dashboard!A25 -> 2 | B21: =Dashboard!B25 -> CCCR- NEW SEWER | C21: =Dashboard!C25 -> No. | D21: =D48-'actual 2021-22'!O46 -> 0 | E21: =E48-D48 -> 0 | F21: =F48-E48 -> 0 | G21: =G48-F48 -> 6 | H21: =H48-G48 -> 0 | I21: =I48-H48 -> 0 | J21: =J48-I48 -> 0 | K21: =K48-J48 -> 0 | L21: =L48-K48 -> 0 | M21: 2 | N21: 0 | O21: 0
A22: =Dashboard!A26 -> 3 | B22: =Dashboard!B26 -> KABATI- NEW SEWER | C22: =Dashboard!C26 -> No. | D22: =D49-'actual 2021-22'!O47 -> 0 | E22: =E49-D49 -> 1 | F22: =F49-E49 -> 2 | G22: =G49-F49 -> 3 | H22: =H49-G49 -> 0 | I22: =I49-H49 -> 0 | J22: =J49-I49 -> 0 | K22: =K49-J49 -> 0 | L22: =L49-K49 -> 2 | M22: 1 | N22: 3 | O22: 0
A23: =Dashboard!A27 -> 4 | B23: =Dashboard!B27 -> SITE- NEW SEWER | C23: =Dashboard!C27 -> No. | D23: =D50-'actual 2021-22'!O48 -> 0 | E23: =E50-D50 -> 0 | F23: =F50-E50 -> 0 | G23: =G50-F50 -> 2 | H23: =H50-G50 -> 2 | I23: =I50-H50 -> 3 | J23: =J50-I50 -> 1 | K23: =K50-J50 -> 6 | L23: =L50-K50 -> 0 | M23: 3 | N23: 1 | O23: 0
A24: =Dashboard!A28 -> 5 | B24: =Dashboard!B28 -> KIHOTO- NEW SEWER | C24: =Dashboard!C28 -> No. | D24: =D51-'actual 2021-22'!O49 -> 0 | E24: =E51-D51 -> 0 | F24: =F51-E51 -> 0 | G24: =G51-F51 -> 0 | H24: =H51-G51 -> 0 | I24: =I51-H51 -> 0 | J24: =J51-I51 -> 0 | K24: =K51-J51 -> 0 | L24: =L51-K51 -> 0 | M24: 0 | N24: 0 | O24: 0
A25: =Dashboard!A29 -> 6 | B25: =Dashboard!B29 -> LAKEVIEW- NEW SEWER | C25: =Dashboard!C29 -> No. | D25: =D52-'actual 2021-22'!O54 -> 1 | E25: =E52-D52 -> 0 | F25: 0 | G25: 1 | H25: 2 | I25: =I52-H52 -> 1 | J25: =J52-I52 -> 0 | K25: =K52-J52 -> 3 | L25: =L52-K52 -> 0 | M25: 1 | N25: 3 | O25: 2
A26: =Dashboard!A31 -> 0 | B26: =Dashboard!B31 -> TOTAL NEW SEWER CONNECTIONS CENTRAL REGION | C26: =Dashboard!C31 -> No. | D26: =SUM(D20:D25) -> 2 | E26: =SUM(E20:E25) -> 2 | F26: =SUM(F20:F25) -> 3 | G26: =SUM(G20:G25) -> 14 | H26: =SUM(H20:H25) -> 4 | I26: =SUM(I20:I25) -> 5 | J26: =SUM(J20:J25) -> 1 | K26: =SUM(K20:K25) -> 11 | ... O26: =SUM(O20:O25) -> 2
A27: =Dashboard!A32 -> 1 | B27: =Dashboard!B32 -> HELLSGATE- NEW SEWER | C27: =Dashboard!C32 -> No. | D27: =D54-'actual 2021-22'!O51 -> 0 | E27: =E54-D54 -> 0 | F27: =F54-E54 -> 0 | G27: =G54-F54 -> 0 | H27: =H54-G54 -> 0 | I27: =I54-H54 -> 0 | J27: =J54-I54 -> 0 | K27: =K54-J54 -> 0 | L27: =L54-K54 -> 0 | M27: 0 | N27: 0
A28: =Dashboard!A33 -> 2 | B28: =Dashboard!B33 -> KAMERE- NEW SEWER | C28: =Dashboard!C33 -> No. | D28: =D55-'actual 2021-22'!O52 -> 0 | E28: =E55-D55 -> 0 | F28: =F55-E55 -> 0 | G28: =G55-F55 -> 0 | H28: =H55-G55 -> 0 | I28: =I55-H55 -> 0 | J28: =J55-I55 -> 0 | K28: =K55-J55 -> 0 | L28: =L55-K55 -> 0 | M28: 0 | N28: 0
A29: =Dashboard!A34 -> 3 | B29: =Dashboard!B34 -> MAI-MAHIU- NEW SEWER | C29: =Dashboard!C34 -> No. | D29: =D56-'actual 2021-22'!O55 -> 0 | E29: =E56-D56 -> 0 | F29: =F56-E56 -> 0 | G29: =G56-F56 -> 0 | H29: =H56-G56 -> 0 | I29: =I56-H56 -> 0 | J29: =J56-I56 -> 0 | K29: =K56-J56 -> 0 | L29: =L56-K56 -> 0 | M29: 0 | N29: 0
A30: =Dashboard!A35 -> 0 | B30: =Dashboard!B35 -> TOTAL NEW S CONNECTION SOUTHERN REGION | C30: =Dashboard!C35 -> No. | D30: =SUM(D27:D29) -> 0 | E30: =SUM(E27:E29) -> 0 | F30: =SUM(F27:F29) -> 0 | G30: =SUM(G27:G29) -> 0 | H30: =SUM(H27:H29) -> 0 | I30: =SUM(I27:I29) -> 0 | J30: =SUM(J27:J29) -> 0 | K30: =SUM(K27:K29) -> 0 | ... O30: =SUM(O27:O29) -> 0
A31: =Dashboard!A37 -> 1 | B31: =Dashboard!B37 -> KAYOLE- NEW SEWER | C31: =Dashboard!C37 -> No. | D31: =D58-'actual 2021-22'!O53 -> 9 | E31: =E58-D58 -> 0 | F31: =F58-E58 -> 1 | G31: =G58-F58 -> 2 | H31: =H58-G58 -> 0 | I31: =I58-H58 -> 0 | J31: =J58-I58 -> 0 | K31: 0 | L31: 0 | M31: 0 | N31: 6 | O31: 6
B32: TOTAL NEW CONNECTIONS -SEWER | D32: =D31+D30+D26 -> 11 | E32: =E31+E30+E26 -> 2 | F32: =F31+F30+F26 -> 4 | G32: =G31+G30+G26 -> 16 | H32: =H31+H30+H26 -> 4 | I32: =I31+I30+I26 -> 5 | J32: =J31+J30+J26 -> 1 | K32: =K31+K30+K26 -> 11 | ... O32: =O31+O30+O26 -> 8
A33: =Dashboard!A38 -> TOTAL CONNECTIONS-WATER
A34: =Dashboard!A39 -> 1 | B34: =Dashboard!B39 -> CBD- WATER | C34: =Dashboard!C39 -> No. | D34: 756 | E34: 756 | F34: 761 | G34: 757 | H34: 760 | I34: 761 | J34: 763 | K34: 766 | L34: 770 | M34: 771 | N34: 774 | O34: 773
A35: =Dashboard!A40 -> 2 | B35: =Dashboard!B40 -> CCCR- WATER | C35: =Dashboard!C40 -> No. | D35: 713 | E35: 719 | F35: 727 | G35: 742 | H35: 747 | I35: 748 | J35: 754 | K35: 759 | L35: 765 | M35: 766 | N35: 765 | O35: 779
A36: =Dashboard!A41 -> 3 | B36: =Dashboard!B41 -> KABATI- WATER | C36: =Dashboard!C41 -> No. | D36: 850 | E36: 860 | F36: 864 | G36: 863 | H36: 865 | I36: 873 | J36: 883 | K36: 888 | L36: 896 | M36: 900 | N36: 904 | O36: 908
A37: =Dashboard!A42 -> 4 | B37: =Dashboard!B42 -> SITE- WATER | C37: =Dashboard!C42 -> No. | D37: 900 | E37: 903 | F37: 904 | G37: 904 | H37: 905 | I37: 905 | J37: 906 | K37: 909 | L37: 911 | M37: 916 | N37: 919 | O37: 921
A38: =Dashboard!A43 -> 5 | B38: =Dashboard!B43 -> KIHOTO- WATER | C38: =Dashboard!C43 -> No. | D38: 192 | E38: 194 | F38: 194 | G38: 194 | H38: 197 | I38: 199 | J38: 200 | K38: 200 | L38: 200 | M38: 202 | N38: 202 | O38: 207
A39: =Dashboard!A44 -> 6 | B39: =Dashboard!B44 -> LAKEVIEW- WATER | C39: =Dashboard!C44 -> No. | D39: 1345 | E39: 1351 | F39: 1353 | G39: 1361 | H39: 1368 | I39: 1375 | J39: 1381 | K39: 1390 | L39: 1400 | M39: 1404 | N39: 1406 | O39: 1413
A40: =Dashboard!A46 -> 0 | B40: =Dashboard!B46 -> TOTALWATER CONNECTION CENTRAL REGION | C40: =Dashboard!C46 -> No. | D40: =SUM(D34:D39) -> 4756 | E40: =SUM(E34:E39) -> 4783 | F40: =SUM(F34:F39) -> 4803 | G40: =SUM(G34:G39) -> 4821 | H40: =SUM(H34:H39) -> 4842 | I40: =SUM(I34:I39) -> 4861 | J40: =SUM(J34:J39) -> 4887 | K40: =SUM(K34:K39) -> 4912 | ... O40: =SUM(O34:O39) -> 5001
A41: =Dashboard!A47 -> 1 | B41: =Dashboard!B47 -> HELLSGATE- WATER | C41: =Dashboard!C47 -> No. | D41: 1384 | E41: 1406 | F41: 1419 | G41: 1448 | H41: 1464 | I41: 1476 | J41: 1486 | K41: 1517 | L41: 1546 | M41: 1564 | N41: 1583 | O41: 1607
...

Sheet Sheet1

Sheet actual 2021-22
A1: =Dashboard!A1 -> SALES & CC DASHBOARD | J1: =J11+J17 -> 51 | K1: =K11+K17 -> 99 | L1: =L11+L17 -> 161 | M1: =M11+M17 -> 103 | N1: =N11+N17 -> 52 | O1: =O11+O17 -> 113
J2: =J24+J30 -> 1 | K2: =K24+K30 -> 1 | L2: =L24+L30 -> 73 | M2: =M24+M30 -> 14 | N2: =N24+N30 -> 1 | O2: =O24+O30 -> 0
B4: MONTH | C4: UNIT | D4: JUL | E4: AUG | F4: SEP | G4: OCT | H4: NOV | I4: DEC | J4: JAN | K4: FEB | L4: MAR | M4: APR | N4: MAY | O4: JUN
A5: =Dashboard!A5 -> NEW CONNECTIONS WATER
